Workbook

Sheet Capex_Summary
B1: LAKESHORE HOSPITAL & RESEARCH CENTRE LIMITED
B2: CAPEX BUDGET FOR THE FY 2026-27 | D2: (Figure in Lakhs )
B5: Asset Category | C5: Asset Sub Category | D5: Amount | E5: Potential Savings | G5: Department | H5: Amount | I5: Potential Savings | K5: Asset Category | L5: Amount | M5: Potential Savings
B6: Asset Category | C6: Asset Sub Category | D6: Sum of Total Cost | E6: (INR) | G6: Row Labels | H6: Sum of Total Cost | I6: (INR) | K6: Row Labels | L6: Sum of Total Cost | M6: (INR)
B7: Buildings | C7: Cutout Strcture | D7: 5200000 | E7: =SUMIF(MIXED_new!D3:D178,"Cutout Strcture",MIXED_new!L3:L178)-SUMIF(MIXED_new!D3:D178,"Cutout Strcture",MIXED_new!AB3:AB178) -> 0 | G7: Admin CEO | H7: 3500000 | I7: =SUMIF(MIXED_new!B3:B178,"Admin CEO",MIXED_new!L3:L178)-SUMIF(MIXED_new!B3:B178,"Admin CEO",MIXED_new!AB3:AB178) -> 0 | K7: Buildings | L7: 183051000 | M7: =SUMIF(MIXED_new!C3:C178,"Buildings",MIXED_new!L3:L178)-SUMIF(MIXED_new!C3:C178,"Buildings",MIXED_new!AB3:AB178) -> 0
C8: DG Platform | D8: 9000000 | E8: =SUMIF(MIXED_new!D3:D178,"DG Platform",MIXED_new!L3:L178)-SUMIF(MIXED_new!D3:D178,"DG Platform",MIXED_new!AB3:AB178) -> 0 | G8: Biochemistry | H8: 6200000 | I8: =SUMIF(MIXED_new!B3:B178,"Biochemistry",MIXED_new!L3:L178)-SUMIF(MIXED_new!B3:B178,"Biochemistry",MIXED_new!AB3:AB178) -> 900000 | K8: Computers & IT Equipment | L8: 43448000 | M8: =SUMIF(MIXED_new!C3:C178,"Computers & IT Equipment",MIXED_new!L3:L178)-SUMIF(MIXED_new!C3:C178,"Computers & IT Equipment",MIXED_new!AB3:AB178) -> 0
C9: Electrical / Mechanical Equipments | D9: 4600000 | E9: =SUMIF(MIXED_new!D3:D178,"Electrical / Mechanical Equipments",MIXED_new!L3:L178)-SUMIF(MIXED_new!D3:D178,"Electrical / Mechanical Equipments",MIXED_new!AB3:AB178) -> 0 | G9: Biomedical | H9: 462305000 | I9: =SUMIF(MIXED_new!B3:B178,"Biomedical",MIXED_new!L3:L178)-SUMIF(MIXED_new!B3:B178,"Biomedical",MIXED_new!AB3:AB178) -> 138385000 | K9: Furniture & Fixtures | L9: 31935200 | M9: =SUMIF(MIXED_new!C3:C178,"Furniture & Fixtures",MIXED_new!L3:L178)-SUMIF(MIXED_new!C3:C178,"Furniture & Fixtures",MIXED_new!AB3:AB178) -> 0
C10: Hospital Building | D10: 142251000 | E10: =SUMIF(MIXED_new!D3:D178,"Hospital Building",MIXED_new!L3:L178)-SUMIF(MIXED_new!D3:D178,"Hospital Building",MIXED_new!AB3:AB178) -> 0 | G10: Clinical Nutrition | H10: 3200000 | I10: =SUMIF(MIXED_new!B3:B178,"Clinical Nutrition",MIXED_new!L3:L178)-SUMIF(MIXED_new!B3:B178,"Clinical Nutrition",MIXED_new!AB3:AB178) -> 0 | K10: Intangible Assets | L10: 5800000 | M10: =SUMIF(MIXED_new!C3:C178,"Intangible Assets",MIXED_new!L3:L178)-SUMIF(MIXED_new!C3:C178,"Intangible Assets",MIXED_new!AB3:AB178) -> 0
C11: Internal Infrastructure | D11: 21500000 | E11: =SUMIF(MIXED_new!D3:D178,"Internal Infrastructure",MIXED_new!L3:L178)-SUMIF(MIXED_new!D3:D178,"Internal Infrastructure",MIXED_new!AB3:AB178) -> 0 | G11: Engeering | H11: 62450000 | I11: =SUMIF(MIXED_new!B3:B178,"Engeering",MIXED_new!L3:L178)-SUMIF(MIXED_new!B3:B178,"Engeering",MIXED_new!AB3:AB178) -> 0 | K11: Office Equipment | L11: 15000 | M11: =SUMIF(MIXED_new!C3:C178,"Office Equipment",MIXED_new!L3:L178)-SUMIF(MIXED_new!C3:C178,"Office Equipment",MIXED_new!AB3:AB178) -> 0
C12: Sanitary & Plumbing Fixtures | D12: 500000 | E12: =SUMIF(MIXED_new!D3:D178,"Sanitary & Plumbing Fixtures",MIXED_new!L3:L178)-SUMIF(MIXED_new!D3:D178,"Sanitary & Plumbing Fixtures",MIXED_new!AB3:AB178) -> 0 | G12: Fire & Safety | H12: 34325000 | I12: =SUMIF(MIXED_new!B3:B178,"Fire & Safety",MIXED_new!L3:L178)-SUMIF(MIXED_new!B3:B178,"Fire & Safety",MIXED_new!AB3:AB178) -> 0 | K12: Plant & Machinery | L12: 551115460 | M12: =SUMIF(MIXED_new!C3:C178,"Plant & Machinery",MIXED_new!L3:L178)-SUMIF(MIXED_new!C3:C178,"Plant & Machinery",MIXED_new!AB3:AB178) -> 144754000
B13: Computers & IT Equipment | C13: CCTV | D13: 525000 | E13: =SUMIF(MIXED_new!D3:D178,"CCTV",MIXED_new!L3:L178)-SUMIF(MIXED_new!D3:D178,"CCTV",MIXED_new!AB3:AB178) -> 0 | G13: Food & Beverage | H13: 3382460 | I13: =SUMIF(MIXED_new!B3:B178,"Food & Beverage",MIXED_new!L3:L178)-SUMIF(MIXED_new!B3:B178,"Food & Beverage",MIXED_new!AB3:AB178) -> 0 | K13: Vehicles | L13: 6700000 | M13: =SUMIF(MIXED_new!C3:C178,"Vehicles",MIXED_new!L3:L178)-SUMIF(MIXED_new!C3:C178,"Vehicles",MIXED_new!AB3:AB178) -> 0
C14: Desktop computers | D14: 6420000 | E14: =SUMIF(MIXED_new!D3:D178,"Desktop computers",MIXED_new!L3:L178)-SUMIF(MIXED_new!D3:D178,"Desktop computers",MIXED_new!AB3:AB178) -> 0 | G14: General Store | H14: 820000 | I14: =SUMIF(MIXED_new!B3:B178,"General Store",MIXED_new!L3:L178)-SUMIF(MIXED_new!B3:B178,"General Store",MIXED_new!AB3:AB178) -> 0 | K14: (blank) | L14: 0 | M14: =(MIXED_new!L179-MIXED_new!AB179)-SUM(M7:M13) -> 0
C15: Digittalization /Automation | D15: 7500000 | E15: =SUMIF(MIXED_new!D3:D178,"Digittalization /Automation",MIXED_new!L3:L178)-SUMIF(MIXED_new!D3:D178,"Digittalization /Automation",MIXED_new!AB3:AB178) -> 0 | G15: Hematology | H15: 8000000 | I15: =SUMIF(MIXED_new!B3:B178,"Hematology",MIXED_new!L3:L178)-SUMIF(MIXED_new!B3:B178,"Hematology",MIXED_new!AB3:AB178) -> 0 | K15: Grand Total | L15: 822064660 | M15: =MIXED_new!L179-MIXED_new!AB179 -> 144754000
C16: Laptops | D16: 1500000 | E16: =SUMIF(MIXED_new!D3:D178,"Laptops",MIXED_new!L3:L178)-SUMIF(MIXED_new!D3:D178,"Laptops",MIXED_new!AB3:AB178) -> 0 | G16: Histopathology | H16: 3600000 | I16: =SUMIF(MIXED_new!B3:B178,"Histopathology",MIXED_new!L3:L178)-SUMIF(MIXED_new!B3:B178,"Histopathology",MIXED_new!AB3:AB178) -> 0
C17: Networking equipment | D17: 25500000 | E17: =SUMIF(MIXED_new!D3:D178,"Networking equipment",MIXED_new!L3:L178)-SUMIF(MIXED_new!D3:D178,"Networking equipment",MIXED_new!AB3:AB178) -> 0 | G17: House Keeping | H17: 1524000 | I17: =SUMIF(MIXED_new!B3:B178,"House Keeping",MIXED_new!L3:L178)-SUMIF(MIXED_new!B3:B178,"House Keeping",MIXED_new!AB3:AB178) -> 0
C18: Other Items | D18: 500000 | E18: =SUMIF(MIXED_new!D3:D178,"Other Items",MIXED_new!L3:L178)-SUMIF(MIXED_new!D3:D178,"Other Items",MIXED_new!AB3:AB178) -> 0 | G18: HRD | H18: 208000 | I18: =SUMIF(MIXED_new!B3:B178,"HRD",MIXED_new!L3:L178)-SUMIF(MIXED_new!B3:B178,"HRD",MIXED_new!AB3:AB178) -> 0
C19: Printers, scanners | D19: 1503000 | E19: =SUMIF(MIXED_new!D3:D178,"Printers, scanners",MIXED_new!L3:L178)-SUMIF(MIXED_new!D3:D178,"Printers, scanners",MIXED_new!AB3:AB178) -> 0 | G19: IT | H19: 47500000 | I19: =SUMIF(MIXED_new!B3:B178,"IT",MIXED_new!L3:L178)-SUMIF(MIXED_new!B3:B178,"IT",MIXED_new!AB3:AB178) -> 0
B20: Furniture & Fixtures | C20: Chairs, tables, cupboards | D20: 1020000 | E20: =SUMIF(MIXED_new!D3:D178,"Chairs, tables, cupboards",MIXED_new!L3:L178)-SUMIF(MIXED_new!D3:D178,"Chairs, tables, cupboards",MIXED_new!AB3:AB178) -> 0 | G20: Pharmacy | H20: 2162200 | I20: =SUMIF(MIXED_new!B3:B178,"Pharmacy",MIXED_new!L3:L178)-SUMIF(MIXED_new!B3:B178,"Pharmacy",MIXED_new!AB3:AB178) -> 0
C21: Curtains, blinds | D21: 27804000 | E21: =SUMIF(MIXED_new!D3:D178,"Curtains, blinds",MIXED_new!L3:L178)-SUMIF(MIXED_new!D3:D178,"Curtains, blinds",MIXED_new!AB3:AB178) -> 0 | G21: PHYSIOTHERAPY | H21: 10938000 | I21: =SUMIF(MIXED_new!B3:B178,"*physiotherapy*",MIXED_new!L3:L178)-SUMIF(MIXED_new!B3:B178,"*physiotherapy*",MIXED_new!AB3:AB178) -> 5469000
C22: Office furniture | D22: 105000 | E22: =SUMIF(MIXED_new!D3:D178,"Office furniture",MIXED_new!L3:L178)-SUMIF(MIXED_new!D3:D178,"Office furniture",MIXED_new!AB3:AB178) -> 0 | G22: Project | H22: 171950000 | I22: =SUMIF(MIXED_new!B3:B178,"Project",MIXED_new!L3:L178)-SUMIF(MIXED_new!B3:B178,"Project",MIXED_new!AB3:AB178) -> 0
C23: Storage Cabinet / Pharmacy Furniture | D23: 1506200 | E23: =SUMIF(MIXED_new!D3:D178,"Storage Cabinet / Pharmacy Furniture",MIXED_new!L3:L178)-SUMIF(MIXED_new!D3:D178,"Storage Cabinet / Pharmacy Furniture",MIXED_new!AB3:AB178) -> 0 | G23: (blank) | H23: 0 | I23: =(MIXED_new!L179-MIXED_new!AB179)-SUM(I7:I22) -> 0
C24: Lab Furniutre | D24: 1500000 | E24: =SUMIF(MIXED_new!D3:D178,"Lab Furniutre",MIXED_new!L3:L178)-SUMIF(MIXED_new!D3:D178,"Lab Furniutre",MIXED_new!AB3:AB178) -> 0 | G24: Grand Total | H24: 822064660 | I24: =MIXED_new!L179-MIXED_new!AB179 -> 144754000
B25: Intangible Assets | C25: Computer software | D25: 5800000 | E25: =SUMIF(MIXED_new!D3:D178,"Computer software",MIXED_new!L3:L178)-SUMIF(MIXED_new!D3:D178,"Computer software",MIXED_new!AB3:AB178) -> 0
B26: Office Equipment | C26: Telephones & EPABX systems | D26: 15000 | E26: =SUMIF(MIXED_new!D3:D178,"Telephones & EPABX systems",MIXED_new!L3:L178)-SUMIF(MIXED_new!D3:D178,"Telephones & EPABX systems",MIXED_new!AB3:AB178) -> 0
B27: Plant & Machinery | C27: Biomedical Equipment | D27: 491943000 | E27: =SUMIF(MIXED_new!D3:D178,"Biomedical Equipment",MIXED_new!L3:L178)-SUMIF(MIXED_new!D3:D178,"Biomedical Equipment",MIXED_new!AB3:AB178) -> 144754000
C28: Electrical / Mechanical Equipments | D28: 46050000 | E28: =SUMIF(MIXED_new!D3:D178,"Electrical / Mechanical Equipments",MIXED_new!L3:L178)-SUMIF(MIXED_new!D3:D178,"Electrical / Mechanical Equipments",MIXED_new!AB3:AB178) -> 0
C29: Electrical Equipments | D29: 700000 | E29: =SUMIF(MIXED_new!D3:D178,"Electrical Equipments",MIXED_new!L3:L178)-SUMIF(MIXED_new!D3:D178,"Electrical Equipments",MIXED_new!AB3:AB178) -> 0
C30: Electrical installations | D30: 3000000 | E30: =SUMIF(MIXED_new!D3:D178,"Electrical installations",MIXED_new!L3:L178)-SUMIF(MIXED_new!D3:D178,"Electrical installations",MIXED_new!AB3:AB178) -> 0
C31: Kitchen / Service Equipment | D31: 2786400 | E31: =SUMIF(MIXED_new!D3:D178,"Kitchen / Service Equipment",MIXED_new!L3:L178)-SUMIF(MIXED_new!D3:D178,"Kitchen / Service Equipment",MIXED_new!AB3:AB178) -> 0
C32: Kitchen utensils | D32: 596060 | E32: =SUMIF(MIXED_new!D3:D178,"Kitchen utensils",MIXED_new!L3:L178)-SUMIF(MIXED_new!D3:D178,"Kitchen utensils",MIXED_new!AB3:AB178) -> 0
C33: Palnt | D33: 5400000 | E33: =SUMIF(MIXED_new!D3:D178,"Palnt",MIXED_new!L3:L178)-SUMIF(MIXED_new!D3:D178,"Palnt",MIXED_new!AB3:AB178) -> 0
C34: Refrigeration Equipment | D34: 640000 | E34: =SUMIF(MIXED_new!D3:D178,"Refrigeration Equipment",MIXED_new!L3:L178)-SUMIF(MIXED_new!D3:D178,"Refrigeration Equipment",MIXED_new!AB3:AB178) -> 0
B35: Vehicles | C35: Ambulances | D35: 3200000 | E35: =SUMIF(MIXED_new!D3:D178,"Ambulances",MIXED_new!L3:L178)-SUMIF(MIXED_new!D3:D178,"Ambulances",MIXED_new!AB3:AB178) -> 0
C36: Passenger | D36: 3500000 | E36: =SUMIF(MIXED_new!D3:D178,"Passenger",MIXED_new!L3:L178)-SUMIF(MIXED_new!D3:D178,"Passenger",MIXED_new!AB3:AB178) -> 0
B37: (blank) | C37: (blank) | D37: 0 | E37: =(MIXED_new!L179-MIXED_new!AB179)-SUM(E7:E36) -> 0
B38: Grand Total | D38: 822064660 | E38: =MIXED_new!L179-MIXED_new!AB179 -> 144754000
B41: ITEMS REDUCED OR REMOVED FROM CAPEX BUDGET — FY 2026-27
B43: SL No | C43: Department | D43: Item Description | E43: Qty | F43: Original Budget (INR) | G43: Final Cost (INR) | H43: Savings (INR) | I43: Type | J43: Status / Notes
B44: 61 | C44: Biomedical | D44: Uretero reno fiber Scope | E44: 4 → 1 | F44: 1600000 | G44: 400000 | H44: 1200000 | I44: Reduced | J44: Approved — Qty reduced
B45: 63 | C45: Biomedical | D45: Dental chair | E45: 4 → 2 | F45: 1600000 | G45: 800000 | H45: 800000 | I45: Reduced | J45: Approved — Qty reduced
...

Sheet Capex_Details
B1: LAKESHORE HOSPITAL & RESEARCH CENTRE LIMITED
B2: CAPEX REQUIREMENT FOR THE FY 2026-27
B3: SL.No | C3: Department | D3: Asset Category | E3: Asset Sub Category | F3: Project Description /Item Name | G3: QTY | H3: Category of CAPEX | I3: Location/ Area of Implementation | J3: Estimated Cost (INR) | K3: XX | L3: XX | M3: Total Cost | N3: Source of Pricing Information | O3: Proposed Timeline for Investment | P3: XX | Q3: Month (Put to Use) | R3: Purpose of the Investment | S3: Impact of Non-Investment | T3: Specifications/Features Required | U3: Maintenance/ Operational Costs | V3: Justification
J4: Equipment Cost | K4: Installation Cost | L4: Other Costs (Specify) | M4: Total | O4: Start Date | P4: End Date
B5: =B4+1 -> 1 | C5: Project | D5: Buildings | E5: Hospital Building | F5: Casualty | G5: 1 | H5: Renovation | I5: Main block G.F. | J5: 38000000 | K5: 0 | L5: 0 | M5: =SUM(J5:L5) -> 38000000 | N5: Inviting tender | O5: 46204 | P5: 46356 | Q5: November | R5: Facility improvement. | S5: Patient capacity enhancing.
B6: =B5+1 -> 2 | C6: Project | D6: Buildings | E6: Hospital Building | F6: ICU Complex | G6: 1 | H6: Renovation | I6: 1st Floor Main Block | J6: 22500000 | K6: 0 | L6: 0 | M6: =SUM(J6:L6) -> 22500000 | N6: Work awarded | O6: 45981 | P6: 46132 | Q6: April | R6: Combine ICUs in one area. | S6: For reducing staff & electrical Consumption | U6: 200000 | V6: Existing ICU space utilise for another purpose
B7: =B6+1 -> 3 | C7: Project | D7: Buildings | E7: Hospital Building | F7: Regularization purpose (fee) | G7: 1 | H7: Other | I7: Main block | J7: 16400000 | K7: 0 | L7: 0 | M7: =SUM(J7:L7) -> 16400000 | N7: Government Fee & Consultant | O7: 46183 | P7: 46203 | Q7: June | R7: Legal Purpose | V7: Statutory Purpose
B8: =B7+1 -> 4 | C8: Project | D8: Buildings | E8: Hospital Building | F8: Ultrasound & Ortho Dept. Renovation | G8: 1 | H8: Renovation | I8: Main block G.F. | J8: 16000000 | K8: 0 | L8: 0 | M8: =SUM(J8:L8) -> 16000000 | N8: Inviting tender | O8: 46042 | P8: 46162 | Q8: May | R8: More space for smooth opeartion | S8: Patient statisfaction
B9: =B8+1 -> 5 | C9: Project | D9: Buildings | E9: Hospital Building | F9: Renal kidney transplant centre | G9: 1 | H9: Renovation | I9: Main block - 1st floor | J9: 15000000 | K9: 0 | L9: 0 | M9: =SUM(J9:L9) -> 15000000 | N9: Inviting tender | O9: 46208 | P9: 46314 | Q9: October | R9: Combine Rental transplant ICU 1 & 2 one area. | S9: For reducing staff & ele. Consumption reducing.
B10: =B9+1 -> 6 | C10: Project | D10: Buildings | E10: Hospital Building | F10: Paediatric OP construction works | G10: 1 | H10: Renovation | I10: Main block 2nd floor | J10: 15000000 | K10: 0 | L10: 0 | M10: =SUM(J10:L10) -> 15000000 | N10: Inviting tender | O10: 46157 | P10: 46275 | Q10: September | R10: Patient friendly.
B11: =B10+1 -> 7 | C11: Project | D11: Buildings | E11: Internal Infrastructure | F11: Porch & Front area | G11: 1 | H11: Renovation | I11: Main block | J11: 14000000 | K11: 0 | L11: 0 | M11: =SUM(J11:L11) -> 14000000 | N11: Inviting tender | O11: 46091 | P11: 46152 | Q11: May | R11: Beautifications & Smooth traffic | S11: Patient friendly | U11: 50000
B12: =B11+1 -> 8 | C12: Project | D12: Buildings | E12: DG Platform | F12: DG overhead platform strengthening & RECD fixing works | G12: 3 | H12: New requirment | I12: Electrical area (DG) | J12: 9000000 | K12: 0 | L12: 0 | M12: =SUM(J12:L12) -> 9000000 | N12: Inviting tender | O12: 46111 | P12: 46157 | Q12: May | R12: Pollution control board rules. | S12: Statutory government rule. | U12: 50000 | V12: Based on pollution control board order.
B13: =B12+1 -> 9 | C13: Engeering | D13: Plant & Machinery | E13: Palnt | F13: STP renovation | G13: 1 | H13: Renovation | I13: Main block | J13: 3700000 | K13: 0 | L13: 0 | M13: =SUM(J13:L13) -> 3700000 | N13: Inviting tender | O13: 46042 | P13: 46091 | Q13: April | R13: PCB related | S13: Environmental Friendly.
B14: =B13+1 -> 10 | C14: Engeering | D14: Plant & Machinery | E14: Palnt | F14: UF Replacement | G14: 1 | H14: Replacement | I14: Main block | J14: 800000 | K14: 0 | L14: 0 | M14: =SUM(J14:L14) -> 800000 | N14: Inviting tender | O14: 46063 | P14: 46101 | Q14: April | R14: Treated water reusage | S14: Water for Gardening purpose.
B15: =B14+1 -> 11 | C15: Engeering | D15: Plant & Machinery | E15: Palnt | F15: Domestic Line hot water and flush line | G15: 1 | H15: Replacement | I15: Main block | J15: 900000 | K15: 0 | L15: 0 | M15: =SUM(J15:L15) -> 900000 | N15: Inviting tender | O15: 46126 | P15: 46252 | Q15: August | R15: Prevent water leak | S15: Water saving.
B16: =B15+1 -> 12 | C16: Project | D16: Buildings | E16: Hospital Building | F16: Architectural & PMC Fees | J16: 7000000 | K16: 0 | L16: 0 | M16: =SUM(J16:L16) -> 7000000 | N16: Inviting tender | Q16: September | R16: Renovation purpose
B17: =B16+1 -> 13 | C17: Project | D17: Buildings | E17: Hospital Building | F17: Main block rooms renovation & delux room renovation | G17: 104 | H17: Renovation | I17: Main block | J17: 5000000 | K17: 0 | L17: 0 | M17: =SUM(J17:L17) -> 5000000 | N17: Inviting tender | O17: 46023 | P17: 46387 | Q17: December | R17: Beautifications
B18: =B17+1 -> 14 | C18: Project | D18: Buildings | E18: Internal Infrastructure | F18: Road & walkway beautification works | G18: 1 | H18: Renovation | I18: Arch gate to 4th gate & casualty | J18: 4000000 | K18: 0 | L18: 0 | M18: =SUM(J18:L18) -> 4000000 | N18: Inviting tender | O18: 46058 | P18: 46122 | Q18: April | R18: Beautifications | S18: Smooth travelling | U18: 50000
B19: =B18+1 -> 15 | C19: Project | D19: Buildings | E19: Cutout Strcture | F19: Central Cutout renovation work | G19: 1 | H19: Renovation | I19: Main block G.F. | J19: 3400000 | K19: 0 | L19: 0 | M19: =SUM(J19:L19) -> 3400000 | N19: Inviting tender | O19: 45698 | P19: 45805 | Q19: May | R19: Stoppage of water sepage & fungus reducing | S19: Beautifications | U19: 50000
B20: =B19+1 -> 16 | C20: Project | D20: Buildings | E20: Cutout Strcture | F20: Exterior Painting - Main block | G20: 1 | H20: Maintenace | I20: Main block | J20: 1800000 | K20: 0 | L20: 0 | M20: =SUM(J20:L20) -> 1800000 | N20: Inviting tender | O20: 46122 | P20: 46157 | Q20: May | R20: Beautifications | S20: Clealiness
B21: =B20+1 -> 17 | C21: Project | D21: Buildings | E21: Hospital Building | F21: Cold room | G21: 1 | H21: Replacement | I21: Main block 2nd floor | J21: 1500000 | K21: 0 | L21: 0 | M21: =SUM(J21:L21) -> 1500000 | N21: Inviting tender | O21: 46085 | P21: 46110 | Q21: April | R21: Based on the request from Pharmacy
B22: =B21+1 -> 18 | C22: Engeering | D22: Plant & Machinery | E22: Electrical / Mechanical Equipments | F22: Multi Level Parking | G22: 1 | H22: New requirment | I22: Parking Area | J22: 44100000 | K22: 0 | L22: 0 | M22: =SUM(J22:L22) -> 44100000 | N22: Inviting tender | O22: 46023 | P22: 46188 | Q22: June | R22: Facility improvement.
B23: =B22+1 -> 19 | C23: Engeering | D23: Plant & Machinery | E23: Electrical / Mechanical Equipments | F23: Coil, Electrical, Water, Soil testing etc. | G23: 1 | H23: New requirment | I23: Parking Area | J23: 750000 | K23: 0 | L23: 0 | M23: =SUM(J23:L23) -> 750000 | N23: Inviting tender | O23: 46023 | P23: 46042 | Q23: April | R23: Facility improvement.
B24: =B23+1 -> 20 | C24: Engeering | D24: Buildings | E24: Internal Infrastructure | F24: Parking area leveling & inter lock laying | G24: 1 | H24: New requirment | I24: Parking Area | J24: 3500000 | K24: 0 | L24: 0 | M24: =SUM(J24:L24) -> 3500000 | N24: Inviting tender | O24: 46183 | P24: 46223 | Q24: April | R24: Facility improvement.
B25: =B24+1 -> 21 | C25: Project | D25: Buildings | E25: Hospital Building | F25: 8th floor Premium suite renovation | G25: 1 | H25: Renovation | I25: Main block | J25: 1200000 | K25: 0 | L25: 0 | M25: =SUM(J25:L25) -> 1200000 | N25: Inviting tender | O25: 46019 | P25: 46050 | Q25: April | R25: Beautifications
B26: =B25+1 -> 22 | C26: Project | D26: Buildings | E26: Hospital Building | F26: Fire Escape & support painting | G26: 1 | H26: Maintenace | I26: Main block | J26: 900000 | K26: 0 | L26: 0 | M26: =SUM(J26:L26) -> 900000 | N26: Inviting tender | O26: 46037 | P26: 46122 | Q26: April | R26: Prevent corrosion | S26: More life.
B27: =B26+1 -> 23 | C27: Engeering | D27: Buildings | E27: Electrical / Mechanical Equipments | F27: Lowside (New block) BMS activation | G27: 1 | H27: Maintenace | I27: New block | J27: 2000000 | K27: 0 | L27: 0 | M27: =SUM(J27:L27) -> 2000000 | N27: Inviting tender | O27: 46117 | P27: 46171 | Q27: May | R27: Centralizing HVAC controle optimizing building performance.
B28: =B27+1 -> 24 | C28: Engeering | D28: Buildings | E28: Electrical / Mechanical Equipments | F28: AHU coil replacement | G28: 4 | H28: Maintenace | I28: All Blocks | J28: 1000000 | K28: 0 | L28: 0 | M28: =SUM(J28:L28) -> 1000000 | N28: Inviting tender | O28: 46055 | P28: 46127 | Q28: April | R28: HVAC performance improving
B29: =B28+1 -> 25 | C29: Engeering | D29: Buildings | E29: Electrical / Mechanical Equipments | F29: AHU unit replacement | G29: 5 | H29: Maintenace | I29: All Blocks | J29: 1000000 | K29: 0 | L29: 0 | M29: =SUM(J29:L29) -> 1000000 | N29: Inviting tender | O29: 46055 | P29: 46127 | Q29: April | R29: HVAC performance improving
B30: =B29+1 -> 26 | C30: Engeering | D30: Buildings | E30: Hospital Building | F30: Chilled water line replacement (Plastic Surgery, NSICU, OT Recovery) 1 1/2" pipe | G30: 1 | H30: Replacement | I30: All Blocks | J30: 2000000 | K30: 0 | L30: 0 | M30: =SUM(J30:L30) -> 2000000 | N30: Inviting tender | O30: 46054 | P30: 46080 | Q30: April | R30: Performance improving
B31: =B30+1 -> 27 | C31: Engeering | D31: Buildings | E31: Hospital Building | F31: Cooling Tower valve replacement | G31: 1 | H31: Replacement | I31: All Blocks | J31: 500000 | K31: 0 | L31: 0 | M31: =SUM(J31:L31) -> 500000 | N31: Inviting tender | O31: 46082 | P31: 46111 | Q31: April | R31: Performance improving
B32: =B31+1 -> 28 | C32: Engeering | D32: Buildings | E32: Electrical / Mechanical Equipments | F32: HRW recovery wheel replacement | G32: 1 | H32: Replacement | I32: All Blocks | J32: 200000 | K32: 0 | L32: 0 | M32: =SUM(J32:L32) -> 200000 | N32: Inviting tender | O32: 46023 | P32: 46052 | Q32: April | R32: Performance improving
B33: =B32+1 -> 29 | C33: Engeering | D33: Plant & Machinery | E33: Electrical / Mechanical Equipments | F33: Split AC replacement (call centre, drivers cabin, 635, 636 doctor's resting area, Biochemistry) | G33: 1 | H33: Replacement | I33: Main Block | J33: 300000 | K33: 0 | L33: 0 | M33: =SUM(J33:L33) -> 300000 | N33: Inviting tender | O33: 46023 | P33: 46052 | Q33: April | R33: Performance improving
B34: =B33+1 -> 30 | C34: Engeering | D34: Plant & Machinery | E34: Electrical / Mechanical Equipments | F34: 5 TR , 1 Tower AC Spare | G34: 2 | H34: Replacement/Spare | I34: All Blocks | J34: 400000 | K34: 0 | L34: 0 | M34: =SUM(J34:L34) -> 400000 | N34: Inviting tender | O34: 46082 | P34: 45746 | Q34: April | R34: Performance improving
B35: =B34+1 -> 31 | C35: Engeering | D35: Buildings | E35: Hospital Building | F35: Main Lobby Glass fixing | G35: 1 | H35: Maintenace | I35: Main block | J35: 400000 | K35: 0 | L35: 0 | M35: =SUM(J35:L35) -> 400000 | N35: Inviting tender | O35: 46082 | P35: 46111 | Q35: April | R35: HVAC performance
B36: =B35+1 -> 32 | C36: Engeering | D36: Plant & Machinery | E36: Electrical / Mechanical Equipments | F36: Robotic duct cleaning in OT passage | G36: 1 | H36: Maintenace | I36: Main block | J36: 400000 | K36: 0 | L36: 0 | M36: =SUM(J36:L36) -> 400000 | N36: Inviting tender | O36: 46058 | P36: 46080 | Q36: April | R36: Dust removal
B37: =B36+1 -> 33 | C37: Engeering | D37: Plant & Machinery | E37: Electrical / Mechanical Equipments | F37: Microfilter & pre filter changing in OT | G37: 1 | H37: Maintenace | I37: Main block | J37: 100000 | K37: 0 | L37: 0 | M37: =SUM(J37:L37) -> 100000 | N37: Inviting tender | O37: 46026 | P37: 46050 | Q37: April | R37: Mandatory requirement
B38: =B37+1 -> 34 | C38: Engeering | D38: Plant & Machinery | E38: Electrical Equipments | F38: Pharmacy Vaccine Refrigerator | G38: 1 | H38: Replacement | I38: All Blocks | J38: 200000 | K38: 0 | L38: 0 | M38: =SUM(J38:L38) -> 200000 | N38: Inviting tender | O38: 46085 | P38: 46110 | Q38: April | R38: Based on the request from Pharmacy
B39: =B38+1 -> 35 | C39: Engeering | D39: Plant & Machinery | E39: Electrical Equipments | F39: Pharmacy Refrigerator | G39: 2 | H39: Replacement | I39: All Blocks | J39: 200000 | K39: 0 | L39: 0 | M39: =SUM(J39:L39) -> 200000 | N39: Inviting tender | O39: 46085 | P39: 46110 | Q39: April | R39: Based on the request from Pharmacy
B40: =B39+1 -> 36 | C40: Project | D40: Buildings | E40: Sanitary & Plumbing Fixtures | F40: Flush with cistern fixing | G40: 40 | H40: Maintenace | I40: New block - various rooms | J40: 500000 | K40: 0 | L40: 0 | M40: =SUM(J40:L40) -> 500000 | N40: Purchasing | O40: 46047 | P40: 46096 | Q40: April | R40: Unavailiability parts (schell brand fittings) | S40: Smooth Operations
...

Sheet MIXED_new
A1: SL. No | B1: Department | C1: Asset Category | D1: Asset Sub Category | E1: Project Description /Item Name | F1: QTY | G1: Category of CAPEX | H1: Location/ Area of Implementation | I1: Estimated Cost (INR) | J1: XX | K1: XX | L1: Total Cost | M1: Source of Pricing Information | N1: Proposed Timeline for Investment | O1: XX | P1: Month (Put to Use) | Q1: Purpose of the Investment | R1: Impact of Non-Investment | S1: Specifications/Features Required | T1: Maintenance/ Operational Costs | U1: Commersial Justification | V1: new or replacements | W1: requested by | X1: curent utilization | Y1: infra structrue | Z1: Approved total quantity | AA1: Quantity to be purchased | AB1: Final cost | AC1: Notes
I2: Equipment Cost | J2: Installation Cost | K2: Other Costs (Specify) | L2: Total | N2: Start Date | O2: End Date
A3: 1 | B3: Biomedical | C3: Plant & Machinery | D3: Biomedical Equipment | E3: Electric bed | F3: 50 | H3: Various department | I3: 150000000 | L3: 7500000 | N3: March | P3: March | Q3: Replacement for the old 76 manual cot for twin sharing rooms as well as executive rooms | R3: For patient comfort and marketing tool | U3: Replacement | V3: Replacements of old cot | W3: Facility Manager | Y3: Nil | AC3: Waiting for operation team reply
A4: 2 | B4: Biomedical | C4: Plant & Machinery | D4: Biomedical Equipment | E4: Digital X Ray | F4: 2 | H4: Radiology | I4: 20000000 | L4: 40000000 | N4: August | P4: August | Q4: Replacement for old machine which was installed in 2002 and 2009 | R4: Advanced technology and reduce the procedure time | T4: After warranty CMC will come | U4: More than 10 years of usage,achieved its life. | V4: Replacements of old machine | W4: Dr Thara | X4: Average of 180 Cases/day (Lowest billing cost 330 rs ) | Y4: Present infracture is accurate | Z4: 2 | AA4: 2 | AB4: 40000000 | AC4: Approved
A5: 3 | B5: Biomedical | C5: Plant & Machinery | D5: Biomedical Equipment | E5: Digital Pathology | F5: 1 | H5: Pathology | I5: 30000000 | L5: 30000000 | N5: November | P5: November | Q5: New requirement | R5: Generate additional income & marketing tool | T5: After warranty CMC will come | U5: New requirement | V5: New requirement | W5: Dr HR,Dr Roy,Dr Chithrathara,Dr Moni | X5: 50 Cases/ month | Y5: Nil | AC5: Hold ,need to discuss with Dr
A6: 4 | B6: Biomedical | C6: Plant & Machinery | D6: Biomedical Equipment | E6: Heart Lung Machine | F6: 1 | H6: Cardiac OT | I6: 25000000 | L6: 25000000 | N6: January | P6: January | Q6: Replacement for old machine installed in 2006 | R6: Supportive for cardiac thoraic surgery | T6: After warranty CMC will come | V6: Replacements of old machine | W6: Dr Sujith,Dr Anand | X6: 5 Cases/month | Y6: Nil | Z6: 1 | AA6: 1 | AB6: 25000000 | AC6: Approved
A7: 5 | B7: Biomedical | C7: Plant & Machinery | D7: Biomedical Equipment | E7: Ventilator(Pead +Adult) | F7: 10 | H7: MDICU | I7: 2250000 | L7: 22500000 | N7: November | P7: November | Q7: Replacement for old machine more than 15 yrs | R7: Patient comfort | T7: After warranty CMC will come | U7: Replacement | V7: Replacements of old machine | W7: Dr Nita | X7: 12-15 Machines/Day | Y7: Nil | Z7: 6+4 | AA7: 10 | AB7: 22500000 | AC7: Approved
A8: 6 | B8: Biomedical | C8: Plant & Machinery | D8: Biomedical Equipment | E8: Digital Slide Scaner | F8: 1 | H8: Histopathology | I8: 25000000 | L8: 25000000 | N8: April | P8: April | Q8: New requirement | R8: Implement advanced technology | T8: After warranty CMC will come | U8: New requirement | V8: New Requirment | W8: Dr. Pushpa | X8: Nil | Y8: Nil | AC8: ON HOLD
A9: 7 | B9: Biomedical | C9: Plant & Machinery | D9: Biomedical Equipment | E9: C -Arm | F9: 1 | H9: Radiology | I9: 20000000 | L9: 20000000 | N9: October | P9: October | Q9: Replacement of old machine more than 10yrs old | R9: Latest technology | T9: After warranty CMC will come | U9: Replacement | V9: Replacements of old machine | W9: Dr Thara | X9: 5 Cases/Day | Z9: 1 | AA9: 1 | AB9: 20000000 | AC9: Approved
A10: 8 | B10: Biomedical | C10: Plant & Machinery | D10: Biomedical Equipment | E10: XI system | F10: 1 | H10: Gastroenterology | I10: 18000000 | L10: 18000000 | N10: September | P10: September | Q10: Replacement for old system | R10: Generate additional income and latest technology | T10: After warranty CMC will come | U10: Replacement | V10: Replacements of old machine | W10: Dr Roy | X10: 25 Cases/Day with 3system Endoscopy 3000/- Colono 9000/- | Y10: Nil | Z10: 1 | AA10: 1 | AB10: 18000000 | AC10: Approved
A11: 9 | B11: Biomedical | C11: Plant & Machinery | D11: Biomedical Equipment | E11: LASER | F11: 1 | H11: Dermatology OPD | I11: 15000000 | L11: 15000000 | N11: May | P11: May | Q11: New technology for laser procedures and treatments | R11: To generate additional income | T11: After warranty CMC will come | U11: New requirment | V11: New requirement | W11: Dr. Abin Abraham Itty | X11: Approx of 10 cases per day (Per patient 10000/ sitting) | Y11: Required | AC11: Checked with vendor for lease bases
A12: 10 | B12: Biomedical | C12: Plant & Machinery | D12: Biomedical Equipment | E12: Surgical Microscope | F12: 1 | H12: Main OT | I12: 10000000 | L12: 10000000 | N12: March | P12: March | Q12: Replacement for old machine installed in 2002 | R12: Latest technology | T12: After warranty CMC will come | U12: Morethan 10 years of usage | V12: Replacement | W12: ENT,Head & Neck,Plastic Surgery | Y12: Nil | Z12: 1 | AA12: 1 | AB12: 10000000 | AC12: Approved
A13: 11 | B13: Biomedical | C13: Plant & Machinery | D13: Biomedical Equipment | E13: Neuro monitoring system | F13: 1 | H13: Neuro OT | I13: 10000000 | L13: 10000000 | N13: April | P13: April | Q13: Replacement for old machine, end of life declared No service support available | T13: After warranty CMC will come | U13: Replacement | V13: Replacement | W13: Dr, SK | X13: 6 Cases/Month 18000/- avg billing | Y13: Nil | Z13: 1 | AA13: 1 | AB13: 10000000 | AC13: Approved
A14: 12 | B14: Biomedical | C14: Plant & Machinery | D14: Biomedical Equipment | E14: PET scan upgradation | F14: 1 | H14: Nuclear medicine | I14: 10000000 | L14: 10000000 | N14: October | P14: October | Q14: Replacement of old machine end of life declared | R14: To generate additional income and latest technology | T14: After warranty CMC will come | U14: Upgrade | V14: Upgrade | W14: Dr Senthil | Y14: Nil | Z14: 1 | AA14: 1 | AB14: 10000000 | AC14: Approved
A15: 13 | B15: Biomedical | C15: Plant & Machinery | D15: Biomedical Equipment | E15: Anesthesia machine | F15: 3 | H15: Main OT | I15: 3000000 | L15: 9000000 | N15: September | P15: September | Q15: Replacement of old machine more than 10yrs old | T15: After warranty CMC will come | U15: Morethan 10 years of usage | V15: Replacement | W15: Dr Mallie | X15: Avargae 22 Cases/Day | Y15: Nil | Z15: 3 | AA15: 3 | AB15: 9000000 | AC15: Approved
A16: 14 | B16: Biomedical | C16: Plant & Machinery | D16: Biomedical Equipment | E16: Monitor | F16: 40 | H16: All ICU,HDU,Ambulance | I16: 600000 | L16: 24000000 | N16: November | P16: November | Q16: Additional ICU bed creating | R16: Additional income generating | U16: New Requirement | V16: New requirement | W16: Dr. Nita | X16: Nil | Y16: Nil | Z16: 40 | AA16: 40 | AB16: 24000000 | AC16: Approved
A17: 15 | B17: Biomedical | C17: Plant & Machinery | D17: Biomedical Equipment | E17: Thulium Laser | F17: 1 | H17: Main OT | I17: 7500000 | L17: 7500000 | N17: November | P17: November | Q17: Additional requirement | R17: Additional income generating | T17: After warranty CMC will come | U17: Additional Requirement | V17: Additional Requirement | W17: Dr Datson | X17: 40 Cases/Month | Y17: Nil | Z17: 1 | AA17: 1 | AB17: 7500000 | AC17: Approved with buyback option
A18: 16 | B18: Biomedical | C18: Plant & Machinery | D18: Biomedical Equipment | E18: Pendent | F18: 15 | H18: MDICU | I18: 500000 | L18: 7500000 | N18: March | P18: March | Q18: New reqirement for new ICU | R18: Latest technology | U18: New requirement | V18: New requirement | W18: Dr Nita | X18: Nil | Y18: Nil | Z18: 15 | AA18: 15 | AB18: 7500000 | AC18: Approved
A19: 17 | B19: Biomedical | C19: Plant & Machinery | D19: Biomedical Equipment | E19: Portable ECHO | F19: 2 | H19: Cardiology OP | I19: 3500000 | L19: 7000000 | N19: April | P19: April | Q19: Replacement of old system more than 10 years old | R19: latest technology | T19: After warranty CMC will come | U19: Frequent complaint | V19: Replacement | W19: Dr Anand | X19: 190 Cases/ Month 2000per case | Y19: Nil | Z19: 2 | AA19: 2 | AB19: 7000000 | AC19: Approved
A20: 18 | B20: Biomedical | C20: Plant & Machinery | D20: Biomedical Equipment | E20: Portable DR | F20: 1 | H20: Radiology | I20: 6000000 | L20: 6000000 | N20: October | P20: October | Q20: Replacement for old machine | R20: To generate additional income and patient comfort | T20: After warranty CMC will come | V20: Replacement | W20: Dr Thara | X20: 80 Cases/Day 450/- per case | Y20: Nil | AC20: ON HOLD
A21: 19 | B21: Biomedical | C21: Plant & Machinery | D21: Biomedical Equipment | E21: Thomsan retractor | F21: 1 | H21: Main OT | I21: 6000000 | L21: 6000000 | N21: December | P21: December | Q21: Replacement for old instrument | R21: Patient saftey | U21: Replacement | V21: Replacement | W21: Dr. HR, Dr Fadal | X21: 8-10 Cases / Month | Y21: Nil | Z21: 1 | AA21: 1 | AB21: 6000000 | AC21: APPROVED
A22: 20 | B22: Biomedical | C22: Plant & Machinery | D22: Biomedical Equipment | E22: Surgical Aspirator - CUSA | F22: 1 | H22: Neuro OT | I22: 6000000 | L22: 6000000 | N22: September | P22: September | Q22: Replacement of ols machine ore than 15 yrs old | R22: Patient saftey | T22: After warranty CMC will come | U22: Morethan 15 years of usage | V22: Replacement | W22: Dr SK | X22: 3 -5 Cases/Month | Y22: Nil | Z22: 1 | AA22: 1 | AB22: 6000000 | AC22: APPROVED ,Need to charge for each case
A23: 21 | B23: Biomedical | C23: Plant & Machinery | D23: Biomedical Equipment | E23: Total body densitometry system | F23: 1 | H23: Radiology | I23: 6000000 | L23: 6000000 | N23: August | P23: August | Q23: Replacement of old system | R23: Additional income generating and latest technolgy | T23: After warranty CMC will come | U23: More than 10 years of usage,achieved its life. | V23: Rreplacement | W23: Dr JV,Dr Vivek | X23: 8 Cases/Day | Y23: Nil | Z23: 1 | AA23: 1 | AB23: 6000000 | AC23: APPROVED
A24: 22 | B24: Biomedical | C24: Plant & Machinery | D24: Biomedical Equipment | E24: WAB for ultrasound | F24: 1 | H24: Radiology | I24: 6000000 | L24: 6000000 | N24: October | P24: October | Q24: New reqirement | R24: Additional income and latest technology | T24: After warranty CMC will come | U24: New requirement | V24: New requirement | W24: Dr Chithratara, Dr Thara | Y24: Nil | AC24: ON HOLD
A25: 23 | B25: Biomedical | C25: Plant & Machinery | D25: Biomedical Equipment | E25: Dialysis machine | F25: 6 | H25: Nephrology | I25: 800000 | L25: 480000 | N25: May | P25: May | Q25: Replacement for old machine | T25: After warranty CMC will come | U25: More than 10 years of usage, needs replacement | V25: Replacement | W25: Dr Abi Abhraham | X25: 60 Cases/Day(26 machine | Y25: Nil | Z25: 6 | AA25: 6 | AB25: 480000 | AC25: APPROVED
A26: 24 | B26: Biomedical | C26: Plant & Machinery | D26: Biomedical Equipment | E26: Ortho Surgical instruments | F26: 1 | H26: Ortho OT | I26: 5000000 | L26: 5000000 | N26: October | P26: October | Q26: Replacement for old instruments | U26: Replacement | V26: Replacement | W26: Dr JV | Y26: Nil | AC26: Waiting for list from CSSD
A27: 25 | B27: Biomedical | C27: Plant & Machinery | D27: Biomedical Equipment | E27: Cardiac workstation with TMT | F27: 2 | H27: Cardiology OP | I27: 250000 | L27: 5000000 | N27: September | P27: September | Q27: Replacement of old system more than 10 years old | T27: After warranty CMC will come | U27: More than 10 years of usage,achieved its life. | V27: Replacement | W27: Dr Anand | X27: 20 Cases/Day (1700/- per case) | Y27: Nil | Z27: 2 | AA27: 2 | AB27: 5000000 | AC27: APPROVED
A28: 26 | B28: Biomedical | C28: Plant & Machinery | D28: Biomedical Equipment | E28: MRI compactable monitor | F28: 1 | H28: Radiology | I28: 5000000 | L28: 5000000 | N28: September | P28: September | Q28: Replacement for old machine more than 10 yrs | U28: More than 10 years of usage,achieved its life. | V28: Replacement | W28: Dr Julio | Y28: Nil | Z28: 1 | AA28: 1 | AB28: 5000000 | AC28: APPROVED
A29: 27 | B29: Biomedical | C29: Plant & Machinery | D29: Biomedical Equipment | E29: Anesthesia work station MRI | F29: 1 | H29: Radiology | I29: 4500000 | L29: 4500000 | N29: September | P29: September | Q29: Replacement of old machine more than 12 years | T29: After warranty CMC will come | U29: More than 10 years of usage,achieved its life. | V29: Replacement | W29: Dr Julio | X29: 10 Cases/Month | Y29: Nil | AC29: Rejected
A30: 28 | B30: Hematology | C30: Plant & Machinery | D30: Biomedical Equipment | E30: Automated Urine Analyzer | F30: 1 | H30: Haematology | I30: 4000000 | L30: 4000000 | P30: July | Q30: An Automated Urine Analyzer is a diagnostic instrument used for rapid and standardized examination of urine samples. In the Hematology setting (or integrated central lab), it supports screening, monitoring, and diagnostic evaluation of various systemic and hematological conditions. | R30: Failure to invest in an Automated Urine Analyzer can significantly affect diagnostic efficiency, patient safety, and laboratory productivity in the Hematology Department. Reliance on manual urine strip reading and microscopy Higher observer variability Increased technician workload Reduced productivity during peak hours | T30: a) Urine Reagent Strips (Major Cost Component) Multi-parameter strips (10–14 parameters depending on model) Cost directly proportional to daily sample volume . Quality Control (QC) Materials Annual Maintenance Contract (AMC) | U30: Automate the current process to improve the tat in clinical pathology, but presently there is limited space available in hematology department. | V30: New requirement | W30: Nishanth | Y30: Nil | Z30: 1 | AA30: 1 | AB30: 4000000 | AC30: APPROVED
A31: 29 | B31: Biomedical | C31: Plant & Machinery | D31: Biomedical Equipment | E31: IABP machine | F31: 1 | H31: Cardiac OT | I31: 4000000 | L31: 4000000 | N31: July | P31: July | Q31: Replacement for old machine installed in 2006 | T31: After warranty CMC will come | U31: Morethan 10 years of usage | V31: Replacement | W31: Dr Sujith | X31: 2cases/month | Y31: Nil | Z31: 1 | AA31: 1 | AB31: 4000000 | AC31: APPROVED
A32: 30 | B32: Biomedical | C32: Plant & Machinery | D32: Biomedical Equipment | E32: Ultrasonic cleaner | F32: 1 | H32: CSSD | I32: 4000000 | L32: 4000000 | N32: February | P32: February | Q32: Replacement for old machine more than 10 years old | T32: After warranty CMC will come | U32: Replacement for old one | V32: Replacement | W32: CSSD ,Manager | X32: Nil | Y32: Nil | Z32: 1 | AA32: 1 | AB32: 4000000 | AC32: APPROVED
A33: 31 | B33: Biomedical | C33: Plant & Machinery | D33: Biomedical Equipment | E33: Reporting Workstation | F33: 4 | H33: Radiology | I33: 1000000 | L33: 4000000 | N33: October | P33: October | Q33: Replacement for old system | U33: More than 10 years of usage,achieved its life. | V33: Replacement | W33: Dr Thara | X33: Nil | Y33: Nil | Z33: 4 | AA33: 4 | AB33: 4000000 | AC33: APPROVED
A34: 32 | B34: Biomedical | C34: Plant & Machinery | D34: Biomedical Equipment | E34: Incubator with portable ventilator | F34: 1 | H34: NICU | I34: 3500000 | L34: 3500000 | N34: January | P34: January | Q34: New requirment for neonatal icu | R34: Additional income generative | T34: After warranty CMC will come | U34: New requirement | V34: New requirement | W34: Dr Navin | X34: Nil | Y34: Nil | AC34: Need to discuss with Dr
A35: 33 | B35: Biomedical | C35: Plant & Machinery | D35: Biomedical Equipment | E35: Electric drill | F35: 1 | H35: Neuro OT | I35: 3200000 | L35: 3200000 | N35: February | P35: February | Q35: Replacement for old machine | U35: Replacement | V35: Replacement | W35: Dr SK | Z35: 1 | AA35: 1 | AB35: 3200000 | AC35: APPROVED
A36: 34 | B36: Biomedical | C36: Plant & Machinery | D36: Biomedical Equipment | E36: Manometry | F36: 1 | H36: Gastroenterology | I36: 3200000 | L36: 3200000 | N36: October | P36: October | Q36: Replacement for old machine | R36: Additional income generative | U36: More than 10 years of usage | V36: Replacement | W36: Dr Roy | X36: 6 Cases/Month 15000/- per case | Y36: Nil | Z36: 1 | AA36: 1 | AB36: 3200000 | AC36: APPROVED
A37: 35 | B37: Biomedical | C37: Plant & Machinery | D37: Biomedical Equipment | E37: OT Table | F37: 1 | H37: Main OT | I37: 1500000 | L37: 1500000 | N37: May | P37: May | Q37: Replacement for old machine more than 10 years old | R37: Patient saftey | U37: Morethan 10 years of usage | V37: Replacement | W37: OT incharge | X37: NIL | Y37: NIL | Z37: 1 | AA37: 1 | AB37: 1500000 | AC37: Approved
A38: 36 | B38: Biomedical | C38: Plant & Machinery | D38: Biomedical Equipment | E38: CO monitor | F38: 1 | H38: Main OT | I38: 3000000 | L38: 3000000 | N38: September | P38: September | Q38: Replacement for old machine more than 10 years old | R38: Latest technology | T38: After warranty CMC will come | U38: Morethan 10 years of usage | V38: Replacement | W38: Dr Mallie | X38: NIL | Y38: NIL | Z38: 1 | AA38: 1 | AB38: 3000000 | AC38: Approved
A39: 37 | B39: Biomedical | C39: Plant & Machinery | D39: Biomedical Equipment | E39: Surgical instruments | F39: 1 | H39: Main OT | I39: 3000000 | L39: 3000000 | N39: December | P39: December | Q39: Replacement for old instruments | R39: Supportive | U39: New requirement | V39: Replacement | W39: Dr HR | X39: Nil | AC39: Waiting for list from CSSD
A40: 38 | B40: Biomedical | C40: Plant & Machinery | D40: Biomedical Equipment | E40: Nasal endoscope | F40: 1 | H40: ENT | I40: 3000000 | L40: 3000000 | N40: June | P40: June | Q40: Replacement of old machine more than 15 yrs old machine | R40: Additional income generative | T40: After warranty CMC will come | U40: More than 10 years of usage, needs replacement | V40: Replacement | W40: Dr Idiculla | X40: 10 Cases/Month | Y40: Nil | Z40: 1 | AA40: 1 | AB40: 3000000 | AC40: Approved
...

Sheet MonthWise
B2: Asset Category Wise Summary
B3: Asset Category | C3: YTD | D3: Apr | E3: May | F3: Jun | G3: Jul | H3: Aug | I3: Sep | J3: Oct | K3: Nov | L3: Dec | M3: Jan | N3: Feb | O3: Mar
B4: Biomedical Assets | C4: =SUMIFS(Capex_Details!$M$4:$M$353,Capex_Details!$E$4:$E$353,MonthWise!B4)/10^5 -> 0 | D4: =SUMIFS(Capex_Details!$M$4:$M$353,Capex_Details!$E$4:$E$353,MonthWise!$B4,Capex_Details!$O$4:$O$353,MonthWise!D$3)/10^5 -> 0 | E4: =SUMIFS(Capex_Details!$M$4:$M$353,Capex_Details!$E$4:$E$353,MonthWise!$B4,Capex_Details!$O$4:$O$353,MonthWise!E$3)/10^5 -> 0 | F4: =SUMIFS(Capex_Details!$M$4:$M$353,Capex_Details!$E$4:$E$353,MonthWise!$B4,Capex_Details!$O$4:$O$353,MonthWise!F$3)/10^5 -> 0 | G4: =SUMIFS(Capex_Details!$M$4:$M$353,Capex_Details!$E$4:$E$353,MonthWise!$B4,Capex_Details!$O$4:$O$353,MonthWise!G$3)/10^5 -> 0 | H4: =SUMIFS(Capex_Details!$M$4:$M$353,Capex_Details!$E$4:$E$353,MonthWise!$B4,Capex_Details!$O$4:$O$353,MonthWise!H$3)/10^5 -> 0 | I4: =SUMIFS(Capex_Details!$M$4:$M$353,Capex_Details!$E$4:$E$353,MonthWise!$B4,Capex_Details!$O$4:$O$353,MonthWise!I$3)/10^5 -> 0 | J4: =SUMIFS(Capex_Details!$M$4:$M$353,Capex_Details!$E$4:$E$353,MonthWise!$B4,Capex_Details!$O$4:$O$353,MonthWise!J$3)/10^5 -> 0 | K4: =SUMIFS(Capex_Details!$M$4:$M$353,Capex_Details!$E$4:$E$353,MonthWise!$B4,Capex_Details!$O$4:$O$353,MonthWise!K$3)/10^5 -> 0 | ... O4: =SUMIFS(Capex_Details!$M$4:$M$353,Capex_Details!$E$4:$E$353,MonthWise!$B4,Capex_Details!$O$4:$O$353,MonthWise!O$3)/10^5 -> 0 | P4: =SUM(D4:O4)-C4 -> 0
B5: Vehicles | C5: =SUMIFS(Capex_Details!$M$4:$M$353,Capex_Details!$E$4:$E$353,MonthWise!B5)/10^5 -> 0 | D5: =SUMIFS(Capex_Details!$M$4:$M$353,Capex_Details!$E$4:$E$353,MonthWise!$B5,Capex_Details!$O$4:$O$353,MonthWise!D$3)/10^5 -> 0 | E5: =SUMIFS(Capex_Details!$M$4:$M$353,Capex_Details!$E$4:$E$353,MonthWise!$B5,Capex_Details!$O$4:$O$353,MonthWise!E$3)/10^5 -> 0 | F5: =SUMIFS(Capex_Details!$M$4:$M$353,Capex_Details!$E$4:$E$353,MonthWise!$B5,Capex_Details!$O$4:$O$353,MonthWise!F$3)/10^5 -> 0 | G5: =SUMIFS(Capex_Details!$M$4:$M$353,Capex_Details!$E$4:$E$353,MonthWise!$B5,Capex_Details!$O$4:$O$353,MonthWise!G$3)/10^5 -> 0 | H5: =SUMIFS(Capex_Details!$M$4:$M$353,Capex_Details!$E$4:$E$353,MonthWise!$B5,Capex_Details!$O$4:$O$353,MonthWise!H$3)/10^5 -> 0 | I5: =SUMIFS(Capex_Details!$M$4:$M$353,Capex_Details!$E$4:$E$353,MonthWise!$B5,Capex_Details!$O$4:$O$353,MonthWise!I$3)/10^5 -> 0 | J5: =SUMIFS(Capex_Details!$M$4:$M$353,Capex_Details!$E$4:$E$353,MonthWise!$B5,Capex_Details!$O$4:$O$353,MonthWise!J$3)/10^5 -> 0 | K5: =SUMIFS(Capex_Details!$M$4:$M$353,Capex_Details!$E$4:$E$353,MonthWise!$B5,Capex_Details!$O$4:$O$353,MonthWise!K$3)/10^5 -> 0 | ... O5: =SUMIFS(Capex_Details!$M$4:$M$353,Capex_Details!$E$4:$E$353,MonthWise!$B5,Capex_Details!$O$4:$O$353,MonthWise!O$3)/10^5 -> 0 | P5: =SUM(D5:O5)-C5 -> 0
B6: Fire & Safety Assets | C6: =SUMIFS(Capex_Details!$M$4:$M$353,Capex_Details!$E$4:$E$353,MonthWise!B6)/10^5 -> 0 | D6: =SUMIFS(Capex_Details!$M$4:$M$353,Capex_Details!$E$4:$E$353,MonthWise!$B6,Capex_Details!$O$4:$O$353,MonthWise!D$3)/10^5 -> 0 | E6: =SUMIFS(Capex_Details!$M$4:$M$353,Capex_Details!$E$4:$E$353,MonthWise!$B6,Capex_Details!$O$4:$O$353,MonthWise!E$3)/10^5 -> 0 | F6: =SUMIFS(Capex_Details!$M$4:$M$353,Capex_Details!$E$4:$E$353,MonthWise!$B6,Capex_Details!$O$4:$O$353,MonthWise!F$3)/10^5 -> 0 | G6: =SUMIFS(Capex_Details!$M$4:$M$353,Capex_Details!$E$4:$E$353,MonthWise!$B6,Capex_Details!$O$4:$O$353,MonthWise!G$3)/10^5 -> 0 | H6: =SUMIFS(Capex_Details!$M$4:$M$353,Capex_Details!$E$4:$E$353,MonthWise!$B6,Capex_Details!$O$4:$O$353,MonthWise!H$3)/10^5 -> 0 | I6: =SUMIFS(Capex_Details!$M$4:$M$353,Capex_Details!$E$4:$E$353,MonthWise!$B6,Capex_Details!$O$4:$O$353,MonthWise!I$3)/10^5 -> 0 | J6: =SUMIFS(Capex_Details!$M$4:$M$353,Capex_Details!$E$4:$E$353,MonthWise!$B6,Capex_Details!$O$4:$O$353,MonthWise!J$3)/10^5 -> 0 | K6: =SUMIFS(Capex_Details!$M$4:$M$353,Capex_Details!$E$4:$E$353,MonthWise!$B6,Capex_Details!$O$4:$O$353,MonthWise!K$3)/10^5 -> 0 | ... O6: =SUMIFS(Capex_Details!$M$4:$M$353,Capex_Details!$E$4:$E$353,MonthWise!$B6,Capex_Details!$O$4:$O$353,MonthWise!O$3)/10^5 -> 0 | P6: =SUM(D6:O6)-C6 -> 0
B7: IT Assets | C7: =SUMIFS(Capex_Details!$M$4:$M$353,Capex_Details!$E$4:$E$353,MonthWise!B7)/10^5 -> 0 | D7: =SUMIFS(Capex_Details!$M$4:$M$353,Capex_Details!$E$4:$E$353,MonthWise!$B7,Capex_Details!$O$4:$O$353,MonthWise!D$3)/10^5 -> 0 | E7: =SUMIFS(Capex_Details!$M$4:$M$353,Capex_Details!$E$4:$E$353,MonthWise!$B7,Capex_Details!$O$4:$O$353,MonthWise!E$3)/10^5 -> 0 | F7: =SUMIFS(Capex_Details!$M$4:$M$353,Capex_Details!$E$4:$E$353,MonthWise!$B7,Capex_Details!$O$4:$O$353,MonthWise!F$3)/10^5 -> 0 | G7: =SUMIFS(Capex_Details!$M$4:$M$353,Capex_Details!$E$4:$E$353,MonthWise!$B7,Capex_Details!$O$4:$O$353,MonthWise!G$3)/10^5 -> 0 | H7: =SUMIFS(Capex_Details!$M$4:$M$353,Capex_Details!$E$4:$E$353,MonthWise!$B7,Capex_Details!$O$4:$O$353,MonthWise!H$3)/10^5 -> 0 | I7: =SUMIFS(Capex_Details!$M$4:$M$353,Capex_Details!$E$4:$E$353,MonthWise!$B7,Capex_Details!$O$4:$O$353,MonthWise!I$3)/10^5 -> 0 | J7: =SUMIFS(Capex_Details!$M$4:$M$353,Capex_Details!$E$4:$E$353,MonthWise!$B7,Capex_Details!$O$4:$O$353,MonthWise!J$3)/10^5 -> 0 | K7: =SUMIFS(Capex_Details!$M$4:$M$353,Capex_Details!$E$4:$E$353,MonthWise!$B7,Capex_Details!$O$4:$O$353,MonthWise!K$3)/10^5 -> 0 | ... O7: =SUMIFS(Capex_Details!$M$4:$M$353,Capex_Details!$E$4:$E$353,MonthWise!$B7,Capex_Details!$O$4:$O$353,MonthWise!O$3)/10^5 -> 0 | P7: =SUM(D7:O7)-C7 -> 0
B8: Furniture & Fixtures Assets | C8: =SUMIFS(Capex_Details!$M$4:$M$353,Capex_Details!$E$4:$E$353,MonthWise!B8)/10^5 -> 0 | D8: =SUMIFS(Capex_Details!$M$4:$M$353,Capex_Details!$E$4:$E$353,MonthWise!$B8,Capex_Details!$O$4:$O$353,MonthWise!D$3)/10^5 -> 0 | E8: =SUMIFS(Capex_Details!$M$4:$M$353,Capex_Details!$E$4:$E$353,MonthWise!$B8,Capex_Details!$O$4:$O$353,MonthWise!E$3)/10^5 -> 0 | F8: =SUMIFS(Capex_Details!$M$4:$M$353,Capex_Details!$E$4:$E$353,MonthWise!$B8,Capex_Details!$O$4:$O$353,MonthWise!F$3)/10^5 -> 0 | G8: =SUMIFS(Capex_Details!$M$4:$M$353,Capex_Details!$E$4:$E$353,MonthWise!$B8,Capex_Details!$O$4:$O$353,MonthWise!G$3)/10^5 -> 0 | H8: =SUMIFS(Capex_Details!$M$4:$M$353,Capex_Details!$E$4:$E$353,MonthWise!$B8,Capex_Details!$O$4:$O$353,MonthWise!H$3)/10^5 -> 0 | I8: =SUMIFS(Capex_Details!$M$4:$M$353,Capex_Details!$E$4:$E$353,MonthWise!$B8,Capex_Details!$O$4:$O$353,MonthWise!I$3)/10^5 -> 0 | J8: =SUMIFS(Capex_Details!$M$4:$M$353,Capex_Details!$E$4:$E$353,MonthWise!$B8,Capex_Details!$O$4:$O$353,MonthWise!J$3)/10^5 -> 0 | K8: =SUMIFS(Capex_Details!$M$4:$M$353,Capex_Details!$E$4:$E$353,MonthWise!$B8,Capex_Details!$O$4:$O$353,MonthWise!K$3)/10^5 -> 0 | ... O8: =SUMIFS(Capex_Details!$M$4:$M$353,Capex_Details!$E$4:$E$353,MonthWise!$B8,Capex_Details!$O$4:$O$353,MonthWise!O$3)/10^5 -> 0 | P8: =SUM(D8:O8)-C8 -> 0
B9: Electrical Equipments | C9: =SUMIFS(Capex_Details!$M$4:$M$353,Capex_Details!$E$4:$E$353,MonthWise!B9)/10^5 -> 7 | D9: =SUMIFS(Capex_Details!$M$4:$M$353,Capex_Details!$E$4:$E$353,MonthWise!$B9,Capex_Details!$O$4:$O$353,MonthWise!D$3)/10^5 -> 0 | E9: =SUMIFS(Capex_Details!$M$4:$M$353,Capex_Details!$E$4:$E$353,MonthWise!$B9,Capex_Details!$O$4:$O$353,MonthWise!E$3)/10^5 -> 0 | F9: =SUMIFS(Capex_Details!$M$4:$M$353,Capex_Details!$E$4:$E$353,MonthWise!$B9,Capex_Details!$O$4:$O$353,MonthWise!F$3)/10^5 -> 0 | G9: =SUMIFS(Capex_Details!$M$4:$M$353,Capex_Details!$E$4:$E$353,MonthWise!$B9,Capex_Details!$O$4:$O$353,MonthWise!G$3)/10^5 -> 0 | H9: =SUMIFS(Capex_Details!$M$4:$M$353,Capex_Details!$E$4:$E$353,MonthWise!$B9,Capex_Details!$O$4:$O$353,MonthWise!H$3)/10^5 -> 0 | I9: =SUMIFS(Capex_Details!$M$4:$M$353,Capex_Details!$E$4:$E$353,MonthWise!$B9,Capex_Details!$O$4:$O$353,MonthWise!I$3)/10^5 -> 0 | J9: =SUMIFS(Capex_Details!$M$4:$M$353,Capex_Details!$E$4:$E$353,MonthWise!$B9,Capex_Details!$O$4:$O$353,MonthWise!J$3)/10^5 -> 0 | K9: =SUMIFS(Capex_Details!$M$4:$M$353,Capex_Details!$E$4:$E$353,MonthWise!$B9,Capex_Details!$O$4:$O$353,MonthWise!K$3)/10^5 -> 0 | ... O9: =SUMIFS(Capex_Details!$M$4:$M$353,Capex_Details!$E$4:$E$353,MonthWise!$B9,Capex_Details!$O$4:$O$353,MonthWise!O$3)/10^5 -> 0 | P9: =SUM(D9:O9)-C9 -> -7
B10: Project | C10: =SUMIFS(Capex_Details!$M$4:$M$353,Capex_Details!$E$4:$E$353,MonthWise!B10)/10^5 -> 0 | D10: =SUMIFS(Capex_Details!$M$4:$M$353,Capex_Details!$E$4:$E$353,MonthWise!$B10,Capex_Details!$O$4:$O$353,MonthWise!D$3)/10^5 -> 0 | E10: =SUMIFS(Capex_Details!$M$4:$M$353,Capex_Details!$E$4:$E$353,MonthWise!$B10,Capex_Details!$O$4:$O$353,MonthWise!E$3)/10^5 -> 0 | F10: =SUMIFS(Capex_Details!$M$4:$M$353,Capex_Details!$E$4:$E$353,MonthWise!$B10,Capex_Details!$O$4:$O$353,MonthWise!F$3)/10^5 -> 0 | G10: =SUMIFS(Capex_Details!$M$4:$M$353,Capex_Details!$E$4:$E$353,MonthWise!$B10,Capex_Details!$O$4:$O$353,MonthWise!G$3)/10^5 -> 0 | H10: =SUMIFS(Capex_Details!$M$4:$M$353,Capex_Details!$E$4:$E$353,MonthWise!$B10,Capex_Details!$O$4:$O$353,MonthWise!H$3)/10^5 -> 0 | I10: =SUMIFS(Capex_Details!$M$4:$M$353,Capex_Details!$E$4:$E$353,MonthWise!$B10,Capex_Details!$O$4:$O$353,MonthWise!I$3)/10^5 -> 0 | J10: =SUMIFS(Capex_Details!$M$4:$M$353,Capex_Details!$E$4:$E$353,MonthWise!$B10,Capex_Details!$O$4:$O$353,MonthWise!J$3)/10^5 -> 0 | K10: =SUMIFS(Capex_Details!$M$4:$M$353,Capex_Details!$E$4:$E$353,MonthWise!$B10,Capex_Details!$O$4:$O$353,MonthWise!K$3)/10^5 -> 0 | ... O10: =SUMIFS(Capex_Details!$M$4:$M$353,Capex_Details!$E$4:$E$353,MonthWise!$B10,Capex_Details!$O$4:$O$353,MonthWise!O$3)/10^5 -> 0 | P10: =SUM(D10:O10)-C10 -> 0
B11: Land | C11: =SUMIFS(Capex_Details!$M$4:$M$353,Capex_Details!$E$4:$E$353,MonthWise!B11)/10^5 -> 0 | D11: =SUMIFS(Capex_Details!$M$4:$M$353,Capex_Details!$E$4:$E$353,MonthWise!$B11,Capex_Details!$O$4:$O$353,MonthWise!D$3)/10^5 -> 0 | E11: =SUMIFS(Capex_Details!$M$4:$M$353,Capex_Details!$E$4:$E$353,MonthWise!$B11,Capex_Details!$O$4:$O$353,MonthWise!E$3)/10^5 -> 0 | F11: =SUMIFS(Capex_Details!$M$4:$M$353,Capex_Details!$E$4:$E$353,MonthWise!$B11,Capex_Details!$O$4:$O$353,MonthWise!F$3)/10^5 -> 0 | G11: =SUMIFS(Capex_Details!$M$4:$M$353,Capex_Details!$E$4:$E$353,MonthWise!$B11,Capex_Details!$O$4:$O$353,MonthWise!G$3)/10^5 -> 0 | H11: =SUMIFS(Capex_Details!$M$4:$M$353,Capex_Details!$E$4:$E$353,MonthWise!$B11,Capex_Details!$O$4:$O$353,MonthWise!H$3)/10^5 -> 0 | I11: =SUMIFS(Capex_Details!$M$4:$M$353,Capex_Details!$E$4:$E$353,MonthWise!$B11,Capex_Details!$O$4:$O$353,MonthWise!I$3)/10^5 -> 0 | J11: =SUMIFS(Capex_Details!$M$4:$M$353,Capex_Details!$E$4:$E$353,MonthWise!$B11,Capex_Details!$O$4:$O$353,MonthWise!J$3)/10^5 -> 0 | K11: =SUMIFS(Capex_Details!$M$4:$M$353,Capex_Details!$E$4:$E$353,MonthWise!$B11,Capex_Details!$O$4:$O$353,MonthWise!K$3)/10^5 -> 0 | ... O11: =SUMIFS(Capex_Details!$M$4:$M$353,Capex_Details!$E$4:$E$353,MonthWise!$B11,Capex_Details!$O$4:$O$353,MonthWise!O$3)/10^5 -> 0 | P11: =SUM(D11:O11)-C11 -> 0
B12: Building | C12: =SUMIFS(Capex_Details!$M$4:$M$353,Capex_Details!$E$4:$E$353,MonthWise!B12)/10^5 -> 0 | D12: =SUMIFS(Capex_Details!$M$4:$M$353,Capex_Details!$E$4:$E$353,MonthWise!$B12,Capex_Details!$O$4:$O$353,MonthWise!D$3)/10^5 -> 0 | E12: =SUMIFS(Capex_Details!$M$4:$M$353,Capex_Details!$E$4:$E$353,MonthWise!$B12,Capex_Details!$O$4:$O$353,MonthWise!E$3)/10^5 -> 0 | F12: =SUMIFS(Capex_Details!$M$4:$M$353,Capex_Details!$E$4:$E$353,MonthWise!$B12,Capex_Details!$O$4:$O$353,MonthWise!F$3)/10^5 -> 0 | G12: =SUMIFS(Capex_Details!$M$4:$M$353,Capex_Details!$E$4:$E$353,MonthWise!$B12,Capex_Details!$O$4:$O$353,MonthWise!G$3)/10^5 -> 0 | H12: =SUMIFS(Capex_Details!$M$4:$M$353,Capex_Details!$E$4:$E$353,MonthWise!$B12,Capex_Details!$O$4:$O$353,MonthWise!H$3)/10^5 -> 0 | I12: =SUMIFS(Capex_Details!$M$4:$M$353,Capex_Details!$E$4:$E$353,MonthWise!$B12,Capex_Details!$O$4:$O$353,MonthWise!I$3)/10^5 -> 0 | J12: =SUMIFS(Capex_Details!$M$4:$M$353,Capex_Details!$E$4:$E$353,MonthWise!$B12,Capex_Details!$O$4:$O$353,MonthWise!J$3)/10^5 -> 0 | K12: =SUMIFS(Capex_Details!$M$4:$M$353,Capex_Details!$E$4:$E$353,MonthWise!$B12,Capex_Details!$O$4:$O$353,MonthWise!K$3)/10^5 -> 0 | ... O12: =SUMIFS(Capex_Details!$M$4:$M$353,Capex_Details!$E$4:$E$353,MonthWise!$B12,Capex_Details!$O$4:$O$353,MonthWise!O$3)/10^5 -> 0 | P12: =SUM(D12:O12)-C12 -> 0
C13: =SUMIFS(Capex_Details!$M$4:$M$353,Capex_Details!$E$4:$E$353,MonthWise!B13)/10^5 -> 0 | D13: =SUMIFS(Capex_Details!$M$4:$M$353,Capex_Details!$E$4:$E$353,MonthWise!$B13,Capex_Details!$O$4:$O$353,MonthWise!D$3)/10^5 -> 0 | E13: =SUMIFS(Capex_Details!$M$4:$M$353,Capex_Details!$E$4:$E$353,MonthWise!$B13,Capex_Details!$O$4:$O$353,MonthWise!E$3)/10^5 -> 0 | F13: =SUMIFS(Capex_Details!$M$4:$M$353,Capex_Details!$E$4:$E$353,MonthWise!$B13,Capex_Details!$O$4:$O$353,MonthWise!F$3)/10^5 -> 0 | G13: =SUMIFS(Capex_Details!$M$4:$M$353,Capex_Details!$E$4:$E$353,MonthWise!$B13,Capex_Details!$O$4:$O$353,MonthWise!G$3)/10^5 -> 0 | H13: =SUMIFS(Capex_Details!$M$4:$M$353,Capex_Details!$E$4:$E$353,MonthWise!$B13,Capex_Details!$O$4:$O$353,MonthWise!H$3)/10^5 -> 0 | I13: =SUMIFS(Capex_Details!$M$4:$M$353,Capex_Details!$E$4:$E$353,MonthWise!$B13,Capex_Details!$O$4:$O$353,MonthWise!I$3)/10^5 -> 0 | J13: =SUMIFS(Capex_Details!$M$4:$M$353,Capex_Details!$E$4:$E$353,MonthWise!$B13,Capex_Details!$O$4:$O$353,MonthWise!J$3)/10^5 -> 0 | K13: =SUMIFS(Capex_Details!$M$4:$M$353,Capex_Details!$E$4:$E$353,MonthWise!$B13,Capex_Details!$O$4:$O$353,MonthWise!K$3)/10^5 -> 0 | ... O13: =SUMIFS(Capex_Details!$M$4:$M$353,Capex_Details!$E$4:$E$353,MonthWise!$B13,Capex_Details!$O$4:$O$353,MonthWise!O$3)/10^5 -> 0 | P13: =SUM(D13:O13)-C13 -> 0
B14: Total | C14: =SUM(C4:C13) -> 7 | D14: =SUM(D4:D13) -> 0 | E14: =SUM(E4:E13) -> 0 | F14: =SUM(F4:F13) -> 0 | G14: =SUM(G4:G13) -> 0 | H14: =SUM(H4:H13) -> 0 | I14: =SUM(I4:I13) -> 0 | J14: =SUM(J4:J13) -> 0 | ... O14: =SUM(O4:O13) -> 0 | P14: =SUM(D14:O14)-C14 -> -7

Sheet Sheet1
B2: Capex Requirement For FY 26-27
B3: Sl.No. | C3: Department | D3: Status
B4: 1 | C4: Clinical Nutrition | D4: Received
B5: 2 | C5: Safety & Security | D5: Received
B6: 3 | C6: Pharmacy | D6: Received
B7: 4 | C7: Food & Beverage | D7: Received
B8: 5 | C8: House Keeping | D8: Received
B9: 6 | C9: IT | D9: Received
B10: 7 | C10: Physiotherapy | D10: Received
B11: 8 | C11: Store | D11: Pending
B12: 9 | C12: CSSD | D12: Pending
B13: 10 | C13: Operation | D13: Pending
B14: 11 | C14: Radiology | D14: Pending
B15: 12 | C15: MRD | D15: Pending
... B25: 22 | C25: Purchase | D25: Pending
