Workbook

Sheet Performance Tracker
A1: VPS LAKESHORE — MONTHLY PERFORMANCE TRACKER | FY 2026–27
A2: All figures ₹ Lakhs | Plan linked from 'Monthly P&L' | enter Actuals in blue columns | % Rev = line ÷ Total Revenue
B3: FY26 Actual | C3: Growth % | D3: FY27 Plan | E3: FY27 Plan % Rev | F3: YTD Plan | G3: % Ach. vs YTD Plan | H3: YTD FY27 | I3: YTD % Rev | J3: % Achieved | K3: 46138 | O3: 46168 | S3: 46199 | W3: 46229 | AA3: 46260 | AE3: 46291 | AI3: 46321 | AM3: 46352 | AQ3: 46382 | AU3: 46049 | AY3: 46080 | BC3: 46108
K4: Plan | L4: Actual | M4: % Achv | N4: % Rev | O4: Plan | P4: Actual | Q4: % Achv | R4: % Rev | S4: Plan | T4: Actual | U4: % Achv | V4: % Rev | W4: Plan | X4: Actual | Y4: % Achv | Z4: % Rev | AA4: Plan | AB4: Actual | AC4: % Achv | AD4: % Rev | AE4: Plan | AF4: Actual | AG4: % Achv | AH4: % Rev | AI4: Plan | AJ4: Actual | AK4: % Achv | AL4: % Rev | AM4: Plan | AN4: Actual | AO4: % Achv | AP4: % Rev | AQ4: Plan | AR4: Actual | AS4: % Achv | AT4: % Rev | AU4: Plan | AV4: Actual | AW4: % Achv | AX4: % Rev | AY4: Plan | AZ4: Actual | BA4: % Achv | BB4: % Rev | BC4: Plan | BD4: Actual | BE4: % Achv | BF4: % Rev
A5: REVENUE
A6: IP Revenue | B6: ='Monthly P&L'!B5 -> 31154.53 | C6: =IF(OR(B6=0,B6=""),"",D6/B6-1) -> 0.27923931 | D6: ='Monthly P&L'!C5 -> 39854.1 | E6: =IF(D$10=0,"",D6/D$10) -> 0.69285692 | F6: =IF(H6="","",K6*(L6<>"")+O6*(P6<>"")+S6*(T6<>"")+W6*(X6<>"")+AA6*(AB6<>"")+AE6*(AF6<>"")+AI6*(AJ6<>"")+AM6*(AN6<>"")+AQ6*(AR6<>"")+AU6*(AV6<>"")+AY6*(AZ6<>"")+BC6*(BD6<>"")) -> 6102.0628 | G6: =IF(OR(F6=0,F6="",H6=""),"",H6/F6) -> 1.0338463 | H6: =IF(SUM(L6,P6,T6,X6,AB6,AF6,AJ6,AN6,AR6,AV6,AZ6,BD6)=0,"",SUM(L6,P6,T6,X6,AB6,AF6,AJ6,AN6,AR6,AV6,AZ6,BD6)) -> 6308.5948 | I6: =IF(OR(H$10="",H$10=0,H6=""),"",H6/H$10) -> 0.72472349 | J6: =IF(OR(D6=0,H6=""),"",H6/D6) -> 0.15829224 | K6: ='Monthly P&L'!D5 -> 2876.8074 | L6: 3091.941 | M6: =IF(OR(L6="",K6=0),"",L6/K6) -> 1.0747821 | N6: =IF(OR(L6="",L$10="",L$10=0),"",L6/L$10) -> 0.72260511 | O6: ='Monthly P&L'!E5 -> 3225.2555 | P6: 3216.6538 | Q6: =IF(OR(P6="",O6=0),"",P6/O6) -> 0.99733304 | R6: =IF(OR(P6="",P$10="",P$10=0),"",P6/P$10) -> 0.72677148 | S6: ='Monthly P&L'!F5 -> 2894.7614 | U6: =IF(OR(T6="",S6=0),"",T6/S6) | V6: =IF(OR(T6="",T$10="",T$10=0),"",T6/T$10) | W6: ='Monthly P&L'!G5 -> 3395.955 | Y6: =IF(OR(X6="",W6=0),"",X6/W6) | Z6: =IF(OR(X6="",X$10="",X$10=0),"",X6/X$10) | AA6: ='Monthly P&L'!H5 -> 3520.9665 | AC6: =IF(OR(AB6="",AA6=0),"",AB6/AA6) | AD6: =IF(OR(AB6="",AB$10="",AB$10=0),"",AB6/AB$10) | AE6: ='Monthly P&L'!I5 -> 3502.6117 | AG6: =IF(OR(AF6="",AE6=0),"",AF6/AE6) | AH6: =IF(OR(AF6="",AF$10="",AF$10=0),"",AF6/AF$10) | AI6: ='Monthly P&L'!J5 -> 3472.181 | AK6: =IF(OR(AJ6="",AI6=0),"",AJ6/AI6) | AL6: =IF(OR(AJ6="",AJ$10="",AJ$10=0),"",AJ6/AJ$10) | AM6: ='Monthly P&L'!K5 -> 3091.2843 | AO6: =IF(OR(AN6="",AM6=0),"",AN6/AM6) | AP6: =IF(OR(AN6="",AN$10="",AN$10=0),"",AN6/AN$10) | AQ6: ='Monthly P&L'!L5 -> 3298.0825 | AS6: =IF(OR(AR6="",AQ6=0),"",AR6/AQ6) | AT6: =IF(OR(AR6="",AR$10="",AR$10=0),"",AR6/AR$10) | AU6: ='Monthly P&L'!M5 -> 3813.4737 | AW6: =IF(OR(AV6="",AU6=0),"",AV6/AU6) | AX6: =IF(OR(AV6="",AV$10="",AV$10=0),"",AV6/AV$10) | AY6: ='Monthly P&L'!N5 -> 3468.5768 | BA6: =IF(OR(AZ6="",AY6=0),"",AZ6/AY6) | BB6: =IF(OR(AZ6="",AZ$10="",AZ$10=0),"",AZ6/AZ$10) | BC6: ='Monthly P&L'!O5 -> 3294.1442 | BE6: =IF(OR(BD6="",BC6=0),"",BD6/BC6) | BF6: =IF(OR(BD6="",BD$10="",BD$10=0),"",BD6/BD$10)
A7: OP Revenue | B7: ='Monthly P&L'!B6 -> 12160.816 | C7: =IF(OR(B7=0,B7=""),"",D7/B7-1) -> 0.19395774 | D7: ='Monthly P&L'!C6 -> 14519.5 | E7: =IF(D$10=0,"",D7/D$10) -> 0.2524191 | F7: =IF(H7="","",K7*(L7<>"")+O7*(P7<>"")+S7*(T7<>"")+W7*(X7<>"")+AA7*(AB7<>"")+AE7*(AF7<>"")+AI7*(AJ7<>"")+AM7*(AN7<>"")+AQ7*(AR7<>"")+AU7*(AV7<>"")+AY7*(AZ7<>"")+BC7*(BD7<>"")) -> 2348.5126 | G7: =IF(OR(F7=0,F7="",H7=""),"",H7/F7) -> 0.85387823 | H7: =IF(SUM(L7,P7,T7,X7,AB7,AF7,AJ7,AN7,AR7,AV7,AZ7,BD7)=0,"",SUM(L7,P7,T7,X7,AB7,AF7,AJ7,AN7,AR7,AV7,AZ7,BD7)) -> 2005.3438 | I7: =IF(OR(H$10="",H$10=0,H7=""),"",H7/H$10) -> 0.23037139 | J7: =IF(OR(D7=0,H7=""),"",H7/D7) -> 0.13811383 | K7: ='Monthly P&L'!D6 -> 1144.8245 | L7: 980.77008 | M7: =IF(OR(L7="",K7=0),"",L7/K7) -> 0.85669908 | N7: =IF(OR(L7="",L$10="",L$10=0),"",L7/L$10) -> 0.22921184 | O7: ='Monthly P&L'!E6 -> 1203.6881 | P7: 1024.5737 | Q7: =IF(OR(P7="",O7=0),"",P7/O7) -> 0.85119532 | R7: =IF(OR(P7="",P$10="",P$10=0),"",P7/P$10) -> 0.2314924 | S7: ='Monthly P&L'!F6 -> 1086.5151 | U7: =IF(OR(T7="",S7=0),"",T7/S7) | V7: =IF(OR(T7="",T$10="",T$10=0),"",T7/T$10) | W7: ='Monthly P&L'!G6 -> 1302.6032 | Y7: =IF(OR(X7="",W7=0),"",X7/W7) | Z7: =IF(OR(X7="",X$10="",X$10=0),"",X7/X$10) | AA7: ='Monthly P&L'!H6 -> 1314.8005 | AC7: =IF(OR(AB7="",AA7=0),"",AB7/AA7) | AD7: =IF(OR(AB7="",AB$10="",AB$10=0),"",AB7/AB$10) | AE7: ='Monthly P&L'!I6 -> 1244.6991 | AG7: =IF(OR(AF7="",AE7=0),"",AF7/AE7) | AH7: =IF(OR(AF7="",AF$10="",AF$10=0),"",AF7/AF$10) | AI7: ='Monthly P&L'!J6 -> 1242.9217 | AK7: =IF(OR(AJ7="",AI7=0),"",AJ7/AI7) | AL7: =IF(OR(AJ7="",AJ$10="",AJ$10=0),"",AJ7/AJ$10) | AM7: ='Monthly P&L'!K6 -> 1120.6707 | AO7: =IF(OR(AN7="",AM7=0),"",AN7/AM7) | AP7: =IF(OR(AN7="",AN$10="",AN$10=0),"",AN7/AN$10) | AQ7: ='Monthly P&L'!L6 -> 1184.946 | AS7: =IF(OR(AR7="",AQ7=0),"",AR7/AQ7) | AT7: =IF(OR(AR7="",AR$10="",AR$10=0),"",AR7/AR$10) | AU7: ='Monthly P&L'!M6 -> 1326.6257 | AW7: =IF(OR(AV7="",AU7=0),"",AV7/AU7) | AX7: =IF(OR(AV7="",AV$10="",AV$10=0),"",AV7/AV$10) | AY7: ='Monthly P&L'!N6 -> 1191.909 | BA7: =IF(OR(AZ7="",AY7=0),"",AZ7/AY7) | BB7: =IF(OR(AZ7="",AZ$10="",AZ$10=0),"",AZ7/AZ$10) | BC7: ='Monthly P&L'!O6 -> 1155.2967 | BE7: =IF(OR(BD7="",BC7=0),"",BD7/BC7) | BF7: =IF(OR(BD7="",BD$10="",BD$10=0),"",BD7/BD$10)
A8: F&B / VPS Gourmet | B8: ='Monthly P&L'!B7 -> 1718.1767 | C8: =IF(OR(B8=0,B8=""),"",D8/B8-1) -> 0.29363878 | D8: ='Monthly P&L'!C7 -> 2222.7 | E8: =IF(D$10=0,"",D8/D$10) -> 0.038641271 | F8: =IF(H8="","",K8*(L8<>"")+O8*(P8<>"")+S8*(T8<>"")+W8*(X8<>"")+AA8*(AB8<>"")+AE8*(AF8<>"")+AI8*(AJ8<>"")+AM8*(AN8<>"")+AQ8*(AR8<>"")+AU8*(AV8<>"")+AY8*(AZ8<>"")+BC8*(BD8<>"")) -> 355.90897 | G8: =IF(OR(F8=0,F8="",H8=""),"",H8/F8) -> 0.9106661 | H8: =IF(SUM(L8,P8,T8,X8,AB8,AF8,AJ8,AN8,AR8,AV8,AZ8,BD8)=0,"",SUM(L8,P8,T8,X8,AB8,AF8,AJ8,AN8,AR8,AV8,AZ8,BD8)) -> 324.11424 | I8: =IF(OR(H$10="",H$10=0,H8=""),"",H8/H$10) -> 0.037233839 | J8: =IF(OR(D8=0,H8=""),"",H8/D8) -> 0.14582006 | K8: ='Monthly P&L'!D7 -> 172.64272 | L8: 157.02992 | M8: =IF(OR(L8="",K8=0),"",L8/K8) -> 0.90956586 | N8: =IF(OR(L8="",L$10="",L$10=0),"",L8/L$10) -> 0.036698833 | O8: ='Monthly P&L'!E7 -> 183.26626 | P8: 167.08431 | Q8: =IF(OR(P8="",O8=0),"",P8/O8) -> 0.91170256 | R8: =IF(OR(P8="",P$10="",P$10=0),"",P8/P$10) -> 0.037751067 | S8: ='Monthly P&L'!F7 -> 169.6418 | U8: =IF(OR(T8="",S8=0),"",T8/S8) | V8: =IF(OR(T8="",T$10="",T$10=0),"",T8/T$10) | W8: ='Monthly P&L'!G7 -> 198.35485 | Y8: =IF(OR(X8="",W8=0),"",X8/W8) | Z8: =IF(OR(X8="",X$10="",X$10=0),"",X8/X$10) | AA8: ='Monthly P&L'!H7 -> 197.8822 | AC8: =IF(OR(AB8="",AA8=0),"",AB8/AA8) | AD8: =IF(OR(AB8="",AB$10="",AB$10=0),"",AB8/AB$10) | AE8: ='Monthly P&L'!I7 -> 191.14197 | AG8: =IF(OR(AF8="",AE8=0),"",AF8/AE8) | AH8: =IF(OR(AF8="",AF$10="",AF$10=0),"",AF8/AF$10) | AI8: ='Monthly P&L'!J7 -> 190.0075 | AK8: =IF(OR(AJ8="",AI8=0),"",AJ8/AI8) | AL8: =IF(OR(AJ8="",AJ$10="",AJ$10=0),"",AJ8/AJ$10) | AM8: ='Monthly P&L'!K7 -> 177.99094 | AO8: =IF(OR(AN8="",AM8=0),"",AN8/AM8) | AP8: =IF(OR(AN8="",AN$10="",AN$10=0),"",AN8/AN$10) | AQ8: ='Monthly P&L'!L7 -> 183.43362 | AS8: =IF(OR(AR8="",AQ8=0),"",AR8/AQ8) | AT8: =IF(OR(AR8="",AR$10="",AR$10=0),"",AR8/AR$10) | AU8: ='Monthly P&L'!M7 -> 201.12799 | AW8: =IF(OR(AV8="",AU8=0),"",AV8/AU8) | AX8: =IF(OR(AV8="",AV$10="",AV$10=0),"",AV8/AV$10) | AY8: ='Monthly P&L'!N7 -> 183.82706 | BA8: =IF(OR(AZ8="",AY8=0),"",AZ8/AY8) | BB8: =IF(OR(AZ8="",AZ$10="",AZ$10=0),"",AZ8/AZ$10) | BC8: ='Monthly P&L'!O7 -> 173.38309 | BE8: =IF(OR(BD8="",BC8=0),"",BD8/BC8) | BF8: =IF(OR(BD8="",BD$10="",BD$10=0),"",BD8/BD$10)
A9: Other Income | B9: ='Monthly P&L'!B8 -> 875.5977 | C9: =IF(OR(B9=0,B9=""),"",D9/B9-1) -> 0.056535441 | D9: ='Monthly P&L'!C8 -> 925.1 | E9: =IF(D$10=0,"",D9/D$10) -> 0.01608271 | F9: =IF(H9="","",K9*(L9<>"")+O9*(P9<>"")+S9*(T9<>"")+W9*(X9<>"")+AA9*(AB9<>"")+AE9*(AF9<>"")+AI9*(AJ9<>"")+AM9*(AN9<>"")+AQ9*(AR9<>"")+AU9*(AV9<>"")+AY9*(AZ9<>"")+BC9*(BD9<>"")) -> 96.610756 | G9: =IF(OR(F9=0,F9="",H9=""),"",H9/F9) -> 0.6911987 | H9: =IF(SUM(L9,P9,T9,X9,AB9,AF9,AJ9,AN9,AR9,AV9,AZ9,BD9)=0,"",SUM(L9,P9,T9,X9,AB9,AF9,AJ9,AN9,AR9,AV9,AZ9,BD9)) -> 66.777229 | I9: =IF(OR(H$10="",H$10=0,H9=""),"",H9/H$10) -> 0.0076712846 | J9: =IF(OR(D9=0,H9=""),"",H9/D9) -> 0.072183795 | K9: ='Monthly P&L'!D8 -> 23.262151 | L9: 49.139616 | M9: =IF(OR(L9="",K9=0),"",L9/K9) -> 2.1124279 | N9: =IF(OR(L9="",L$10="",L$10=0),"",L9/L$10) -> 0.011484222 | O9: ='Monthly P&L'!E8 -> 73.348605 | P9: 17.637613 | Q9: =IF(OR(P9="",O9=0),"",P9/O9) -> 0.24046283 | R9: =IF(OR(P9="",P$10="",P$10=0),"",P9/P$10) -> 0.0039850462 | S9: ='Monthly P&L'!F8 -> 66.43931 | U9: =IF(OR(T9="",S9=0),"",T9/S9) | V9: =IF(OR(T9="",T$10="",T$10=0),"",T9/T$10) | W9: ='Monthly P&L'!G8 -> 16.323444 | Y9: =IF(OR(X9="",W9=0),"",X9/W9) | Z9: =IF(OR(X9="",X$10="",X$10=0),"",X9/X$10) | AA9: ='Monthly P&L'!H8 -> 23.353976 | AC9: =IF(OR(AB9="",AA9=0),"",AB9/AA9) | AD9: =IF(OR(AB9="",AB$10="",AB$10=0),"",AB9/AB$10) | AE9: ='Monthly P&L'!I8 -> 26.985795 | AG9: =IF(OR(AF9="",AE9=0),"",AF9/AE9) | AH9: =IF(OR(AF9="",AF$10="",AF$10=0),"",AF9/AF$10) | AI9: ='Monthly P&L'!J8 -> 45.125736 | AK9: =IF(OR(AJ9="",AI9=0),"",AJ9/AI9) | AL9: =IF(OR(AJ9="",AJ$10="",AJ$10=0),"",AJ9/AJ$10) | AM9: ='Monthly P&L'!K8 -> 31.312755 | AO9: =IF(OR(AN9="",AM9=0),"",AN9/AM9) | AP9: =IF(OR(AN9="",AN$10="",AN$10=0),"",AN9/AN$10) | AQ9: ='Monthly P&L'!L8 -> 14.044394 | AS9: =IF(OR(AR9="",AQ9=0),"",AR9/AQ9) | AT9: =IF(OR(AR9="",AR$10="",AR$10=0),"",AR9/AR$10) | AU9: ='Monthly P&L'!M8 -> 53.197681 | AW9: =IF(OR(AV9="",AU9=0),"",AV9/AU9) | AX9: =IF(OR(AV9="",AV$10="",AV$10=0),"",AV9/AV$10) | AY9: ='Monthly P&L'!N8 -> 219.67586 | BA9: =IF(OR(AZ9="",AY9=0),"",AZ9/AY9) | BB9: =IF(OR(AZ9="",AZ$10="",AZ$10=0),"",AZ9/AZ$10) | BC9: ='Monthly P&L'!O8 -> 332.04697 | BE9: =IF(OR(BD9="",BC9=0),"",BD9/BC9) | BF9: =IF(OR(BD9="",BD$10="",BD$10=0),"",BD9/BD$10)
A10: Total Revenue | B10: ='Monthly P&L'!B9 -> 45909.12 | C10: =IF(OR(B10=0,B10=""),"",D10/B10-1) -> 0.25294058 | D10: ='Monthly P&L'!C9 -> 57521.4 | E10: =IF(D$10=0,"",D10/D$10) -> 1 | F10: =IF(H10="","",K10*(L10<>"")+O10*(P10<>"")+S10*(T10<>"")+W10*(X10<>"")+AA10*(AB10<>"")+AE10*(AF10<>"")+AI10*(AJ10<>"")+AM10*(AN10<>"")+AQ10*(AR10<>"")+AU10*(AV10<>"")+AY10*(AZ10<>"")+BC10*(BD10<>"")) -> 8903.0952 | G10: =IF(OR(F10=0,F10="",H10=""),"",H10/F10) -> 0.97773077 | H10: =IF(SUM(L10,P10,T10,X10,AB10,AF10,AJ10,AN10,AR10,AV10,AZ10,BD10)=0,"",SUM(L10,P10,T10,X10,AB10,AF10,AJ10,AN10,AR10,AV10,AZ10,BD10)) -> 8704.8301 | I10: =IF(OR(H$10="",H$10=0,H10=""),"",H10/H$10) -> 1 | J10: =IF(OR(D10=0,H10=""),"",H10/D10) -> 0.15133203 | K10: ='Monthly P&L'!D9 -> 4217.5367 | L10: =IF(SUM(L6:L9)=0,"",SUM(L6:L9)) -> 4278.8806 | M10: =IF(OR(L10="",K10=0),"",L10/K10) -> 1.014545 | N10: =IF(OR(L10="",L$10="",L$10=0),"",L10/L$10) -> 1 | O10: ='Monthly P&L'!E9 -> 4685.5584 | P10: =IF(SUM(P6:P9)=0,"",SUM(P6:P9)) -> 4425.9494 | Q10: =IF(OR(P10="",O10=0),"",P10/O10) -> 0.9445938 | R10: =IF(OR(P10="",P$10="",P$10=0),"",P10/P$10) -> 1 | S10: ='Monthly P&L'!F9 -> 4217.3576 | T10: =IF(SUM(T6:T9)=0,"",SUM(T6:T9)) | U10: =IF(OR(T10="",S10=0),"",T10/S10) | V10: =IF(OR(T10="",T$10="",T$10=0),"",T10/T$10) | W10: ='Monthly P&L'!G9 -> 4913.2364 | X10: =IF(SUM(X6:X9)=0,"",SUM(X6:X9)) | Y10: =IF(OR(X10="",W10=0),"",X10/W10) | Z10: =IF(OR(X10="",X$10="",X$10=0),"",X10/X$10) | AA10: ='Monthly P&L'!H9 -> 5057.0032 | AB10: =IF(SUM(AB6:AB9)=0,"",SUM(AB6:AB9)) | AC10: =IF(OR(AB10="",AA10=0),"",AB10/AA10) | AD10: =IF(OR(AB10="",AB$10="",AB$10=0),"",AB10/AB$10) | AE10: ='Monthly P&L'!I9 -> 4965.4385 | AF10: =IF(SUM(AF6:AF9)=0,"",SUM(AF6:AF9)) | AG10: =IF(OR(AF10="",AE10=0),"",AF10/AE10) | AH10: =IF(OR(AF10="",AF$10="",AF$10=0),"",AF10/AF$10) | AI10: ='Monthly P&L'!J9 -> 4950.2359 | AJ10: =IF(SUM(AJ6:AJ9)=0,"",SUM(AJ6:AJ9)) | AK10: =IF(OR(AJ10="",AI10=0),"",AJ10/AI10) | AL10: =IF(OR(AJ10="",AJ$10="",AJ$10=0),"",AJ10/AJ$10) | AM10: ='Monthly P&L'!K9 -> 4421.2587 | AN10: =IF(SUM(AN6:AN9)=0,"",SUM(AN6:AN9)) | AO10: =IF(OR(AN10="",AM10=0),"",AN10/AM10) | AP10: =IF(OR(AN10="",AN$10="",AN$10=0),"",AN10/AN$10) | AQ10: ='Monthly P&L'!L9 -> 4680.5064 | AR10: =IF(SUM(AR6:AR9)=0,"",SUM(AR6:AR9)) | AS10: =IF(OR(AR10="",AQ10=0),"",AR10/AQ10) | AT10: =IF(OR(AR10="",AR$10="",AR$10=0),"",AR10/AR$10) | AU10: ='Monthly P&L'!M9 -> 5394.4251 | AV10: =IF(SUM(AV6:AV9)=0,"",SUM(AV6:AV9)) | AW10: =IF(OR(AV10="",AU10=0),"",AV10/AU10) | AX10: =IF(OR(AV10="",AV$10="",AV$10=0),"",AV10/AV$10) | AY10: ='Monthly P&L'!N9 -> 5063.9887 | AZ10: =IF(SUM(AZ6:AZ9)=0,"",SUM(AZ6:AZ9)) | BA10: =IF(OR(AZ10="",AY10=0),"",AZ10/AY10) | BB10: =IF(OR(AZ10="",AZ$10="",AZ$10=0),"",AZ10/AZ$10) | BC10: ='Monthly P&L'!O9 -> 4954.8709 | BD10: =IF(SUM(BD6:BD9)=0,"",SUM(BD6:BD9)) | BE10: =IF(OR(BD10="",BC10=0),"",BD10/BC10) | BF10: =IF(OR(BD10="",BD$10="",BD$10=0),"",BD10/BD$10)
A11: VARIABLE COSTS
A12: Consumption / Drug & Consumables | B12: ='Monthly P&L'!B12 -> 13709.978 | C12: =IF(OR(B12=0,B12=""),"",D12/B12-1) -> 0.11183076 | D12: ='Monthly P&L'!C12 -> 15243.175 | E12: =IF(D$10=0,"",D12/D$10) -> 0.26500008 | F12: =IF(H12="","",K12*(L12<>"")+O12*(P12<>"")+S12*(T12<>"")+W12*(X12<>"")+AA12*(AB12<>"")+AE12*(AF12<>"")+AI12*(AJ12<>"")+AM12*(AN12<>"")+AQ12*(AR12<>"")+AU12*(AV12<>"")+AY12*(AZ12<>"")+BC12*(BD12<>"")) -> 2235.185 | G12: =IF(OR(F12=0,F12="",H12=""),"",H12/F12) -> 1.1593003 | H12: =IF(SUM(L12,P12,T12,X12,AB12,AF12,AJ12,AN12,AR12,AV12,AZ12,BD12)=0,"",SUM(L12,P12,T12,X12,AB12,AF12,AJ12,AN12,AR12,AV12,AZ12,BD12)) -> 2591.2507 | I12: =IF(OR(H$10="",H$10=0,H12=""),"",H12/H$10) -> 0.29767964 | J12: =IF(OR(D12=0,H12=""),"",H12/D12) -> 0.16999415 | K12: ='Monthly P&L'!D12 -> 960.94761 | L12: 1246.2882 | M12: =IF(OR(L12="",K12=0),"",L12/K12) -> 1.2969366 | N12: =IF(OR(L12="",L$10="",L$10=0),"",L12/L$10) -> 0.291265 | O12: ='Monthly P&L'!E12 -> 1274.2374 | P12: 1344.9625 | Q12: =IF(OR(P12="",O12=0),"",P12/O12) -> 1.0555039 | R12: =IF(OR(P12="",P$10="",P$10=0),"",P12/P$10) -> 0.30388114 | S12: ='Monthly P&L'!F12 -> 1245.8601 | U12: =IF(OR(T12="",S12=0),"",T12/S12) | V12: =IF(OR(T12="",T$10="",T$10=0),"",T12/T$10) | W12: ='Monthly P&L'!G12 -> 1420.1062 | Y12: =IF(OR(X12="",W12=0),"",X12/W12) | Z12: =IF(OR(X12="",X$10="",X$10=0),"",X12/X$10) | AA12: ='Monthly P&L'!H12 -> 1356.5204 | AC12: =IF(OR(AB12="",AA12=0),"",AB12/AA12) | AD12: =IF(OR(AB12="",AB$10="",AB$10=0),"",AB12/AB$10) | AE12: ='Monthly P&L'!I12 -> 1289.868 | AG12: =IF(OR(AF12="",AE12=0),"",AF12/AE12) | AH12: =IF(OR(AF12="",AF$10="",AF$10=0),"",AF12/AF$10) | AI12: ='Monthly P&L'!J12 -> 1366.0106 | AK12: =IF(OR(AJ12="",AI12=0),"",AJ12/AI12) | AL12: =IF(OR(AJ12="",AJ$10="",AJ$10=0),"",AJ12/AJ$10) | AM12: ='Monthly P&L'!K12 -> 1200.5291 | AO12: =IF(OR(AN12="",AM12=0),"",AN12/AM12) | AP12: =IF(OR(AN12="",AN$10="",AN$10=0),"",AN12/AN$10) | AQ12: ='Monthly P&L'!L12 -> 1281.6389 | AS12: =IF(OR(AR12="",AQ12=0),"",AR12/AQ12) | AT12: =IF(OR(AR12="",AR$10="",AR$10=0),"",AR12/AR$10) | AU12: ='Monthly P&L'!M12 -> 1380.4566 | AW12: =IF(OR(AV12="",AU12=0),"",AV12/AU12) | AX12: =IF(OR(AV12="",AV$10="",AV$10=0),"",AV12/AV$10) | AY12: ='Monthly P&L'!N12 -> 1301.0576 | BA12: =IF(OR(AZ12="",AY12=0),"",AZ12/AY12) | BB12: =IF(OR(AZ12="",AZ$10="",AZ$10=0),"",AZ12/AZ$10) | BC12: ='Monthly P&L'!O12 -> 1165.9428 | BE12: =IF(OR(BD12="",BC12=0),"",BD12/BC12) | BF12: =IF(OR(BD12="",BD$10="",BD$10=0),"",BD12/BD$10)
A13: Doctor Cost | B13: ='Monthly P&L'!B13 -> 7978.262 | C13: =IF(OR(B13=0,B13=""),"",D13/B13-1) -> 0.12806411 | D13: ='Monthly P&L'!C13 -> 8999.991 | E13: =IF(D$10=0,"",D13/D$10) -> 0.15646335 | F13: =IF(H13="","",K13*(L13<>"")+O13*(P13<>"")+S13*(T13<>"")+W13*(X13<>"")+AA13*(AB13<>"")+AE13*(AF13<>"")+AI13*(AJ13<>"")+AM13*(AN13<>"")+AQ13*(AR13<>"")+AU13*(AV13<>"")+AY13*(AZ13<>"")+BC13*(BD13<>"")) -> 1499.9985 | G13: =IF(OR(F13=0,F13="",H13=""),"",H13/F13) -> 0.93851002 | H13: =IF(SUM(L13,P13,T13,X13,AB13,AF13,AJ13,AN13,AR13,AV13,AZ13,BD13)=0,"",SUM(L13,P13,T13,X13,AB13,AF13,AJ13,AN13,AR13,AV13,AZ13,BD13)) -> 1407.7636 | I13: =IF(OR(H$10="",H$10=0,H13=""),"",H13/H$10) -> 0.16172213 | J13: =IF(OR(D13=0,H13=""),"",H13/D13) -> 0.15641834 | K13: ='Monthly P&L'!D13 -> 749.99925 | L13: 715.16936 | M13: =IF(OR(L13="",K13=0),"",L13/K13) -> 0.9535601 | N13: =IF(OR(L13="",L$10="",L$10=0),"",L13/L$10) -> 0.16713936 | O13: ='Monthly P&L'!E13 -> 749.99925 | P13: 692.59426 | Q13: =IF(OR(P13="",O13=0),"",P13/O13) -> 0.92345994 | R13: =IF(OR(P13="",P$10="",P$10=0),"",P13/P$10) -> 0.1564849 | S13: ='Monthly P&L'!F13 -> 749.99925 | U13: =IF(OR(T13="",S13=0),"",T13/S13) | V13: =IF(OR(T13="",T$10="",T$10=0),"",T13/T$10) | W13: ='Monthly P&L'!G13 -> 749.99925 | Y13: =IF(OR(X13="",W13=0),"",X13/W13) | Z13: =IF(OR(X13="",X$10="",X$10=0),"",X13/X$10) | AA13: ='Monthly P&L'!H13 -> 749.99925 | AC13: =IF(OR(AB13="",AA13=0),"",AB13/AA13) | AD13: =IF(OR(AB13="",AB$10="",AB$10=0),"",AB13/AB$10) | AE13: ='Monthly P&L'!I13 -> 749.99925 | AG13: =IF(OR(AF13="",AE13=0),"",AF13/AE13) | AH13: =IF(OR(AF13="",AF$10="",AF$10=0),"",AF13/AF$10) | AI13: ='Monthly P&L'!J13 -> 749.99925 | AK13: =IF(OR(AJ13="",AI13=0),"",AJ13/AI13) | AL13: =IF(OR(AJ13="",AJ$10="",AJ$10=0),"",AJ13/AJ$10) | AM13: ='Monthly P&L'!K13 -> 749.99925 | AO13: =IF(OR(AN13="",AM13=0),"",AN13/AM13) | AP13: =IF(OR(AN13="",AN$10="",AN$10=0),"",AN13/AN$10) | AQ13: ='Monthly P&L'!L13 -> 749.99925 | AS13: =IF(OR(AR13="",AQ13=0),"",AR13/AQ13) | AT13: =IF(OR(AR13="",AR$10="",AR$10=0),"",AR13/AR$10) | AU13: ='Monthly P&L'!M13 -> 749.99925 | AW13: =IF(OR(AV13="",AU13=0),"",AV13/AU13) | AX13: =IF(OR(AV13="",AV$10="",AV$10=0),"",AV13/AV$10) | AY13: ='Monthly P&L'!N13 -> 749.99925 | BA13: =IF(OR(AZ13="",AY13=0),"",AZ13/AY13) | BB13: =IF(OR(AZ13="",AZ$10="",AZ$10=0),"",AZ13/AZ$10) | BC13: ='Monthly P&L'!O13 -> 749.99925 | BE13: =IF(OR(BD13="",BC13=0),"",BD13/BC13) | BF13: =IF(OR(BD13="",BD$10="",BD$10=0),"",BD13/BD$10)
A14: Total Variable Cost | B14: ='Monthly P&L'!B14 -> 21688.24 | C14: =IF(OR(B14=0,B14=""),"",D14/B14-1) -> 0.11780238 | D14: ='Monthly P&L'!C14 -> 24243.166 | E14: =IF(D$10=0,"",D14/D$10) -> 0.42146343 | F14: =IF(H14="","",K14*(L14<>"")+O14*(P14<>"")+S14*(T14<>"")+W14*(X14<>"")+AA14*(AB14<>"")+AE14*(AF14<>"")+AI14*(AJ14<>"")+AM14*(AN14<>"")+AQ14*(AR14<>"")+AU14*(AV14<>"")+AY14*(AZ14<>"")+BC14*(BD14<>"")) -> 3735.1835 | G14: =IF(OR(F14=0,F14="",H14=""),"",H14/F14) -> 1.070634 | H14: =IF(SUM(L14,P14,T14,X14,AB14,AF14,AJ14,AN14,AR14,AV14,AZ14,BD14)=0,"",SUM(L14,P14,T14,X14,AB14,AF14,AJ14,AN14,AR14,AV14,AZ14,BD14)) -> 3999.0143 | I14: =IF(OR(H$10="",H$10=0,H14=""),"",H14/H$10) -> 0.45940177 | J14: =IF(OR(D14=0,H14=""),"",H14/D14) -> 0.16495429 | K14: ='Monthly P&L'!D14 -> 1710.9469 | L14: =IF(L$10="","",L12+L13) -> 1961.4575 | M14: =IF(OR(L14="",K14=0),"",L14/K14) -> 1.1464164 | N14: =IF(OR(L14="",L$10="",L$10=0),"",L14/L$10) -> 0.45840436 | O14: ='Monthly P&L'!E14 -> 2024.2366 | P14: =IF(P$10="","",P12+P13) -> 2037.5568 | Q14: =IF(OR(P14="",O14=0),"",P14/O14) -> 1.0065804 | R14: =IF(OR(P14="",P$10="",P$10=0),"",P14/P$10) -> 0.46036604 | S14: ='Monthly P&L'!F14 -> 1995.8594 | T14: =IF(T$10="","",T12+T13) | U14: =IF(OR(T14="",S14=0),"",T14/S14) | V14: =IF(OR(T14="",T$10="",T$10=0),"",T14/T$10) | W14: ='Monthly P&L'!G14 -> 2170.1055 | X14: =IF(X$10="","",X12+X13) | Y14: =IF(OR(X14="",W14=0),"",X14/W14) | Z14: =IF(OR(X14="",X$10="",X$10=0),"",X14/X$10) | AA14: ='Monthly P&L'!H14 -> 2106.5197 | AB14: =IF(AB$10="","",AB12+AB13) | AC14: =IF(OR(AB14="",AA14=0),"",AB14/AA14) | AD14: =IF(OR(AB14="",AB$10="",AB$10=0),"",AB14/AB$10) | AE14: ='Monthly P&L'!I14 -> 2039.8673 | AF14: =IF(AF$10="","",AF12+AF13) | AG14: =IF(OR(AF14="",AE14=0),"",AF14/AE14) | AH14: =IF(OR(AF14="",AF$10="",AF$10=0),"",AF14/AF$10) | AI14: ='Monthly P&L'!J14 -> 2116.0099 | AJ14: =IF(AJ$10="","",AJ12+AJ13) | AK14: =IF(OR(AJ14="",AI14=0),"",AJ14/AI14) | AL14: =IF(OR(AJ14="",AJ$10="",AJ$10=0),"",AJ14/AJ$10) | AM14: ='Monthly P&L'!K14 -> 1950.5283 | AN14: =IF(AN$10="","",AN12+AN13) | AO14: =IF(OR(AN14="",AM14=0),"",AN14/AM14) | AP14: =IF(OR(AN14="",AN$10="",AN$10=0),"",AN14/AN$10) | AQ14: ='Monthly P&L'!L14 -> 2031.6382 | AR14: =IF(AR$10="","",AR12+AR13) | AS14: =IF(OR(AR14="",AQ14=0),"",AR14/AQ14) | AT14: =IF(OR(AR14="",AR$10="",AR$10=0),"",AR14/AR$10) | AU14: ='Monthly P&L'!M14 -> 2130.4558 | AV14: =IF(AV$10="","",AV12+AV13) | AW14: =IF(OR(AV14="",AU14=0),"",AV14/AU14) | AX14: =IF(OR(AV14="",AV$10="",AV$10=0),"",AV14/AV$10) | AY14: ='Monthly P&L'!N14 -> 2051.0569 | AZ14: =IF(AZ$10="","",AZ12+AZ13) | BA14: =IF(OR(AZ14="",AY14=0),"",AZ14/AY14) | BB14: =IF(OR(AZ14="",AZ$10="",AZ$10=0),"",AZ14/AZ$10) | BC14: ='Monthly P&L'!O14 -> 1915.9421 | BD14: =IF(BD$10="","",BD12+BD13) | BE14: =IF(OR(BD14="",BC14=0),"",BD14/BC14) | BF14: =IF(OR(BD14="",BD$10="",BD$10=0),"",BD14/BD$10)
A15: Contribution | B15: ='Monthly P&L'!B15 -> 24220.88 | C15: =IF(OR(B15=0,B15=""),"",D15/B15-1) -> 0.37394815 | D15: ='Monthly P&L'!C15 -> 33278.234 | E15: =IF(D$10=0,"",D15/D$10) -> 0.57853657 | F15: =IF(H15="","",K15*(L15<>"")+O15*(P15<>"")+S15*(T15<>"")+W15*(X15<>"")+AA15*(AB15<>"")+AE15*(AF15<>"")+AI15*(AJ15<>"")+AM15*(AN15<>"")+AQ15*(AR15<>"")+AU15*(AV15<>"")+AY15*(AZ15<>"")+BC15*(BD15<>"")) -> 5167.9117 | G15: =IF(OR(F15=0,F15="",H15=""),"",H15/F15) -> 0.91058362 | H15: =IF(SUM(L15,P15,T15,X15,AB15,AF15,AJ15,AN15,AR15,AV15,AZ15,BD15)=0,"",SUM(L15,P15,T15,X15,AB15,AF15,AJ15,AN15,AR15,AV15,AZ15,BD15)) -> 4705.8157 | I15: =IF(OR(H$10="",H$10=0,H15=""),"",H15/H$10) -> 0.54059823 | J15: =IF(OR(D15=0,H15=""),"",H15/D15) -> 0.14140822 | K15: ='Monthly P&L'!D15 -> 2506.5899 | L15: =IF(L$10="","",L10-L14) -> 2317.4231 | M15: =IF(OR(L15="",K15=0),"",L15/K15) -> 0.92453222 | N15: =IF(OR(L15="",L$10="",L$10=0),"",L15/L$10) -> 0.54159564 | O15: ='Monthly P&L'!E15 -> 2661.3218 | P15: =IF(P$10="","",P10-P14) -> 2388.3926 | Q15: =IF(OR(P15="",O15=0),"",P15/O15) -> 0.89744601 | R15: =IF(OR(P15="",P$10="",P$10=0),"",P15/P$10) -> 0.53963396 | S15: ='Monthly P&L'!F15 -> 2221.4983 | T15: =IF(T$10="","",T10-T14) | U15: =IF(OR(T15="",S15=0),"",T15/S15) | V15: =IF(OR(T15="",T$10="",T$10=0),"",T15/T$10) | W15: ='Monthly P&L'!G15 -> 2743.1309 | X15: =IF(X$10="","",X10-X14) | Y15: =IF(OR(X15="",W15=0),"",X15/W15) | Z15: =IF(OR(X15="",X$10="",X$10=0),"",X15/X$10) | AA15: ='Monthly P&L'!H15 -> 2950.4835 | AB15: =IF(AB$10="","",AB10-AB14) | AC15: =IF(OR(AB15="",AA15=0),"",AB15/AA15) | AD15: =IF(OR(AB15="",AB$10="",AB$10=0),"",AB15/AB$10) | AE15: ='Monthly P&L'!I15 -> 2925.5713 | AF15: =IF(AF$10="","",AF10-AF14) | AG15: =IF(OR(AF15="",AE15=0),"",AF15/AE15) | AH15: =IF(OR(AF15="",AF$10="",AF$10=0),"",AF15/AF$10) | AI15: ='Monthly P&L'!J15 -> 2834.226 | AJ15: =IF(AJ$10="","",AJ10-AJ14) | AK15: =IF(OR(AJ15="",AI15=0),"",AJ15/AI15) | AL15: =IF(OR(AJ15="",AJ$10="",AJ$10=0),"",AJ15/AJ$10) | AM15: ='Monthly P&L'!K15 -> 2470.7304 | AN15: =IF(AN$10="","",AN10-AN14) | AO15: =IF(OR(AN15="",AM15=0),"",AN15/AM15) | AP15: =IF(OR(AN15="",AN$10="",AN$10=0),"",AN15/AN$10) | AQ15: ='Monthly P&L'!L15 -> 2648.8683 | AR15: =IF(AR$10="","",AR10-AR14) | AS15: =IF(OR(AR15="",AQ15=0),"",AR15/AQ15) | AT15: =IF(OR(AR15="",AR$10="",AR$10=0),"",AR15/AR$10) | AU15: ='Monthly P&L'!M15 -> 3263.9693 | AV15: =IF(AV$10="","",AV10-AV14) | AW15: =IF(OR(AV15="",AU15=0),"",AV15/AU15) | AX15: =IF(OR(AV15="",AV$10="",AV$10=0),"",AV15/AV$10) | AY15: ='Monthly P&L'!N15 -> 3012.9318 | AZ15: =IF(AZ$10="","",AZ10-AZ14) | BA15: =IF(OR(AZ15="",AY15=0),"",AZ15/AY15) | BB15: =IF(OR(AZ15="",AZ$10="",AZ$10=0),"",AZ15/AZ$10) | BC15: ='Monthly P&L'!O15 -> 3038.9288 | BD15: =IF(BD$10="","",BD10-BD14) | BE15: =IF(OR(BD15="",BC15=0),"",BD15/BC15) | BF15: =IF(OR(BD15="",BD$10="",BD$10=0),"",BD15/BD$10)
A16: Contribution Margin % | B16: ='Monthly P&L'!B16 -> 0.52758319 | D16: ='Monthly P&L'!C16 -> 0.57853657 | F16: =IF($F$10="","",F15/$F$10) -> 0.58046237 | H16: =IF(H$10="","",H15/H$10) -> 0.54059823 | K16: ='Monthly P&L'!D16 -> 0.59432556 | L16: =IF(L$10="","",L15/L10) -> 0.54159564 | O16: ='Monthly P&L'!E16 -> 0.56798391 | P16: =IF(P$10="","",P15/P10) -> 0.53963396 | S16: ='Monthly P&L'!F16 -> 0.52675122 | T16: =IF(T$10="","",T15/T10) | W16: ='Monthly P&L'!G16 -> 0.55831446 | X16: =IF(X$10="","",X15/X10) | AA16: ='Monthly P&L'!H16 -> 0.58344506 | AB16: =IF(AB$10="","",AB15/AB10) | AE16: ='Monthly P&L'!I16 -> 0.58918689 | AF16: =IF(AF$10="","",AF15/AF10) | AI16: ='Monthly P&L'!J16 -> 0.57254362 | AJ16: =IF(AJ$10="","",AJ15/AJ10) | AM16: ='Monthly P&L'!K16 -> 0.55882963 | AN16: =IF(AN$10="","",AN15/AN10) | AQ16: ='Monthly P&L'!L16 -> 0.56593625 | AR16: =IF(AR$10="","",AR15/AR10) | AU16: ='Monthly P&L'!M16 -> 0.60506342 | AV16: =IF(AV$10="","",AV15/AV10) | AY16: ='Monthly P&L'!N16 -> 0.59497207 | AZ16: =IF(AZ$10="","",AZ15/AZ10) | BC16: ='Monthly P&L'!O16 -> 0.61332149 | BD16: =IF(BD$10="","",BD15/BD10)
A17: FIXED COSTS
A18: Employee Cost | B18: ='Monthly P&L'!B19 -> 7510.1356 | C18: =IF(OR(B18=0,B18=""),"",D18/B18-1) -> 0.22137617 | D18: ='Monthly P&L'!C19 -> 9172.7007 | E18: =IF(D$10=0,"",D18/D$10) -> 0.15946588 | F18: =IF(H18="","",K18*(L18<>"")+O18*(P18<>"")+S18*(T18<>"")+W18*(X18<>"")+AA18*(AB18<>"")+AE18*(AF18<>"")+AI18*(AJ18<>"")+AM18*(AN18<>"")+AQ18*(AR18<>"")+AU18*(AV18<>"")+AY18*(AZ18<>"")+BC18*(BD18<>"")) -> 1528.7834 | G18: =IF(OR(F18=0,F18="",H18=""),"",H18/F18) -> 0.86221677 | H18: =IF(SUM(L18,P18,T18,X18,AB18,AF18,AJ18,AN18,AR18,AV18,AZ18,BD18)=0,"",SUM(L18,P18,T18,X18,AB18,AF18,AJ18,AN18,AR18,AV18,AZ18,BD18)) -> 1318.1427 | I18: =IF(OR(H$10="",H$10=0,H18=""),"",H18/H$10) -> 0.15142659 | J18: =IF(OR(D18=0,H18=""),"",H18/D18) -> 0.14370279 | K18: ='Monthly P&L'!D19 -> 764.39172 | L18: 658.26274 | M18: =IF(OR(L18="",K18=0),"",L18/K18) -> 0.86115891 | N18: =IF(OR(L18="",L$10="",L$10=0),"",L18/L$10) -> 0.15383994 | O18: ='Monthly P&L'!E19 -> 764.39172 | P18: 659.87997 | Q18: =IF(OR(P18="",O18=0),"",P18/O18) -> 0.86327462 | R18: =IF(OR(P18="",P$10="",P$10=0),"",P18/P$10) -> 0.14909343 | S18: ='Monthly P&L'!F19 -> 764.39172 | U18: =IF(OR(T18="",S18=0),"",T18/S18) | V18: =IF(OR(T18="",T$10="",T$10=0),"",T18/T$10) | W18: ='Monthly P&L'!G19 -> 764.39172 | Y18: =IF(OR(X18="",W18=0),"",X18/W18) | Z18: =IF(OR(X18="",X$10="",X$10=0),"",X18/X$10) | AA18: ='Monthly P&L'!H19 -> 764.39172 | AC18: =IF(OR(AB18="",AA18=0),"",AB18/AA18) | AD18: =IF(OR(AB18="",AB$10="",AB$10=0),"",AB18/AB$10) | AE18: ='Monthly P&L'!I19 -> 764.39172 | AG18: =IF(OR(AF18="",AE18=0),"",AF18/AE18) | AH18: =IF(OR(AF18="",AF$10="",AF$10=0),"",AF18/AF$10) | AI18: ='Monthly P&L'!J19 -> 764.39172 | AK18: =IF(OR(AJ18="",AI18=0),"",AJ18/AI18) | AL18: =IF(OR(AJ18="",AJ$10="",AJ$10=0),"",AJ18/AJ$10) | AM18: ='Monthly P&L'!K19 -> 764.39172 | AO18: =IF(OR(AN18="",AM18=0),"",AN18/AM18) | AP18: =IF(OR(AN18="",AN$10="",AN$10=0),"",AN18/AN$10) | AQ18: ='Monthly P&L'!L19 -> 764.39172 | AS18: =IF(OR(AR18="",AQ18=0),"",AR18/AQ18) | AT18: =IF(OR(AR18="",AR$10="",AR$10=0),"",AR18/AR$10) | AU18: ='Monthly P&L'!M19 -> 764.39172 | AW18: =IF(OR(AV18="",AU18=0),"",AV18/AU18) | AX18: =IF(OR(AV18="",AV$10="",AV$10=0),"",AV18/AV$10) | AY18: ='Monthly P&L'!N19 -> 764.39172 | BA18: =IF(OR(AZ18="",AY18=0),"",AZ18/AY18) | BB18: =IF(OR(AZ18="",AZ$10="",AZ$10=0),"",AZ18/AZ$10) | BC18: ='Monthly P&L'!O19 -> 764.39172 | BE18: =IF(OR(BD18="",BC18=0),"",BD18/BC18) | BF18: =IF(OR(BD18="",BD$10="",BD$10=0),"",BD18/BD$10)
A19: Utilities & Power | B19: ='Monthly P&L'!B20 -> 1190.744 | C19: =IF(OR(B19=0,B19=""),"",D19/B19-1) -> 0.19748659 | D19: ='Monthly P&L'!C20 -> 1425.9 | E19: =IF(D$10=0,"",D19/D$10) -> 0.024789035 | F19: =IF(H19="","",K19*(L19<>"")+O19*(P19<>"")+S19*(T19<>"")+W19*(X19<>"")+AA19*(AB19<>"")+AE19*(AF19<>"")+AI19*(AJ19<>"")+AM19*(AN19<>"")+AQ19*(AR19<>"")+AU19*(AV19<>"")+AY19*(AZ19<>"")+BC19*(BD19<>"")) -> 221.00486 | G19: =IF(OR(F19=0,F19="",H19=""),"",H19/F19) -> 0.96621736 | H19: =IF(SUM(L19,P19,T19,X19,AB19,AF19,AJ19,AN19,AR19,AV19,AZ19,BD19)=0,"",SUM(L19,P19,T19,X19,AB19,AF19,AJ19,AN19,AR19,AV19,AZ19,BD19)) -> 213.53873 | I19: =IF(OR(H$10="",H$10=0,H19=""),"",H19/H$10) -> 0.024531062 | J19: =IF(OR(D19=0,H19=""),"",H19/D19) -> 0.14975716 | K19: ='Monthly P&L'!D20 -> 106.51425 | L19: 108.91587 | M19: =IF(OR(L19="",K19=0),"",L19/K19) -> 1.0225474 | N19: =IF(OR(L19="",L$10="",L$10=0),"",L19/L$10) -> 0.02545429 | O19: ='Monthly P&L'!E20 -> 114.4906 | P19: 104.62286 | Q19: =IF(OR(P19="",O19=0),"",P19/O19) -> 0.91381177 | R19: =IF(OR(P19="",P$10="",P$10=0),"",P19/P$10) -> 0.023638512 | S19: ='Monthly P&L'!F20 -> 125.70903 | U19: =IF(OR(T19="",S19=0),"",T19/S19) | V19: =IF(OR(T19="",T$10="",T$10=0),"",T19/T$10) | W19: ='Monthly P&L'!G20 -> 117.11542 | Y19: =IF(OR(X19="",W19=0),"",X19/W19) | Z19: =IF(OR(X19="",X$10="",X$10=0),"",X19/X$10) | AA19: ='Monthly P&L'!H20 -> 108.99724 | AC19: =IF(OR(AB19="",AA19=0),"",AB19/AA19) | AD19: =IF(OR(AB19="",AB$10="",AB$10=0),"",AB19/AB$10) | AE19: ='Monthly P&L'!I20 -> 117.12588 | AG19: =IF(OR(AF19="",AE19=0),"",AF19/AE19) | AH19: =IF(OR(AF19="",AF$10="",AF$10=0),"",AF19/AF$10) | AI19: ='Monthly P&L'!J20 -> 130.7755 | AK19: =IF(OR(AJ19="",AI19=0),"",AJ19/AI19) | AL19: =IF(OR(AJ19="",AJ$10="",AJ$10=0),"",AJ19/AJ$10) | AM19: ='Monthly P&L'!K20 -> 106.15133 | AO19: =IF(OR(AN19="",AM19=0),"",AN19/AM19) | AP19: =IF(OR(AN19="",AN$10="",AN$10=0),"",AN19/AN$10) | AQ19: ='Monthly P&L'!L20 -> 118.14686 | AS19: =IF(OR(AR19="",AQ19=0),"",AR19/AQ19) | AT19: =IF(OR(AR19="",AR$10="",AR$10=0),"",AR19/AR$10) | AU19: ='Monthly P&L'!M20 -> 125.67155 | AW19: =IF(OR(AV19="",AU19=0),"",AV19/AU19) | AX19: =IF(OR(AV19="",AV$10="",AV$10=0),"",AV19/AV$10) | AY19: ='Monthly P&L'!N20 -> 109.14156 | BA19: =IF(OR(AZ19="",AY19=0),"",AZ19/AY19) | BB19: =IF(OR(AZ19="",AZ$10="",AZ$10=0),"",AZ19/AZ$10) | BC19: ='Monthly P&L'!O20 -> 146.06078 | BE19: =IF(OR(BD19="",BC19=0),"",BD19/BC19) | BF19: =IF(OR(BD19="",BD$10="",BD$10=0),"",BD19/BD$10)
A20: Lab Test Charges | B20: ='Monthly P&L'!B21 -> 267.69115 | C20: =IF(OR(B20=0,B20=""),"",D20/B20-1) -> 0.049717187 | D20: ='Monthly P&L'!C21 -> 281 | E20: =IF(D$10=0,"",D20/D$10) -> 0.0048851384 | F20: =IF(H20="","",K20*(L20<>"")+O20*(P20<>"")+S20*(T20<>"")+W20*(X20<>"")+AA20*(AB20<>"")+AE20*(AF20<>"")+AI20*(AJ20<>"")+AM20*(AN20<>"")+AQ20*(AR20<>"")+AU20*(AV20<>"")+AY20*(AZ20<>"")+BC20*(BD20<>"")) -> 37.149869 | G20: =IF(OR(F20=0,F20="",H20=""),"",H20/F20) -> 1.4429022 | H20: =IF(SUM(L20,P20,T20,X20,AB20,AF20,AJ20,AN20,AR20,AV20,AZ20,BD20)=0,"",SUM(L20,P20,T20,X20,AB20,AF20,AJ20,AN20,AR20,AV20,AZ20,BD20)) -> 53.603629 | I20: =IF(OR(H$10="",H$10=0,H20=""),"",H20/H$10) -> 0.006157918 | J20: =IF(OR(D20=0,H20=""),"",H20/D20) -> 0.19076025 | K20: ='Monthly P&L'!D21 -> 17.614643 | L20: 24.101609 | M20: =IF(OR(L20="",K20=0),"",L20/K20) -> 1.3682713 | N20: =IF(OR(L20="",L$10="",L$10=0),"",L20/L$10) -> 0.0056326903 | O20: ='Monthly P&L'!E21 -> 19.535226 | P20: 29.50202 | Q20: =IF(OR(P20="",O20=0),"",P20/O20) -> 1.510196 | R20: =IF(OR(P20="",P$10="",P$10=0),"",P20/P$10) -> 0.0066656929 | S20: ='Monthly P&L'!F21 -> 22.497812 | U20: =IF(OR(T20="",S20=0),"",T20/S20) | V20: =IF(OR(T20="",T$10="",T$10=0),"",T20/T$10) | W20: ='Monthly P&L'!G21 -> 19.284869 | Y20: =IF(OR(X20="",W20=0),"",X20/W20) | Z20: =IF(OR(X20="",X$10="",X$10=0),"",X20/X$10) | AA20: ='Monthly P&L'!H21 -> 27.862517 | AC20: =IF(OR(AB20="",AA20=0),"",AB20/AA20) | AD20: =IF(OR(AB20="",AB$10="",AB$10=0),"",AB20/AB$10) | AE20: ='Monthly P&L'!I21 -> 17.60298 | AG20: =IF(OR(AF20="",AE20=0),"",AF20/AE20) | AH20: =IF(OR(AF20="",AF$10="",AF$10=0),"",AF20/AF$10) | AI20: ='Monthly P&L'!J21 -> 23.917082 | AK20: =IF(OR(AJ20="",AI20=0),"",AJ20/AI20) | AL20: =IF(OR(AJ20="",AJ$10="",AJ$10=0),"",AJ20/AJ$10) | AM20: ='Monthly P&L'!K21 -> 9.6772168 | AO20: =IF(OR(AN20="",AM20=0),"",AN20/AM20) | AP20: =IF(OR(AN20="",AN$10="",AN$10=0),"",AN20/AN$10) | AQ20: ='Monthly P&L'!L21 -> 39.487348 | AS20: =IF(OR(AR20="",AQ20=0),"",AR20/AQ20) | AT20: =IF(OR(AR20="",AR$10="",AR$10=0),"",AR20/AR$10) | AU20: ='Monthly P&L'!M21 -> 31.569099 | AW20: =IF(OR(AV20="",AU20=0),"",AV20/AU20) | AX20: =IF(OR(AV20="",AV$10="",AV$10=0),"",AV20/AV$10) | AY20: ='Monthly P&L'!N21 -> 28.746253 | BA20: =IF(OR(AZ20="",AY20=0),"",AZ20/AY20) | BB20: =IF(OR(AZ20="",AZ$10="",AZ$10=0),"",AZ20/AZ$10) | BC20: ='Monthly P&L'!O21 -> 23.204954 | BE20: =IF(OR(BD20="",BC20=0),"",BD20/BC20) | BF20: =IF(OR(BD20="",BD$10="",BD$10=0),"",BD20/BD$10)
A21: Rent Paid | B21: ='Monthly P&L'!B22 -> 279.27305 | C21: =IF(OR(B21=0,B21=""),"",D21/B21-1) -> -0.25413497 | D21: ='Monthly P&L'!C22 -> 208.3 | E21: =IF(D$10=0,"",D21/D$10) -> 0.003621261 | F21: =IF(H21="","",K21*(L21<>"")+O21*(P21<>"")+S21*(T21<>"")+W21*(X21<>"")+AA21*(AB21<>"")+AE21*(AF21<>"")+AI21*(AJ21<>"")+AM21*(AN21<>"")+AQ21*(AR21<>"")+AU21*(AV21<>"")+AY21*(AZ21<>"")+BC21*(BD21<>"")) -> 32.305533 | G21: =IF(OR(F21=0,F21="",H21=""),"",H21/F21) -> 1.4168109 | H21: =IF(SUM(L21,P21,T21,X21,AB21,AF21,AJ21,AN21,AR21,AV21,AZ21,BD21)=0,"",SUM(L21,P21,T21,X21,AB21,AF21,AJ21,AN21,AR21,AV21,AZ21,BD21)) -> 45.77083 | I21: =IF(OR(H$10="",H$10=0,H21=""),"",H21/H$10) -> 0.0052580957 | J21: =IF(OR(D21=0,H21=""),"",H21/D21) -> 0.21973514 | K21: ='Monthly P&L'!D22 -> 16.634946 | L21: 22.68199 | M21: =IF(OR(L21="",K21=0),"",L21/K21) -> 1.3635145 | N21: =IF(OR(L21="",L$10="",L$10=0),"",L21/L$10) -> 0.0053009167 | O21: ='Monthly P&L'!E22 -> 15.670587 | P21: 23.08884 | Q21: =IF(OR(P21="",O21=0),"",P21/O21) -> 1.4733871 | R21: =IF(OR(P21="",P$10="",P$10=0),"",P21/P$10) -> 0.0052166976 | S21: ='Monthly P&L'!F22 -> 17.61895 | U21: =IF(OR(T21="",S21=0),"",T21/S21) | V21: =IF(OR(T21="",T$10="",T$10=0),"",T21/T$10) | W21: ='Monthly P&L'!G22 -> 12.414811 | Y21: =IF(OR(X21="",W21=0),"",X21/W21) | Z21: =IF(OR(X21="",X$10="",X$10=0),"",X21/X$10) | AA21: ='Monthly P&L'!H22 -> 19.683796 | AC21: =IF(OR(AB21="",AA21=0),"",AB21/AA21) | AD21: =IF(OR(AB21="",AB$10="",AB$10=0),"",AB21/AB$10) | AE21: ='Monthly P&L'!I22 -> 19.513104 | AG21: =IF(OR(AF21="",AE21=0),"",AF21/AE21) | AH21: =IF(OR(AF21="",AF$10="",AF$10=0),"",AF21/AF$10) | AI21: ='Monthly P&L'!J22 -> 15.669426 | AK21: =IF(OR(AJ21="",AI21=0),"",AJ21/AI21) | AL21: =IF(OR(AJ21="",AJ$10="",AJ$10=0),"",AJ21/AJ$10) | AM21: ='Monthly P&L'!K22 -> 15.549287 | AO21: =IF(OR(AN21="",AM21=0),"",AN21/AM21) | AP21: =IF(OR(AN21="",AN$10="",AN$10=0),"",AN21/AN$10) | AQ21: ='Monthly P&L'!L22 -> 18.107216 | AS21: =IF(OR(AR21="",AQ21=0),"",AR21/AQ21) | AT21: =IF(OR(AR21="",AR$10="",AR$10=0),"",AR21/AR$10) | AU21: ='Monthly P&L'!M22 -> 17.154054 | AW21: =IF(OR(AV21="",AU21=0),"",AV21/AU21) | AX21: =IF(OR(AV21="",AV$10="",AV$10=0),"",AV21/AV$10) | AY21: ='Monthly P&L'!N22 -> 17.050806 | BA21: =IF(OR(AZ21="",AY21=0),"",AZ21/AY21) | BB21: =IF(OR(AZ21="",AZ$10="",AZ$10=0),"",AZ21/AZ$10) | BC21: ='Monthly P&L'!O22 -> 23.233017 | BE21: =IF(OR(BD21="",BC21=0),"",BD21/BC21) | BF21: =IF(OR(BD21="",BD$10="",BD$10=0),"",BD21/BD$10)
A22: Repair & Maintenance | B22: ='Monthly P&L'!B23 -> 1559.2231 | C22: =IF(OR(B22=0,B22=""),"",D22/B22-1) -> 0.048849239 | D22: ='Monthly P&L'!C23 -> 1635.39 | E22: =IF(D$10=0,"",D22/D$10) -> 0.028430984 | F22: =IF(H22="","",K22*(L22<>"")+O22*(P22<>"")+S22*(T22<>"")+W22*(X22<>"")+AA22*(AB22<>"")+AE22*(AF22<>"")+AI22*(AJ22<>"")+AM22*(AN22<>"")+AQ22*(AR22<>"")+AU22*(AV22<>"")+AY22*(AZ22<>"")+BC22*(BD22<>"")) -> 184.52 | G22: =IF(OR(F22=0,F22="",H22=""),"",H22/F22) -> 1.051622 | H22: =IF(SUM(L22,P22,T22,X22,AB22,AF22,AJ22,AN22,AR22,AV22,AZ22,BD22)=0,"",SUM(L22,P22,T22,X22,AB22,AF22,AJ22,AN22,AR22,AV22,AZ22,BD22)) -> 194.04528 | I22: =IF(OR(H$10="",H$10=0,H22=""),"",H22/H$10) -> 0.02229168 | J22: =IF(OR(D22=0,H22=""),"",H22/D22) -> 0.11865383 | K22: ='Monthly P&L'!D23 -> 84.96 | L22: 114.68122 | M22: =IF(OR(L22="",K22=0),"",L22/K22) -> 1.349826 | N22: =IF(OR(L22="",L$10="",L$10=0),"",L22/L$10) -> 0.026801687 | O22: ='Monthly P&L'!E23 -> 99.56 | P22: 79.364062 | Q22: =IF(OR(P22="",O22=0),"",P22/O22) -> 0.79714808 | R22: =IF(OR(P22="",P$10="",P$10=0),"",P22/P$10) -> 0.017931534 | S22: ='Monthly P&L'!F23 -> 132.21 | U22: =IF(OR(T22="",S22=0),"",T22/S22) | V22: =IF(OR(T22="",T$10="",T$10=0),"",T22/T$10) | W22: ='Monthly P&L'!G23 -> 132.29 | Y22: =IF(OR(X22="",W22=0),"",X22/W22) | Z22: =IF(OR(X22="",X$10="",X$10=0),"",X22/X$10) | AA22: ='Monthly P&L'!H23 -> 143.62 | AC22: =IF(OR(AB22="",AA22=0),"",AB22/AA22) | AD22: =IF(OR(AB22="",AB$10="",AB$10=0),"",AB22/AB$10) | AE22: ='Monthly P&L'!I23 -> 158.24 | AG22: =IF(OR(AF22="",AE22=0),"",AF22/AE22) | AH22: =IF(OR(AF22="",AF$10="",AF$10=0),"",AF22/AF$10) | AI22: ='Monthly P&L'!J23 -> 163.31 | AK22: =IF(OR(AJ22="",AI22=0),"",AJ22/AI22) | AL22: =IF(OR(AJ22="",AJ$10="",AJ$10=0),"",AJ22/AJ$10) | AM22: ='Monthly P&L'!K23 -> 134.81 | AO22: =IF(OR(AN22="",AM22=0),"",AN22/AM22) | AP22: =IF(OR(AN22="",AN$10="",AN$10=0),"",AN22/AN$10) | AQ22: ='Monthly P&L'!L23 -> 109.05 | AS22: =IF(OR(AR22="",AQ22=0),"",AR22/AQ22) | AT22: =IF(OR(AR22="",AR$10="",AR$10=0),"",AR22/AR$10) | AU22: ='Monthly P&L'!M23 -> 98.93 | AW22: =IF(OR(AV22="",AU22=0),"",AV22/AU22) | AX22: =IF(OR(AV22="",AV$10="",AV$10=0),"",AV22/AV$10) | AY22: ='Monthly P&L'!N23 -> 189.56 | BA22: =IF(OR(AZ22="",AY22=0),"",AZ22/AY22) | BB22: =IF(OR(AZ22="",AZ$10="",AZ$10=0),"",AZ22/AZ$10) | BC22: ='Monthly P&L'!O23 -> 188.85 | BE22: =IF(OR(BD22="",BC22=0),"",BD22/BC22) | BF22: =IF(OR(BD22="",BD$10="",BD$10=0),"",BD22/BD$10)
A23: Housekeeping | B23: ='Monthly P&L'!B24 -> 1011.1753 | C23: =IF(OR(B23=0,B23=""),"",D23/B23-1) -> 0.17091471 | D23: ='Monthly P&L'!C24 -> 1184 | E23: =IF(D$10=0,"",D23/D$10) -> 0.020583644 | F23: =IF(H23="","",K23*(L23<>"")+O23*(P23<>"")+S23*(T23<>"")+W23*(X23<>"")+AA23*(AB23<>"")+AE23*(AF23<>"")+AI23*(AJ23<>"")+AM23*(AN23<>"")+AQ23*(AR23<>"")+AU23*(AV23<>"")+AY23*(AZ23<>"")+BC23*(BD23<>"")) -> 156.93586 | G23: =IF(OR(F23=0,F23="",H23=""),"",H23/F23) -> 1.2959928 | H23: =IF(SUM(L23,P23,T23,X23,AB23,AF23,AJ23,AN23,AR23,AV23,AZ23,BD23)=0,"",SUM(L23,P23,T23,X23,AB23,AF23,AJ23,AN23,AR23,AV23,AZ23,BD23)) -> 203.38774 | I23: =IF(OR(H$10="",H$10=0,H23=""),"",H23/H$10) -> 0.02336493 | J23: =IF(OR(D23=0,H23=""),"",H23/D23) -> 0.17178019 | K23: ='Monthly P&L'!D24 -> 72.842371 | L23: 89.327925 | M23: =IF(OR(L23="",K23=0),"",L23/K23) -> 1.2263182 | N23: =IF(OR(L23="",L$10="",L$10=0),"",L23/L$10) -> 0.02087647 | O23: ='Monthly P&L'!E24 -> 84.093491 | P23: 114.05982 | Q23: =IF(OR(P23="",O23=0),"",P23/O23) -> 1.3563454 | R23: =IF(OR(P23="",P$10="",P$10=0),"",P23/P$10) -> 0.025770701 | S23: ='Monthly P&L'!F24 -> 101.11201 | U23: =IF(OR(T23="",S23=0),"",T23/S23) | V23: =IF(OR(T23="",T$10="",T$10=0),"",T23/T$10) | W23: ='Monthly P&L'!G24 -> 87.15006 | Y23: =IF(OR(X23="",W23=0),"",X23/W23) | Z23: =IF(OR(X23="",X$10="",X$10=0),"",X23/X$10) | AA23: ='Monthly P&L'!H24 -> 79.411635 | AC23: =IF(OR(AB23="",AA23=0),"",AB23/AA23) | AD23: =IF(OR(AB23="",AB$10="",AB$10=0),"",AB23/AB$10) | AE23: ='Monthly P&L'!I24 -> 87.829971 | AG23: =IF(OR(AF23="",AE23=0),"",AF23/AE23) | AH23: =IF(OR(AF23="",AF$10="",AF$10=0),"",AF23/AF$10) | AI23: ='Monthly P&L'!J24 -> 103.13467 | AK23: =IF(OR(AJ23="",AI23=0),"",AJ23/AI23) | AL23: =IF(OR(AJ23="",AJ$10="",AJ$10=0),"",AJ23/AJ$10) | AM23: ='Monthly P&L'!K24 -> 74.265622 | AO23: =IF(OR(AN23="",AM23=0),"",AN23/AM23) | AP23: =IF(OR(AN23="",AN$10="",AN$10=0),"",AN23/AN$10) | AQ23: ='Monthly P&L'!L24 -> 79.782965 | AS23: =IF(OR(AR23="",AQ23=0),"",AR23/AQ23) | AT23: =IF(OR(AR23="",AR$10="",AR$10=0),"",AR23/AR$10) | AU23: ='Monthly P&L'!M24 -> 57.876277 | AW23: =IF(OR(AV23="",AU23=0),"",AV23/AU23) | AX23: =IF(OR(AV23="",AV$10="",AV$10=0),"",AV23/AV$10) | AY23: ='Monthly P&L'!N24 -> 141.54075 | BA23: =IF(OR(AZ23="",AY23=0),"",AZ23/AY23) | BB23: =IF(OR(AZ23="",AZ$10="",AZ$10=0),"",AZ23/AZ$10) | BC23: ='Monthly P&L'!O24 -> 214.96018 | BE23: =IF(OR(BD23="",BC23=0),"",BD23/BC23) | BF23: =IF(OR(BD23="",BD$10="",BD$10=0),"",BD23/BD$10)
A24: Security | B24: ='Monthly P&L'!B25 -> 265.1163 | C24: =IF(OR(B24=0,B24=""),"",D24/B24-1) -> 0.3914648 | D24: ='Monthly P&L'!C25 -> 368.9 | E24: =IF(D$10=0,"",D24/D$10) -> 0.0064132653 | F24: =IF(H24="","",K24*(L24<>"")+O24*(P24<>"")+S24*(T24<>"")+W24*(X24<>"")+AA24*(AB24<>"")+AE24*(AF24<>"")+AI24*(AJ24<>"")+AM24*(AN24<>"")+AQ24*(AR24<>"")+AU24*(AV24<>"")+AY24*(AZ24<>"")+BC24*(BD24<>"")) -> 61.772591 | G24: =IF(OR(F24=0,F24="",H24=""),"",H24/F24) -> 0.6942119 | H24: =IF(SUM(L24,P24,T24,X24,AB24,AF24,AJ24,AN24,AR24,AV24,AZ24,BD24)=0,"",SUM(L24,P24,T24,X24,AB24,AF24,AJ24,AN24,AR24,AV24,AZ24,BD24)) -> 42.883268 | I24: =IF(OR(H$10="",H$10=0,H24=""),"",H24/H$10) -> 0.0049263762 | J24: =IF(OR(D24=0,H24=""),"",H24/D24) -> 0.11624632 | K24: ='Monthly P&L'!D25 -> 28.914527 | L24: 24.095348 | M24: =IF(OR(L24="",K24=0),"",L24/K24) -> 0.83333016 | N24: =IF(OR(L24="",L$10="",L$10=0),"",L24/L$10) -> 0.0056312269 | O24: ='Monthly P&L'!E25 -> 32.858064 | P24: 18.78792 | Q24: =IF(OR(P24="",O24=0),"",P24/O24) -> 0.57179024 | R24: =IF(OR(P24="",P$10="",P$10=0),"",P24/P$10) -> 0.0042449468 | S24: ='Monthly P&L'!F25 -> 32.858064 | U24: =IF(OR(T24="",S24=0),"",T24/S24) | V24: =IF(OR(T24="",T$10="",T$10=0),"",T24/T$10) | W24: ='Monthly P&L'!G25 -> 32.454901 | Y24: =IF(OR(X24="",W24=0),"",X24/W24) | Z24: =IF(OR(X24="",X$10="",X$10=0),"",X24/X$10) | AA24: ='Monthly P&L'!H25 -> 27.57367 | AC24: =IF(OR(AB24="",AA24=0),"",AB24/AA24) | AD24: =IF(OR(AB24="",AB$10="",AB$10=0),"",AB24/AB$10) | AE24: ='Monthly P&L'!I25 -> 26.491382 | AG24: =IF(OR(AF24="",AE24=0),"",AF24/AE24) | AH24: =IF(OR(AF24="",AF$10="",AF$10=0),"",AF24/AF$10) | AI24: ='Monthly P&L'!J25 -> 35.5005 | AK24: =IF(OR(AJ24="",AI24=0),"",AJ24/AI24) | AL24: =IF(OR(AJ24="",AJ$10="",AJ$10=0),"",AJ24/AJ$10) | AM24: ='Monthly P&L'!K25 -> 29.279706 | AO24: =IF(OR(AN24="",AM24=0),"",AN24/AM24) | AP24: =IF(OR(AN24="",AN$10="",AN$10=0),"",AN24/AN$10) | AQ24: ='Monthly P&L'!L25 -> 29.746206 | AS24: =IF(OR(AR24="",AQ24=0),"",AR24/AQ24) | AT24: =IF(OR(AR24="",AR$10="",AR$10=0),"",AR24/AR$10) | AU24: ='Monthly P&L'!M25 -> 31.465653 | AW24: =IF(OR(AV24="",AU24=0),"",AV24/AU24) | AX24: =IF(OR(AV24="",AV$10="",AV$10=0),"",AV24/AV$10) | AY24: ='Monthly P&L'!N25 -> 29.391243 | BA24: =IF(OR(AZ24="",AY24=0),"",AZ24/AY24) | BB24: =IF(OR(AZ24="",AZ$10="",AZ$10=0),"",AZ24/AZ$10) | BC24: ='Monthly P&L'!O25 -> 32.366085 | BE24: =IF(OR(BD24="",BC24=0),"",BD24/BC24) | BF24: =IF(OR(BD24="",BD$10="",BD$10=0),"",BD24/BD$10)
A25: Printing & Stationery | B25: ='Monthly P&L'!B26 -> 182.70992 | C25: =IF(OR(B25=0,B25=""),"",D25/B25-1) -> -0.089814056 | D25: ='Monthly P&L'!C26 -> 166.3 | E25: =IF(D$10=0,"",D25/D$10) -> 0.0028910979 | F25: =IF(H25="","",K25*(L25<>"")+O25*(P25<>"")+S25*(T25<>"")+W25*(X25<>"")+AA25*(AB25<>"")+AE25*(AF25<>"")+AI25*(AJ25<>"")+AM25*(AN25<>"")+AQ25*(AR25<>"")+AU25*(AV25<>"")+AY25*(AZ25<>"")+BC25*(BD25<>"")) -> 26.211723 | G25: =IF(OR(F25=0,F25="",H25=""),"",H25/F25) -> 1.407712 | H25: =IF(SUM(L25,P25,T25,X25,AB25,AF25,AJ25,AN25,AR25,AV25,AZ25,BD25)=0,"",SUM(L25,P25,T25,X25,AB25,AF25,AJ25,AN25,AR25,AV25,AZ25,BD25)) -> 36.898556 | I25: =IF(OR(H$10="",H$10=0,H25=""),"",H25/H$10) -> 0.0042388601 | J25: =IF(OR(D25=0,H25=""),"",H25/D25) -> 0.22187947 | K25: ='Monthly P&L'!D26 -> 10.388101 | L25: 18.924059 | M25: =IF(OR(L25="",K25=0),"",L25/K25) -> 1.8217054 | N25: =IF(OR(L25="",L$10="",L$10=0),"",L25/L$10) -> 0.0044226659 | O25: ='Monthly P&L'!E26 -> 15.823622 | P25: 17.974497 | Q25: =IF(OR(P25="",O25=0),"",P25/O25) -> 1.1359281 | R25: =IF(OR(P25="",P$10="",P$10=0),"",P25/P$10) -> 0.0040611618 | S25: ='Monthly P&L'!F26 -> 12.298557 | U25: =IF(OR(T25="",S25=0),"",T25/S25) | V25: =IF(OR(T25="",T$10="",T$10=0),"",T25/T$10) | W25: ='Monthly P&L'!G26 -> 15.191548 | Y25: =IF(OR(X25="",W25=0),"",X25/W25) | Z25: =IF(OR(X25="",X$10="",X$10=0),"",X25/X$10) | AA25: ='Monthly P&L'!H26 -> 12.674734 | AC25: =IF(OR(AB25="",AA25=0),"",AB25/AA25) | AD25: =IF(OR(AB25="",AB$10="",AB$10=0),"",AB25/AB$10) | AE25: ='Monthly P&L'!I26 -> 13.101131 | AG25: =IF(OR(AF25="",AE25=0),"",AF25/AE25) | AH25: =IF(OR(AF25="",AF$10="",AF$10=0),"",AF25/AF$10) | AI25: ='Monthly P&L'!J26 -> 16.453661 | AK25: =IF(OR(AJ25="",AI25=0),"",AJ25/AI25) | AL25: =IF(OR(AJ25="",AJ$10="",AJ$10=0),"",AJ25/AJ$10) | AM25: ='Monthly P&L'!K26 -> 10.592546 | AO25: =IF(OR(AN25="",AM25=0),"",AN25/AM25) | AP25: =IF(OR(AN25="",AN$10="",AN$10=0),"",AN25/AN$10) | AQ25: ='Monthly P&L'!L26 -> 12.725547 | AS25: =IF(OR(AR25="",AQ25=0),"",AR25/AQ25) | AT25: =IF(OR(AR25="",AR$10="",AR$10=0),"",AR25/AR$10) | AU25: ='Monthly P&L'!M26 -> 12.94168 | AW25: =IF(OR(AV25="",AU25=0),"",AV25/AU25) | AX25: =IF(OR(AV25="",AV$10="",AV$10=0),"",AV25/AV$10) | AY25: ='Monthly P&L'!N26 -> 16.412919 | BA25: =IF(OR(AZ25="",AY25=0),"",AZ25/AY25) | BB25: =IF(OR(AZ25="",AZ$10="",AZ$10=0),"",AZ25/AZ$10) | BC25: ='Monthly P&L'!O26 -> 17.695954 | BE25: =IF(OR(BD25="",BC25=0),"",BD25/BC25) | BF25: =IF(OR(BD25="",BD$10="",BD$10=0),"",BD25/BD$10)
A26: Insurance | B26: ='Monthly P&L'!B27 -> 31.991355 | C26: =IF(OR(B26=0,B26=""),"",D26/B26-1) -> 0.12217815 | D26: ='Monthly P&L'!C27 -> 35.9 | E26: =IF(D$10=0,"",D26/D$10) -> 0.00062411555 | F26: =IF(H26="","",K26*(L26<>"")+O26*(P26<>"")+S26*(T26<>"")+W26*(X26<>"")+AA26*(AB26<>"")+AE26*(AF26<>"")+AI26*(AJ26<>"")+AM26*(AN26<>"")+AQ26*(AR26<>"")+AU26*(AV26<>"")+AY26*(AZ26<>"")+BC26*(BD26<>"")) -> 5.2335674 | G26: =IF(OR(F26=0,F26="",H26=""),"",H26/F26) -> 1.2084354 | H26: =IF(SUM(L26,P26,T26,X26,AB26,AF26,AJ26,AN26,AR26,AV26,AZ26,BD26)=0,"",SUM(L26,P26,T26,X26,AB26,AF26,AJ26,AN26,AR26,AV26,AZ26,BD26)) -> 6.3244283 | I26: =IF(OR(H$10="",H$10=0,H26=""),"",H26/H$10) -> 0.00072654242 | J26: =IF(OR(D26=0,H26=""),"",H26/D26) -> 0.17616792 | K26: ='Monthly P&L'!D27 -> 2.5586521 | L26: 3.0348463 | M26: =IF(OR(L26="",K26=0),"",L26/K26) -> 1.1861113 | N26: =IF(OR(L26="",L$10="",L$10=0),"",L26/L$10) -> 0.00070926175 | O26: ='Monthly P&L'!E27 -> 2.6749153 | P26: 3.289582 | Q26: =IF(OR(P26="",O26=0),"",P26/O26) -> 1.2297892 | R26: =IF(OR(P26="",P$10="",P$10=0),"",P26/P$10) -> 0.00074324889 | S26: ='Monthly P&L'!F27 -> 2.1797664 | U26: =IF(OR(T26="",S26=0),"",T26/S26) | V26: =IF(OR(T26="",T$10="",T$10=0),"",T26/T$10) | W26: ='Monthly P&L'!G27 -> 2.069981 | Y26: =IF(OR(X26="",W26=0),"",X26/W26) | Z26: =IF(OR(X26="",X$10="",X$10=0),"",X26/X$10) | AA26: ='Monthly P&L'!H27 -> 2.9522487 | AC26: =IF(OR(AB26="",AA26=0),"",AB26/AA26) | AD26: =IF(OR(AB26="",AB$10="",AB$10=0),"",AB26/AB$10) | AE26: ='Monthly P&L'!I27 -> 3.8088144 | AG26: =IF(OR(AF26="",AE26=0),"",AF26/AE26) | AH26: =IF(OR(AF26="",AF$10="",AF$10=0),"",AF26/AF$10) | AI26: ='Monthly P&L'!J27 -> 3.0101004 | AK26: =IF(OR(AJ26="",AI26=0),"",AJ26/AI26) | AL26: =IF(OR(AJ26="",AJ$10="",AJ$10=0),"",AJ26/AJ$10) | AM26: ='Monthly P&L'!K27 -> 3.2638714 | AO26: =IF(OR(AN26="",AM26=0),"",AN26/AM26) | AP26: =IF(OR(AN26="",AN$10="",AN$10=0),"",AN26/AN$10) | AQ26: ='Monthly P&L'!L27 -> 3.5089919 | AS26: =IF(OR(AR26="",AQ26=0),"",AR26/AQ26) | AT26: =IF(OR(AR26="",AR$10="",AR$10=0),"",AR26/AR$10) | AU26: ='Monthly P&L'!M27 -> 3.0436151 | AW26: =IF(OR(AV26="",AU26=0),"",AV26/AU26) | AX26: =IF(OR(AV26="",AV$10="",AV$10=0),"",AV26/AV$10) | AY26: ='Monthly P&L'!N27 -> 3.242325 | BA26: =IF(OR(AZ26="",AY26=0),"",AZ26/AY26) | BB26: =IF(OR(AZ26="",AZ$10="",AZ$10=0),"",AZ26/AZ$10) | BC26: ='Monthly P&L'!O27 -> 3.5867181 | BE26: =IF(OR(BD26="",BC26=0),"",BD26/BC26) | BF26: =IF(OR(BD26="",BD$10="",BD$10=0),"",BD26/BD$10)
A27: Rates & Taxes | B27: ='Monthly P&L'!B28 -> 58.321304 | C27: =IF(OR(B27=0,B27=""),"",D27/B27-1) -> 0.12308875 | D27: ='Monthly P&L'!C28 -> 65.5 | E27: =IF(D$10=0,"",D27/D$10) -> 0.0011387066 | F27: =IF(H27="","",K27*(L27<>"")+O27*(P27<>"")+S27*(T27<>"")+W27*(X27<>"")+AA27*(AB27<>"")+AE27*(AF27<>"")+AI27*(AJ27<>"")+AM27*(AN27<>"")+AQ27*(AR27<>"")+AU27*(AV27<>"")+AY27*(AZ27<>"")+BC27*(BD27<>"")) -> 10.442583 | G27: =IF(OR(F27=0,F27="",H27=""),"",H27/F27) -> 0.2529366 | H27: =IF(SUM(L27,P27,T27,X27,AB27,AF27,AJ27,AN27,AR27,AV27,AZ27,BD27)=0,"",SUM(L27,P27,T27,X27,AB27,AF27,AJ27,AN27,AR27,AV27,AZ27,BD27)) -> 2.6413113 | I27: =IF(OR(H$10="",H$10=0,H27=""),"",H27/H$10) -> 0.00030343055 | J27: =IF(OR(D27=0,H27=""),"",H27/D27) -> 0.040325364 | K27: ='Monthly P&L'!D28 -> 3.8349731 | L27: 1.311025 | M27: =IF(OR(L27="",K27=0),"",L27/K27) -> 0.3418603 | N27: =IF(OR(L27="",L$10="",L$10=0),"",L27/L$10) -> 0.00030639439 | O27: ='Monthly P&L'!E28 -> 6.6076095 | P27: 1.3302863 | Q27: =IF(OR(P27="",O27=0),"",P27/O27) -> 0.20132641 | R27: =IF(OR(P27="",P$10="",P$10=0),"",P27/P$10) -> 0.00030056518 | S27: ='Monthly P&L'!F28 -> 4.9727993 | U27: =IF(OR(T27="",S27=0),"",T27/S27) | V27: =IF(OR(T27="",T$10="",T$10=0),"",T27/T$10) | W27: ='Monthly P&L'!G28 -> 6.8288177 | Y27: =IF(OR(X27="",W27=0),"",X27/W27) | Z27: =IF(OR(X27="",X$10="",X$10=0),"",X27/X$10) | AA27: ='Monthly P&L'!H28 -> 3.3504462 | AC27: =IF(OR(AB27="",AA27=0),"",AB27/AA27) | AD27: =IF(OR(AB27="",AB$10="",AB$10=0),"",AB27/AB$10) | AE27: ='Monthly P&L'!I28 -> 1.8130073 | AG27: =IF(OR(AF27="",AE27=0),"",AF27/AE27) | AH27: =IF(OR(AF27="",AF$10="",AF$10=0),"",AF27/AF$10) | AI27: ='Monthly P&L'!J28 -> 10.612213 | AK27: =IF(OR(AJ27="",AI27=0),"",AJ27/AI27) | AL27: =IF(OR(AJ27="",AJ$10="",AJ$10=0),"",AJ27/AJ$10) | AM27: ='Monthly P&L'!K28 -> 1.8985126 | AO27: =IF(OR(AN27="",AM27=0),"",AN27/AM27) | AP27: =IF(OR(AN27="",AN$10="",AN$10=0),"",AN27/AN$10) | AQ27: ='Monthly P&L'!L28 -> 2.4640354 | AS27: =IF(OR(AR27="",AQ27=0),"",AR27/AQ27) | AT27: =IF(OR(AR27="",AR$10="",AR$10=0),"",AR27/AR$10) | AU27: ='Monthly P&L'!M28 -> 5.0194067 | AW27: =IF(OR(AV27="",AU27=0),"",AV27/AU27) | AX27: =IF(OR(AV27="",AV$10="",AV$10=0),"",AV27/AV$10) | AY27: ='Monthly P&L'!N28 -> 2.9702682 | BA27: =IF(OR(AZ27="",AY27=0),"",AZ27/AY27) | BB27: =IF(OR(AZ27="",AZ$10="",AZ$10=0),"",AZ27/AZ$10) | BC27: ='Monthly P&L'!O28 -> 15.127911 | BE27: =IF(OR(BD27="",BC27=0),"",BD27/BC27) | BF27: =IF(OR(BD27="",BD$10="",BD$10=0),"",BD27/BD$10)
A28: Professional Fee | B28: ='Monthly P&L'!B29 -> 201.10741 | C28: =IF(OR(B28=0,B28=""),"",D28/B28-1) -> 2.9779737 | D28: ='Monthly P&L'!C29 -> 800 | E28: =IF(D$10=0,"",D28/D$10) -> 0.013907867 | F28: =IF(H28="","",K28*(L28<>"")+O28*(P28<>"")+S28*(T28<>"")+W28*(X28<>"")+AA28*(AB28<>"")+AE28*(AF28<>"")+AI28*(AJ28<>"")+AM28*(AN28<>"")+AQ28*(AR28<>"")+AU28*(AV28<>"")+AY28*(AZ28<>"")+BC28*(BD28<>"")) -> 145.58 | G28: =IF(OR(F28=0,F28="",H28=""),"",H28/F28) -> 0.19800061 | H28: =IF(SUM(L28,P28,T28,X28,AB28,AF28,AJ28,AN28,AR28,AV28,AZ28,BD28)=0,"",SUM(L28,P28,T28,X28,AB28,AF28,AJ28,AN28,AR28,AV28,AZ28,BD28)) -> 28.824928 | I28: =IF(OR(H$10="",H$10=0,H28=""),"",H28/H$10) -> 0.0033113717 | J28: =IF(OR(D28=0,H28=""),"",H28/D28) -> 0.03603116 | K28: ='Monthly P&L'!D29 -> 69.46 | L28: 14.323616 | M28: =IF(OR(L28="",K28=0),"",L28/K28) -> 0.20621387 | N28: =IF(OR(L28="",L$10="",L$10=0),"",L28/L$10) -> 0.0033475146 | O28: ='Monthly P&L'!E29 -> 76.12 | P28: 14.501313 | Q28: =IF(OR(P28="",O28=0),"",P28/O28) -> 0.19050595 | R28: =IF(OR(P28="",P$10="",P$10=0),"",P28/P$10) -> 0.0032764298 | S28: ='Monthly P&L'!F29 -> 70.61 | U28: =IF(OR(T28="",S28=0),"",T28/S28) | V28: =IF(OR(T28="",T$10="",T$10=0),"",T28/T$10) | W28: ='Monthly P&L'!G29 -> 79.24 | Y28: =IF(OR(X28="",W28=0),"",X28/W28) | Z28: =IF(OR(X28="",X$10="",X$10=0),"",X28/X$10) | AA28: ='Monthly P&L'!H29 -> 62.89 | AC28: =IF(OR(AB28="",AA28=0),"",AB28/AA28) | AD28: =IF(OR(AB28="",AB$10="",AB$10=0),"",AB28/AB$10) | AE28: ='Monthly P&L'!I29 -> 61.45 | AG28: =IF(OR(AF28="",AE28=0),"",AF28/AE28) | AH28: =IF(OR(AF28="",AF$10="",AF$10=0),"",AF28/AF$10) | AI28: ='Monthly P&L'!J29 -> 56.15 | AK28: =IF(OR(AJ28="",AI28=0),"",AJ28/AI28) | AL28: =IF(OR(AJ28="",AJ$10="",AJ$10=0),"",AJ28/AJ$10) | AM28: ='Monthly P&L'!K29 -> 56.78 | AO28: =IF(OR(AN28="",AM28=0),"",AN28/AM28) | AP28: =IF(OR(AN28="",AN$10="",AN$10=0),"",AN28/AN$10) | AQ28: ='Monthly P&L'!L29 -> 49.93 | AS28: =IF(OR(AR28="",AQ28=0),"",AR28/AQ28) | AT28: =IF(OR(AR28="",AR$10="",AR$10=0),"",AR28/AR$10) | AU28: ='Monthly P&L'!M29 -> 59.1 | AW28: =IF(OR(AV28="",AU28=0),"",AV28/AU28) | AX28: =IF(OR(AV28="",AV$10="",AV$10=0),"",AV28/AV$10) | AY28: ='Monthly P&L'!N29 -> 72.08 | BA28: =IF(OR(AZ28="",AY28=0),"",AZ28/AY28) | BB28: =IF(OR(AZ28="",AZ$10="",AZ$10=0),"",AZ28/AZ$10) | BC28: ='Monthly P&L'!O29 -> 86.19 | BE28: =IF(OR(BD28="",BC28=0),"",BD28/BC28) | BF28: =IF(OR(BD28="",BD$10="",BD$10=0),"",BD28/BD$10)
A29: Quality & Infection | B29: ='Monthly P&L'!B30 -> 5.675688 | C29: =IF(OR(B29=0,B29=""),"",D29/B29-1) -> 0.10999759 | D29: ='Monthly P&L'!C30 -> 6.3 | E29: =IF(D$10=0,"",D29/D$10) -> 0.00010952446 | F29: =IF(H29="","",K29*(L29<>"")+O29*(P29<>"")+S29*(T29<>"")+W29*(X29<>"")+AA29*(AB29<>"")+AE29*(AF29<>"")+AI29*(AJ29<>"")+AM29*(AN29<>"")+AQ29*(AR29<>"")+AU29*(AV29<>"")+AY29*(AZ29<>"")+BC29*(BD29<>"")) | G29: =IF(OR(F29=0,F29="",H29=""),"",H29/F29) | H29: =IF(SUM(L29,P29,T29,X29,AB29,AF29,AJ29,AN29,AR29,AV29,AZ29,BD29)=0,"",SUM(L29,P29,T29,X29,AB29,AF29,AJ29,AN29,AR29,AV29,AZ29,BD29)) | I29: =IF(OR(H$10="",H$10=0,H29=""),"",H29/H$10) | J29: =IF(OR(D29=0,H29=""),"",H29/D29) | K29: ='Monthly P&L'!D30 -> 0 | L29: 0 | M29: =IF(OR(L29="",K29=0),"",L29/K29) | N29: =IF(OR(L29="",L$10="",L$10=0),"",L29/L$10) -> 0 | O29: ='Monthly P&L'!E30 -> 0 | P29: 0 | Q29: =IF(OR(P29="",O29=0),"",P29/O29) | R29: =IF(OR(P29="",P$10="",P$10=0),"",P29/P$10) -> 0 | S29: ='Monthly P&L'!F30 -> 0 | U29: =IF(OR(T29="",S29=0),"",T29/S29) | V29: =IF(OR(T29="",T$10="",T$10=0),"",T29/T$10) | W29: ='Monthly P&L'!G30 -> 0 | Y29: =IF(OR(X29="",W29=0),"",X29/W29) | Z29: =IF(OR(X29="",X$10="",X$10=0),"",X29/X$10) | AA29: ='Monthly P&L'!H30 -> 0 | AC29: =IF(OR(AB29="",AA29=0),"",AB29/AA29) | AD29: =IF(OR(AB29="",AB$10="",AB$10=0),"",AB29/AB$10) | AE29: ='Monthly P&L'!I30 -> 3.5221196 | AG29: =IF(OR(AF29="",AE29=0),"",AF29/AE29) | AH29: =IF(OR(AF29="",AF$10="",AF$10=0),"",AF29/AF$10) | AI29: ='Monthly P&L'!J30 -> 0 | AK29: =IF(OR(AJ29="",AI29=0),"",AJ29/AI29) | AL29: =IF(OR(AJ29="",AJ$10="",AJ$10=0),"",AJ29/AJ$10) | AM29: ='Monthly P&L'!K30 -> 2.1438989 | AO29: =IF(OR(AN29="",AM29=0),"",AN29/AM29) | AP29: =IF(OR(AN29="",AN$10="",AN$10=0),"",AN29/AN$10) | AQ29: ='Monthly P&L'!L30 -> 0 | AS29: =IF(OR(AR29="",AQ29=0),"",AR29/AQ29) | AT29: =IF(OR(AR29="",AR$10="",AR$10=0),"",AR29/AR$10) | AU29: ='Monthly P&L'!M30 -> 0 | AW29: =IF(OR(AV29="",AU29=0),"",AV29/AU29) | AX29: =IF(OR(AV29="",AV$10="",AV$10=0),"",AV29/AV$10) | AY29: ='Monthly P&L'!N30 -> 0 | BA29: =IF(OR(AZ29="",AY29=0),"",AZ29/AY29) | BB29: =IF(OR(AZ29="",AZ$10="",AZ$10=0),"",AZ29/AZ$10) | BC29: ='Monthly P&L'!O30 -> 0.63398153 | BE29: =IF(OR(BD29="",BC29=0),"",BD29/BC29) | BF29: =IF(OR(BD29="",BD$10="",BD$10=0),"",BD29/BD$10)
... A35: CSR | B35: ='Monthly P&L'!B36 -> 147.22187 | C35: =IF(OR(B35=0,B35=""),"",D35/B35-1) -> -0.13192245 | D35: ='Monthly P&L'!C36 -> 127.8 | E35: =IF(D$10=0,"",D35/D$10) -> 0.0022217818 | F35: =IF(H35="","",K35*(L35<>"")+O35*(P35<>"")+S35*(T35<>"")+W35*(X35<>"")+AA35*(AB35<>"")+AE35*(AF35<>"")+AI35*(AJ35<>"")+AM35*(AN35<>"")+AQ35*(AR35<>"")+AU35*(AV35<>"")+AY35*(AZ35<>"")+BC35*(BD35<>"")) -> 13.926704 | G35: =IF(OR(F35=0,F35="",H35=""),"",H35/F35) -> 2.1543983 | H35: =IF(SUM(L35,P35,T35,X35,AB35,AF35,AJ35,AN35,AR35,AV35,AZ35,BD35)=0,"",SUM(L35,P35,T35,X35,AB35,AF35,AJ35,AN35,AR35,AV35,AZ35,BD35)) -> 30.003668 | I35: =IF(OR(H$10="",H$10=0,H35=""),"",H35/H$10) -> 0.0034467839 | J35: =IF(OR(D35=0,H35=""),"",H35/D35) -> 0.23477049 | K35: ='Monthly P&L'!D36 -> 6.6176445 | L35: 15.003668 | M35: =IF(OR(L35="",K35=0),"",L35/K35) -> 2.2672218 | N35: =IF(OR(L35="",L$10="",L$10=0),"",L35/L$10) -> 0.003506447 | O35: ='Monthly P&L'!E36 -> 7.3090596 | P35: 15 | Q35: =IF(OR(P35="",O35=0),"",P35/O35) -> 2.0522476 | R35: =IF(OR(P35="",P$10="",P$10=0),"",P35/P$10) -> 0.0033891033 | S35: ='Monthly P&L'!F36 -> 9.1856176 | U35: =IF(OR(T35="",S35=0),"",T35/S35) | V35: =IF(OR(T35="",T$10="",T$10=0),"",T35/T$10) | W35: ='Monthly P&L'!G36 -> 8.7444345 | Y35: =IF(OR(X35="",W35=0),"",X35/W35) | Z35: =IF(OR(X35="",X$10="",X$10=0),"",X35/X$10) | AA35: ='Monthly P&L'!H36 -> 7.6984011 | AC35: =IF(OR(AB35="",AA35=0),"",AB35/AA35) | AD35: =IF(OR(AB35="",AB$10="",AB$10=0),"",AB35/AB$10) | AE35: ='Monthly P&L'!I36 -> 8.8291242 | AG35: =IF(OR(AF35="",AE35=0),"",AF35/AE35) | AH35: =IF(OR(AF35="",AF$10="",AF$10=0),"",AF35/AF$10) | AI35: ='Monthly P&L'!J36 -> 7.8339427 | AK35: =IF(OR(AJ35="",AI35=0),"",AJ35/AI35) | AL35: =IF(OR(AJ35="",AJ$10="",AJ$10=0),"",AJ35/AJ$10) | AM35: ='Monthly P&L'!K36 -> 6.6176445 | AO35: =IF(OR(AN35="",AM35=0),"",AN35/AM35) | AP35: =IF(OR(AN35="",AN$10="",AN$10=0),"",AN35/AN$10) | AQ35: ='Monthly P&L'!L36 -> 26.210858 | AS35: =IF(OR(AR35="",AQ35=0),"",AR35/AQ35) | AT35: =IF(OR(AR35="",AR$10="",AR$10=0),"",AR35/AR$10) | AU35: ='Monthly P&L'!M36 -> 6.6176445 | AW35: =IF(OR(AV35="",AU35=0),"",AV35/AU35) | AX35: =IF(OR(AV35="",AV$10="",AV$10=0),"",AV35/AV$10) | AY35: ='Monthly P&L'!N36 -> 8.3537996 | BA35: =IF(OR(AZ35="",AY35=0),"",AZ35/AY35) | BB35: =IF(OR(AZ35="",AZ$10="",AZ$10=0),"",AZ35/AZ$10) | BC35: ='Monthly P&L'!O36 -> 23.781829 | BE35: =IF(OR(BD35="",BC35=0),"",BD35/BC35) | BF35: =IF(OR(BD35="",BD$10="",BD$10=0),"",BD35/BD$10)
A36: Total Fixed Cost | B36: ='Monthly P&L'!B37 -> 14151.028 | C36: =IF(OR(B36=0,B36=""),"",D36/B36-1) -> 0.30720469 | D36: ='Monthly P&L'!C37 -> 18498.291 | E36: =IF(D$10=0,"",D36/D$10) -> 0.32158972 | F36: =IF(H36="","",K36*(L36<>"")+O36*(P36<>"")+S36*(T36<>"")+W36*(X36<>"")+AA36*(AB36<>"")+AE36*(AF36<>"")+AI36*(AJ36<>"")+AM36*(AN36<>"")+AQ36*(AR36<>"")+AU36*(AV36<>"")+AY36*(AZ36<>"")+BC36*(BD36<>"")) -> 2873.2491 | G36: =IF(OR(F36=0,F36="",H36=""),"",H36/F36) -> 0.82300815 | H36: =IF(SUM(L36,P36,T36,X36,AB36,AF36,AJ36,AN36,AR36,AV36,AZ36,BD36)=0,"",SUM(L36,P36,T36,X36,AB36,AF36,AJ36,AN36,AR36,AV36,AZ36,BD36)) -> 2364.7074 | I36: =IF(OR(H$10="",H$10=0,H36=""),"",H36/H$10) -> 0.27165463 | J36: =IF(OR(D36=0,H36=""),"",H36/D36) -> 0.12783383 | K36: ='Monthly P&L'!D37 -> 1421.1935 | L36: =IF(L$10="","",SUM(L18:L35)) -> 1207.1934 | M36: =IF(OR(L36="",K36=0),"",L36/K36) -> 0.84942227 | N36: =IF(OR(L36="",L$10="",L$10=0),"",L36/L$10) -> 0.28212832 | O36: ='Monthly P&L'!E37 -> 1452.0556 | P36: =IF(P$10="","",SUM(P18:P35)) -> 1157.514 | Q36: =IF(OR(P36="",O36=0),"",P36/O36) -> 0.79715545 | R36: =IF(OR(P36="",P$10="",P$10=0),"",P36/P$10) -> 0.26152897 | S36: ='Monthly P&L'!F37 -> 1502.0205 | T36: =IF(T$10="","",SUM(T18:T35)) | U36: =IF(OR(T36="",S36=0),"",T36/S36) | V36: =IF(OR(T36="",T$10="",T$10=0),"",T36/T$10) | W36: ='Monthly P&L'!G37 -> 1491.9882 | X36: =IF(X$10="","",SUM(X18:X35)) | Y36: =IF(OR(X36="",W36=0),"",X36/W36) | Z36: =IF(OR(X36="",X$10="",X$10=0),"",X36/X$10) | AA36: ='Monthly P&L'!H37 -> 1514.0599 | AB36: =IF(AB$10="","",SUM(AB18:AB35)) | AC36: =IF(OR(AB36="",AA36=0),"",AB36/AA36) | AD36: =IF(OR(AB36="",AB$10="",AB$10=0),"",AB36/AB$10) | AE36: ='Monthly P&L'!I37 -> 1554.9948 | AF36: =IF(AF$10="","",SUM(AF18:AF35)) | AG36: =IF(OR(AF36="",AE36=0),"",AF36/AE36) | AH36: =IF(OR(AF36="",AF$10="",AF$10=0),"",AF36/AF$10) | AI36: ='Monthly P&L'!J37 -> 1599.1013 | AJ36: =IF(AJ$10="","",SUM(AJ18:AJ35)) | AK36: =IF(OR(AJ36="",AI36=0),"",AJ36/AI36) | AL36: =IF(OR(AJ36="",AJ$10="",AJ$10=0),"",AJ36/AJ$10) | AM36: ='Monthly P&L'!K37 -> 1476.7066 | AN36: =IF(AN$10="","",SUM(AN18:AN35)) | AO36: =IF(OR(AN36="",AM36=0),"",AN36/AM36) | AP36: =IF(OR(AN36="",AN$10="",AN$10=0),"",AN36/AN$10) | AQ36: ='Monthly P&L'!L37 -> 1511.7954 | AR36: =IF(AR$10="","",SUM(AR18:AR35)) | AS36: =IF(OR(AR36="",AQ36=0),"",AR36/AQ36) | AT36: =IF(OR(AR36="",AR$10="",AR$10=0),"",AR36/AR$10) | AU36: ='Monthly P&L'!M37 -> 1478.452 | AV36: =IF(AV$10="","",SUM(AV18:AV35)) | AW36: =IF(OR(AV36="",AU36=0),"",AV36/AU36) | AX36: =IF(OR(AV36="",AV$10="",AV$10=0),"",AV36/AV$10) | AY36: ='Monthly P&L'!N37 -> 1697.7097 | AZ36: =IF(AZ$10="","",SUM(AZ18:AZ35)) | BA36: =IF(OR(AZ36="",AY36=0),"",AZ36/AY36) | BB36: =IF(OR(AZ36="",AZ$10="",AZ$10=0),"",AZ36/AZ$10) | BC36: ='Monthly P&L'!O37 -> 1798.2131 | BD36: =IF(BD$10="","",SUM(BD18:BD35)) | BE36: =IF(OR(BD36="",BC36=0),"",BD36/BC36) | BF36: =IF(OR(BD36="",BD$10="",BD$10=0),"",BD36/BD$10)
