Workbook

Sheet PL_Consol
B1: LAKESHORE HOSPITAL AND RESEARCH CENTRE LIMITED
B2: Consolidated Profit and Loss Statement FY27 (Amount in lakhs)
D4: SMLY | E4: SMLY | O4: PM | S4: PM | T4: CM | U4: Budget | V4: Growth & Ach %
B5: Particulars | C5: Anx | D5: 45748 | E5: 45778 | F5: 45809 | G5: 45839 | H5: 45870 | I5: 45901 | J5: 45931 | K5: 45962 | L5: 45992 | M5: 46023 | N5: 46054 | O5: 46082 | P5: YTD | Q5: Bud | R5: FY25 | S5: 46113 | T5: 46143 | U5: 46143 | V5: YOY Gr. | W5: MOM Gr. | X5: BUD Ach.
B6: Revenue
B7: IP Revenue | C7: 1 | D7: =SUMIFS(PL_Kochi!C:C,PL_Kochi!$B:$B,PL_Consol!$B7)+SUMIFS(PL_Calicut!C:C,PL_Calicut!$B:$B,PL_Consol!$B7)+SUMIFS(PL_FNB!C:C,PL_FNB!$B:$B,PL_Consol!$B7) -> 1288.4786 | E7: =SUMIFS(PL_Kochi!D:D,PL_Kochi!$B:$B,PL_Consol!$B7)+SUMIFS(PL_Calicut!D:D,PL_Calicut!$B:$B,PL_Consol!$B7)+SUMIFS(PL_FNB!D:D,PL_FNB!$B:$B,PL_Consol!$B7) -> 1389.486 | F7: =SUMIFS(PL_Kochi!E:E,PL_Kochi!$B:$B,PL_Consol!$B7)+SUMIFS(PL_Calicut!E:E,PL_Calicut!$B:$B,PL_Consol!$B7)+SUMIFS(PL_FNB!E:E,PL_FNB!$B:$B,PL_Consol!$B7) -> 1243.0957 | G7: =SUMIFS(PL_Kochi!F:F,PL_Kochi!$B:$B,PL_Consol!$B7)+SUMIFS(PL_Calicut!F:F,PL_Calicut!$B:$B,PL_Consol!$B7)+SUMIFS(PL_FNB!F:F,PL_FNB!$B:$B,PL_Consol!$B7) -> 1443.6384 | H7: =SUMIFS(PL_Kochi!G:G,PL_Kochi!$B:$B,PL_Consol!$B7)+SUMIFS(PL_Calicut!G:G,PL_Calicut!$B:$B,PL_Consol!$B7)+SUMIFS(PL_FNB!G:G,PL_FNB!$B:$B,PL_Consol!$B7) -> 1583.9548 | I7: =SUMIFS(PL_Kochi!H:H,PL_Kochi!$B:$B,PL_Consol!$B7)+SUMIFS(PL_Calicut!H:H,PL_Calicut!$B:$B,PL_Consol!$B7)+SUMIFS(PL_FNB!H:H,PL_FNB!$B:$B,PL_Consol!$B7) -> 1505.3154 | J7: =SUMIFS(PL_Kochi!I:I,PL_Kochi!$B:$B,PL_Consol!$B7)+SUMIFS(PL_Calicut!I:I,PL_Calicut!$B:$B,PL_Consol!$B7)+SUMIFS(PL_FNB!I:I,PL_FNB!$B:$B,PL_Consol!$B7) -> 1554.3693 | K7: =SUMIFS(PL_Kochi!J:J,PL_Kochi!$B:$B,PL_Consol!$B7)+SUMIFS(PL_Calicut!J:J,PL_Calicut!$B:$B,PL_Consol!$B7)+SUMIFS(PL_FNB!J:J,PL_FNB!$B:$B,PL_Consol!$B7) -> 1402.5104 | L7: =SUMIFS(PL_Kochi!K:K,PL_Kochi!$B:$B,PL_Consol!$B7)+SUMIFS(PL_Calicut!K:K,PL_Calicut!$B:$B,PL_Consol!$B7)+SUMIFS(PL_FNB!K:K,PL_FNB!$B:$B,PL_Consol!$B7) -> 1476.794 | M7: =SUMIFS(PL_Kochi!L:L,PL_Kochi!$B:$B,PL_Consol!$B7)+SUMIFS(PL_Calicut!L:L,PL_Calicut!$B:$B,PL_Consol!$B7)+SUMIFS(PL_FNB!L:L,PL_FNB!$B:$B,PL_Consol!$B7) -> 1717.568 | N7: =SUMIFS(PL_Kochi!M:M,PL_Kochi!$B:$B,PL_Consol!$B7)+SUMIFS(PL_Calicut!M:M,PL_Calicut!$B:$B,PL_Consol!$B7)+SUMIFS(PL_FNB!M:M,PL_FNB!$B:$B,PL_Consol!$B7) -> 1569.515 | O7: =SUMIFS(PL_Kochi!N:N,PL_Kochi!$B:$B,PL_Consol!$B7)+SUMIFS(PL_Calicut!N:N,PL_Calicut!$B:$B,PL_Consol!$B7)+SUMIFS(PL_FNB!N:N,PL_FNB!$B:$B,PL_Consol!$B7) -> 1386.8843 | P7: =SUM(D7:O7) -> 17561.61 | Q7: 20170.36 | R7: 16277.82 | S7: =SUMIFS(PL_Kochi!R:R,PL_Kochi!$B:$B,PL_Consol!$B7)+SUMIFS(PL_Calicut!R:R,PL_Calicut!$B:$B,PL_Consol!$B7)+SUMIFS(PL_FNB!R:R,PL_FNB!$B:$B,PL_Consol!$B7) -> 1722.7909 | T7: =SUMIFS(PL_Kochi!$S:$S,PL_Kochi!$B:$B,PL_Consol!B7)+SUMIFS(PL_Calicut!$S:$S,PL_Calicut!$B:$B,PL_Consol!B7)+SUMIFS(PL_FNB!$S:$S,PL_FNB!$B:$B,PL_Consol!B7) -> 1795.5768 | U7: =2959.7-1469.5 -> 1490.2 | V7: =IFERROR(T7/E7-1,"-") -> 0.29225966 | W7: =IFERROR(T7/S7-1,"-") -> 0.042248824 | X7: =IFERROR(T7/U7,"-") -> 1.2049233
B8: IP Pharmacy | C8: 2 | D8: =SUMIFS(PL_Kochi!C:C,PL_Kochi!$B:$B,PL_Consol!$B8)+SUMIFS(PL_Calicut!C:C,PL_Calicut!$B:$B,PL_Consol!$B8)+SUMIFS(PL_FNB!C:C,PL_FNB!$B:$B,PL_Consol!$B8) -> 962.09911 | E8: =SUMIFS(PL_Kochi!D:D,PL_Kochi!$B:$B,PL_Consol!$B8)+SUMIFS(PL_Calicut!D:D,PL_Calicut!$B:$B,PL_Consol!$B8)+SUMIFS(PL_FNB!D:D,PL_FNB!$B:$B,PL_Consol!$B8) -> 1132.1552 | F8: =SUMIFS(PL_Kochi!E:E,PL_Kochi!$B:$B,PL_Consol!$B8)+SUMIFS(PL_Calicut!E:E,PL_Calicut!$B:$B,PL_Consol!$B8)+SUMIFS(PL_FNB!E:E,PL_FNB!$B:$B,PL_Consol!$B8) -> 1020.1168 | G8: =SUMIFS(PL_Kochi!F:F,PL_Kochi!$B:$B,PL_Consol!$B8)+SUMIFS(PL_Calicut!F:F,PL_Calicut!$B:$B,PL_Consol!$B8)+SUMIFS(PL_FNB!F:F,PL_FNB!$B:$B,PL_Consol!$B8) -> 1210.9126 | H8: =SUMIFS(PL_Kochi!G:G,PL_Kochi!$B:$B,PL_Consol!$B8)+SUMIFS(PL_Calicut!G:G,PL_Calicut!$B:$B,PL_Consol!$B8)+SUMIFS(PL_FNB!G:G,PL_FNB!$B:$B,PL_Consol!$B8) -> 1170.6095 | I8: =SUMIFS(PL_Kochi!H:H,PL_Kochi!$B:$B,PL_Consol!$B8)+SUMIFS(PL_Calicut!H:H,PL_Calicut!$B:$B,PL_Consol!$B8)+SUMIFS(PL_FNB!H:H,PL_FNB!$B:$B,PL_Consol!$B8) -> 1233.0387 | J8: =SUMIFS(PL_Kochi!I:I,PL_Kochi!$B:$B,PL_Consol!$B8)+SUMIFS(PL_Calicut!I:I,PL_Calicut!$B:$B,PL_Consol!$B8)+SUMIFS(PL_FNB!I:I,PL_FNB!$B:$B,PL_Consol!$B8) -> 1161.8466 | K8: =SUMIFS(PL_Kochi!J:J,PL_Kochi!$B:$B,PL_Consol!$B8)+SUMIFS(PL_Calicut!J:J,PL_Calicut!$B:$B,PL_Consol!$B8)+SUMIFS(PL_FNB!J:J,PL_FNB!$B:$B,PL_Consol!$B8) -> 1016.3118 | L8: =SUMIFS(PL_Kochi!K:K,PL_Kochi!$B:$B,PL_Consol!$B8)+SUMIFS(PL_Calicut!K:K,PL_Calicut!$B:$B,PL_Consol!$B8)+SUMIFS(PL_FNB!K:K,PL_FNB!$B:$B,PL_Consol!$B8) -> 1099.892 | M8: =SUMIFS(PL_Kochi!L:L,PL_Kochi!$B:$B,PL_Consol!$B8)+SUMIFS(PL_Calicut!L:L,PL_Calicut!$B:$B,PL_Consol!$B8)+SUMIFS(PL_FNB!L:L,PL_FNB!$B:$B,PL_Consol!$B8) -> 1265.8426 | N8: =SUMIFS(PL_Kochi!M:M,PL_Kochi!$B:$B,PL_Consol!$B8)+SUMIFS(PL_Calicut!M:M,PL_Calicut!$B:$B,PL_Consol!$B8)+SUMIFS(PL_FNB!M:M,PL_FNB!$B:$B,PL_Consol!$B8) -> 1140.9099 | O8: =SUMIFS(PL_Kochi!N:N,PL_Kochi!$B:$B,PL_Consol!$B8)+SUMIFS(PL_Calicut!N:N,PL_Calicut!$B:$B,PL_Consol!$B8)+SUMIFS(PL_FNB!N:N,PL_FNB!$B:$B,PL_Consol!$B8) -> 1187.7072 | P8: =SUM(D8:O8) -> 13601.442 | Q8: 15621.359 | R8: 12607.149 | S8: =SUMIFS(PL_Kochi!R:R,PL_Kochi!$B:$B,PL_Consol!$B8)+SUMIFS(PL_Calicut!R:R,PL_Calicut!$B:$B,PL_Consol!$B8)+SUMIFS(PL_FNB!R:R,PL_FNB!$B:$B,PL_Consol!$B8) -> 1369.1501 | T8: =SUMIFS(PL_Kochi!$S:$S,PL_Kochi!$B:$B,PL_Consol!B8)+SUMIFS(PL_Calicut!$S:$S,PL_Calicut!$B:$B,PL_Consol!B8)+SUMIFS(PL_FNB!$S:$S,PL_FNB!$B:$B,PL_Consol!B8) -> 1421.0771 | U8: 1469.5434 | V8: =IFERROR(T8/E8-1,"-") -> 0.25519634 | W8: =IFERROR(T8/S8-1,"-") -> 0.037926411 | X8: =IFERROR(T8/U8,"-") -> 0.9670195
B9: OP Revenue | C9: 3 | D9: =SUMIFS(PL_Kochi!C:C,PL_Kochi!$B:$B,PL_Consol!$B9)+SUMIFS(PL_Calicut!C:C,PL_Calicut!$B:$B,PL_Consol!$B9)+SUMIFS(PL_FNB!C:C,PL_FNB!$B:$B,PL_Consol!$B9) -> 637.60032 | E9: =SUMIFS(PL_Kochi!D:D,PL_Kochi!$B:$B,PL_Consol!$B9)+SUMIFS(PL_Calicut!D:D,PL_Calicut!$B:$B,PL_Consol!$B9)+SUMIFS(PL_FNB!D:D,PL_FNB!$B:$B,PL_Consol!$B9) -> 663.57897 | F9: =SUMIFS(PL_Kochi!E:E,PL_Kochi!$B:$B,PL_Consol!$B9)+SUMIFS(PL_Calicut!E:E,PL_Calicut!$B:$B,PL_Consol!$B9)+SUMIFS(PL_FNB!E:E,PL_FNB!$B:$B,PL_Consol!$B9) -> 612.20136 | G9: =SUMIFS(PL_Kochi!F:F,PL_Kochi!$B:$B,PL_Consol!$B9)+SUMIFS(PL_Calicut!F:F,PL_Calicut!$B:$B,PL_Consol!$B9)+SUMIFS(PL_FNB!F:F,PL_FNB!$B:$B,PL_Consol!$B9) -> 743.56545 | H9: =SUMIFS(PL_Kochi!G:G,PL_Kochi!$B:$B,PL_Consol!$B9)+SUMIFS(PL_Calicut!G:G,PL_Calicut!$B:$B,PL_Consol!$B9)+SUMIFS(PL_FNB!G:G,PL_FNB!$B:$B,PL_Consol!$B9) -> 713.72688 | I9: =SUMIFS(PL_Kochi!H:H,PL_Kochi!$B:$B,PL_Consol!$B9)+SUMIFS(PL_Calicut!H:H,PL_Calicut!$B:$B,PL_Consol!$B9)+SUMIFS(PL_FNB!H:H,PL_FNB!$B:$B,PL_Consol!$B9) -> 699.15029 | J9: =SUMIFS(PL_Kochi!I:I,PL_Kochi!$B:$B,PL_Consol!$B9)+SUMIFS(PL_Calicut!I:I,PL_Calicut!$B:$B,PL_Consol!$B9)+SUMIFS(PL_FNB!I:I,PL_FNB!$B:$B,PL_Consol!$B9) -> 692.3888 | K9: =SUMIFS(PL_Kochi!J:J,PL_Kochi!$B:$B,PL_Consol!$B9)+SUMIFS(PL_Calicut!J:J,PL_Calicut!$B:$B,PL_Consol!$B9)+SUMIFS(PL_FNB!J:J,PL_FNB!$B:$B,PL_Consol!$B9) -> 631.3311 | L9: =SUMIFS(PL_Kochi!K:K,PL_Kochi!$B:$B,PL_Consol!$B9)+SUMIFS(PL_Calicut!K:K,PL_Calicut!$B:$B,PL_Consol!$B9)+SUMIFS(PL_FNB!K:K,PL_FNB!$B:$B,PL_Consol!$B9) -> 650.09553 | M9: =SUMIFS(PL_Kochi!L:L,PL_Kochi!$B:$B,PL_Consol!$B9)+SUMIFS(PL_Calicut!L:L,PL_Calicut!$B:$B,PL_Consol!$B9)+SUMIFS(PL_FNB!L:L,PL_FNB!$B:$B,PL_Consol!$B9) -> 742.60137 | N9: =SUMIFS(PL_Kochi!M:M,PL_Kochi!$B:$B,PL_Consol!$B9)+SUMIFS(PL_Calicut!M:M,PL_Calicut!$B:$B,PL_Consol!$B9)+SUMIFS(PL_FNB!M:M,PL_FNB!$B:$B,PL_Consol!$B9) -> 667.29975 | O9: =SUMIFS(PL_Kochi!N:N,PL_Kochi!$B:$B,PL_Consol!$B9)+SUMIFS(PL_Calicut!N:N,PL_Calicut!$B:$B,PL_Consol!$B9)+SUMIFS(PL_FNB!N:N,PL_FNB!$B:$B,PL_Consol!$B9) -> 619.02266 | P9: =SUM(D9:O9) -> 8072.5625 | Q9: 8131.6124 | R9: 6731.8624 | S9: =SUMIFS(PL_Kochi!R:R,PL_Kochi!$B:$B,PL_Consol!$B9)+SUMIFS(PL_Calicut!R:R,PL_Calicut!$B:$B,PL_Consol!$B9)+SUMIFS(PL_FNB!R:R,PL_FNB!$B:$B,PL_Consol!$B9) -> 631.38286 | T9: =SUMIFS(PL_Kochi!$S:$S,PL_Kochi!$B:$B,PL_Consol!B9)+SUMIFS(PL_Calicut!$S:$S,PL_Calicut!$B:$B,PL_Consol!B9)+SUMIFS(PL_FNB!$S:$S,PL_FNB!$B:$B,PL_Consol!B9) -> 681.16854 | U9: =1161.6-431.3 -> 730.3 | V9: =IFERROR(T9/E9-1,"-") -> 0.026507118 | W9: =IFERROR(T9/S9-1,"-") -> 0.078851806 | X9: =IFERROR(T9/U9,"-") -> 0.93272427
B10: OP Pharmacy | C10: 4 | D10: =SUMIFS(PL_Kochi!C:C,PL_Kochi!$B:$B,PL_Consol!$B10)+SUMIFS(PL_Calicut!C:C,PL_Calicut!$B:$B,PL_Consol!$B10)+SUMIFS(PL_FNB!C:C,PL_FNB!$B:$B,PL_Consol!$B10) -> 322.0861 | E10: =SUMIFS(PL_Kochi!D:D,PL_Kochi!$B:$B,PL_Consol!$B10)+SUMIFS(PL_Calicut!D:D,PL_Calicut!$B:$B,PL_Consol!$B10)+SUMIFS(PL_FNB!D:D,PL_FNB!$B:$B,PL_Consol!$B10) -> 344.86247 | F10: =SUMIFS(PL_Kochi!E:E,PL_Kochi!$B:$B,PL_Consol!$B10)+SUMIFS(PL_Calicut!E:E,PL_Calicut!$B:$B,PL_Consol!$B10)+SUMIFS(PL_FNB!E:E,PL_FNB!$B:$B,PL_Consol!$B10) -> 299.17609 | G10: =SUMIFS(PL_Kochi!F:F,PL_Kochi!$B:$B,PL_Consol!$B10)+SUMIFS(PL_Calicut!F:F,PL_Calicut!$B:$B,PL_Consol!$B10)+SUMIFS(PL_FNB!F:F,PL_FNB!$B:$B,PL_Consol!$B10) -> 348.22764 | H10: =SUMIFS(PL_Kochi!G:G,PL_Kochi!$B:$B,PL_Consol!$B10)+SUMIFS(PL_Calicut!G:G,PL_Calicut!$B:$B,PL_Consol!$B10)+SUMIFS(PL_FNB!G:G,PL_FNB!$B:$B,PL_Consol!$B10) -> 384.8945 | I10: =SUMIFS(PL_Kochi!H:H,PL_Kochi!$B:$B,PL_Consol!$B10)+SUMIFS(PL_Calicut!H:H,PL_Calicut!$B:$B,PL_Consol!$B10)+SUMIFS(PL_FNB!H:H,PL_FNB!$B:$B,PL_Consol!$B10) -> 344.28042 | J10: =SUMIFS(PL_Kochi!I:I,PL_Kochi!$B:$B,PL_Consol!$B10)+SUMIFS(PL_Calicut!I:I,PL_Calicut!$B:$B,PL_Consol!$B10)+SUMIFS(PL_FNB!I:I,PL_FNB!$B:$B,PL_Consol!$B10) -> 348.91355 | K10: =SUMIFS(PL_Kochi!J:J,PL_Kochi!$B:$B,PL_Consol!$B10)+SUMIFS(PL_Calicut!J:J,PL_Calicut!$B:$B,PL_Consol!$B10)+SUMIFS(PL_FNB!J:J,PL_FNB!$B:$B,PL_Consol!$B10) -> 308.22255 | L10: =SUMIFS(PL_Kochi!K:K,PL_Kochi!$B:$B,PL_Consol!$B10)+SUMIFS(PL_Calicut!K:K,PL_Calicut!$B:$B,PL_Consol!$B10)+SUMIFS(PL_FNB!K:K,PL_FNB!$B:$B,PL_Consol!$B10) -> 345.34109 | M10: =SUMIFS(PL_Kochi!L:L,PL_Kochi!$B:$B,PL_Consol!$B10)+SUMIFS(PL_Calicut!L:L,PL_Calicut!$B:$B,PL_Consol!$B10)+SUMIFS(PL_FNB!L:L,PL_FNB!$B:$B,PL_Consol!$B10) -> 369.29489 | N10: =SUMIFS(PL_Kochi!M:M,PL_Kochi!$B:$B,PL_Consol!$B10)+SUMIFS(PL_Calicut!M:M,PL_Calicut!$B:$B,PL_Consol!$B10)+SUMIFS(PL_FNB!M:M,PL_FNB!$B:$B,PL_Consol!$B10) -> 335.17451 | O10: =SUMIFS(PL_Kochi!N:N,PL_Kochi!$B:$B,PL_Consol!$B10)+SUMIFS(PL_Calicut!N:N,PL_Calicut!$B:$B,PL_Consol!$B10)+SUMIFS(PL_FNB!N:N,PL_FNB!$B:$B,PL_Consol!$B10) -> 346.93941 | P10: =SUM(D10:O10) -> 4097.4132 | Q10: 4127.4305 | R10: 3416.9103 | S10: =SUMIFS(PL_Kochi!R:R,PL_Kochi!$B:$B,PL_Consol!$B10)+SUMIFS(PL_Calicut!R:R,PL_Calicut!$B:$B,PL_Consol!$B10)+SUMIFS(PL_FNB!R:R,PL_FNB!$B:$B,PL_Consol!$B10) -> 349.32571 | T10: =SUMIFS(PL_Kochi!$S:$S,PL_Kochi!$B:$B,PL_Consol!B10)+SUMIFS(PL_Calicut!$S:$S,PL_Calicut!$B:$B,PL_Consol!B10)+SUMIFS(PL_FNB!$S:$S,PL_FNB!$B:$B,PL_Consol!B10) -> 343.25514 | U10: 431.31397 | V10: =IFERROR(T10/E10-1,"-") -> -0.0046607679 | W10: =IFERROR(T10/S10-1,"-") -> -0.017377953 | X10: =IFERROR(T10/U10,"-") -> 0.7958359
B11: Aurveda | C11: 5 | D11: =SUMIFS(PL_Kochi!C:C,PL_Kochi!$B:$B,PL_Consol!$B11)+SUMIFS(PL_Calicut!C:C,PL_Calicut!$B:$B,PL_Consol!$B11)+SUMIFS(PL_FNB!C:C,PL_FNB!$B:$B,PL_Consol!$B11) -> 0 | E11: =SUMIFS(PL_Kochi!D:D,PL_Kochi!$B:$B,PL_Consol!$B11)+SUMIFS(PL_Calicut!D:D,PL_Calicut!$B:$B,PL_Consol!$B11)+SUMIFS(PL_FNB!D:D,PL_FNB!$B:$B,PL_Consol!$B11) -> 0 | F11: =SUMIFS(PL_Kochi!E:E,PL_Kochi!$B:$B,PL_Consol!$B11)+SUMIFS(PL_Calicut!E:E,PL_Calicut!$B:$B,PL_Consol!$B11)+SUMIFS(PL_FNB!E:E,PL_FNB!$B:$B,PL_Consol!$B11) -> 0 | G11: =SUMIFS(PL_Kochi!F:F,PL_Kochi!$B:$B,PL_Consol!$B11)+SUMIFS(PL_Calicut!F:F,PL_Calicut!$B:$B,PL_Consol!$B11)+SUMIFS(PL_FNB!F:F,PL_FNB!$B:$B,PL_Consol!$B11) -> 1.3048497 | H11: =SUMIFS(PL_Kochi!G:G,PL_Kochi!$B:$B,PL_Consol!$B11)+SUMIFS(PL_Calicut!G:G,PL_Calicut!$B:$B,PL_Consol!$B11)+SUMIFS(PL_FNB!G:G,PL_FNB!$B:$B,PL_Consol!$B11) -> 1.9660111 | I11: =SUMIFS(PL_Kochi!H:H,PL_Kochi!$B:$B,PL_Consol!$B11)+SUMIFS(PL_Calicut!H:H,PL_Calicut!$B:$B,PL_Consol!$B11)+SUMIFS(PL_FNB!H:H,PL_FNB!$B:$B,PL_Consol!$B11) -> 0.28107447 | J11: =SUMIFS(PL_Kochi!I:I,PL_Kochi!$B:$B,PL_Consol!$B11)+SUMIFS(PL_Calicut!I:I,PL_Calicut!$B:$B,PL_Consol!$B11)+SUMIFS(PL_FNB!I:I,PL_FNB!$B:$B,PL_Consol!$B11) -> 0.49013011 | K11: =SUMIFS(PL_Kochi!J:J,PL_Kochi!$B:$B,PL_Consol!$B11)+SUMIFS(PL_Calicut!J:J,PL_Calicut!$B:$B,PL_Consol!$B11)+SUMIFS(PL_FNB!J:J,PL_FNB!$B:$B,PL_Consol!$B11) -> 0.41512359 | L11: =SUMIFS(PL_Kochi!K:K,PL_Kochi!$B:$B,PL_Consol!$B11)+SUMIFS(PL_Calicut!K:K,PL_Calicut!$B:$B,PL_Consol!$B11)+SUMIFS(PL_FNB!K:K,PL_FNB!$B:$B,PL_Consol!$B11) -> 0.46913222 | M11: =SUMIFS(PL_Kochi!L:L,PL_Kochi!$B:$B,PL_Consol!$B11)+SUMIFS(PL_Calicut!L:L,PL_Calicut!$B:$B,PL_Consol!$B11)+SUMIFS(PL_FNB!L:L,PL_FNB!$B:$B,PL_Consol!$B11) -> 0.23805783 | N11: =SUMIFS(PL_Kochi!M:M,PL_Kochi!$B:$B,PL_Consol!$B11)+SUMIFS(PL_Calicut!M:M,PL_Calicut!$B:$B,PL_Consol!$B11)+SUMIFS(PL_FNB!M:M,PL_FNB!$B:$B,PL_Consol!$B11) -> 0.2362908 | O11: =SUMIFS(PL_Kochi!N:N,PL_Kochi!$B:$B,PL_Consol!$B11)+SUMIFS(PL_Calicut!N:N,PL_Calicut!$B:$B,PL_Consol!$B11)+SUMIFS(PL_FNB!N:N,PL_FNB!$B:$B,PL_Consol!$B11) -> 0.62416156 | P11: =SUM(D11:O11) -> 6.0248314 | Q11: 0 | R11: 0 | S11: =SUMIFS(PL_Kochi!R:R,PL_Kochi!$B:$B,PL_Consol!$B11)+SUMIFS(PL_Calicut!R:R,PL_Calicut!$B:$B,PL_Consol!$B11)+SUMIFS(PL_FNB!R:R,PL_FNB!$B:$B,PL_Consol!$B11) -> 0.061515039 | T11: =SUMIFS(PL_Kochi!$S:$S,PL_Kochi!$B:$B,PL_Consol!B11)+SUMIFS(PL_Calicut!$S:$S,PL_Calicut!$B:$B,PL_Consol!B11)+SUMIFS(PL_FNB!$S:$S,PL_FNB!$B:$B,PL_Consol!B11) -> 0.15 | U11: 0 | V11: =IFERROR(T11/E11-1,"-") -> - | W11: =IFERROR(T11/S11-1,"-") -> 1.4384281 | X11: =IFERROR(T11/U11,"-") -> -
B12: F & B Revenue | C12: 6 | D12: =SUMIFS(PL_Kochi!C:C,PL_Kochi!$B:$B,PL_Consol!$B12)+SUMIFS(PL_Calicut!C:C,PL_Calicut!$B:$B,PL_Consol!$B12)+SUMIFS(PL_FNB!C:C,PL_FNB!$B:$B,PL_Consol!$B12) -> 134.45512 | E12: =SUMIFS(PL_Kochi!D:D,PL_Kochi!$B:$B,PL_Consol!$B12)+SUMIFS(PL_Calicut!D:D,PL_Calicut!$B:$B,PL_Consol!$B12)+SUMIFS(PL_FNB!D:D,PL_FNB!$B:$B,PL_Consol!$B12) -> 142.66725 | F12: =SUMIFS(PL_Kochi!E:E,PL_Kochi!$B:$B,PL_Consol!$B12)+SUMIFS(PL_Calicut!E:E,PL_Calicut!$B:$B,PL_Consol!$B12)+SUMIFS(PL_FNB!E:E,PL_FNB!$B:$B,PL_Consol!$B12) -> 132.13448 | G12: =SUMIFS(PL_Kochi!F:F,PL_Kochi!$B:$B,PL_Consol!$B12)+SUMIFS(PL_Calicut!F:F,PL_Calicut!$B:$B,PL_Consol!$B12)+SUMIFS(PL_FNB!F:F,PL_FNB!$B:$B,PL_Consol!$B12) -> 154.33057 | H12: =SUMIFS(PL_Kochi!G:G,PL_Kochi!$B:$B,PL_Consol!$B12)+SUMIFS(PL_Calicut!G:G,PL_Calicut!$B:$B,PL_Consol!$B12)+SUMIFS(PL_FNB!G:G,PL_FNB!$B:$B,PL_Consol!$B12) -> 153.96558 | I12: =SUMIFS(PL_Kochi!H:H,PL_Kochi!$B:$B,PL_Consol!$B12)+SUMIFS(PL_Calicut!H:H,PL_Calicut!$B:$B,PL_Consol!$B12)+SUMIFS(PL_FNB!H:H,PL_FNB!$B:$B,PL_Consol!$B12) -> 148.75409 | J12: =SUMIFS(PL_Kochi!I:I,PL_Kochi!$B:$B,PL_Consol!$B12)+SUMIFS(PL_Calicut!I:I,PL_Calicut!$B:$B,PL_Consol!$B12)+SUMIFS(PL_FNB!I:I,PL_FNB!$B:$B,PL_Consol!$B12) -> 147.87833 | K12: =SUMIFS(PL_Kochi!J:J,PL_Kochi!$B:$B,PL_Consol!$B12)+SUMIFS(PL_Calicut!J:J,PL_Calicut!$B:$B,PL_Consol!$B12)+SUMIFS(PL_FNB!J:J,PL_FNB!$B:$B,PL_Consol!$B12) -> 138.58874 | L12: =SUMIFS(PL_Kochi!K:K,PL_Kochi!$B:$B,PL_Consol!$B12)+SUMIFS(PL_Calicut!K:K,PL_Calicut!$B:$B,PL_Consol!$B12)+SUMIFS(PL_FNB!K:K,PL_FNB!$B:$B,PL_Consol!$B12) -> 142.79663 | M12: =SUMIFS(PL_Kochi!L:L,PL_Kochi!$B:$B,PL_Consol!$B12)+SUMIFS(PL_Calicut!L:L,PL_Calicut!$B:$B,PL_Consol!$B12)+SUMIFS(PL_FNB!L:L,PL_FNB!$B:$B,PL_Consol!$B12) -> 156.47398 | N12: =SUMIFS(PL_Kochi!M:M,PL_Kochi!$B:$B,PL_Consol!$B12)+SUMIFS(PL_Calicut!M:M,PL_Calicut!$B:$B,PL_Consol!$B12)+SUMIFS(PL_FNB!M:M,PL_FNB!$B:$B,PL_Consol!$B12) -> 143.10076 | O12: =SUMIFS(PL_Kochi!N:N,PL_Kochi!$B:$B,PL_Consol!$B12)+SUMIFS(PL_Calicut!N:N,PL_Calicut!$B:$B,PL_Consol!$B12)+SUMIFS(PL_FNB!N:N,PL_FNB!$B:$B,PL_Consol!$B12) -> 135.02678 | P12: =SUM(D12:O12) -> 1730.1723 | Q12: 1853.3035 | R12: 1643.72 | S12: =SUMIFS(PL_Kochi!R:R,PL_Kochi!$B:$B,PL_Consol!$B12)+SUMIFS(PL_Calicut!R:R,PL_Calicut!$B:$B,PL_Consol!$B12)+SUMIFS(PL_FNB!R:R,PL_FNB!$B:$B,PL_Consol!$B12) -> 157.02992 | T12: =SUMIFS(PL_Kochi!$S:$S,PL_Kochi!$B:$B,PL_Consol!B12)+SUMIFS(PL_Calicut!$S:$S,PL_Calicut!$B:$B,PL_Consol!B12)+SUMIFS(PL_FNB!$S:$S,PL_FNB!$B:$B,PL_Consol!B12) -> 167.08431 | U12: 172.6 | V12: =IFERROR(T12/E12-1,"-") -> 0.17114691 | W12: =IFERROR(T12/S12-1,"-") -> 0.064028504 | X12: =IFERROR(T12/U12,"-") -> 0.96804354
B13: Revenue From Operation | D13: =SUM(D7:D12) -> 3344.7193 | E13: =SUM(E7:E12) -> 3672.7499 | F13: =SUM(F7:F12) -> 3306.7245 | G13: =SUM(G7:G12) -> 3901.9795 | H13: =SUM(H7:H12) -> 4009.1172 | I13: =SUM(I7:I12) -> 3930.82 | J13: =SUM(J7:J12) -> 3905.8867 | K13: =SUM(K7:K12) -> 3497.3797 | ... U13: =SUM(U7:U12) -> 4293.9573 | V13: =IFERROR(T13/E13-1,"-") -> 0.20027552 | W13: =IFERROR(T13/S13-1,"-") -> 0.042217911 | X13: =IFERROR(S13/U13,"-") -> 0.98504495
B14: Other Income | C14: 7 | D14: =SUMIFS(PL_Kochi!C:C,PL_Kochi!$B:$B,PL_Consol!$B14)+SUMIFS(PL_Calicut!C:C,PL_Calicut!$B:$B,PL_Consol!$B14)+SUMIFS(PL_FNB!C:C,PL_FNB!$B:$B,PL_Consol!$B14) -> 22.023867 | E14: =SUMIFS(PL_Kochi!D:D,PL_Kochi!$B:$B,PL_Consol!$B14)+SUMIFS(PL_Calicut!D:D,PL_Calicut!$B:$B,PL_Consol!$B14)+SUMIFS(PL_FNB!D:D,PL_FNB!$B:$B,PL_Consol!$B14) -> 69.441876 | F14: =SUMIFS(PL_Kochi!E:E,PL_Kochi!$B:$B,PL_Consol!$B14)+SUMIFS(PL_Calicut!E:E,PL_Calicut!$B:$B,PL_Consol!$B14)+SUMIFS(PL_FNB!E:E,PL_FNB!$B:$B,PL_Consol!$B14) -> 62.903433 | G14: =SUMIFS(PL_Kochi!F:F,PL_Kochi!$B:$B,PL_Consol!$B14)+SUMIFS(PL_Calicut!F:F,PL_Calicut!$B:$B,PL_Consol!$B14)+SUMIFS(PL_FNB!F:F,PL_FNB!$B:$B,PL_Consol!$B14) -> 15.475536 | H14: =SUMIFS(PL_Kochi!G:G,PL_Kochi!$B:$B,PL_Consol!$B14)+SUMIFS(PL_Calicut!G:G,PL_Calicut!$B:$B,PL_Consol!$B14)+SUMIFS(PL_FNB!G:G,PL_FNB!$B:$B,PL_Consol!$B14) -> 22.113476 | I14: =SUMIFS(PL_Kochi!H:H,PL_Kochi!$B:$B,PL_Consol!$B14)+SUMIFS(PL_Calicut!H:H,PL_Calicut!$B:$B,PL_Consol!$B14)+SUMIFS(PL_FNB!H:H,PL_FNB!$B:$B,PL_Consol!$B14) -> 25.552787 | J14: =SUMIFS(PL_Kochi!I:I,PL_Kochi!$B:$B,PL_Consol!$B14)+SUMIFS(PL_Calicut!I:I,PL_Calicut!$B:$B,PL_Consol!$B14)+SUMIFS(PL_FNB!I:I,PL_FNB!$B:$B,PL_Consol!$B14) -> 42.725339 | K14: =SUMIFS(PL_Kochi!J:J,PL_Kochi!$B:$B,PL_Consol!$B14)+SUMIFS(PL_Calicut!J:J,PL_Calicut!$B:$B,PL_Consol!$B14)+SUMIFS(PL_FNB!J:J,PL_FNB!$B:$B,PL_Consol!$B14) -> 29.650772 | L14: =SUMIFS(PL_Kochi!K:K,PL_Kochi!$B:$B,PL_Consol!$B14)+SUMIFS(PL_Calicut!K:K,PL_Calicut!$B:$B,PL_Consol!$B14)+SUMIFS(PL_FNB!K:K,PL_FNB!$B:$B,PL_Consol!$B14) -> 13.299825 | M14: =SUMIFS(PL_Kochi!L:L,PL_Kochi!$B:$B,PL_Consol!$B14)+SUMIFS(PL_Calicut!L:L,PL_Calicut!$B:$B,PL_Consol!$B14)+SUMIFS(PL_FNB!L:L,PL_FNB!$B:$B,PL_Consol!$B14) -> 50.366286 | N14: =SUMIFS(PL_Kochi!M:M,PL_Kochi!$B:$B,PL_Consol!$B14)+SUMIFS(PL_Calicut!M:M,PL_Calicut!$B:$B,PL_Consol!$B14)+SUMIFS(PL_FNB!M:M,PL_FNB!$B:$B,PL_Consol!$B14) -> 207.9737 | O14: =SUMIFS(PL_Kochi!N:N,PL_Kochi!$B:$B,PL_Consol!$B14)+SUMIFS(PL_Calicut!N:N,PL_Calicut!$B:$B,PL_Consol!$B14)+SUMIFS(PL_FNB!N:N,PL_FNB!$B:$B,PL_Consol!$B14) -> 353.06963 | P14: =SUM(D14:O14) -> 914.59653 | Q14: 498.81309 | R14: 897.75892 | S14: =SUMIFS(PL_Kochi!R:R,PL_Kochi!$B:$B,PL_Consol!$B14)+SUMIFS(PL_Calicut!R:R,PL_Calicut!$B:$B,PL_Consol!$B14)+SUMIFS(PL_FNB!R:R,PL_FNB!$B:$B,PL_Consol!$B14) -> 49.139616 | T14: =SUMIFS(PL_Kochi!$S:$S,PL_Kochi!$B:$B,PL_Consol!B14)+SUMIFS(PL_Calicut!$S:$S,PL_Calicut!$B:$B,PL_Consol!B14)+SUMIFS(PL_FNB!$S:$S,PL_FNB!$B:$B,PL_Consol!B14) -> 17.637613 | U14: 75.6 | V14: =IFERROR(T14/E14-1,"-") -> -0.74600898 | W14: =IFERROR(T14/S14-1,"-") -> -0.64107141 | X14: =IFERROR(S14/U14,"-") -> 0.64999492
B15: Total Revenue | D15: =SUM(D13:D14) -> 3366.7431 | E15: =SUM(E13:E14) -> 3742.1918 | F15: =SUM(F13:F14) -> 3369.6279 | G15: =SUM(G13:G14) -> 3917.4551 | H15: =SUM(H13:H14) -> 4031.2307 | I15: =SUM(I13:I14) -> 3956.3728 | J15: =SUM(J13:J14) -> 3948.612 | K15: =SUM(K13:K14) -> 3527.0305 | ... U15: =SUM(U13:U14) -> 4369.5573 | V15: =IFERROR(T15/E15-1,"-") -> 0.18271582 | W15: =IFERROR(T15/S15-1,"-") -> 0.034370864 | X15: =IFERROR(S15/U15,"-") -> 0.97924808
V16: =IFERROR(S16/D16-1,"-") -> - | W16: =IFERROR(S16/O16-1,"-") -> - | X16: =IFERROR(S16/U16,"-") -> -
B17: Material Cost | C17: 8 | D17: =SUMIFS(PL_Kochi!C:C,PL_Kochi!$B:$B,PL_Consol!$B17)+SUMIFS(PL_Calicut!C:C,PL_Calicut!$B:$B,PL_Consol!$B17)+SUMIFS(PL_FNB!C:C,PL_FNB!$B:$B,PL_Consol!$B17) -> 865.38086 | E17: =SUMIFS(PL_Kochi!D:D,PL_Kochi!$B:$B,PL_Consol!$B17)+SUMIFS(PL_Calicut!D:D,PL_Calicut!$B:$B,PL_Consol!$B17)+SUMIFS(PL_FNB!D:D,PL_FNB!$B:$B,PL_Consol!$B17) -> 1147.3681 | F17: =SUMIFS(PL_Kochi!E:E,PL_Kochi!$B:$B,PL_Consol!$B17)+SUMIFS(PL_Calicut!E:E,PL_Calicut!$B:$B,PL_Consol!$B17)+SUMIFS(PL_FNB!E:E,PL_FNB!$B:$B,PL_Consol!$B17) -> 1121.87 | G17: =SUMIFS(PL_Kochi!F:F,PL_Kochi!$B:$B,PL_Consol!$B17)+SUMIFS(PL_Calicut!F:F,PL_Calicut!$B:$B,PL_Consol!$B17)+SUMIFS(PL_FNB!F:F,PL_FNB!$B:$B,PL_Consol!$B17) -> 1278.5375 | H17: =SUMIFS(PL_Kochi!G:G,PL_Kochi!$B:$B,PL_Consol!$B17)+SUMIFS(PL_Calicut!G:G,PL_Calicut!$B:$B,PL_Consol!$B17)+SUMIFS(PL_FNB!G:G,PL_FNB!$B:$B,PL_Consol!$B17) -> 1221.3064 | I17: =SUMIFS(PL_Kochi!H:H,PL_Kochi!$B:$B,PL_Consol!$B17)+SUMIFS(PL_Calicut!H:H,PL_Calicut!$B:$B,PL_Consol!$B17)+SUMIFS(PL_FNB!H:H,PL_FNB!$B:$B,PL_Consol!$B17) -> 1161.3552 | J17: =SUMIFS(PL_Kochi!I:I,PL_Kochi!$B:$B,PL_Consol!$B17)+SUMIFS(PL_Calicut!I:I,PL_Calicut!$B:$B,PL_Consol!$B17)+SUMIFS(PL_FNB!I:I,PL_FNB!$B:$B,PL_Consol!$B17) -> 1229.9506 | K17: =SUMIFS(PL_Kochi!J:J,PL_Kochi!$B:$B,PL_Consol!$B17)+SUMIFS(PL_Calicut!J:J,PL_Calicut!$B:$B,PL_Consol!$B17)+SUMIFS(PL_FNB!J:J,PL_FNB!$B:$B,PL_Consol!$B17) -> 1081.0936 | L17: =SUMIFS(PL_Kochi!K:K,PL_Kochi!$B:$B,PL_Consol!$B17)+SUMIFS(PL_Calicut!K:K,PL_Calicut!$B:$B,PL_Consol!$B17)+SUMIFS(PL_FNB!K:K,PL_FNB!$B:$B,PL_Consol!$B17) -> 1154.1166 | M17: =SUMIFS(PL_Kochi!L:L,PL_Kochi!$B:$B,PL_Consol!$B17)+SUMIFS(PL_Calicut!L:L,PL_Calicut!$B:$B,PL_Consol!$B17)+SUMIFS(PL_FNB!L:L,PL_FNB!$B:$B,PL_Consol!$B17) -> 1242.8874 | N17: =SUMIFS(PL_Kochi!M:M,PL_Kochi!$B:$B,PL_Consol!$B17)+SUMIFS(PL_Calicut!M:M,PL_Calicut!$B:$B,PL_Consol!$B17)+SUMIFS(PL_FNB!M:M,PL_FNB!$B:$B,PL_Consol!$B17) -> 1171.5098 | O17: =SUMIFS(PL_Kochi!N:N,PL_Kochi!$B:$B,PL_Consol!$B17)+SUMIFS(PL_Calicut!N:N,PL_Calicut!$B:$B,PL_Consol!$B17)+SUMIFS(PL_FNB!N:N,PL_FNB!$B:$B,PL_Consol!$B17) -> 1050.0197 | P17: =SUM(D17:O17) -> 13725.396 | Q17: 13960.301 | R17: 12513.66 | S17: =SUMIFS(PL_Kochi!R:R,PL_Kochi!$B:$B,PL_Consol!$B17)+SUMIFS(PL_Calicut!R:R,PL_Calicut!$B:$B,PL_Consol!$B17)+SUMIFS(PL_FNB!R:R,PL_FNB!$B:$B,PL_Consol!$B17) -> 1246.2882 | T17: =SUMIFS(PL_Kochi!S:S,PL_Kochi!$B:$B,PL_Consol!$B17)+SUMIFS(PL_Calicut!S:S,PL_Calicut!$B:$B,PL_Consol!$B17)+SUMIFS(PL_FNB!S:S,PL_FNB!$B:$B,PL_Consol!$B17) -> 1344.9625 | U17: 1179.8 | V17: =IFERROR(T17/E17-1,"-") -> 0.17221537 | W17: =IFERROR(T17/S17-1,"-") -> 0.079174623 | X17: =IFERROR(S17/U17,"-") -> 1.0563554
B18: Doctor Cost | C18: 9 | D18: =SUMIFS(PL_Kochi!C:C,PL_Kochi!$B:$B,PL_Consol!$B18)+SUMIFS(PL_Calicut!C:C,PL_Calicut!$B:$B,PL_Consol!$B18)+SUMIFS(PL_FNB!C:C,PL_FNB!$B:$B,PL_Consol!$B18) -> 625.32472 | E18: =SUMIFS(PL_Kochi!D:D,PL_Kochi!$B:$B,PL_Consol!$B18)+SUMIFS(PL_Calicut!D:D,PL_Calicut!$B:$B,PL_Consol!$B18)+SUMIFS(PL_FNB!D:D,PL_FNB!$B:$B,PL_Consol!$B18) -> 633.17885 | F18: =SUMIFS(PL_Kochi!E:E,PL_Kochi!$B:$B,PL_Consol!$B18)+SUMIFS(PL_Calicut!E:E,PL_Calicut!$B:$B,PL_Consol!$B18)+SUMIFS(PL_FNB!E:E,PL_FNB!$B:$B,PL_Consol!$B18) -> 615.54412 | G18: =SUMIFS(PL_Kochi!F:F,PL_Kochi!$B:$B,PL_Consol!$B18)+SUMIFS(PL_Calicut!F:F,PL_Calicut!$B:$B,PL_Consol!$B18)+SUMIFS(PL_FNB!F:F,PL_FNB!$B:$B,PL_Consol!$B18) -> 671.81447 | H18: =SUMIFS(PL_Kochi!G:G,PL_Kochi!$B:$B,PL_Consol!$B18)+SUMIFS(PL_Calicut!G:G,PL_Calicut!$B:$B,PL_Consol!$B18)+SUMIFS(PL_FNB!G:G,PL_FNB!$B:$B,PL_Consol!$B18) -> 672.78128 | I18: =SUMIFS(PL_Kochi!H:H,PL_Kochi!$B:$B,PL_Consol!$B18)+SUMIFS(PL_Calicut!H:H,PL_Calicut!$B:$B,PL_Consol!$B18)+SUMIFS(PL_FNB!H:H,PL_FNB!$B:$B,PL_Consol!$B18) -> 676.88154 | J18: =SUMIFS(PL_Kochi!I:I,PL_Kochi!$B:$B,PL_Consol!$B18)+SUMIFS(PL_Calicut!I:I,PL_Calicut!$B:$B,PL_Consol!$B18)+SUMIFS(PL_FNB!I:I,PL_FNB!$B:$B,PL_Consol!$B18) -> 654.77264 | K18: =SUMIFS(PL_Kochi!J:J,PL_Kochi!$B:$B,PL_Consol!$B18)+SUMIFS(PL_Calicut!J:J,PL_Calicut!$B:$B,PL_Consol!$B18)+SUMIFS(PL_FNB!J:J,PL_FNB!$B:$B,PL_Consol!$B18) -> 662.30433 | L18: =SUMIFS(PL_Kochi!K:K,PL_Kochi!$B:$B,PL_Consol!$B18)+SUMIFS(PL_Calicut!K:K,PL_Calicut!$B:$B,PL_Consol!$B18)+SUMIFS(PL_FNB!K:K,PL_FNB!$B:$B,PL_Consol!$B18) -> 689.30664 | M18: =SUMIFS(PL_Kochi!L:L,PL_Kochi!$B:$B,PL_Consol!$B18)+SUMIFS(PL_Calicut!L:L,PL_Calicut!$B:$B,PL_Consol!$B18)+SUMIFS(PL_FNB!L:L,PL_FNB!$B:$B,PL_Consol!$B18) -> 699.5981 | N18: =SUMIFS(PL_Kochi!M:M,PL_Kochi!$B:$B,PL_Consol!$B18)+SUMIFS(PL_Calicut!M:M,PL_Calicut!$B:$B,PL_Consol!$B18)+SUMIFS(PL_FNB!M:M,PL_FNB!$B:$B,PL_Consol!$B18) -> 683.83619 | O18: =SUMIFS(PL_Kochi!N:N,PL_Kochi!$B:$B,PL_Consol!$B18)+SUMIFS(PL_Calicut!N:N,PL_Calicut!$B:$B,PL_Consol!$B18)+SUMIFS(PL_FNB!N:N,PL_FNB!$B:$B,PL_Consol!$B18) -> 699.42364 | P18: =SUM(D18:O18) -> 7984.7665 | Q18: 9779.2563 | R18: 7546.99 | S18: =SUMIFS(PL_Kochi!R:R,PL_Kochi!$B:$B,PL_Consol!$B18)+SUMIFS(PL_Calicut!R:R,PL_Calicut!$B:$B,PL_Consol!$B18)+SUMIFS(PL_FNB!R:R,PL_FNB!$B:$B,PL_Consol!$B18) -> 715.16936 | T18: =SUMIFS(PL_Kochi!S:S,PL_Kochi!$B:$B,PL_Consol!$B18)+SUMIFS(PL_Calicut!S:S,PL_Calicut!$B:$B,PL_Consol!$B18)+SUMIFS(PL_FNB!S:S,PL_FNB!$B:$B,PL_Consol!$B18) -> 692.59426 | U18: 736 | V18: =IFERROR(T18/E18-1,"-") -> 0.093836693 | W18: =IFERROR(T18/S18-1,"-") -> -0.031566088 | X18: =IFERROR(S18/U18,"-") -> 0.9716975
B19: Employee Cost | C19: 10 | D19: =SUMIFS(PL_Kochi!C:C,PL_Kochi!$B:$B,PL_Consol!$B19)+SUMIFS(PL_Calicut!C:C,PL_Calicut!$B:$B,PL_Consol!$B19)+SUMIFS(PL_FNB!C:C,PL_FNB!$B:$B,PL_Consol!$B19) -> 554.73431 | E19: =SUMIFS(PL_Kochi!D:D,PL_Kochi!$B:$B,PL_Consol!$B19)+SUMIFS(PL_Calicut!D:D,PL_Calicut!$B:$B,PL_Consol!$B19)+SUMIFS(PL_FNB!D:D,PL_FNB!$B:$B,PL_Consol!$B19) -> 628.21321 | F19: =SUMIFS(PL_Kochi!E:E,PL_Kochi!$B:$B,PL_Consol!$B19)+SUMIFS(PL_Calicut!E:E,PL_Calicut!$B:$B,PL_Consol!$B19)+SUMIFS(PL_FNB!E:E,PL_FNB!$B:$B,PL_Consol!$B19) -> 617.87253 | G19: =SUMIFS(PL_Kochi!F:F,PL_Kochi!$B:$B,PL_Consol!$B19)+SUMIFS(PL_Calicut!F:F,PL_Calicut!$B:$B,PL_Consol!$B19)+SUMIFS(PL_FNB!F:F,PL_FNB!$B:$B,PL_Consol!$B19) -> 628.60267 | H19: =SUMIFS(PL_Kochi!G:G,PL_Kochi!$B:$B,PL_Consol!$B19)+SUMIFS(PL_Calicut!G:G,PL_Calicut!$B:$B,PL_Consol!$B19)+SUMIFS(PL_FNB!G:G,PL_FNB!$B:$B,PL_Consol!$B19) -> 622.55297 | I19: =SUMIFS(PL_Kochi!H:H,PL_Kochi!$B:$B,PL_Consol!$B19)+SUMIFS(PL_Calicut!H:H,PL_Calicut!$B:$B,PL_Consol!$B19)+SUMIFS(PL_FNB!H:H,PL_FNB!$B:$B,PL_Consol!$B19) -> 681.43864 | J19: =SUMIFS(PL_Kochi!I:I,PL_Kochi!$B:$B,PL_Consol!$B19)+SUMIFS(PL_Calicut!I:I,PL_Calicut!$B:$B,PL_Consol!$B19)+SUMIFS(PL_FNB!I:I,PL_FNB!$B:$B,PL_Consol!$B19) -> 645.91964 | K19: =SUMIFS(PL_Kochi!J:J,PL_Kochi!$B:$B,PL_Consol!$B19)+SUMIFS(PL_Calicut!J:J,PL_Calicut!$B:$B,PL_Consol!$B19)+SUMIFS(PL_FNB!J:J,PL_FNB!$B:$B,PL_Consol!$B19) -> 596.10196 | L19: =SUMIFS(PL_Kochi!K:K,PL_Kochi!$B:$B,PL_Consol!$B19)+SUMIFS(PL_Calicut!K:K,PL_Calicut!$B:$B,PL_Consol!$B19)+SUMIFS(PL_FNB!K:K,PL_FNB!$B:$B,PL_Consol!$B19) -> 620.42651 | M19: =SUMIFS(PL_Kochi!L:L,PL_Kochi!$B:$B,PL_Consol!$B19)+SUMIFS(PL_Calicut!L:L,PL_Calicut!$B:$B,PL_Consol!$B19)+SUMIFS(PL_FNB!L:L,PL_FNB!$B:$B,PL_Consol!$B19) -> 609.70921 | N19: =SUMIFS(PL_Kochi!M:M,PL_Kochi!$B:$B,PL_Consol!$B19)+SUMIFS(PL_Calicut!M:M,PL_Calicut!$B:$B,PL_Consol!$B19)+SUMIFS(PL_FNB!M:M,PL_FNB!$B:$B,PL_Consol!$B19) -> 642.58791 | O19: =SUMIFS(PL_Kochi!N:N,PL_Kochi!$B:$B,PL_Consol!$B19)+SUMIFS(PL_Calicut!N:N,PL_Calicut!$B:$B,PL_Consol!$B19)+SUMIFS(PL_FNB!N:N,PL_FNB!$B:$B,PL_Consol!$B19) -> 668.03247 | P19: =SUM(D19:O19) -> 7516.192 | Q19: 10174.401 | R19: 7400.74 | S19: =SUMIFS(PL_Kochi!R:R,PL_Kochi!$B:$B,PL_Consol!$B19)+SUMIFS(PL_Calicut!R:R,PL_Calicut!$B:$B,PL_Consol!$B19)+SUMIFS(PL_FNB!R:R,PL_FNB!$B:$B,PL_Consol!$B19) -> 658.26274 | T19: =SUMIFS(PL_Kochi!S:S,PL_Kochi!$B:$B,PL_Consol!$B19)+SUMIFS(PL_Calicut!S:S,PL_Calicut!$B:$B,PL_Consol!$B19)+SUMIFS(PL_FNB!S:S,PL_FNB!$B:$B,PL_Consol!$B19) -> 659.87997 | U19: 785.9 | V19: =IFERROR(T19/E19-1,"-") -> 0.050407666 | W19: =IFERROR(T19/S19-1,"-") -> 0.0024568175 | X19: =IFERROR(S19/U19,"-") -> 0.83759097
B20: Utilities-Power, fuel & water charges | C20: 11 | D20: =SUMIFS(PL_Kochi!C:C,PL_Kochi!$B:$B,PL_Consol!$B20)+SUMIFS(PL_Calicut!C:C,PL_Calicut!$B:$B,PL_Consol!$B20)+SUMIFS(PL_FNB!C:C,PL_FNB!$B:$B,PL_Consol!$B20) -> 89.079465 | E20: =SUMIFS(PL_Kochi!D:D,PL_Kochi!$B:$B,PL_Consol!$B20)+SUMIFS(PL_Calicut!D:D,PL_Calicut!$B:$B,PL_Consol!$B20)+SUMIFS(PL_FNB!D:D,PL_FNB!$B:$B,PL_Consol!$B20) -> 95.752945 | F20: =SUMIFS(PL_Kochi!E:E,PL_Kochi!$B:$B,PL_Consol!$B20)+SUMIFS(PL_Calicut!E:E,PL_Calicut!$B:$B,PL_Consol!$B20)+SUMIFS(PL_FNB!E:E,PL_FNB!$B:$B,PL_Consol!$B20) -> 105.11128 | G20: =SUMIFS(PL_Kochi!F:F,PL_Kochi!$B:$B,PL_Consol!$B20)+SUMIFS(PL_Calicut!F:F,PL_Calicut!$B:$B,PL_Consol!$B20)+SUMIFS(PL_FNB!F:F,PL_FNB!$B:$B,PL_Consol!$B20) -> 97.919884 | H20: =SUMIFS(PL_Kochi!G:G,PL_Kochi!$B:$B,PL_Consol!$B20)+SUMIFS(PL_Calicut!G:G,PL_Calicut!$B:$B,PL_Consol!$B20)+SUMIFS(PL_FNB!G:G,PL_FNB!$B:$B,PL_Consol!$B20) -> 91.137033 | I20: =SUMIFS(PL_Kochi!H:H,PL_Kochi!$B:$B,PL_Consol!$B20)+SUMIFS(PL_Calicut!H:H,PL_Calicut!$B:$B,PL_Consol!$B20)+SUMIFS(PL_FNB!H:H,PL_FNB!$B:$B,PL_Consol!$B20) -> 97.924134 | J20: =SUMIFS(PL_Kochi!I:I,PL_Kochi!$B:$B,PL_Consol!$B20)+SUMIFS(PL_Calicut!I:I,PL_Calicut!$B:$B,PL_Consol!$B20)+SUMIFS(PL_FNB!I:I,PL_FNB!$B:$B,PL_Consol!$B20) -> 109.33022 | K20: =SUMIFS(PL_Kochi!J:J,PL_Kochi!$B:$B,PL_Consol!$B20)+SUMIFS(PL_Calicut!J:J,PL_Calicut!$B:$B,PL_Consol!$B20)+SUMIFS(PL_FNB!J:J,PL_FNB!$B:$B,PL_Consol!$B20) -> 88.771923 | L20: =SUMIFS(PL_Kochi!K:K,PL_Kochi!$B:$B,PL_Consol!$B20)+SUMIFS(PL_Calicut!K:K,PL_Calicut!$B:$B,PL_Consol!$B20)+SUMIFS(PL_FNB!K:K,PL_FNB!$B:$B,PL_Consol!$B20) -> 98.77479 | M20: =SUMIFS(PL_Kochi!L:L,PL_Kochi!$B:$B,PL_Consol!$B20)+SUMIFS(PL_Calicut!L:L,PL_Calicut!$B:$B,PL_Consol!$B20)+SUMIFS(PL_FNB!L:L,PL_FNB!$B:$B,PL_Consol!$B20) -> 105.06447 | N20: =SUMIFS(PL_Kochi!M:M,PL_Kochi!$B:$B,PL_Consol!$B20)+SUMIFS(PL_Calicut!M:M,PL_Calicut!$B:$B,PL_Consol!$B20)+SUMIFS(PL_FNB!M:M,PL_FNB!$B:$B,PL_Consol!$B20) -> 91.249222 | O20: =SUMIFS(PL_Kochi!N:N,PL_Kochi!$B:$B,PL_Consol!$B20)+SUMIFS(PL_Calicut!N:N,PL_Calicut!$B:$B,PL_Consol!$B20)+SUMIFS(PL_FNB!N:N,PL_FNB!$B:$B,PL_Consol!$B20) -> 122.10168 | P20: =SUM(D20:O20) -> 1192.217 | Q20: 1306.9786 | R20: 1245.62 | S20: =SUMIFS(PL_Kochi!R:R,PL_Kochi!$B:$B,PL_Consol!$B20)+SUMIFS(PL_Calicut!R:R,PL_Calicut!$B:$B,PL_Consol!$B20)+SUMIFS(PL_FNB!R:R,PL_FNB!$B:$B,PL_Consol!$B20) -> 108.91587 | T20: =SUMIFS(PL_Kochi!S:S,PL_Kochi!$B:$B,PL_Consol!$B20)+SUMIFS(PL_Calicut!S:S,PL_Calicut!$B:$B,PL_Consol!$B20)+SUMIFS(PL_FNB!S:S,PL_FNB!$B:$B,PL_Consol!$B20) -> 104.62286 | U20: 119.4 | V20: =IFERROR(T20/E20-1,"-") -> 0.092633348 | W20: =IFERROR(T20/S20-1,"-") -> -0.039415816 | X20: =IFERROR(S20/U20,"-") -> 0.91219321
B21: Repair & Maintenance | C21: 12 | D21: =SUMIFS(PL_Kochi!C:C,PL_Kochi!$B:$B,PL_Consol!$B21)+SUMIFS(PL_Calicut!C:C,PL_Calicut!$B:$B,PL_Consol!$B21)+SUMIFS(PL_FNB!C:C,PL_FNB!$B:$B,PL_Consol!$B21) -> 71.970159 | E21: =SUMIFS(PL_Kochi!D:D,PL_Kochi!$B:$B,PL_Consol!$B21)+SUMIFS(PL_Calicut!D:D,PL_Calicut!$B:$B,PL_Consol!$B21)+SUMIFS(PL_FNB!D:D,PL_FNB!$B:$B,PL_Consol!$B21) -> 88.984337 | F21: =SUMIFS(PL_Kochi!E:E,PL_Kochi!$B:$B,PL_Consol!$B21)+SUMIFS(PL_Calicut!E:E,PL_Calicut!$B:$B,PL_Consol!$B21)+SUMIFS(PL_FNB!E:E,PL_FNB!$B:$B,PL_Consol!$B21) -> 124.64797 | G21: =SUMIFS(PL_Kochi!F:F,PL_Kochi!$B:$B,PL_Consol!$B21)+SUMIFS(PL_Calicut!F:F,PL_Calicut!$B:$B,PL_Consol!$B21)+SUMIFS(PL_FNB!F:F,PL_FNB!$B:$B,PL_Consol!$B21) -> 125.7808 | H21: =SUMIFS(PL_Kochi!G:G,PL_Kochi!$B:$B,PL_Consol!$B21)+SUMIFS(PL_Calicut!G:G,PL_Calicut!$B:$B,PL_Consol!$B21)+SUMIFS(PL_FNB!G:G,PL_FNB!$B:$B,PL_Consol!$B21) -> 138.05387 | I21: =SUMIFS(PL_Kochi!H:H,PL_Kochi!$B:$B,PL_Consol!$B21)+SUMIFS(PL_Calicut!H:H,PL_Calicut!$B:$B,PL_Consol!$B21)+SUMIFS(PL_FNB!H:H,PL_FNB!$B:$B,PL_Consol!$B21) -> 153.57039 | J21: =SUMIFS(PL_Kochi!I:I,PL_Kochi!$B:$B,PL_Consol!$B21)+SUMIFS(PL_Calicut!I:I,PL_Calicut!$B:$B,PL_Consol!$B21)+SUMIFS(PL_FNB!I:I,PL_FNB!$B:$B,PL_Consol!$B21) -> 160.26832 | K21: =SUMIFS(PL_Kochi!J:J,PL_Kochi!$B:$B,PL_Consol!$B21)+SUMIFS(PL_Calicut!J:J,PL_Calicut!$B:$B,PL_Consol!$B21)+SUMIFS(PL_FNB!J:J,PL_FNB!$B:$B,PL_Consol!$B21) -> 129.30591 | L21: =SUMIFS(PL_Kochi!K:K,PL_Kochi!$B:$B,PL_Consol!$B21)+SUMIFS(PL_Calicut!K:K,PL_Calicut!$B:$B,PL_Consol!$B21)+SUMIFS(PL_FNB!K:K,PL_FNB!$B:$B,PL_Consol!$B21) -> 100.64707 | M21: =SUMIFS(PL_Kochi!L:L,PL_Kochi!$B:$B,PL_Consol!$B21)+SUMIFS(PL_Calicut!L:L,PL_Calicut!$B:$B,PL_Consol!$B21)+SUMIFS(PL_FNB!L:L,PL_FNB!$B:$B,PL_Consol!$B21) -> 90.417465 | N21: =SUMIFS(PL_Kochi!M:M,PL_Kochi!$B:$B,PL_Consol!$B21)+SUMIFS(PL_Calicut!M:M,PL_Calicut!$B:$B,PL_Consol!$B21)+SUMIFS(PL_FNB!M:M,PL_FNB!$B:$B,PL_Consol!$B21) -> 190.35786 | O21: =SUMIFS(PL_Kochi!N:N,PL_Kochi!$B:$B,PL_Consol!$B21)+SUMIFS(PL_Calicut!N:N,PL_Calicut!$B:$B,PL_Consol!$B21)+SUMIFS(PL_FNB!N:N,PL_FNB!$B:$B,PL_Consol!$B21) -> 186.61879 | P21: =SUM(D21:O21) -> 1560.623 | Q21: 1275.5024 | R21: 1328.28 | S21: =SUMIFS(PL_Kochi!R:R,PL_Kochi!$B:$B,PL_Consol!$B21)+SUMIFS(PL_Calicut!R:R,PL_Calicut!$B:$B,PL_Consol!$B21)+SUMIFS(PL_FNB!R:R,PL_FNB!$B:$B,PL_Consol!$B21) -> 114.68122 | T21: =SUMIFS(PL_Kochi!S:S,PL_Kochi!$B:$B,PL_Consol!$B21)+SUMIFS(PL_Calicut!S:S,PL_Calicut!$B:$B,PL_Consol!$B21)+SUMIFS(PL_FNB!S:S,PL_FNB!$B:$B,PL_Consol!$B21) -> 79.364062 | U21: 23.4 | V21: =IFERROR(T21/E21-1,"-") -> -0.108112 | W21: =IFERROR(T21/S21-1,"-") -> -0.30795939 | X21: =IFERROR(S21/U21,"-") -> 4.9009069
B22: Marketing Cost | C22: 13 | D22: =SUMIFS(PL_Kochi!C:C,PL_Kochi!$B:$B,PL_Consol!$B22)+SUMIFS(PL_Calicut!C:C,PL_Calicut!$B:$B,PL_Consol!$B22)+SUMIFS(PL_FNB!C:C,PL_FNB!$B:$B,PL_Consol!$B22) -> 79.802357 | E22: =SUMIFS(PL_Kochi!D:D,PL_Kochi!$B:$B,PL_Consol!$B22)+SUMIFS(PL_Calicut!D:D,PL_Calicut!$B:$B,PL_Consol!$B22)+SUMIFS(PL_FNB!D:D,PL_FNB!$B:$B,PL_Consol!$B22) -> 57.816802 | F22: =SUMIFS(PL_Kochi!E:E,PL_Kochi!$B:$B,PL_Consol!$B22)+SUMIFS(PL_Calicut!E:E,PL_Calicut!$B:$B,PL_Consol!$B22)+SUMIFS(PL_FNB!E:E,PL_FNB!$B:$B,PL_Consol!$B22) -> 59.621195 | G22: =SUMIFS(PL_Kochi!F:F,PL_Kochi!$B:$B,PL_Consol!$B22)+SUMIFS(PL_Calicut!F:F,PL_Calicut!$B:$B,PL_Consol!$B22)+SUMIFS(PL_FNB!F:F,PL_FNB!$B:$B,PL_Consol!$B22) -> 50.836791 | H22: =SUMIFS(PL_Kochi!G:G,PL_Kochi!$B:$B,PL_Consol!$B22)+SUMIFS(PL_Calicut!G:G,PL_Calicut!$B:$B,PL_Consol!$B22)+SUMIFS(PL_FNB!G:G,PL_FNB!$B:$B,PL_Consol!$B22) -> 66.430517 | I22: =SUMIFS(PL_Kochi!H:H,PL_Kochi!$B:$B,PL_Consol!$B22)+SUMIFS(PL_Calicut!H:H,PL_Calicut!$B:$B,PL_Consol!$B22)+SUMIFS(PL_FNB!H:H,PL_FNB!$B:$B,PL_Consol!$B22) -> 84.857807 | J22: =SUMIFS(PL_Kochi!I:I,PL_Kochi!$B:$B,PL_Consol!$B22)+SUMIFS(PL_Calicut!I:I,PL_Calicut!$B:$B,PL_Consol!$B22)+SUMIFS(PL_FNB!I:I,PL_FNB!$B:$B,PL_Consol!$B22) -> 81.86046 | K22: =SUMIFS(PL_Kochi!J:J,PL_Kochi!$B:$B,PL_Consol!$B22)+SUMIFS(PL_Calicut!J:J,PL_Calicut!$B:$B,PL_Consol!$B22)+SUMIFS(PL_FNB!J:J,PL_FNB!$B:$B,PL_Consol!$B22) -> 71.772029 | L22: =SUMIFS(PL_Kochi!K:K,PL_Kochi!$B:$B,PL_Consol!$B22)+SUMIFS(PL_Calicut!K:K,PL_Calicut!$B:$B,PL_Consol!$B22)+SUMIFS(PL_FNB!K:K,PL_FNB!$B:$B,PL_Consol!$B22) -> 77.663979 | M22: =SUMIFS(PL_Kochi!L:L,PL_Kochi!$B:$B,PL_Consol!$B22)+SUMIFS(PL_Calicut!L:L,PL_Calicut!$B:$B,PL_Consol!$B22)+SUMIFS(PL_FNB!L:L,PL_FNB!$B:$B,PL_Consol!$B22) -> 74.179736 | N22: =SUMIFS(PL_Kochi!M:M,PL_Kochi!$B:$B,PL_Consol!$B22)+SUMIFS(PL_Calicut!M:M,PL_Calicut!$B:$B,PL_Consol!$B22)+SUMIFS(PL_FNB!M:M,PL_FNB!$B:$B,PL_Consol!$B22) -> 111.7871 | O22: =SUMIFS(PL_Kochi!N:N,PL_Kochi!$B:$B,PL_Consol!$B22)+SUMIFS(PL_Calicut!N:N,PL_Calicut!$B:$B,PL_Consol!$B22)+SUMIFS(PL_FNB!N:N,PL_FNB!$B:$B,PL_Consol!$B22) -> 63.518614 | P22: =SUM(D22:O22) -> 880.14738 | Q22: 1209.9732 | R22: 703.25 | S22: =SUMIFS(PL_Kochi!R:R,PL_Kochi!$B:$B,PL_Consol!$B22)+SUMIFS(PL_Calicut!R:R,PL_Calicut!$B:$B,PL_Consol!$B22)+SUMIFS(PL_FNB!R:R,PL_FNB!$B:$B,PL_Consol!$B22) -> 72.019957 | T22: =SUMIFS(PL_Kochi!S:S,PL_Kochi!$B:$B,PL_Consol!$B22)+SUMIFS(PL_Calicut!S:S,PL_Calicut!$B:$B,PL_Consol!$B22)+SUMIFS(PL_FNB!S:S,PL_FNB!$B:$B,PL_Consol!$B22) -> 51.2846 | U22: 17.4 | V22: =IFERROR(T22/E22-1,"-") -> -0.11298103 | W22: =IFERROR(T22/S22-1,"-") -> -0.28791126 | X22: =IFERROR(S22/U22,"-") -> 4.139078
B23: Lab Test Charges | C23: 14 | D23: =SUMIFS(PL_Kochi!C:C,PL_Kochi!$B:$B,PL_Consol!$B23)+SUMIFS(PL_Calicut!C:C,PL_Calicut!$B:$B,PL_Consol!$B23)+SUMIFS(PL_FNB!C:C,PL_FNB!$B:$B,PL_Consol!$B23) -> 16.785611 | E23: =SUMIFS(PL_Kochi!D:D,PL_Kochi!$B:$B,PL_Consol!$B23)+SUMIFS(PL_Calicut!D:D,PL_Calicut!$B:$B,PL_Consol!$B23)+SUMIFS(PL_FNB!D:D,PL_FNB!$B:$B,PL_Consol!$B23) -> 18.615196 | F23: =SUMIFS(PL_Kochi!E:E,PL_Kochi!$B:$B,PL_Consol!$B23)+SUMIFS(PL_Calicut!E:E,PL_Calicut!$B:$B,PL_Consol!$B23)+SUMIFS(PL_FNB!E:E,PL_FNB!$B:$B,PL_Consol!$B23) -> 21.438936 | G23: =SUMIFS(PL_Kochi!F:F,PL_Kochi!$B:$B,PL_Consol!$B23)+SUMIFS(PL_Calicut!F:F,PL_Calicut!$B:$B,PL_Consol!$B23)+SUMIFS(PL_FNB!F:F,PL_FNB!$B:$B,PL_Consol!$B23) -> 18.376415 | H23: =SUMIFS(PL_Kochi!G:G,PL_Kochi!$B:$B,PL_Consol!$B23)+SUMIFS(PL_Calicut!G:G,PL_Calicut!$B:$B,PL_Consol!$B23)+SUMIFS(PL_FNB!G:G,PL_FNB!$B:$B,PL_Consol!$B23) -> 26.549782 | I23: =SUMIFS(PL_Kochi!H:H,PL_Kochi!$B:$B,PL_Consol!$B23)+SUMIFS(PL_Calicut!H:H,PL_Calicut!$B:$B,PL_Consol!$B23)+SUMIFS(PL_FNB!H:H,PL_FNB!$B:$B,PL_Consol!$B23) -> 16.773704 | J23: =SUMIFS(PL_Kochi!I:I,PL_Kochi!$B:$B,PL_Consol!$B23)+SUMIFS(PL_Calicut!I:I,PL_Calicut!$B:$B,PL_Consol!$B23)+SUMIFS(PL_FNB!I:I,PL_FNB!$B:$B,PL_Consol!$B23) -> 22.79036 | K23: =SUMIFS(PL_Kochi!J:J,PL_Kochi!$B:$B,PL_Consol!$B23)+SUMIFS(PL_Calicut!J:J,PL_Calicut!$B:$B,PL_Consol!$B23)+SUMIFS(PL_FNB!J:J,PL_FNB!$B:$B,PL_Consol!$B23) -> 9.2216255 | L23: =SUMIFS(PL_Kochi!K:K,PL_Kochi!$B:$B,PL_Consol!$B23)+SUMIFS(PL_Calicut!K:K,PL_Calicut!$B:$B,PL_Consol!$B23)+SUMIFS(PL_FNB!K:K,PL_FNB!$B:$B,PL_Consol!$B23) -> 37.627735 | M23: =SUMIFS(PL_Kochi!L:L,PL_Kochi!$B:$B,PL_Consol!$B23)+SUMIFS(PL_Calicut!L:L,PL_Calicut!$B:$B,PL_Consol!$B23)+SUMIFS(PL_FNB!L:L,PL_FNB!$B:$B,PL_Consol!$B23) -> 30.08253 | N23: =SUMIFS(PL_Kochi!M:M,PL_Kochi!$B:$B,PL_Consol!$B23)+SUMIFS(PL_Calicut!M:M,PL_Calicut!$B:$B,PL_Consol!$B23)+SUMIFS(PL_FNB!M:M,PL_FNB!$B:$B,PL_Consol!$B23) -> 27.391808 | O23: =SUMIFS(PL_Kochi!N:N,PL_Kochi!$B:$B,PL_Consol!$B23)+SUMIFS(PL_Calicut!N:N,PL_Calicut!$B:$B,PL_Consol!$B23)+SUMIFS(PL_FNB!N:N,PL_FNB!$B:$B,PL_Consol!$B23) -> 22.111633 | P23: =SUM(D23:O23) -> 267.76534 | Q23: 274.99371 | R23: 237.77 | S23: =SUMIFS(PL_Kochi!R:R,PL_Kochi!$B:$B,PL_Consol!$B23)+SUMIFS(PL_Calicut!R:R,PL_Calicut!$B:$B,PL_Consol!$B23)+SUMIFS(PL_FNB!R:R,PL_FNB!$B:$B,PL_Consol!$B23) -> 24.101609 | T23: =SUMIFS(PL_Kochi!S:S,PL_Kochi!$B:$B,PL_Consol!$B23)+SUMIFS(PL_Calicut!S:S,PL_Calicut!$B:$B,PL_Consol!$B23)+SUMIFS(PL_FNB!S:S,PL_FNB!$B:$B,PL_Consol!$B23) -> 29.50202 | U23: 136.3 | V23: =IFERROR(T23/E23-1,"-") -> 0.58483528 | W23: =IFERROR(T23/S23-1,"-") -> 0.22406847 | X23: =IFERROR(S23/U23,"-") -> 0.17682765
B24: Rent Paid | C24: 15 | D24: =SUMIFS(PL_Kochi!C:C,PL_Kochi!$B:$B,PL_Consol!$B24)+SUMIFS(PL_Calicut!C:C,PL_Calicut!$B:$B,PL_Consol!$B24)+SUMIFS(PL_FNB!C:C,PL_FNB!$B:$B,PL_Consol!$B24) -> 22.641747 | E24: =SUMIFS(PL_Kochi!D:D,PL_Kochi!$B:$B,PL_Consol!$B24)+SUMIFS(PL_Calicut!D:D,PL_Calicut!$B:$B,PL_Consol!$B24)+SUMIFS(PL_FNB!D:D,PL_FNB!$B:$B,PL_Consol!$B24) -> 21.421681 | F24: =SUMIFS(PL_Kochi!E:E,PL_Kochi!$B:$B,PL_Consol!$B24)+SUMIFS(PL_Calicut!E:E,PL_Calicut!$B:$B,PL_Consol!$B24)+SUMIFS(PL_FNB!E:E,PL_FNB!$B:$B,PL_Consol!$B24) -> 24.008923 | G24: =SUMIFS(PL_Kochi!F:F,PL_Kochi!$B:$B,PL_Consol!$B24)+SUMIFS(PL_Calicut!F:F,PL_Calicut!$B:$B,PL_Consol!$B24)+SUMIFS(PL_FNB!F:F,PL_FNB!$B:$B,PL_Consol!$B24) -> 16.951312 | H24: =SUMIFS(PL_Kochi!G:G,PL_Kochi!$B:$B,PL_Consol!$B24)+SUMIFS(PL_Calicut!G:G,PL_Calicut!$B:$B,PL_Consol!$B24)+SUMIFS(PL_FNB!G:G,PL_FNB!$B:$B,PL_Consol!$B24) -> 26.720004 | I24: =SUMIFS(PL_Kochi!H:H,PL_Kochi!$B:$B,PL_Consol!$B24)+SUMIFS(PL_Calicut!H:H,PL_Calicut!$B:$B,PL_Consol!$B24)+SUMIFS(PL_FNB!H:H,PL_FNB!$B:$B,PL_Consol!$B24) -> 26.464045 | J24: =SUMIFS(PL_Kochi!I:I,PL_Kochi!$B:$B,PL_Consol!$B24)+SUMIFS(PL_Calicut!I:I,PL_Calicut!$B:$B,PL_Consol!$B24)+SUMIFS(PL_FNB!I:I,PL_FNB!$B:$B,PL_Consol!$B24) -> 21.325308 | K24: =SUMIFS(PL_Kochi!J:J,PL_Kochi!$B:$B,PL_Consol!$B24)+SUMIFS(PL_Calicut!J:J,PL_Calicut!$B:$B,PL_Consol!$B24)+SUMIFS(PL_FNB!J:J,PL_FNB!$B:$B,PL_Consol!$B24) -> 21.235651 | L24: =SUMIFS(PL_Kochi!K:K,PL_Kochi!$B:$B,PL_Consol!$B24)+SUMIFS(PL_Calicut!K:K,PL_Calicut!$B:$B,PL_Consol!$B24)+SUMIFS(PL_FNB!K:K,PL_FNB!$B:$B,PL_Consol!$B24) -> 24.573338 | M24: =SUMIFS(PL_Kochi!L:L,PL_Kochi!$B:$B,PL_Consol!$B24)+SUMIFS(PL_Calicut!L:L,PL_Calicut!$B:$B,PL_Consol!$B24)+SUMIFS(PL_FNB!L:L,PL_FNB!$B:$B,PL_Consol!$B24) -> 23.386038 | N24: =SUMIFS(PL_Kochi!M:M,PL_Kochi!$B:$B,PL_Consol!$B24)+SUMIFS(PL_Calicut!M:M,PL_Calicut!$B:$B,PL_Consol!$B24)+SUMIFS(PL_FNB!M:M,PL_FNB!$B:$B,PL_Consol!$B24) -> 23.189508 | O24: =SUMIFS(PL_Kochi!N:N,PL_Kochi!$B:$B,PL_Consol!$B24)+SUMIFS(PL_Calicut!N:N,PL_Calicut!$B:$B,PL_Consol!$B24)+SUMIFS(PL_FNB!N:N,PL_FNB!$B:$B,PL_Consol!$B24) -> 31.523178 | P24: =SUM(D24:O24) -> 283.44073 | Q24: 180 | R24: 178.89 | S24: =SUMIFS(PL_Kochi!R:R,PL_Kochi!$B:$B,PL_Consol!$B24)+SUMIFS(PL_Calicut!R:R,PL_Calicut!$B:$B,PL_Consol!$B24)+SUMIFS(PL_FNB!R:R,PL_FNB!$B:$B,PL_Consol!$B24) -> 22.68199 | T24: =SUMIFS(PL_Kochi!S:S,PL_Kochi!$B:$B,PL_Consol!$B24)+SUMIFS(PL_Calicut!S:S,PL_Calicut!$B:$B,PL_Consol!$B24)+SUMIFS(PL_FNB!S:S,PL_FNB!$B:$B,PL_Consol!$B24) -> 23.08884 | U24: 98.7 | V24: =IFERROR(T24/E24-1,"-") -> 0.077825769 | W24: =IFERROR(T24/S24-1,"-") -> 0.017937149 | X24: =IFERROR(S24/U24,"-") -> 0.22980739
B25: House Keeping Expenses | C25: 16 | D25: =SUMIFS(PL_Kochi!C:C,PL_Kochi!$B:$B,PL_Consol!$B25)+SUMIFS(PL_Calicut!C:C,PL_Calicut!$B:$B,PL_Consol!$B25)+SUMIFS(PL_FNB!C:C,PL_FNB!$B:$B,PL_Consol!$B25) -> 66.117028 | E25: =SUMIFS(PL_Kochi!D:D,PL_Kochi!$B:$B,PL_Consol!$B25)+SUMIFS(PL_Calicut!D:D,PL_Calicut!$B:$B,PL_Consol!$B25)+SUMIFS(PL_FNB!D:D,PL_FNB!$B:$B,PL_Consol!$B25) -> 71.893894 | F25: =SUMIFS(PL_Kochi!E:E,PL_Kochi!$B:$B,PL_Consol!$B25)+SUMIFS(PL_Calicut!E:E,PL_Calicut!$B:$B,PL_Consol!$B25)+SUMIFS(PL_FNB!E:E,PL_FNB!$B:$B,PL_Consol!$B25) -> 78.735924 | G25: =SUMIFS(PL_Kochi!F:F,PL_Kochi!$B:$B,PL_Consol!$B25)+SUMIFS(PL_Calicut!F:F,PL_Calicut!$B:$B,PL_Consol!$B25)+SUMIFS(PL_FNB!F:F,PL_FNB!$B:$B,PL_Consol!$B25) -> 74.499295 | H25: =SUMIFS(PL_Kochi!G:G,PL_Kochi!$B:$B,PL_Consol!$B25)+SUMIFS(PL_Calicut!G:G,PL_Calicut!$B:$B,PL_Consol!$B25)+SUMIFS(PL_FNB!G:G,PL_FNB!$B:$B,PL_Consol!$B25) -> 67.888813 | I25: =SUMIFS(PL_Kochi!H:H,PL_Kochi!$B:$B,PL_Consol!$B25)+SUMIFS(PL_Calicut!H:H,PL_Calicut!$B:$B,PL_Consol!$B25)+SUMIFS(PL_FNB!H:H,PL_FNB!$B:$B,PL_Consol!$B25) -> 75.070654 | J25: =SUMIFS(PL_Kochi!I:I,PL_Kochi!$B:$B,PL_Consol!$B25)+SUMIFS(PL_Calicut!I:I,PL_Calicut!$B:$B,PL_Consol!$B25)+SUMIFS(PL_FNB!I:I,PL_FNB!$B:$B,PL_Consol!$B25) -> 88.145987 | K25: =SUMIFS(PL_Kochi!J:J,PL_Kochi!$B:$B,PL_Consol!$B25)+SUMIFS(PL_Calicut!J:J,PL_Calicut!$B:$B,PL_Consol!$B25)+SUMIFS(PL_FNB!J:J,PL_FNB!$B:$B,PL_Consol!$B25) -> 63.493011 | L25: =SUMIFS(PL_Kochi!K:K,PL_Kochi!$B:$B,PL_Consol!$B25)+SUMIFS(PL_Calicut!K:K,PL_Calicut!$B:$B,PL_Consol!$B25)+SUMIFS(PL_FNB!K:K,PL_FNB!$B:$B,PL_Consol!$B25) -> 68.196841 | M25: =SUMIFS(PL_Kochi!L:L,PL_Kochi!$B:$B,PL_Consol!$B25)+SUMIFS(PL_Calicut!L:L,PL_Calicut!$B:$B,PL_Consol!$B25)+SUMIFS(PL_FNB!L:L,PL_FNB!$B:$B,PL_Consol!$B25) -> 49.50565 | N25: =SUMIFS(PL_Kochi!M:M,PL_Kochi!$B:$B,PL_Consol!$B25)+SUMIFS(PL_Calicut!M:M,PL_Calicut!$B:$B,PL_Consol!$B25)+SUMIFS(PL_FNB!M:M,PL_FNB!$B:$B,PL_Consol!$B25) -> 120.95571 | O25: =SUMIFS(PL_Kochi!N:N,PL_Kochi!$B:$B,PL_Consol!$B25)+SUMIFS(PL_Calicut!N:N,PL_Calicut!$B:$B,PL_Consol!$B25)+SUMIFS(PL_FNB!N:N,PL_FNB!$B:$B,PL_Consol!$B25) -> 183.70153 | P25: =SUM(D25:O25) -> 1008.2043 | Q25: 926.03153 | R25: 1028.68 | S25: =SUMIFS(PL_Kochi!R:R,PL_Kochi!$B:$B,PL_Consol!$B25)+SUMIFS(PL_Calicut!R:R,PL_Calicut!$B:$B,PL_Consol!$B25)+SUMIFS(PL_FNB!R:R,PL_FNB!$B:$B,PL_Consol!$B25) -> 89.327925 | T25: =SUMIFS(PL_Kochi!S:S,PL_Kochi!$B:$B,PL_Consol!$B25)+SUMIFS(PL_Calicut!S:S,PL_Calicut!$B:$B,PL_Consol!$B25)+SUMIFS(PL_FNB!S:S,PL_FNB!$B:$B,PL_Consol!$B25) -> 114.05982 | U25: 30.7 | V25: =IFERROR(T25/E25-1,"-") -> 0.58650217 | W25: =IFERROR(T25/S25-1,"-") -> 0.27686632 | X25: =IFERROR(S25/U25,"-") -> 2.9097044
B26: Security Expenses | C26: 17 | D26: =SUMIFS(PL_Kochi!C:C,PL_Kochi!$B:$B,PL_Consol!$B26)+SUMIFS(PL_Calicut!C:C,PL_Calicut!$B:$B,PL_Consol!$B26)+SUMIFS(PL_FNB!C:C,PL_FNB!$B:$B,PL_Consol!$B26) -> 20.799117 | E26: =SUMIFS(PL_Kochi!D:D,PL_Kochi!$B:$B,PL_Consol!$B26)+SUMIFS(PL_Calicut!D:D,PL_Calicut!$B:$B,PL_Consol!$B26)+SUMIFS(PL_FNB!D:D,PL_FNB!$B:$B,PL_Consol!$B26) -> 23.636231 | F26: =SUMIFS(PL_Kochi!E:E,PL_Kochi!$B:$B,PL_Consol!$B26)+SUMIFS(PL_Calicut!E:E,PL_Calicut!$B:$B,PL_Consol!$B26)+SUMIFS(PL_FNB!E:E,PL_FNB!$B:$B,PL_Consol!$B26) -> 23.635804 | G26: =SUMIFS(PL_Kochi!F:F,PL_Kochi!$B:$B,PL_Consol!$B26)+SUMIFS(PL_Calicut!F:F,PL_Calicut!$B:$B,PL_Consol!$B26)+SUMIFS(PL_FNB!F:F,PL_FNB!$B:$B,PL_Consol!$B26) -> 23.342055 | H26: =SUMIFS(PL_Kochi!G:G,PL_Kochi!$B:$B,PL_Consol!$B26)+SUMIFS(PL_Calicut!G:G,PL_Calicut!$B:$B,PL_Consol!$B26)+SUMIFS(PL_FNB!G:G,PL_FNB!$B:$B,PL_Consol!$B26) -> 19.828358 | I26: =SUMIFS(PL_Kochi!H:H,PL_Kochi!$B:$B,PL_Consol!$B26)+SUMIFS(PL_Calicut!H:H,PL_Calicut!$B:$B,PL_Consol!$B26)+SUMIFS(PL_FNB!H:H,PL_FNB!$B:$B,PL_Consol!$B26) -> 19.054742 | J26: =SUMIFS(PL_Kochi!I:I,PL_Kochi!$B:$B,PL_Consol!$B26)+SUMIFS(PL_Calicut!I:I,PL_Calicut!$B:$B,PL_Consol!$B26)+SUMIFS(PL_FNB!I:I,PL_FNB!$B:$B,PL_Consol!$B26) -> 25.530817 | K26: =SUMIFS(PL_Kochi!J:J,PL_Kochi!$B:$B,PL_Consol!$B26)+SUMIFS(PL_Calicut!J:J,PL_Calicut!$B:$B,PL_Consol!$B26)+SUMIFS(PL_FNB!J:J,PL_FNB!$B:$B,PL_Consol!$B26) -> 21.061225 | L26: =SUMIFS(PL_Kochi!K:K,PL_Kochi!$B:$B,PL_Consol!$B26)+SUMIFS(PL_Calicut!K:K,PL_Calicut!$B:$B,PL_Consol!$B26)+SUMIFS(PL_FNB!K:K,PL_FNB!$B:$B,PL_Consol!$B26) -> 21.393371 | M26: =SUMIFS(PL_Kochi!L:L,PL_Kochi!$B:$B,PL_Consol!$B26)+SUMIFS(PL_Calicut!L:L,PL_Calicut!$B:$B,PL_Consol!$B26)+SUMIFS(PL_FNB!L:L,PL_FNB!$B:$B,PL_Consol!$B26) -> 22.631518 | N26: =SUMIFS(PL_Kochi!M:M,PL_Kochi!$B:$B,PL_Consol!$B26)+SUMIFS(PL_Calicut!M:M,PL_Calicut!$B:$B,PL_Consol!$B26)+SUMIFS(PL_FNB!M:M,PL_FNB!$B:$B,PL_Consol!$B26) -> 21.138675 | O26: =SUMIFS(PL_Kochi!N:N,PL_Kochi!$B:$B,PL_Consol!$B26)+SUMIFS(PL_Calicut!N:N,PL_Calicut!$B:$B,PL_Consol!$B26)+SUMIFS(PL_FNB!N:N,PL_FNB!$B:$B,PL_Consol!$B26) -> 23.288502 | P26: =SUM(D26:O26) -> 265.34041 | Q26: 241.48542 | R26: 227.63 | S26: =SUMIFS(PL_Kochi!R:R,PL_Kochi!$B:$B,PL_Consol!$B26)+SUMIFS(PL_Calicut!R:R,PL_Calicut!$B:$B,PL_Consol!$B26)+SUMIFS(PL_FNB!R:R,PL_FNB!$B:$B,PL_Consol!$B26) -> 24.095348 | T26: =SUMIFS(PL_Kochi!S:S,PL_Kochi!$B:$B,PL_Consol!$B26)+SUMIFS(PL_Calicut!S:S,PL_Calicut!$B:$B,PL_Consol!$B26)+SUMIFS(PL_FNB!S:S,PL_FNB!$B:$B,PL_Consol!$B26) -> 18.78792 | U26: 17.2 | V26: =IFERROR(T26/E26-1,"-") -> -0.20512201 | W26: =IFERROR(T26/S26-1,"-") -> -0.22026773 | X26: =IFERROR(S26/U26,"-") -> 1.4008923
B27: Printing & Stationery | C27: 18 | D27: =SUMIFS(PL_Kochi!C:C,PL_Kochi!$B:$B,PL_Consol!$B27)+SUMIFS(PL_Calicut!C:C,PL_Calicut!$B:$B,PL_Consol!$B27)+SUMIFS(PL_FNB!C:C,PL_FNB!$B:$B,PL_Consol!$B27) -> 11.416728 | E27: =SUMIFS(PL_Kochi!D:D,PL_Kochi!$B:$B,PL_Consol!$B27)+SUMIFS(PL_Calicut!D:D,PL_Calicut!$B:$B,PL_Consol!$B27)+SUMIFS(PL_FNB!D:D,PL_FNB!$B:$B,PL_Consol!$B27) -> 17.394012 | F27: =SUMIFS(PL_Kochi!E:E,PL_Kochi!$B:$B,PL_Consol!$B27)+SUMIFS(PL_Calicut!E:E,PL_Calicut!$B:$B,PL_Consol!$B27)+SUMIFS(PL_FNB!E:E,PL_FNB!$B:$B,PL_Consol!$B27) -> 13.518077 | G27: =SUMIFS(PL_Kochi!F:F,PL_Kochi!$B:$B,PL_Consol!$B27)+SUMIFS(PL_Calicut!F:F,PL_Calicut!$B:$B,PL_Consol!$B27)+SUMIFS(PL_FNB!F:F,PL_FNB!$B:$B,PL_Consol!$B27) -> 16.703076 | H27: =SUMIFS(PL_Kochi!G:G,PL_Kochi!$B:$B,PL_Consol!$B27)+SUMIFS(PL_Calicut!G:G,PL_Calicut!$B:$B,PL_Consol!$B27)+SUMIFS(PL_FNB!G:G,PL_FNB!$B:$B,PL_Consol!$B27) -> 13.933211 | I27: =SUMIFS(PL_Kochi!H:H,PL_Kochi!$B:$B,PL_Consol!$B27)+SUMIFS(PL_Calicut!H:H,PL_Calicut!$B:$B,PL_Consol!$B27)+SUMIFS(PL_FNB!H:H,PL_FNB!$B:$B,PL_Consol!$B27) -> 14.397721 | J27: =SUMIFS(PL_Kochi!I:I,PL_Kochi!$B:$B,PL_Consol!$B27)+SUMIFS(PL_Calicut!I:I,PL_Calicut!$B:$B,PL_Consol!$B27)+SUMIFS(PL_FNB!I:I,PL_FNB!$B:$B,PL_Consol!$B27) -> 18.095623 | K27: =SUMIFS(PL_Kochi!J:J,PL_Kochi!$B:$B,PL_Consol!$B27)+SUMIFS(PL_Calicut!J:J,PL_Calicut!$B:$B,PL_Consol!$B27)+SUMIFS(PL_FNB!J:J,PL_FNB!$B:$B,PL_Consol!$B27) -> 11.643462 | L27: =SUMIFS(PL_Kochi!K:K,PL_Kochi!$B:$B,PL_Consol!$B27)+SUMIFS(PL_Calicut!K:K,PL_Calicut!$B:$B,PL_Consol!$B27)+SUMIFS(PL_FNB!K:K,PL_FNB!$B:$B,PL_Consol!$B27) -> 13.987179 | M27: =SUMIFS(PL_Kochi!L:L,PL_Kochi!$B:$B,PL_Consol!$B27)+SUMIFS(PL_Calicut!L:L,PL_Calicut!$B:$B,PL_Consol!$B27)+SUMIFS(PL_FNB!L:L,PL_FNB!$B:$B,PL_Consol!$B27) -> 14.229374 | N27: =SUMIFS(PL_Kochi!M:M,PL_Kochi!$B:$B,PL_Consol!$B27)+SUMIFS(PL_Calicut!M:M,PL_Calicut!$B:$B,PL_Consol!$B27)+SUMIFS(PL_FNB!M:M,PL_FNB!$B:$B,PL_Consol!$B27) -> 18.054122 | O27: =SUMIFS(PL_Kochi!N:N,PL_Kochi!$B:$B,PL_Consol!$B27)+SUMIFS(PL_Calicut!N:N,PL_Calicut!$B:$B,PL_Consol!$B27)+SUMIFS(PL_FNB!N:N,PL_FNB!$B:$B,PL_Consol!$B27) -> 19.449988 | P27: =SUM(D27:O27) -> 182.82258 | Q27: 180 | R27: 167.97 | S27: =SUMIFS(PL_Kochi!R:R,PL_Kochi!$B:$B,PL_Consol!$B27)+SUMIFS(PL_Calicut!R:R,PL_Calicut!$B:$B,PL_Consol!$B27)+SUMIFS(PL_FNB!R:R,PL_FNB!$B:$B,PL_Consol!$B27) -> 18.924059 | T27: =SUMIFS(PL_Kochi!S:S,PL_Kochi!$B:$B,PL_Consol!$B27)+SUMIFS(PL_Calicut!S:S,PL_Calicut!$B:$B,PL_Consol!$B27)+SUMIFS(PL_FNB!S:S,PL_FNB!$B:$B,PL_Consol!$B27) -> 17.974497 | U27: 3 | V27: =IFERROR(T27/E27-1,"-") -> 0.033372677 | W27: =IFERROR(T27/S27-1,"-") -> -0.050177526 | X27: =IFERROR(S27/U27,"-") -> 6.3080198
B28: Insurance | C28: 19 | D28: =SUMIFS(PL_Kochi!C:C,PL_Kochi!$B:$B,PL_Consol!$B28)+SUMIFS(PL_Calicut!C:C,PL_Calicut!$B:$B,PL_Consol!$B28)+SUMIFS(PL_FNB!C:C,PL_FNB!$B:$B,PL_Consol!$B28) -> 2.2859503 | E28: =SUMIFS(PL_Kochi!D:D,PL_Kochi!$B:$B,PL_Consol!$B28)+SUMIFS(PL_Calicut!D:D,PL_Calicut!$B:$B,PL_Consol!$B28)+SUMIFS(PL_FNB!D:D,PL_FNB!$B:$B,PL_Consol!$B28) -> 2.3843484 | F28: =SUMIFS(PL_Kochi!E:E,PL_Kochi!$B:$B,PL_Consol!$B28)+SUMIFS(PL_Calicut!E:E,PL_Calicut!$B:$B,PL_Consol!$B28)+SUMIFS(PL_FNB!E:E,PL_FNB!$B:$B,PL_Consol!$B28) -> 1.9492875 | G28: =SUMIFS(PL_Kochi!F:F,PL_Kochi!$B:$B,PL_Consol!$B28)+SUMIFS(PL_Calicut!F:F,PL_Calicut!$B:$B,PL_Consol!$B28)+SUMIFS(PL_FNB!F:F,PL_FNB!$B:$B,PL_Consol!$B28) -> 1.8451045 | H28: =SUMIFS(PL_Kochi!G:G,PL_Kochi!$B:$B,PL_Consol!$B28)+SUMIFS(PL_Calicut!G:G,PL_Calicut!$B:$B,PL_Consol!$B28)+SUMIFS(PL_FNB!G:G,PL_FNB!$B:$B,PL_Consol!$B28) -> 2.6315041 | I28: =SUMIFS(PL_Kochi!H:H,PL_Kochi!$B:$B,PL_Consol!$B28)+SUMIFS(PL_Calicut!H:H,PL_Calicut!$B:$B,PL_Consol!$B28)+SUMIFS(PL_FNB!H:H,PL_FNB!$B:$B,PL_Consol!$B28) -> 3.41898 | J28: =SUMIFS(PL_Kochi!I:I,PL_Kochi!$B:$B,PL_Consol!$B28)+SUMIFS(PL_Calicut!I:I,PL_Calicut!$B:$B,PL_Consol!$B28)+SUMIFS(PL_FNB!I:I,PL_FNB!$B:$B,PL_Consol!$B28) -> 2.6836979 | K28: =SUMIFS(PL_Kochi!J:J,PL_Kochi!$B:$B,PL_Consol!$B28)+SUMIFS(PL_Calicut!J:J,PL_Calicut!$B:$B,PL_Consol!$B28)+SUMIFS(PL_FNB!J:J,PL_FNB!$B:$B,PL_Consol!$B28) -> 2.9104056 | L28: =SUMIFS(PL_Kochi!K:K,PL_Kochi!$B:$B,PL_Consol!$B28)+SUMIFS(PL_Calicut!K:K,PL_Calicut!$B:$B,PL_Consol!$B28)+SUMIFS(PL_FNB!K:K,PL_FNB!$B:$B,PL_Consol!$B28) -> 3.1283705 | M28: =SUMIFS(PL_Kochi!L:L,PL_Kochi!$B:$B,PL_Consol!$B28)+SUMIFS(PL_Calicut!L:L,PL_Calicut!$B:$B,PL_Consol!$B28)+SUMIFS(PL_FNB!L:L,PL_FNB!$B:$B,PL_Consol!$B28) -> 2.6990206 | N28: =SUMIFS(PL_Kochi!M:M,PL_Kochi!$B:$B,PL_Consol!$B28)+SUMIFS(PL_Calicut!M:M,PL_Calicut!$B:$B,PL_Consol!$B28)+SUMIFS(PL_FNB!M:M,PL_FNB!$B:$B,PL_Consol!$B28) -> 2.8924163 | O28: =SUMIFS(PL_Kochi!N:N,PL_Kochi!$B:$B,PL_Consol!$B28)+SUMIFS(PL_Calicut!N:N,PL_Calicut!$B:$B,PL_Consol!$B28)+SUMIFS(PL_FNB!N:N,PL_FNB!$B:$B,PL_Consol!$B28) -> 3.1997823 | P28: =SUM(D28:O28) -> 32.028868 | Q28: 32 | R28: 22.78 | S28: =SUMIFS(PL_Kochi!R:R,PL_Kochi!$B:$B,PL_Consol!$B28)+SUMIFS(PL_Calicut!R:R,PL_Calicut!$B:$B,PL_Consol!$B28)+SUMIFS(PL_FNB!R:R,PL_FNB!$B:$B,PL_Consol!$B28) -> 3.0348463 | T28: =SUMIFS(PL_Kochi!S:S,PL_Kochi!$B:$B,PL_Consol!$B28)+SUMIFS(PL_Calicut!S:S,PL_Calicut!$B:$B,PL_Consol!$B28)+SUMIFS(PL_FNB!S:S,PL_FNB!$B:$B,PL_Consol!$B28) -> 3.289582 | U28: 4.2 | V28: =IFERROR(T28/E28-1,"-") -> 0.37965662 | W28: =IFERROR(T28/S28-1,"-") -> 0.083936923 | X28: =IFERROR(S28/U28,"-") -> 0.72258246
... B31: Quality & Infection control expense | C31: 22 | D31: =SUMIFS(PL_Kochi!C:C,PL_Kochi!$B:$B,PL_Consol!$B31)+SUMIFS(PL_Calicut!C:C,PL_Calicut!$B:$B,PL_Consol!$B31)+SUMIFS(PL_FNB!C:C,PL_FNB!$B:$B,PL_Consol!$B31) -> 0 | E31: =SUMIFS(PL_Kochi!D:D,PL_Kochi!$B:$B,PL_Consol!$B31)+SUMIFS(PL_Calicut!D:D,PL_Calicut!$B:$B,PL_Consol!$B31)+SUMIFS(PL_FNB!D:D,PL_FNB!$B:$B,PL_Consol!$B31) -> 0 | F31: =SUMIFS(PL_Kochi!E:E,PL_Kochi!$B:$B,PL_Consol!$B31)+SUMIFS(PL_Calicut!E:E,PL_Calicut!$B:$B,PL_Consol!$B31)+SUMIFS(PL_FNB!E:E,PL_FNB!$B:$B,PL_Consol!$B31) -> 0 | G31: =SUMIFS(PL_Kochi!F:F,PL_Kochi!$B:$B,PL_Consol!$B31)+SUMIFS(PL_Calicut!F:F,PL_Calicut!$B:$B,PL_Consol!$B31)+SUMIFS(PL_FNB!F:F,PL_FNB!$B:$B,PL_Consol!$B31) -> 0 | H31: =SUMIFS(PL_Kochi!G:G,PL_Kochi!$B:$B,PL_Consol!$B31)+SUMIFS(PL_Calicut!G:G,PL_Calicut!$B:$B,PL_Consol!$B31)+SUMIFS(PL_FNB!G:G,PL_FNB!$B:$B,PL_Consol!$B31) -> 0.084021841 | I31: =SUMIFS(PL_Kochi!H:H,PL_Kochi!$B:$B,PL_Consol!$B31)+SUMIFS(PL_Calicut!H:H,PL_Calicut!$B:$B,PL_Consol!$B31)+SUMIFS(PL_FNB!H:H,PL_FNB!$B:$B,PL_Consol!$B31) -> 0.59515768 | J31: =SUMIFS(PL_Kochi!I:I,PL_Kochi!$B:$B,PL_Consol!$B31)+SUMIFS(PL_Calicut!I:I,PL_Calicut!$B:$B,PL_Consol!$B31)+SUMIFS(PL_FNB!I:I,PL_FNB!$B:$B,PL_Consol!$B31) -> 0.41771089 | K31: =SUMIFS(PL_Kochi!J:J,PL_Kochi!$B:$B,PL_Consol!$B31)+SUMIFS(PL_Calicut!J:J,PL_Calicut!$B:$B,PL_Consol!$B31)+SUMIFS(PL_FNB!J:J,PL_FNB!$B:$B,PL_Consol!$B31) -> 0.42412627 | L31: =SUMIFS(PL_Kochi!K:K,PL_Kochi!$B:$B,PL_Consol!$B31)+SUMIFS(PL_Calicut!K:K,PL_Calicut!$B:$B,PL_Consol!$B31)+SUMIFS(PL_FNB!K:K,PL_FNB!$B:$B,PL_Consol!$B31) -> 0.88160848 | M31: =SUMIFS(PL_Kochi!L:L,PL_Kochi!$B:$B,PL_Consol!$B31)+SUMIFS(PL_Calicut!L:L,PL_Calicut!$B:$B,PL_Consol!$B31)+SUMIFS(PL_FNB!L:L,PL_FNB!$B:$B,PL_Consol!$B31) -> 0.63415405 | N31: =SUMIFS(PL_Kochi!M:M,PL_Kochi!$B:$B,PL_Consol!$B31)+SUMIFS(PL_Calicut!M:M,PL_Calicut!$B:$B,PL_Consol!$B31)+SUMIFS(PL_FNB!M:M,PL_FNB!$B:$B,PL_Consol!$B31) -> 0.049612765 | O31: =SUMIFS(PL_Kochi!N:N,PL_Kochi!$B:$B,PL_Consol!$B31)+SUMIFS(PL_Calicut!N:N,PL_Calicut!$B:$B,PL_Consol!$B31)+SUMIFS(PL_FNB!N:N,PL_FNB!$B:$B,PL_Consol!$B31) -> 2.5907986 | P31: =SUM(D31:O31) -> 5.6771906 | Q31: 4.4806926 | R31: 6.814546 | S31: =SUMIFS(PL_Kochi!R:R,PL_Kochi!$B:$B,PL_Consol!$B31)+SUMIFS(PL_Calicut!R:R,PL_Calicut!$B:$B,PL_Consol!$B31)+SUMIFS(PL_FNB!R:R,PL_FNB!$B:$B,PL_Consol!$B31) -> 0 | T31: =SUMIFS(PL_Kochi!S:S,PL_Kochi!$B:$B,PL_Consol!$B31)+SUMIFS(PL_Calicut!S:S,PL_Calicut!$B:$B,PL_Consol!$B31)+SUMIFS(PL_FNB!S:S,PL_FNB!$B:$B,PL_Consol!$B31) -> 0 | U31: 88.3 | V31: =IFERROR(T31/E31-1,"-") -> - | W31: =IFERROR(T31/S31-1,"-") -> - | X31: =IFERROR(S31/U31,"-") -> 0
B32: Provission for Bad Debts | C32: 23 | D32: =SUMIFS(PL_Kochi!C:C,PL_Kochi!$B:$B,PL_Consol!$B32)+SUMIFS(PL_Calicut!C:C,PL_Calicut!$B:$B,PL_Consol!$B32)+SUMIFS(PL_FNB!C:C,PL_FNB!$B:$B,PL_Consol!$B32) -> 18.713982 | E32: =SUMIFS(PL_Kochi!D:D,PL_Kochi!$B:$B,PL_Consol!$B32)+SUMIFS(PL_Calicut!D:D,PL_Calicut!$B:$B,PL_Consol!$B32)+SUMIFS(PL_FNB!D:D,PL_FNB!$B:$B,PL_Consol!$B32) -> 1.3771271 | F32: =SUMIFS(PL_Kochi!E:E,PL_Kochi!$B:$B,PL_Consol!$B32)+SUMIFS(PL_Calicut!E:E,PL_Calicut!$B:$B,PL_Consol!$B32)+SUMIFS(PL_FNB!E:E,PL_FNB!$B:$B,PL_Consol!$B32) -> 1.3771708 | G32: =SUMIFS(PL_Kochi!F:F,PL_Kochi!$B:$B,PL_Consol!$B32)+SUMIFS(PL_Calicut!F:F,PL_Calicut!$B:$B,PL_Consol!$B32)+SUMIFS(PL_FNB!F:F,PL_FNB!$B:$B,PL_Consol!$B32) -> 1.3771111 | H32: =SUMIFS(PL_Kochi!G:G,PL_Kochi!$B:$B,PL_Consol!$B32)+SUMIFS(PL_Calicut!G:G,PL_Calicut!$B:$B,PL_Consol!$B32)+SUMIFS(PL_FNB!G:G,PL_FNB!$B:$B,PL_Consol!$B32) -> 1.3771 | I32: =SUMIFS(PL_Kochi!H:H,PL_Kochi!$B:$B,PL_Consol!$B32)+SUMIFS(PL_Calicut!H:H,PL_Calicut!$B:$B,PL_Consol!$B32)+SUMIFS(PL_FNB!H:H,PL_FNB!$B:$B,PL_Consol!$B32) -> 1.3771068 | J32: =SUMIFS(PL_Kochi!I:I,PL_Kochi!$B:$B,PL_Consol!$B32)+SUMIFS(PL_Calicut!I:I,PL_Calicut!$B:$B,PL_Consol!$B32)+SUMIFS(PL_FNB!I:I,PL_FNB!$B:$B,PL_Consol!$B32) -> 1.3771076 | K32: =SUMIFS(PL_Kochi!J:J,PL_Kochi!$B:$B,PL_Consol!$B32)+SUMIFS(PL_Calicut!J:J,PL_Calicut!$B:$B,PL_Consol!$B32)+SUMIFS(PL_FNB!J:J,PL_FNB!$B:$B,PL_Consol!$B32) -> 1.377152 | L32: =SUMIFS(PL_Kochi!K:K,PL_Kochi!$B:$B,PL_Consol!$B32)+SUMIFS(PL_Calicut!K:K,PL_Calicut!$B:$B,PL_Consol!$B32)+SUMIFS(PL_FNB!K:K,PL_FNB!$B:$B,PL_Consol!$B32) -> 1.3771301 | M32: =SUMIFS(PL_Kochi!L:L,PL_Kochi!$B:$B,PL_Consol!$B32)+SUMIFS(PL_Calicut!L:L,PL_Calicut!$B:$B,PL_Consol!$B32)+SUMIFS(PL_FNB!L:L,PL_FNB!$B:$B,PL_Consol!$B32) -> 1.3770765 | N32: =SUMIFS(PL_Kochi!M:M,PL_Kochi!$B:$B,PL_Consol!$B32)+SUMIFS(PL_Calicut!M:M,PL_Calicut!$B:$B,PL_Consol!$B32)+SUMIFS(PL_FNB!M:M,PL_FNB!$B:$B,PL_Consol!$B32) -> 1.3770963 | O32: =SUMIFS(PL_Kochi!N:N,PL_Kochi!$B:$B,PL_Consol!$B32)+SUMIFS(PL_Calicut!N:N,PL_Calicut!$B:$B,PL_Consol!$B32)+SUMIFS(PL_FNB!N:N,PL_FNB!$B:$B,PL_Consol!$B32) -> 18.712983 | P32: =SUM(D32:O32) -> 51.198143 | Q32: 370 | R32: 243.91 | S32: =ECL!M43 -> 16.520904 | T32: =SUMIFS(PL_Kochi!S:S,PL_Kochi!$B:$B,PL_Consol!$B32)+SUMIFS(PL_Calicut!S:S,PL_Calicut!$B:$B,PL_Consol!$B32)+SUMIFS(PL_FNB!S:S,PL_FNB!$B:$B,PL_Consol!$B32) -> 1.376742 | U32: 118.3 | V32: =IFERROR(T32/E32-1,"-") -> -0.00027968462 | W32: =IFERROR(T32/S32-1,"-") -> -0.91666667 | X32: =IFERROR(S32/U32,"-") -> 0.13965261
