Workbook

Sheet Assumptions
A3: When revenue is projected only variable kept is OP count, rest OP to IP conversion, ARPP-op, ARPP-IP all kept constant
A4: The opex - one time and recurring are only evaluated.
A5: The capex are mentioned but need an independent evaluation and it will be useful to determine cash flow
A10: Bequip Comments
A11: Bringing in new age specialities
A12: Improving OP to IP conversion
J13: {=+_xlfn.UNIQUE('Initiative Register'!C:C)} -> 0
J14: Initiative ID
J15: R-01 | K15: =+SUMIFS('Initiative Register'!AA:AA,'Initiative Register'!C:C,Assumptions!J15) -> 0
J16: R-02 | K16: =+SUMIFS('Initiative Register'!AA:AA,'Initiative Register'!C:C,Assumptions!J16) -> 2.335
J17: R-03 | K17: =+SUMIFS('Initiative Register'!AA:AA,'Initiative Register'!C:C,Assumptions!J17) -> 0
J18: R-04 | K18: =+SUMIFS('Initiative Register'!AA:AA,'Initiative Register'!C:C,Assumptions!J18) -> 0
J19: R-05 | K19: =+SUMIFS('Initiative Register'!AA:AA,'Initiative Register'!C:C,Assumptions!J19) -> 0
J20: R-06 | K20: =+SUMIFS('Initiative Register'!AA:AA,'Initiative Register'!C:C,Assumptions!J20) -> 0
J21: R-07 | K21: =+SUMIFS('Initiative Register'!AA:AA,'Initiative Register'!C:C,Assumptions!J21) -> 0
J22: R-08 | K22: =+SUMIFS('Initiative Register'!AA:AA,'Initiative Register'!C:C,Assumptions!J22) -> 0
J23: R-09 | K23: =+SUMIFS('Initiative Register'!AA:AA,'Initiative Register'!C:C,Assumptions!J23) -> 0
J24: R-10 | K24: =+SUMIFS('Initiative Register'!AA:AA,'Initiative Register'!C:C,Assumptions!J24) -> 425.09111
J25: R-11 | K25: =+SUMIFS('Initiative Register'!AA:AA,'Initiative Register'!C:C,Assumptions!J25) -> 42.822427
J26: R-12 | K26: =+SUMIFS('Initiative Register'!AA:AA,'Initiative Register'!C:C,Assumptions!J26) -> 0
... J49: Cost New 1 | K49: =+SUMIFS('Initiative Register'!AA:AA,'Initiative Register'!C:C,Assumptions!J49) -> 61.800787
K50: =+SUMIFS('Initiative Register'!AA:AA,'Initiative Register'!C:C,Assumptions!J50) -> 0

Sheet Initiative Register
K1: =+K3-K5 -> 0 | L1: =+L3-L5 -> 0 | AA1: =+M3-M4 -> 115.09
A2: VPS LAKESHORE HOSPITAL — AOP INITIATIVE REGISTER | FY 2026–27 | 33 Initiatives | K2: =+K4-K6 -> 0 | L2: =+L4-L6 -> 0 | AA2: =+AA1-AA3 -> -472.47104
K3: 1087.5 | L3: 109 | M3: 125.6 | O3: =SUM(O8:O460) -> 39.572417 | P3: =SUM(P8:P460) -> 40.54019 | Q3: =SUM(Q8:Q460) -> 41.303689 | R3: =SUM(R8:R460) -> 48.384232 | S3: =SUM(S8:S460) -> 47.846026 | T3: =SUM(T8:T460) -> 49.017426 | U3: =SUM(U8:U460) -> 52.021551 | V3: =SUM(V8:V460) -> 49.829776 | ... AA3: =SUM(AA8:AA460) -> 587.56104
L4: 100 | M4: 10.51
A5: TOTAL REVENUE IMPACT | G5: Sum of 15 revenue initiatives (R-01 to R-15) — opex, capex, and revenue impact | K5: =SUM(K8:K26) -> 1087.5 | L5: =SUM(L8:L26) -> 109 | M5: =SUM(M8:M26) -> 125.6
A6: TOTAL COST SAVING | G6: Sum of 13 cost initiatives (C-01 to C-13) — opex, capex, and cost saving | L6: =SUM(L28:L40) -> 100 | M6: =SUM(M28:M40) -> 10.51 | O6: All Rs. In Crores
A7: Type | B7: # | C7: Initiative ID | D7: Sub Initiative | E7: Initiative Name | F7: Category | G7: Description | H7: Start Month | I7: Est. Cost | J7: Est. Cost Detailed | K7: Opex (₹L/yr) | L7: Capex (₹L) | M7: Est. Impact (₹ Cr) | N7: P&L Head to Link | O7: 46113 | P7: 46143 | Q7: 46174 | R7: 46204 | S7: 46235 | T7: 46266 | U7: 46296 | V7: 46327 | W7: 46357 | X7: 46388 | Y7: 46419 | Z7: 46447 | AA7: Total
A8: REVENUE — PRICING & YIELD | B8: 1 | C8: R-01 | E8: Annual Rate Revision Policy | F8: Revenue — Pricing & Yield | G8: Revise all IP room, nursing, and procedure rates for cash/self-pay patients effective May-26. Room & nursing tariffs benchmarked against Aster, Welcare, Rajagiri, and Sunrise across 19 bed categories (avg increase ~12%). Top 50 revenue procedures repriced to midpoint of Lakeshore and highest competitor rate. TPA/insurer tariff renegotiation under R-03. | H8: 46113 | I8: Nil — internal process; CFO time only | K8: 0 | L8: 0 | M8: 9.6 | AA8: =SUM(O8:Z8) -> 0
A9: REVENUE — PRICING & YIELD | B9: 2 | C9: R-02 | D9: 1 | E9: Procedure Contribution Framework | F9: Revenue — Pricing & Yield | G9: Launch a contribution framework for all IP procedures. Cost out top 50 procedures by revenue — include doctor fees, team costs, consumables, and overhead allocation. Identify low-contribution procedures (<50% margin). Reprice for both cash AND insurance. Flag insurer tariff renegotiation list. Build sustainable contribution model: target 58% average contribution for 26% EBITDA. | H9: 46113 | I9: ₹1.5L one-time (costing consultant or internal CFO + pharmacy time) | K9: 1.5 | L9: 0 | M9: 2.5 | O9: =+'R-02'!E4/10^7 -> 0 | P9: =+'R-02'!F4/10^7 -> 0 | Q9: =+'R-02'!G4/10^7 -> 0 | R9: =+'R-02'!H4/10^7 -> 0.075 | S9: =+'R-02'!I4/10^7 -> 0.125 | T9: =+'R-02'!J4/10^7 -> 0.175 | U9: =+'R-02'!K4/10^7 -> 0.225 | V9: =+'R-02'!L4/10^7 -> 0.275 | ... Z9: =+'R-02'!P4/10^7 -> 0.5 | AA9: =SUM(O9:Z9) -> 2.5
A10: REVENUE — PRICING & YIELD | B10: 2 | C10: R-02 | D10: 2 | E10: Procedure Contribution Framework | F10: Revenue — Pricing & Yield | G10: Launch a contribution framework for all IP procedures. Cost out top 50 procedures by revenue — include doctor fees, team costs, consumables, and overhead allocation. Identify low-contribution procedures (<50% margin). Reprice for both cash AND insurance. Flag insurer tariff renegotiation list. Build sustainable contribution model: target 58% average contribution for 26% EBITDA. | H10: 46113 | O10: =+'R-02'!E6/10^7 -> 0 | P10: =-+'R-02'!F6/10^7 -> -0.015 | Q10: =-+'R-02'!G6/10^7 -> -0.015 | R10: =-+'R-02'!H6/10^7 -> -0.015 | S10: =-+'R-02'!I6/10^7 -> -0.015 | T10: =-+'R-02'!J6/10^7 -> -0.015 | U10: =-+'R-02'!K6/10^7 -> -0.015 | V10: =-+'R-02'!L6/10^7 -> -0.015 | W10: =-+'R-02'!M6/10^7 -> -0.015 | ... Z10: =-+'R-02'!P6/10^7 -> -0.015 | AA10: =SUM(O10:Z10) -> -0.165
A11: REVENUE — PRICING & YIELD | B11: 3 | C11: R-03 | E11: Insurance Renegotiation & Empanelment | F11: Revenue — Pricing & Yield | G11: Three-pronged insurance revenue initiative: (A) Charge Capture Audit — audit IP bills against TPA tariff schedules; fix charge master for covered-but-unbilled items (nursing, monitoring, physio, ICU); train nursing on charge initiation. (B) TPA/Insurer Tariff Renegotiation — formal annual revision with all empanelled TPAs (most agreements 2–3 yrs old vs 12–15% cost inflation); target 8–12% rate improvement. (C) Competitive Empanelment Analysis — compare gap insurers vs Aster/Rajagiri/KIMS (Star Health, Go Digit, Navi, SBI General, TATA AIG etc.); pursue new empanelments with incremental revenue impact. | H11: 46113 | I11: ₹4L one-time (billing audit + legal + data prep; internal CFO time) | K11: 4 | L11: 0 | M11: 9 | AA11: =SUM(O11:Z11) -> 0
A12: REVENUE — NETWORK EXPANSION | B12: 4 | C12: R-04 | E12: Distributed Healthcare Network (DHCN) | F12: Revenue — Network Expansion | G12: Deploy two network prototypes across Kerala: (a) Satellite clinics — Lakeshore-branded OPD in suburban/district locations with VPS surgeons running weekly clinics; target 10 clinics. (b) Risk Assessment Centres (RACs) — cancer screening + cardiac/metabolic risk triage at high-footfall locations; target 25 RACs. Both funnel referrals to Kochi main campus. Project referral revenue, revenue share models, and spare capacity utilisation (doctor OP consult analysis). Includes oncology hub-and-spoke scope. | H12: 46143 | I12: ₹65L/yr (10 satellite clinics fit-out + 25 RAC stations + oncology consultant travel + partner MOUs + admin) | K12: 65 | L12: 0 | M12: 13 | AA12: =SUM(O12:Z12) -> 0
A13: REVENUE — NETWORK EXPANSION | B13: 5 | C13: R-05 | E13: Corporate Health Programme | F13: Revenue — Network Expansion | G13: Build a structured corporate health programme targeting top 50 corporates (PSU + private) within 20km of Kochi campus. | H13: 46143 | I13: ₹17L/yr (2 corporate RMs + package design + billing desk) | K13: 17 | L13: 0 | M13: 5 | AA13: =SUM(O13:Z13) -> 0
A14: REVENUE — NETWORK EXPANSION | B14: 6 | C14: R-06 | E14: Residential & Community Outreach | F14: Revenue — Network Expansion | G14: Partner with major gated communities and apartment complexes within 15km for on-site health camps, resident doctor visits, and emergency response agreements. Handled by dedicated corporate/residential team within BD organisation. Includes community health camps: monthly programmes in schools, temples/mosques, and residential complexes. | H14: 46143 | I14: ₹30L/yr (logistics, portable diagnostic equipment, community coordinator + camp logistics) | K14: 30 | L14: 0 | M14: 3 | AA14: =SUM(O14:Z14) -> 0
A15: REVENUE — REFERRAL DEVELOPMENT | B15: 7 | C15: R-07 | E15: International Medical Value Travel | F15: Revenue — Referral Development | G15: Expand medical value travel (MVT) beyond Middle East to all viable source markets for Kerala. Score countries on multi-parameter framework: flight connectivity to Kochi, diaspora size, healthcare gap vs local system, insurance/reimbursement coverage, competitor presence, and VPS Healthcare group synergies (Abu Dhabi, Oman network). Map ecosystem: HCF agents, embassy health attachés, corporate medical evacuation contracts, international insurance TPAs. Build online reputation (Arabic/Bengali/Dhivehi Google Business, Practo international, Vaidam/Bookimed/Medical Departures). Sign clinical referral MOUs with 2–3 Maldives + 2 Gulf hospitals. Target: 200+ MVT patients Year 1, scaling to 500 by Year 3. | H15: 46143 | I15: ₹25L/yr (MVT coordinator + content + aggregator onboarding) | K15: 25 | L15: 0 | M15: 6 | AA15: =SUM(O15:Z15) -> 0
A16: REVENUE — REFERRAL DEVELOPMENT | B16: 8 | C16: R-08 | E16: Government Scheme Empanelment Optimisation | F16: Revenue — Referral Development | G16: Review PMJAY, KASP, CGHS, ECHS, and ESI empanelments — kept separate from insurance (R-03). Ensure all eligible complex procedures (transplant, cardiac interventions, cancer treatments) are listed. Renegotiate rates for high-volume procedures. | H16: 46143 | I16: ₹6L/yr (dedicated scheme coordinator, 1 FTE) | K16: 6 | L16: 0 | M16: 3 | AA16: =SUM(O16:Z16) -> 0
A17: REVENUE — REFERRAL DEVELOPMENT | B17: 9 | C17: R-09 | E17: Scaled BD Organisation & Referral Programme | F17: Revenue — Referral Development | G17: Expand to a full-spectrum BD function with three verticals: (A) Referral Development (3 zones — North/Central/South Kerala): map referring doctors within 50km; A/B/C tier classification; BD field executives on A-tier (top 100) with monthly visit cadence; 500+ registered referring doctors; 24-hr discharge summary SOP. (B) Institutional & Partnerships: corporate accounts (R-05), MVT (R-07), satellite clinics (R-04), government schemes (R-08). (C) Communications & Branding: CME calendar — monthly specialty CMEs across suburban/district locations; dedicated CME Coordinator; MCI accreditation; digital CME platform. 27-person BD organisation under BD Head reporting to CEO. | H17: 46113 | I17: ₹3.5 Cr/yr total BD function (6 open roles + CRM + CME events + FE travel) | K17: 350 | L17: 0 | M17: 25 | AA17: =SUM(O17:Z17) -> 0
A18: REVENUE — REFERRAL DEVELOPMENT | B18: 10 | C18: R-10 | D18: 1 | E18: OP-IP Conversion & Follow-Up | F18: Revenue — Referral Development | G18: OP-to-IP conversion initiative with two tracks: (A) Surgical OPD Counselling — deploy trained financial counsellors at surgical OPD (ortho, cardiac, neurosurgery, oncology, transplant); explain package costs; initiate insurance pre-auth on day of consultation; arrange EMI/loan tie-ups for self-pay. (B) Follow-Up & Dropout Prevention — analyse OP follow-up calls to curtail dropouts; appointment reminders; 48-hour post-consult callbacks; treatment plan adherence tracking; lapsed patient re-engagement. Target: +5pp conversion = ~2,000 incremental IP admissions/yr. | H18: 46143 | I18: ₹17L/yr (3–4 counsellor salaries + TPA training + NBFC onboarding) | O18: =-'R-10'!J5/10^7 -> -0.014 | P18: =-'R-10'!K5/10^7 -> -0.014 | Q18: =-'R-10'!L5/10^7 -> -0.014 | R18: =-'R-10'!M5/10^7 -> -0.014 | S18: =-'R-10'!N5/10^7 -> -0.014 | T18: =-'R-10'!O5/10^7 -> -0.014 | U18: =-'R-10'!P5/10^7 -> -0.014 | V18: =-'R-10'!Q5/10^7 -> -0.014 | ... Z18: =-'R-10'!U5/10^7 -> -0.014 | AA18: =SUM(O18:Z18) -> -0.168
A19: REVENUE — REFERRAL DEVELOPMENT | B19: 10 | C19: R-10 | D19: 2 | E19: OP-IP Conversion & Follow-Up | F19: Revenue — Referral Development | G19: OP-to-IP conversion initiative with two tracks: (A) Surgical OPD Counselling — deploy trained financial counsellors at surgical OPD (ortho, cardiac, neurosurgery, oncology, transplant); explain package costs; initiate insurance pre-auth on day of consultation; arrange EMI/loan tie-ups for self-pay. (B) Follow-Up & Dropout Prevention — analyse OP follow-up calls to curtail dropouts; appointment reminders; 48-hour post-consult callbacks; treatment plan adherence tracking; lapsed patient re-engagement. Target: +5pp conversion = ~2,000 incremental IP admissions/yr. | H19: 46143 | I19: ₹17L/yr (3–4 counsellor salaries + TPA training + NBFC onboarding) | K19: 17 | L19: 0 | M19: 4 | O19: 32.437148 | P19: 32.437148 | Q19: 32.240848 | R19: 38.367325 | S19: 36.651286 | T19: 36.651286 | U19: 36.827255 | V19: 33.596443 | W19: 35.83597 | X19: 39.476666 | Y19: 34.608664 | Z19: 36.129073 | AA19: =SUM(O19:Z19) -> 425.25911
A20: REVENUE — HIGH-VALUE SERVICES | B20: 11 | C20: R-11 | E20: Departmental Organic Growth Initiative | F20: Revenue — High-Value Services | G20: Monthly department review: each clinical department presents its growth plan, infrastructure needs, staffing gaps, and volume targets. | H20: 46143 | I20: Nil — internal process; dept-level investment decisions routed through normal capex approval | K20: 0 | L20: 0 | M20: 8 | O20: =+'R-11'!T4/10000000 -> 0 | P20: =+'R-11'!U4/10000000 -> 0.31394309 | Q20: =+'R-11'!V4/10000000 -> 1.0036637 | R20: =+'R-11'!W4/10000000 -> 1.8401196 | S20: =+'R-11'!X4/10000000 -> 2.4398645 | T20: =+'R-11'!Y4/10000000 -> 3.1779269 | U20: =+'R-11'!Z4/10000000 -> 3.9264253 | V20: =+'R-11'!AA4/10000000 -> 4.215596 | ... Z20: =+'R-11'!AE4/10000000 -> 7.3996918 | AA20: =SUM(O20:Z20) -> 42.822427
A21: REVENUE — HIGH-VALUE SERVICES | B21: 12 | C21: R-12 | E21: New Specialties, Procedures & Packages | F21: Revenue — High-Value Services | G21: Launch new high-end, high-value specialties and packages based on Kochi/Kerala market dynamics: (A) Structural Heart & EP — TAVR/MitraClip/LAAO programme. (B) Orthopaedics — all-inclusive joint replacement packages, sports medicine. (C) Additional specialties/packages identified from market analysis. Focus on high-end procedures with unmet demand and strong uptake potential. | H21: 46143 | I21: ₹19L one-time capex (device partnerships + package design + billing config + marketing collateral) | K21: 0 | L21: 19 | M21: 11 | AA21: =SUM(O21:Z21) -> 0
A22: REVENUE — HIGH-VALUE SERVICES | B22: 13 | C22: R-13 | E22: Clinician Recruitment & Specialty Team Building | F22: Revenue — High-Value Services | G22: Recruit senior clinicians and clinical teams in 6 specialties where Lakeshore is underweight vs competitors: (A) Women’s Health & Obstetrics, (B) Paediatrics & Neonatology, (C) Pulmonology, (D) Endocrinology, (E) Rheumatology, (F) ENT & Head-Neck Surgery. Each senior consultant brings ₹3–5 Cr/yr IP revenue with established referral network. | H22: 46143 | I22: ₹4 Cr/yr opex (7–8 senior consultants @ ₹60L–1 Cr each incl. relocation + 12-mo practice guarantee top-up); ₹90L one-time capex (NICU upgrade + sleep lab + maternity branding). Year 1 practice-guarantee exposure may add ₹1–2 Cr one-time. | K22: 400 | L22: 90 | M22: 20 | AA22: =SUM(O22:Z22) -> 0
A23: REVENUE — MARKETING & PATIENT ACQUISITION | B23: 14 | C23: R-14 | D23: 0 | E23: Quarterly Health Events Calendar | F23: Revenue — Marketing & Patient Acquisition | G23: Rebrand from single Heart Run to a structured quarterly events calendar. Four flagship events per year: (1) Lakeshore Heart Run (Q2 — cardiac awareness, half-marathon/10K), (2) Liver Week (Q3 — liver health screenings, transplant awareness), (3) Cancer Awareness Drive (Q4 — aligned with Breast Cancer/World Cancer Day), (4) Diabetes & Metabolic Health Camp (Q1 — aligned with World Diabetes Day). Each event: 3,000–5,000 participants, health screenings, OPD follow-ups, media coverage, sponsorship. Entry fees + pharma/device sponsorship partially offset costs. | H23: 46266 | I23: ₹1.1 Cr/yr (5 events × ₹10–12L + media ₹40–50L; partial sponsorship recovery) Actual cost per eveny around Rs. 30L estimated | J23: 5*22L | K23: 110 | L23: 0 | M23: 1.5 | O23: =+'R-14'!F5/10000000 -> 0 | P23: =+'R-14'!G5/10000000 -> 0 | Q23: =+'R-14'!H5/10000000 -> -0.3 | R23: =+'R-14'!I5/10000000 -> 0 | S23: =+'R-14'!J5/10000000 -> -0.3 | T23: =+'R-14'!K5/10000000 -> 0 | U23: =+'R-14'!L5/10000000 -> 0 | V23: =+'R-14'!M5/10000000 -> -0.3 | ... Z23: =+'R-14'!Q5/10000000 -> -0.3 | AA23: =SUM(O23:Z23) -> -1.5
A24: REVENUE — MARKETING & PATIENT ACQUISITION | B24: 14 | C24: =+C23 -> R-14 | D24: =+D23+1 -> 1 | E24: Quarterly Health Events Calendar | F24: Revenue — Marketing & Patient Acquisition | G24: Rebrand from single Heart Run to a structured quarterly events calendar. Four flagship events per year: (1) Lakeshore Heart Run (Q2 — cardiac awareness, half-marathon/10K), (2) Liver Week (Q3 — liver health screenings, transplant awareness), (3) Cancer Awareness Drive (Q4 — aligned with Breast Cancer/World Cancer Day), (4) Diabetes & Metabolic Health Camp (Q1 — aligned with World Diabetes Day). Each event: 3,000–5,000 participants, health screenings, OPD follow-ups, media coverage, sponsorship. Entry fees + pharma/device sponsorship partially offset costs. | H24: 46266 | I24: Total Estiamted Cost of each program including media coverage Rs. 30L. Out of this 25% sponsorship revenue approx. Rs. 7 lakhs | J24: 5*7L each | O24: =+'R-14'!F6/10000000 -> 0 | P24: =+'R-14'!G6/10000000 -> 0 | Q24: =+'R-14'!H6/10000000 -> 0.07 | R24: =+'R-14'!I6/10000000 -> 0 | S24: =+'R-14'!J6/10000000 -> 0.07 | T24: =+'R-14'!K6/10000000 -> 0 | U24: =+'R-14'!L6/10000000 -> 0 | V24: =+'R-14'!M6/10000000 -> 0.07 | ... Z24: =+'R-14'!Q6/10000000 -> 0.07 | AA24: =SUM(O24:Z24) -> 0.35
A25: REVENUE — MARKETING & PATIENT ACQUISITION | B25: 14 | C25: =+C24 -> R-14 | D25: =+D24+1 -> 2 | E25: Quarterly Health Events Calendar | F25: Revenue — Marketing & Patient Acquisition | G25: Rebrand from single Heart Run to a structured quarterly events calendar. Four flagship events per year: (1) Lakeshore Heart Run (Q2 — cardiac awareness, half-marathon/10K), (2) Liver Week (Q3 — liver health screenings, transplant awareness), (3) Cancer Awareness Drive (Q4 — aligned with Breast Cancer/World Cancer Day), (4) Diabetes & Metabolic Health Camp (Q1 — aligned with World Diabetes Day). Each event: 3,000–5,000 participants, health screenings, OPD follow-ups, media coverage, sponsorship. Entry fees + pharma/device sponsorship partially offset costs. | H25: 46266 | I25: Estimated Revenue Increase | O25: =+'R-14'!F7/10000000 -> 0 | P25: =+'R-14'!G7/10000000 -> 0 | Q25: =+'R-14'!H7/10000000 -> 0.22761 | R25: =+'R-14'!I7/10000000 -> 0 | S25: =+'R-14'!J7/10000000 -> 0.377912 | T25: =+'R-14'!K7/10000000 -> 0 | U25: =+'R-14'!L7/10000000 -> 0 | V25: =+'R-14'!M7/10000000 -> 0.450904 | ... Z25: =+'R-14'!Q7/10000000 -> 0.145978 | AA25: =SUM(O25:Z25) -> 1.503006
A26: REVENUE — MARKETING & PATIENT ACQUISITION | B26: 15 | C26: R-15 | D26: 0 | E26: Patient Acquisition & Digital Platform | F26: Revenue — Marketing & Patient Acquisition | G26: Comprehensive patient acquisition analysis: How do patients find us vs competition? Marketing spend ~₹7Cr = 10–15% commission → only ₹50–70Cr revenue through referral channel. Remaining patients walked in — understand why. Magnify the strongest channels. Digital platform: 3 health videos/week, SEO, Google Ads, doctor online reputation management (Google Business, Practo, Doctorundi), post-OPD review collection. Track digital-to-enquiry conversion. Includes online reputation management scope. | H26: 46113 | I26: ₹62L/yr (2 content staff + Malayalam agency + Google Ads + SEO + platform management) | K26: 62 | L26: 0 | M26: 5 | O26: =+-'R-15'!H3/10000000 -> 0 | P26: =+-'R-15'!I3/10000000 -> -0.0905 | Q26: =+-'R-15'!J3/10000000 -> -0.0555 | R26: =+-'R-15'!K3/10000000 -> -0.0505 | S26: =+-'R-15'!L3/10000000 -> -0.0555 | T26: =+-'R-15'!M3/10000000 -> -0.0505 | U26: =+-'R-15'!N3/10000000 -> -0.0505 | V26: =+-'R-15'!O3/10000000 -> -0.0555 | ... Z26: =+-'R-15'!S3/10000000 -> -0.0555 | AA26: =SUM(O26:Z26) -> -0.6205
A27: =+A26 -> REVENUE — MARKETING & PATIENT ACQUISITION | B27: 15 | C27: R-15 | D27: =+D26+1 -> 1 | E27: Patient Acquisition & Digital Platform | F27: Revenue — Marketing & Patient Acquisition | G27: Comprehensive patient acquisition analysis: How do patients find us vs competition? Marketing spend ~₹7Cr = 10–15% commission → only ₹50–70Cr revenue through referral channel. Remaining patients walked in — understand why. Magnify the strongest channels. Digital platform: 3 health videos/week, SEO, Google Ads, doctor online reputation management (Google Business, Practo, Doctorundi), post-OPD review collection. Track digital-to-enquiry conversion. Includes online reputation management scope. | H27: 46113 | I27: Increase in Overall Revenue through footfall increase | O27: =+'R-15'!H13/10000000 -> 0 | P27: =+'R-15'!I13/10000000 -> 0.010161 | Q27: =+'R-15'!J13/10000000 -> 0.018753 | R27: =+'R-15'!K13/10000000 -> 0.051312 | S27: =+'R-15'!L13/10000000 -> 0.21845 | T27: =+'R-15'!M13/10000000 -> 0.314556 | U27: =+'R-15'!N13/10000000 -> 0.467231 | V27: =+'R-15'!O13/10000000 -> 0.541018 | ... Z27: =+'R-15'!S13/10000000 -> 0.989893 | AA27: =SUM(O27:Z27) -> 5.020543
A28: COST — MATERIALS / COGS | B28: 16 | C28: C-01 | E28: Drug Brand Substitution | F28: Cost — Materials / COGS | G28: Substitute 16 high-spend branded drugs with clinically equivalent alternatives at lower procurement cost. Formulary analysis identifies ₹38.8L/month (₹4.66 Cr/year) incremental profit at full compliance. | H28: 46113 | I28: Nil — formulary committee process; HMIS alert = existing config | L28: 0 | M28: 3 | O28: 0.18714138 | P28: 0.25397285 | Q28: 0.24845956 | R28: 0.28395704 | S28: 0.26940211 | T28: 0.25682815 | U28: 0.27178223 | V28: 0.23745317 | W28: 0.25242729 | X28: 0.27417722 | Y28: 0.2581575 | Z28: 0.22963407 | AA28: =SUM(O28:Z28) -> 3.0233926
A29: COST — MATERIALS / COGS | B29: 17 | C29: C-02 | E29: Manufacturer Rate Contract | F29: Cost — Materials / COGS | G29: MD/CEO-level engagement with top 20 manufacturers. Negotiate higher discounts via volume commitment. Replace spot purchase with 12-month rate contracts. | H29: 46113 | I29: Nil — internal negotiation | L29: 0 | M29: 1.3 | O29: 0.081094597 | P29: 0.1100549 | Q29: 0.10766581 | R29: 0.12304805 | S29: 0.11674091 | T29: 0.1112922 | U29: 0.1177723 | V29: 0.10289637 | W29: 0.10938516 | X29: 0.11881013 | Y29: 0.11186825 | Z29: 0.099508099 | AA29: =SUM(O29:Z29) -> 1.3101368
A30: COST — MATERIALS / COGS | B30: 18 | C30: C-03 | E30: Distributor Consolidation | F30: Cost — Materials / COGS | G30: Reduce to 3 core distributors. Extract volume-linked discounts. Eliminate margin leakage from fragmented procurement. | H30: 46113 | I30: Nil — procurement process change only | L30: 0 | M30: 0.8 | O30: 0.049904367 | P30: 0.067726095 | Q30: 0.066255884 | R30: 0.075721877 | S30: 0.071840563 | T30: 0.068487507 | U30: 0.072475261 | V30: 0.063320845 | W30: 0.067313944 | X30: 0.073113925 | Y30: 0.068842 | Z30: 0.061235753 | AA30: =SUM(O30:Z30) -> 0.80623802
A31: COST — MATERIALS / COGS | B31: 19 | C31: C-04 | E31: Surgical BOQ Standardisation | F31: Cost — Materials / COGS | G31: Standardise preference cards and consumable kits per procedure. Eliminate inter-surgeon variation. | H31: 46174 | I31: ₹2.5L one-time (OT audit, preference card redesign, store system config) | L31: 0 | M31: 0.575 | O31: 0.037428275 | P31: 0.050794571 | Q31: 0.049691913 | R31: 0.056791408 | S31: 0.053880422 | T31: 0.05136563 | U31: 0.054356446 | V31: 0.047490634 | W31: 0.050485458 | X31: 0.054835444 | Y31: 0.0516315 | Z31: 0.045926815 | AA31: =SUM(O31:Z31) -> 0.60467852
A32: COST — MATERIALS / COGS | B32: 20 | C32: C-05 | E32: Inventory, Expiry & Wastage Control | F32: Cost — Materials / COGS | G32: Comprehensive wastage reduction across all material categories: (A) Drug Inventory & Expiry — reduce drug inventory holding to <20 days; eliminate expiry write-offs; vendor return clauses in all new supply contracts; HMIS-enforced FEFO dispensing + reorder-point alerts. (B) F&B Meal Wastage — reduce cost per patient meal via menu standardisation and order accuracy; cut wastage 20% through demand forecasting + plate return analysis; dietitian-driven menu. (C) Consumables & Surgical Wastage — cut-strip wastage, opened-but-unused consumables, OT preference card over-ordering; monthly wastage reporting by department. | H32: 46113 | I32: Nil — HMIS config + pharmacy/F&B process change | L32: 0 | M32: 0.7 | O32: 0.043666321 | P32: 0.059260333 | Q32: 0.057973898 | R32: 0.066256643 | S32: 0.062860493 | T32: 0.059926568 | U32: 0.063415854 | V32: 0.05540574 | W32: 0.058899701 | X32: 0.063974684 | Y32: 0.06023675 | Z32: 0.053581284 | AA32: =SUM(O32:Z32) -> 0.70545827
A33: COST — MATERIALS / COGS | B33: 21 | C33: C-06 | E33: Laundry Cost Reduction | F33: Cost — Materials / COGS | G33: Reduce cost per kg of linen processing. Outsourcing optimisation and linen tagging/RFID to reduce loss. | H33: 46113 | I33: ₹1.5L one-time (linen tagging/RFID if required) | L33: 0 | M33: 0.135 | O33: =+'C-06'!H5/10^7 -> 0.010778138 | P33: =+'C-06'!I5/10^7 -> 0.010776414 | Q33: =+'C-06'!J5/10^7 -> 0.010222622 | R33: =+'C-06'!K5/10^7 -> 0.011179147 | S33: =+'C-06'!L5/10^7 -> 0.015679308 | T33: =+'C-06'!M5/10^7 -> 0.0064171674 | U33: =+'C-06'!N5/10^7 -> 0.010553442 | V33: =+'C-06'!O5/10^7 -> 0.012022228 | ... Z33: =+'C-06'!S5/10^7 -> 0.02604834 | AA33: =SUM(O33:Z33) -> 0.15
A34: COST — MATERIALS / COGS | B34: 22 | C34: C-07 | E34: AMC Renegotiation | F34: Cost — Materials / COGS | G34: Replace OEM AMC with third-party maintenance for non-critical equipment. Renegotiate using competitive quotes. | H34: 46143 | I34: ₹2.5L one-time (biomedical vendor empanelment + criticality classification) | L34: 0 | M34: 0.275 | O34: =+'C-07'!F6/10^7 -> 0.066868793 | P34: =+'C-07'!G6/10^7 -> -0.35229928 | Q34: =+'C-07'!H6/10^7 -> 0.020288969 | R34: =+'C-07'!I6/10^7 -> -0.7414554 | S34: =+'C-07'!J6/10^7 -> -0.68174847 | T34: =+'C-07'!K6/10^7 -> -1.1148352 | U34: =+'C-07'!L6/10^7 -> 0.7629488 | V34: =+'C-07'!M6/10^7 -> 1.6039326 | ... Z34: =+'C-07'!Q6/10^7 -> 0.79849147 | AA34: =SUM(O34:Z34) -> -1.0995505
A35: COST — PAYROLL | B35: 23 | C35: C-08 | E35: Nursing Headcount to Occupied-Bed Norm | F35: Cost — Payroll | G35: Align nursing strength to occupied bed norm (1:3 general, 1:1 ICU). Reduce ~97 surplus via natural attrition. | H35: 46113 | I35: Nil — attrition-based; hiring freeze only | L35: 0 | M35: 1.5 | O35: 0.73981207 | P35: 0.83780464 | Q35: 0.82399179 | R35: 0.83842656 | S35: 0.83034662 | T35: 0.90894849 | U35: 0.86150935 | V35: 0.79498983 | W35: 0.82753294 | X35: 0.81319568 | Y35: 0.85709359 | Z35: 0.89100905 | AA35: =SUM(O35:Z35) -> 10.024661
A36: COST — PAYROLL | B36: 24 | C36: C-09 | E36: Pharmacy Headcount Post-Automation | F36: Cost — Payroll | G36: Reduce pharmacy staff 93→86 post barcode dispensing. Hard dependency: barcode capex first. | H36: 46174 | I36: ₹1 Cr one-time capex (barcode dispensing system — hard dependency before savings) | L36: 100 | M36: 1 | O36: 0.49320805 | P36: 0.55853643 | Q36: 0.54932786 | R36: 0.55895104 | S36: 0.55356441 | T36: 0.60596566 | U36: 0.57433957 | V36: 0.52999322 | W36: 0.55168863 | X36: 0.54213046 | Y36: 0.57139573 | Z36: 0.59400604 | AA36: =SUM(O36:Z36) -> 6.6831071
A37: COST — PAYROLL | B37: 25 | C37: C-10 | E37: PCS Reduction via EMR | F37: Cost — Payroll | G37: Eliminate ward secretary roles made redundant by EMR. Target: 97→80. Natural attrition post-EMR. | H37: 46174 | I37: Nil incremental — dependent on EMR go-live (separate capital project) | L37: 0 | M37: 0.5 | O37: 0.24660402 | P37: 0.27926821 | Q37: 0.27466393 | R37: 0.27947552 | S37: 0.27678221 | T37: 0.30298283 | U37: 0.28716978 | V37: 0.26499661 | W37: 0.27584431 | X37: 0.27106523 | Y37: 0.28569786 | Z37: 0.29700302 | AA37: =SUM(O37:Z37) -> 3.3415535
A38: COST — PAYROLL | B38: 26 | C38: C-11 | E38: Contract Staff Rebid | F38: Cost — Payroll | G38: Competitive rebidding of outsourced staffing contracts. 416 contracted staff, ₹1,290L annual spend. Structured RFQ with SLAs. | H38: 46143 | I38: ₹2.5L one-time (RFQ/tender + legal review of existing contracts) | J38: No scope seen for cost optimisation | L38: 0 | M38: 0.375 | O38: 0 | P38: 0 | Q38: 0 | R38: 0 | S38: 0 | T38: 0 | U38: 0 | V38: 0 | W38: 0 | X38: 0 | Y38: 0 | Z38: 0 | AA38: =SUM(O38:Z38) -> 0
A39: COST — MISCELLANEOUS | B39: 27 | C39: C-12 | E39: Creditor Days Extension | F39: Cost — Miscellaneous | G39: Extend creditor payment days with top vendors. Each 15-day extension on ₹1,000Cr payables = ₹40Cr working capital freed. | H39: 46143 | I39: Nil — CFO-led vendor negotiation | J39: Need a periodic analysis cannot estimate now | L39: 0 | M39: 0.2 | O39: 0 | P39: 0 | Q39: 0 | R39: 0 | S39: 0 | T39: 0 | U39: 0 | V39: 0 | W39: 0 | X39: 0 | Y39: 0 | Z39: 0 | AA39: =SUM(O39:Z39) -> 0
A40: COST — MISCELLANEOUS | B40: 28 | C40: C-13 | E40: Expense Analysis & Financial Discipline | F40: Cost — Miscellaneous | G40: Establish a structured expense governance programme across the hospital: (A) Hidden Expense Identification — map all recurring payments (professional fees, retainers, subscriptions, AMCs, memberships) against active deliverables; eliminate spend with no demonstrable ROI. (B) IT & Software Licence Rationalisation — audit active licences, SaaS subscriptions, IT AMCs; identify unused seats, duplicate tools, open-source alternatives; bandwidth optimisation. (C) Contract Review — systematic review of active contracts; surface expired auto-renewals, favourable-to-vendor terms, renegotiation opportunities. (D) Financial Discipline — PO compliance, monthly budget variance reporting, cost centre accountability, quarterly cost reviews. (E) Material Cost Programme — COGS 28.5%→26.5% target via rate contracts, BOQ standardisation, volume consolidation (strategic umbrella over C-01 to C-12). | H40: 46113 | I40: Nil — CFO + Procurement Head review; possible ₹1L legal advisory for contract exits | L40: 0 | M40: 0.15 | O40: =+'C-13'!E4/10^5 -> 0 | P40: =+'C-13'!F4/10^5 -> 0 | Q40: =+'C-13'!G4/10^5 -> 0 | R40: =+'C-13'!H4/10^5 -> 0.45 | S40: =+'C-13'!I4/10^5 -> 0.75 | T40: =+'C-13'!J4/10^5 -> 1.05 | U40: =+'C-13'!K4/10^5 -> 1.35 | V40: =+'C-13'!L4/10^5 -> 1.65 | ... Z40: =+'C-13'!P4/10^5 -> 3 | AA40: =SUM(O40:Z40) -> 15
...

Sheet R-01
A1: R-01 | Annual Rate Revision Policy
A2: Revenue — Pricing & Yield
A3: OVERVIEW
A4: Description / Objective | B4: Revise all IP room, nursing, and procedure rates for cash/self-pay patients effective May-26. Room & nursing tariffs benchmarked against Aster, Welcare, Rajagiri, and Sunrise across 19 bed categories (avg increase ~12%). Top 50 revenue procedures repriced to midpoint of Lakeshore and highest competitor rate.
A5: Start Month | B5: 46113
A6: Estimated Cost | B6: Nil — internal process; CFO time only
A7: Expected Impact | B7: ₹9.6 Cr (Room & Nursing ₹3.5 Cr + Procedure repricing ₹6.1 Cr)
A9: BASIS FOR THIS INITIATIVE
A10: • Room & nursing tariffs benchmarked across 19 bed categories against Aster, Welcare, Rajagiri, and Sunrise • Revised tariff effective May-26 applies to cash/self-pay patients; avg increase ~12% (wards 11–25%, rooms 4–13%, suites 10–11%, critical care 10–16%) • Lakeshore remains below Aster post-revision — AC Room ₹6,500 vs ₹7,500 (−13%); Deluxe ₹7,500 vs ₹12,500 (−40%) • Chemo Ward held flat at ₹1,700 to protect oncology volume • Top 50 revenue procedures benchmarked against estimated Aster, Rajagiri, and Welcare rates; proposed hike to midpoint of Lakeshore and highest competitor • Competitor procedure rates are estimates from room tariff premium patterns — to be validated with actual competitor rate sheets • Note: Lakeshore is already priced above Rajagiri (40 of 50 procedures) and Welcare (all 50). Proposed hikes widen this gap further. Consider selective restraint on procedures where the gap to Rajagiri/Welcare exceeds 15–20%
A11: EXECUTION TRACKING (to be completed)
A12: Owner | B12: CFO
A13: Key Milestones / Actions | B13: 1. Tariff card signed off with 19-category rate grid (done) 2. Update HIS billing master with new rates by 30-Apr 3. Front-office and billing-counter staff briefing by 30-Apr 4. Monitor first-month revenue per occupied bed vs baseline (Jun review)
A14: Risks / Dependencies | B14: 1. Patient pushback on ward categories with >20% increase (General Ward +25%, Triple Sharing +22%) — front-desk scripts and patient counsellors needed 2. Cash patient share may vary seasonally; monsoon months see higher insurance utilisation 3. HIS billing-master update must be error-free to avoid under-billing cash patients at old rates
A15: Remarks | B15: Competitor benchmarking confirms room for increase vs Aster, but Lakeshore is already above Rajagiri and Welcare on most procedures — hikes should be selective. Chemo Ward held flat to protect oncology volumes. Diet and F&B service charges unchanged.
A18: ANALYSIS 1 : Room & Nursing Tariff Revision — Nursing Increment Pass-Through
A19: All rates are all-inclusive daily rates (room rent + nursing charges + diet + F&B service). Revision effective May-26, cash/self-pay patients only.
A21: Bed Category | B21: Existing (₹/day) | C21: Proposed (₹/day) | D21: Increase % | E21: Aster (₹/day) | F21: Welcare (₹/day) | G21: Rajagiri (₹/day) | H21: Sunrise (₹/day) | I21: vs Aster
A22: SINGLE ROOM NON A/C. | B22: 3400 | C22: 3750 | D22: =(C22-B22)/B22 -> 0.10294118 | E22: — | F22: — | G22: 4000 | H22: 3500 | I22: —
A23: GENERAL WARD | B23: 1200 | C23: 1500 | D23: =(C23-B23)/B23 -> 0.25 | E23: 2250 | F23: — | G23: — | H23: — | I23: =(C23-E23)/E23 -> -0.33333333
A24: GENERAL WARD A/C. | B24: 1800 | C24: 2000 | D24: =(C24-B24)/B24 -> 0.11111111 | E24: — | F24: — | G24: — | H24: — | I24: —
A25: TWIN SHARING A/C | B25: 3100 | C25: 3500 | D25: =(C25-B25)/B25 -> 0.12903226 | E25: 4500 | F25: 3150 | G25: — | H25: — | I25: =(C25-E25)/E25 -> -0.22222222
A26: TRIPLE SHARING A/C | B26: 2450 | C26: 3000 | D26: =(C26-B26)/B26 -> 0.2244898 | E26: — | F26: — | G26: — | H26: — | I26: —
A27: AC ROOM | B27: 6250 | C27: 6500 | D27: =(C27-B27)/B27 -> 0.04 | E27: 7500 | F27: 4900 | G27: 4500 | H27: 4500 | I27: =(C27-E27)/E27 -> -0.13333333
A28: DELUXE A/C. | B28: 6760 | C28: 7500 | D28: =(C28-B28)/B28 -> 0.10946746 | E28: 12500 | F28: 5800 | G28: 7300 | H28: — | I28: =(C28-E28)/E28 -> -0.4
A29: EXECUTIVE ROOM | B29: 9175 | C29: 10100 | D29: =(C29-B29)/B29 -> 0.10081744 | E29: 16000 | F29: — | G29: — | H29: 6000 | I29: =(C29-E29)/E29 -> -0.36875
A30: EXECUTIVE SUITE | B30: 30200 | C30: 33500 | D30: =(C30-B30)/B30 -> 0.10927152 | E30: — | F30: 11000 | G30: — | H30: — | I30: —
A31: PRESIDENTIAL SUITE | B31: 42200 | C31: 46500 | D31: =(C31-B31)/B31 -> 0.10189573 | E31: 75000 | F31: — | G31: — | H31: — | I31: =(C31-E31)/E31 -> -0.38
A32: CHEMO WARD | B32: 1700 | C32: 1700 | D32: =(C32-B32)/B32 -> 0 | E32: 1250 | F32: — | G32: — | H32: — | I32: =(C32-E32)/E32 -> 0.36
A33: DAY CARE | B33: 1800 | C33: 2000 | D33: =(C33-B33)/B33 -> 0.11111111 | E33: 1250 | F33: — | G33: — | H33: — | I33: =(C33-E33)/E33 -> 0.6
A34: LABOUR ROOM | B34: 5200 | C34: 6000 | D34: =(C34-B34)/B34 -> 0.15384615 | E34: — | F34: — | G34: — | H34: — | I34: —
A35: HDU | B35: 5650 | C35: 6500 | D35: =(C35-B35)/B35 -> 0.15044248 | E35: — | F35: — | G35: — | H35: — | I35: —
A36: ICU | B36: 7300 | C36: 8000 | D36: =(C36-B36)/B36 -> 0.095890411 | E36: — | F36: — | G36: — | H36: — | I36: —
A37: ISOLATION ICU | B37: 7500 | C37: 8500 | D37: =(C37-B37)/B37 -> 0.13333333 | E37: — | F37: — | G37: — | H37: — | I37: —
A38: ICCU / KTXICU | B38: 8650 | C38: 10000 | D38: =(C38-B38)/B38 -> 0.15606936 | E38: — | F38: — | G38: — | H38: — | I38: —
A39: LIVERTX ICU / CSICU | B39: 13000 | C39: 14500 | D39: =(C39-B39)/B39 -> 0.11538462 | E39: — | F39: — | G39: — | H39: — | I39: —
A40: PRIVATE ICU | B40: 21000 | C40: 23500 | D40: =(C40-B40)/B40 -> 0.11904762 | E40: — | F40: — | G40: — | H40: — | I40: —
A44: ANALYSIS 2 : Top 50 Revenue Procedures — Competitor Benchmarking & Repricing Impact
A45: Lakeshore rate card (PDN rate) for top 50 clinical procedures by FY26 revenue. Competitor rates estimated from room tariff premium patterns. Cleaned list: excludes diet, bystander, oxygen, CSSD, equipment, anaesthetist, MRD, registration.
A47: # | B47: Procedure | C47: Group | D47: FY26 Rev (₹L) | E47: Qty | F47: Lakeshore Rate (₹) | G47: Aster (est.) | H47: Rajagiri (est.) | I47: Welcare (est.) | J47: Proposed Rate (₹) | K47: Hike % | L47: Annual Impact (₹L)
A48: 1 | B48: PET CT WHOLE BODY SCAN | C48: PET CT | D48: 355 | E48: 1846 | F48: 19000 | G48: 23750 | H48: 18050 | I48: 15200 | J48: =ROUND((F48+MAX(G48,H48,I48))/2,0) -> 21375 | K48: =(J48-F48)/F48 -> 0.125 | L48: =(J48-F48)*E48/100000 -> 43.8425
...

Sheet R-02
A1: R-02 | Procedure Contribution Framework
A2: Revenue — Pricing & Yield | H2: 0.03 | I2: 0.05 | J2: 0.07 | K2: 0.09 | L2: 0.11 | M2: 0.13 | N2: 0.15 | O2: 0.17 | P2: 0.2 | Q2: =SUM(H2:P2) -> 1
A3: OVERVIEW | D3: YTD | E3: Apr | F3: May | G3: Jun | H3: Jul | I3: Aug | J3: Sep | K3: Oct | L3: Nov | M3: Dec | N3: Jan | O3: Feb | P3: Mar
A4: Description / Objective | B4: Launch a contribution framework for all IP procedures — for both cash and insurance patients. Cost out top 50 procedures by revenue: include doctor fees, team costs (OT staff, anaesthesia, nursing), consumables, and overhead allocation per procedure. Identify low-contribution procedures (<50% contribution). Reprice cash rates and flag insurer tariff renegotiation list. Target: 58% average contribution for 26% EBITDA. This is a per-procedure P&L that reveals which services make money and which don't after fully loading doctor and team costs. | C4: Rev Impact overall by bringing cost measurements | D4: 25000000 | E4: 0 | F4: 0 | G4: 0 | H4: =+H$2*$D$4 -> 750000 | I4: =+I$2*$D$4 -> 1250000 | J4: =+J$2*$D$4 -> 1750000 | K4: =+K$2*$D$4 -> 2250000 | L4: =+L$2*$D$4 -> 2750000 | M4: =+M$2*$D$4 -> 3250000 | N4: =+N$2*$D$4 -> 3750000 | O4: =+O$2*$D$4 -> 4250000 | P4: =+P$2*$D$4 -> 5000000
A5: Start Month | B5: 46113 | C5: Cost Impact for the above
A6: Estimated Cost | B6: ₹1.5L one-time (costing consultant or internal CFO + pharmacy time) | C6: Costing Consultant | D6: =+SUM(E6:P6) -> 1650000 | F6: 150000 | G6: 150000 | H6: 150000 | I6: 150000 | J6: 150000 | K6: 150000 | L6: 150000 | M6: 150000 | N6: 150000 | O6: 150000 | P6: 150000
A7: Expected Impact | B7: ₹2.5 Cr | C7: Costing Staff
A9: BASIS FOR THIS INITIATIVE
A10: Current pricing is set without systematic visibility into per-procedure profitability. A contribution framework reveals per-procedure P&L after fully loading doctor fees, team costs, consumables, and overhead. IMPACT BUILD-UP (₹2.5 Cr conservative): (A) Cash rate correction (top 25 procedures): • Build per-procedure P&L for top 50 revenue procedures • Identify cash-patient procedures where current rate sits below competitive benchmark and contribution floor • Cardiology (PTCA + Coronary Angiography): largest single opportunity • Achievable rate correction on cash patients: ~60% of identified opportunity (rest constrained by market pricing / volume elasticity) • Estimated recovery: ₹2 Cr (B) Contribution-based repricing (low-margin procedures): • Target: identify procedures below 50% contribution after full cost loading • Reprice or restructure bottom 20 procedures → estimated ₹50L incremental Total conservative: ₹2 Cr (cash rate correction) + ₹0.5 Cr (contribution repricing) = ₹2.5 Cr
A11: EXECUTION TRACKING (to be completed)
A12: Owner | B12: CFO / Operations Manager
A13: Key Milestones / Actions | B13: 1. Build per-procedure P&L for top 50 procedures: include doctor fees, OT team costs, consumables, overhead allocation by Jul-26 2. Identify all procedures below 50% contribution margin — reprice or discontinue by Aug-26 3. Cardiology: PTCA and Coronary Angiography to be reviewed with department head 4. Lab/Biochemistry: review rate card — bulk revision through LIS update by Jun-26 5. MRI/Ultrasound: review radiology tariff card by Jun-26 6. Flag insurance-specific procedures for R-03 tariff renegotiation 7. Target: 58% average contribution for 26% EBITDA
A14: Risks / Dependencies | B14: 1. Doctor fee data is sensitive and may face resistance from Finance/HR in sharing 2. Some surgeons may resist transparency on per-procedure profitability 3. Contribution analysis depends on accurate consumable BOQ data (C-05 must deliver) 4. Repricing low-contribution insured procedures requires TPA renegotiation (R-03 dependency) 5. Risk of volume loss if cash prices are raised too aggressively on price-sensitive procedures
A15: Remarks | B15: Contribution framework is the analytical foundation for downstream pricing decisions. Feeds R-03 (insurance renegotiation priority list) and informs R-10 (new package design).
A16: Bequip Remarks | B16: Intrduce back the Billing Department wise and the Procedure Department wise P&L with maximum cost allcoation to direct, allocated and absorbed costs
A17: Bequip Remarks | B17: 1. Cost Consultant 1 time cost seems to be low, either have an in house staff 2. need to work out department PL of top 15 and bottom 15 and renegotiate the doctor payouts, low fixed pay and high variable pay, also sensitise the doctor and the administrative representative of the need to focus on procedures that we list, OP to IP ocnversion and Lab and Radiology counts that we propose.

Sheet R-03
A1: R-03 | Insurance Renegotiation & Empanelment
A2: Revenue — Pricing & Yield
A3: OVERVIEW
A4: Description / Objective | B4: Three-pronged insurance revenue initiative: (A) Charge Capture Audit: Audit current insurance bills against TPA tariff schedules. Identify covered items (nursing charges, monitoring, clinical charges, physiotherapy, ICU charges) not systematically billed. Fix charge master. Train nursing on charge initiation. (B) TPA/Insurer Tariff Renegotiation: Formal annual tariff revision with all empanelled TPAs and insurers. Most agreements not revised in 2–3 years while costs rose 12–15%. Leverage volume and case complexity data. Target: 8–12% rate improvement. (C) Competitive Empanelment Analysis: Compare insurer MoU package/reimbursement rates. Top 50 procedures by value. Identify which schemes/insurers competitors (Aster, Rajagiri, KIMS) have that we don’t. Recommend new empanelments with incremental revenue impact.
A5: Start Month | B5: 46113
A6: Estimated Cost | B6: ₹4L one-time (billing audit + legal + data prep; internal CFO time)
A7: Expected Impact | B7: ₹9 Cr
A9: BASIS FOR THIS INITIATIVE
A10: Multiple billable line items are covered under standard TPA tariffs but not raised due to charge master gaps or nursing documentation failures. Simultaneously, TPA/insurer rates have not been renegotiated in 2–3 years while costs rose 12–15%. IMPACT BUILD-UP (₹9 Cr conservative): (A) Charge Capture — ₹3 Cr: • Insurance IP admissions: ~12,000/yr • Avg missed billable items per admission: ₹2,500 (nursing charges, monitoring, physio, clinical charges) • Recovery: 12,000 × ₹2,500 = ₹3 Cr (B) TPA Tariff Renegotiation — ₹4 Cr: • Current insurance IP revenue: ~₹160 Cr/yr (est. 40% of ₹399 Cr total IP) • Target rate increase: 8–12% across empanelled TPAs (most agreements 2–3 yrs old) • Conservative 2.5% effective blended increase (some TPAs will resist): ₹160 Cr × 2.5% = ₹4 Cr (C) New Empanelments (gap insurers from comparison table) — ₹2 Cr: • 10 gap insurers identified (Star Health, Go Digit, Navi, SBI General, etc.) • Avg incremental volume per new empanelment: 100 IP cases/yr × ₹1.5L avg ticket • 10 insurers × 100 cases × ₹1.5L = ₹1.5 Cr, rounded to ₹2 Cr with OP Total: ₹3 + ₹4 + ₹2 = ₹9 Cr
A11: EXECUTION TRACKING (to be completed)
A12: Owner | B12: CFO / Head Insurance & TPA
A13: Key Milestones / Actions | B13: 1. Audit 50 representative IP bills against TPA tariff schedules for missing items by May-26 2. Update charge master with all covered-but-unbilled items by Jun-26 3. Train nursing on charge initiation protocols (monitoring, physio, ICU charges) by Jun-26 4. Compile insurer-wise tariff comparison matrix — top 50 procedures by value by Jun-26 5. Identify which insurers/schemes Aster, Rajagiri, KIMS have that we don’t by Jun-26 6. Submit formal tariff revision requests to top 10 TPAs by Jul-26 (target: 8–12% improvement) 7. Prepare new empanelment applications for identified gaps by Aug-26 8. Track charge capture uplift monthly from Jul-26
A14: Risks / Dependencies | B14: 1. TPA tariff renegotiation has 60–90 day contract cycle lag 2. Some TPAs may push back or threaten delisting — need volume data to negotiate from strength 3. New empanelments take 3–6 months for processing 4. Charge master update requires IT + billing coordination
A15: Remarks | B15: This is the single largest revenue opportunity after rate revision. Combines charge capture (immediate), tariff renegotiation (medium-term), and new empanelments (strategic). Feeds from R-02 contribution framework data for evidence-based renegotiation.
A17: COMPETITOR EMPANELMENT ANALYSIS
A18: Source: Hospital websites (asterhospitals.in, vpslakeshorehospital.com, kimshospitals.com). Lists are dynamic — confirm with Insurance Help Desk before acting.
A20: Insurer / TPA | B20: VPS Lakeshore | C20: Aster Medcity | D20: KIMS | E20: Action
A21: Aditya Birla Health Insurance | B21: — | C21: ✓ | D21: ✓ | E21: Pursue — large retail insurer, growing Kerala presence
A22: SBI General Insurance | B22: — | C22: ✓ | D22: ? | E22: Pursue — PSU bank-linked, high volume potential
A23: TATA AIG General Insurance | B23: — | C23: ✓ | D23: ? | E23: Pursue — major corporate insurer
A24: Go Digit General Insurance | B24: — | C24: ✓ | D24: ? | E24: Pursue — fast-growing digital-first insurer
A25: Navi General Insurance | B25: — | C25: ✓ | D25: ? | E25: Pursue — digital insurer, younger demographics
A26: Niva Bupa Health Insurance | B26: — | C26: ✓ | D26: ? | E26: Pursue — standalone health insurer, high claim volumes
A27: Star Health & Allied Insurance | B27: — | C27: ✓ | D27: ? | E27: High priority — India's largest standalone health insurer
A28: Liberty General Insurance | B28: — | C28: ✓ | D28: ? | E28: Evaluate — niche but growing
A29: Galaxy Health Insurance | B29: — | C29: ✓ | D29: ? | E29: Evaluate — TPA with growing network
A30: Volo Health / East West Assist | B30: — | C30: ✓ | D30: ? | E30: Evaluate — TPA serving multiple insurers
A32: INTERNATIONAL INSURANCE GAPS
A33: Aster Medcity has 14 international insurers (Gulf + Maldives) that VPS Lakeshore likely lacks. Key gaps:
A34: Aasandha Insurance (Maldives), Allied Insurance (Maldives), Amana Takaful (Maldives), Daman Insurance (UAE), Almadalla (UAE), Alkoot (Qatar), Dubai Insurance Co, NowHealth, MSH Insurance, NLGI, Union Insurance, Health 360, Dar-Takaful, Allianz International
A35: VPS Lakeshore benefits from VPS Healthcare group presence in UAE/Oman. Internal VPS referral pathways may already exist outside formal insurance empanelment. International patient cell to confirm which Gulf/Maldives insurers are currently active.

Sheet R-04
A1: R-04 | Distributed Healthcare Network (DHCN)
A2: Revenue — Network Expansion
A3: OVERVIEW
A4: Description / Objective | B4: Deploy two network prototypes across Kerala: (A) Satellite Clinics (Prototype 4 — Partner Hospital model): Dedicated Lakeshore-branded floor or wing within partner hospitals (MBMMH Kothamangalam, Malankara Mission Kunnamkulam, VPS Calicut), with VPS clinical staff, protocols, and full EMR integration. Phase 1 target: 10 satellite clinic locations across Kerala. (B) Risk Assessment Centres (Prototype 5 — RAC): Structured risk-assessment and triage stations at high-footfall locations. 5-cancer screening (oral, breast, cervical, colorectal, lung), cardiac/metabolic risk profiling, genomic risk assessment. Phase 1 target: 25 RAC stations. All nodes funnel diagnosed/complex cases to Lakeshore Kochi for surgery, radiation, transplant, and complex chemotherapy. Revenue share models define economics at each node. Oncology hub-and-spoke (screening → Lakeshore radiation/surgery) is a core use case within this network.
A5: Start Month | B5: 46143
A6: Estimated Cost | B6: ₹65L/yr (10 satellite clinics fit-out + 25 RAC stations + oncology consultant travel + partner MOUs + admin)
A7: Expected Impact | B7: ₹13 Cr
A9: BASIS FOR THIS INITIATIVE
A10: Over 60% of Lakeshore’s addressable catchment lives beyond 20km. Patients in Thrissur, Muvattupuzha, and North Ernakulam default to local hospitals because the first consult is inconvenient. A weekly surgeon-run OPD brings Lakeshore’s clinical brand to the patient. IP referral back to main campus is the primary financial lever. PHASED REVENUE MODEL (Year 1, conservative): Satellite Clinics (10 locations, phased: 2 in Q1, +3 in Q2, +3 in Q3, +2 in Q4): • Per clinic at steady state: 30 consults/wk → 10% IP conversion = 3 admissions/wk × ₹1.5L avg ticket = ₹4.5L/wk gross • After partner revenue share and ramp-up: net ₹2.7L/wk per clinic • Utilisation ramp: Q1 50%, Q2 65%, Q3 80%, Q4 90% • Q1: 2 clinics × ₹1.4L/wk × 13 wks = ₹35L • Q2: 5 clinics × ₹1.8L/wk × 13 wks = ₹114L • Q3: 8 clinics × ₹2.2L/wk × 13 wks = ₹224L • Q4: 10 clinics × ₹2.4L/wk × 13 wks = ₹316L • Clinic Year 1 total: ₹689L = ₹6.9 Cr RAC Stations (25 locations, phased: 0 in Q1, 5 in Q2, +5 in Q3, +15 in Q4): • Per RAC at steady state: 60 screens/wk × ₹1,500 = ₹0.9L/wk screening + 1 IP referral/wk × ₹2L = ₹2L/wk → total ₹2.9L/wk gross • After ramp-up: net ₹1.6L/wk per RAC • Utilisation ramp: Q2 50%, Q3 65%, Q4 80% • Q1: 0 RACs = ₹0 • Q2: 5 RACs × ₹0.8L/wk × 13 wks = ₹52L • Q3: 10 RACs × ₹1.0L/wk × 13 wks = ₹135L • Q4: 25 RACs × ₹1.3L/wk × 13 wks = ₹416L • RAC Year 1 total: ₹603L = ₹6.0 Cr Total Year 1 conservative: ₹6.9 + ₹6.0 = ₹12.9 Cr ≈ ₹13 Cr (heavily weighted to H2 as network matures)
A11: EXECUTION TRACKING (to be completed)
A12: Owner | B12: Head BD / Head of DHCN
A13: Key Milestones / Actions | B13: 1. Finalise MOUs with 3 existing partner hospitals (Kothamangalam, Kunnamkulam, Calicut) by May-26 2. Identify 7 additional satellite locations — Thrissur, Muvattupuzha, Perumbavoor, Angamaly, Aluva, Thodupuzha, Palakkad by Jun-26 3. Build per-location financial model: lease + fit-out + 2 consultants/wk + admin = break-even at ~40 consults/week 4. RAC pilot at Kochi campus (Jul-26), then MBMMH & Calicut (Aug–Sep-26), then suburban roll-out 5. Analyse doctor OP consult data to identify surgeons with spare OPD capacity for satellite deployment 6. Define revenue share model per prototype: satellite = Lakeshore 70%/Partner 30% vs RAC = Lakeshore retains screening revenue, referral conversion = main campus revenue 7. Project referral revenue: 10 clinics × 40 consults/wk × 15% IP conversion × ₹2L avg ticket = ₹62L/yr conservative; 25 RACs × 100 screens/wk × 5% positive × ₹3L avg = ₹19.5L/yr 8. Phase 2 targets: scale to 25 clinics + 50 RACs by FY28
A14: Risks / Dependencies | B14: 1. Partner hospital clinical standards may not match Lakeshore protocols — clinical audit required before co-branding 2. RAC regulatory clearance required for screening equipment at non-hospital locations 3. Satellite OPD days reduce surgeon availability at main campus — scheduling discipline required 4. EMR integration with partner hospitals requires IT investment (₹5–10L per site) 5. Break-even at <40 consults/week is achievable only in high-density catchments
A15: Remarks | B15: Hub-and-spoke model: satellite clinics and RACs serve as referral funnels to the Kochi main campus. Partner MOU quality should take precedence over clinic count; prioritise locations with limited existing tertiary access. Dependencies: R-09 (BD referral programme) for partner doctor onboarding and R-12 (new specialties) for onco/cardiac referral capture.

Sheet R-05
A1: R-05 | Corporate Health Programme
A2: Revenue — Network Expansion
A3: OVERVIEW
A4: Description / Objective | B4: Build a structured corporate health programme targeting top 50 corporates (PSU + private) within 20km of Kochi campus. Tiered offering: (a) Executive Health Check packages — cardiac, oncology, and metabolic risk profiling; (b) Company insurance tie-ups — negotiate group mediclaim with preferential IP rates; (c) On-premises multispecialty OP clinics — deploy VPS consultants to corporate campuses for weekly/fortnightly clinics. Deduplicate against existing corporate accounts to avoid channel conflict. Assign 2 dedicated corporate relationship managers. Track conversion: health check → OPD follow-up → IP admission.
A5: Start Month | B5: 46143
A6: Estimated Cost | B6: ₹17L/yr (2 corporate RMs + package design + billing desk)
A7: Expected Impact | B7: ₹5 Cr
A9: BASIS FOR THIS INITIATIVE
A10: Corporate volumes are captive, predictable, and have very low acquisition cost once contracted. Kochi's industrial and IT belt represents 100,000+ covered lives within 15km. Anchor accounts (BPCL, Cochin Port, FACT alone = ~15,000 employees) can seed significant IP volume through health check conversions. TARGET CORPORATE LIST (Top 50, representative): PSU (15): BPCL Kochi Refinery (~4,500), Cochin Shipyard (~3,000), FACT (~2,500), Cochin Port Trust (~2,000), KSEB Ernakulam (~1,500), Naval Base Kochi (~3,000), Southern Air Command, HMT, BHEL, CIAL, Kochi Metro Rail, KITCO, BSNL, FCI, LIC Regional IT/ITES (20): TCS Infopark (~5,000), Wipro, Cognizant, UST Global (~3,500), IBS Software (~2,000), QBurst (~2,000), Ernst & Young GDS, NeST, NIC, Envestnet, Nissan Digital Hub, SunTec, Litmus7, TechM, HCL, Fingent, Baker Hughes, Teleperformance, Byju's, Muthoot Private/MNC (15): Federal Bank, South Indian Bank, Muthoot Finance, GCDA, Lulu Group, Le Meridien/Marriott/Taj, V-Guard, Kitex, Nitta Gelatin, Synthite, SFO Technologies, Century Metal, Geojit, Manorama, Asianet REVENUE BASIS (₹5 Cr conservative): • Target: 25 signed corporates in Year 1 (50% of target list) • Executive health checks: 25 cos × 200 avg employees screened × ₹5,000 avg package = ₹2.5 Cr • IP conversion from health checks: 3% positive finding rate × 5,000 screened × ₹1.5L avg ticket = ₹2.25 Cr • On-premises OP clinics: 10 active clients × 50 consults/mo × ₹500 × 12 mo = ₹3L = ~₹30L • Total: ~₹5 Cr
A11: EXECUTION TRACKING (to be completed)
A12: Owner | B12: Head BD / Corporate Marketing team
A13: Key Milestones / Actions | B13: 1. Compile target list of top 50 corporates with employee strength, current health partner, and insurance status by May-26 2. Audit existing 20 corporate accounts — revenue per account, services used, upsell potential by May-26 3. Design 3-tier health check packages (Basic ₹3,500 / Premium ₹8,000 / Executive ₹15,000) by Jun-26 4. Pilot on-premises OP clinic at 3 anchor corporates (1 IT, 1 PSU, 1 hospitality) by Jul-26 5. Assign 2 dedicated corporate RMs — target 15 new accounts in Year 1 6. Build conversion tracking: health check → abnormal finding → OPD follow-up → IP admission 7. Target: 5,000 health checks Year 1 × ₹8,000 avg = ₹4 Cr direct; 8% IP conversion × ₹2L avg = ₹8 Cr indirect
A14: Risks / Dependencies | B14: 1. On-premises clinics require regulatory clearance for off-site consultations 2. Corporate decision cycles typically run 3–6 months, tied to annual budget planning 3. Established corporate sales teams at Aster and existing PSU relationships at AIMS present competitive resistance 4. Health check package pricing must be competitive against standalone diagnostic centres (SRL, Metropolis) 5. Insurance tie-ups depend on TPA cooperation (dependency on R-03)
A15: Remarks | B15: Health check volume is the funnel metric; IP conversion is the revenue metric. Target ratio: ₹5–8 of downstream IP revenue for every ₹1 of health check fee. Suggested sequencing: secure 3–5 PSU/IT anchor accounts first to support reference-based selling. Dependencies: R-03 (corporate TPAs) and R-09 (Corporate-Residential RM team).

Sheet R-06
A1: R-06 | Residential & Community Outreach
A2: Revenue — Network Expansion
A3: OVERVIEW
A4: Description / Objective | B4: Partner with major gated communities and apartment complexes within 15km (Sobha, Prestige, Purva in Kakkanad, Edapally, Thrippunithura) for on-site health camps, resident doctor visits, and emergency response agreements. Handled by dedicated corporate/residential team within BD organisation. Includes community health camps: two monthly health awareness programmes in schools (adolescent health, vision, nutrition), temples and mosques (senior citizen camps, post-Ramadan diabetes/cardiac screening), and residential complexes. Low cost, high community trust. | F4: Apr | G4: May | H4: Jun | I4: Jul | J4: Aug | K4: Sep | L4: Oct | M4: Nov | N4: Dec | O4: Jan | P4: Feb | Q4: Mar
A5: Start Month | B5: 46143 | H5: 3000000 | K5: 3000000 | N5: 3000000 | Q5: 3000000
A6: Estimated Cost | B6: ₹30L/yr (logistics, portable diagnostic equipment, community coordinator + camp logistics)
A7: Expected Impact | B7: ₹3 Cr
A9: BASIS FOR THIS INITIATIVE
A10: Gated communities represent high-income, high-compliance patient segments. Emergency tie-ups create first-call advantage. Health camps drive diagnostics, OPD footfall, and early detection conversions. Acquisition cost is far lower than digital advertising for this segment. TARGET RESIDENTIAL COMMUNITIES (20+, within 15km): Kakkanad: DLF New Town Heights (~1,200 units), Prestige Hillside Gateway (~800), Joyalukkas Gold Tower (~400), Confident Group properties, Mather projects Edapally: SFS Grandville (~600 units), Skyline Apartments, Asset Homes projects, Desai Homes DD Kings Square/Queens Square Thrippunithura: Sobha projects (~500 units), Purva Eternity Maradu/Nettoor: Waterfront communities (proximity to Lakeshore), DD Sunset Island Aluva: CIAL township housing, Rajagiri Valley Other: Panangad communities, Vyttila premium apartments, Marine Drive high-rises Total addressable: ~8,000–10,000 households = 25,000–30,000 residents REVENUE BASIS (₹3 Cr conservative): • Target: 15 active community partnerships in Year 1 • Health camps: 15 communities × 4 camps/yr × 200 screens/camp × ₹2,000 avg = ₹2.4 Cr • Emergency response tie-ups: 15 communities × ~5 emergency transfers/yr × ₹2L avg IP ticket = ₹1.5 Cr (but discounted for overlap) • OPD follow-up from camps: 10% of 12,000 screened = 1,200 OPD visits × ₹1,500 = ₹18L • Conservative total (camps + follow-up + emergency): ~₹3 Cr
A11: EXECUTION TRACKING (to be completed)
A12: Owner | B12: Head BD / Community Health Coordinator / Corporate-Residential RM team
A13: Key Milestones / Actions | B13: 1. Map all gated communities >200 units within 15km — with RWA contact, population estimate by May-26 2. Design 3 camp formats: (a) Senior wellness, (b) Women's health, (c) General screening — standardised protocols 3. Pilot 4 camps in May–Jun-26: 1 school, 1 temple/mosque, 2 residential complexes 4. Negotiate emergency response MOUs with top 10 RWAs by Jun-26 (ambulance SLA, doctor-on-call) 5. Launch monthly camp calendar (4–6 camps/month) from Jul-26 onwards 6. Track camp → OPD → IP conversion funnel monthly 7. Target Year 1: 60 camps, 8,000 screenings, 800 OPD conversions, 120 IP admissions
A14: Risks / Dependencies | B14: 1. RWA cooperation varies; some associations restrict commercial health activities in common areas 2. Regulatory clearance required for portable diagnostic equipment at off-site locations 3. Overlap with R-04 community outreach in satellite clinic catchments — territory mapping required to avoid duplication 4. Consistent camp quality is required; a single substandard experience can affect brand perception across a community
