Workbook

Sheet Dashboard
A1: AOP EXECUTION DASHBOARD — FY 2026-27 | VPS Lakeshore Hospital
A2: FY 2026-27 | Auto-linked from all sheets | Refresh after actuals entry each month
A4: INITIATIVE STATUS
A5: Total Initiatives | C5: Completed | E5: In Progress | G5: Delayed | I5: On Hold | K5: Not Started
A6: =COUNTIF('Initiative Register'!C5:C55,"<>") -> 50 | C6: =COUNTIF('Initiative Register'!R5:R55,"Completed") -> 1 | E6: =COUNTIF('Initiative Register'!R5:R55,"In Progress") -> 1 | G6: =COUNTIF('Initiative Register'!R5:R55,"Delayed") -> 0 | I6: =COUNTIF('Initiative Register'!R5:R55,"On Hold") -> 0 | K6: =COUNTIF('Initiative Register'!R5:R55,"Not Started") -> 48
A9: FINANCIAL SUMMARY (Rs Lakhs)
A10: Metric | B10: AOP Budget | C10: YTD Actual | D10: Variance (Rs) | E10: Variance % | F10: Status
A11: Revenue from Initiatives | B11: ='Revenue Impact'!P71 -> 0 | C11: ='Monthly Actuals'!P73 -> 0 | D11: =C11-B11 -> 0 | E11: =IFERROR(D11/B11,"") | F11: =IF(E11="","",IF(E11<0,"▼ BEHIND","▲ AHEAD"))
A12: Cost of Initiatives | B12: ='Cost Plan'!P55 -> 0 | C12: ='Monthly Actuals'!P127 -> 0 | D12: =C12-B12 -> 0 | E12: =IFERROR(D12/B12,"") | F12: =IF(E12="","",IF(E12<0,"▼ BEHIND","▲ AHEAD"))
A13: Net EBITDA Impact | B13: =B11-B12 -> 0 | C13: =C11-C12 -> 0 | D13: =C13-B13 -> 0 | E13: =IFERROR(D13/B13,"") | F13: =IF(E13="","",IF(E13<0,"▼ BEHIND","▲ AHEAD"))
A15: MONTHLY TREND (Rs Lakhs)
A16: Month | B16: Bdg Revenue | C16: Act Revenue | D16: Rev Var | E16: Bdg Cost | F16: Act Cost | G16: Cost Var | H16: Net EBITDA (Bdg) | I16: Net EBITDA (Act)
A17: Apr | B17: ='Revenue Impact'!D71 -> 0 | C17: ='Monthly Actuals'!D73 -> 0 | D17: =C17-B17 -> 0 | E17: ='Cost Plan'!D55 -> 0 | F17: ='Monthly Actuals'!D127 -> 0 | G17: =F17-E17 -> 0 | H17: =B17-E17 -> 0 | I17: =C17-F17 -> 0
A18: May | B18: ='Revenue Impact'!E71 -> 0 | C18: ='Monthly Actuals'!E73 -> 0 | D18: =C18-B18 -> 0 | E18: ='Cost Plan'!E55 -> 0 | F18: ='Monthly Actuals'!E127 -> 0 | G18: =F18-E18 -> 0 | H18: =B18-E18 -> 0 | I18: =C18-F18 -> 0
A19: Jun | B19: ='Revenue Impact'!F71 -> 0 | C19: ='Monthly Actuals'!F73 -> 0 | D19: =C19-B19 -> 0 | E19: ='Cost Plan'!F55 -> 0 | F19: ='Monthly Actuals'!F127 -> 0 | G19: =F19-E19 -> 0 | H19: =B19-E19 -> 0 | I19: =C19-F19 -> 0
A20: Jul | B20: ='Revenue Impact'!G71 -> 0 | C20: ='Monthly Actuals'!G73 -> 0 | D20: =C20-B20 -> 0 | E20: ='Cost Plan'!G55 -> 0 | F20: ='Monthly Actuals'!G127 -> 0 | G20: =F20-E20 -> 0 | H20: =B20-E20 -> 0 | I20: =C20-F20 -> 0
A21: Aug | B21: ='Revenue Impact'!H71 -> 0 | C21: ='Monthly Actuals'!H73 -> 0 | D21: =C21-B21 -> 0 | E21: ='Cost Plan'!H55 -> 0 | F21: ='Monthly Actuals'!H127 -> 0 | G21: =F21-E21 -> 0 | H21: =B21-E21 -> 0 | I21: =C21-F21 -> 0
A22: Sep | B22: ='Revenue Impact'!I71 -> 0 | C22: ='Monthly Actuals'!I73 -> 0 | D22: =C22-B22 -> 0 | E22: ='Cost Plan'!I55 -> 0 | F22: ='Monthly Actuals'!I127 -> 0 | G22: =F22-E22 -> 0 | H22: =B22-E22 -> 0 | I22: =C22-F22 -> 0
A23: Oct | B23: ='Revenue Impact'!J71 -> 0 | C23: ='Monthly Actuals'!J73 -> 0 | D23: =C23-B23 -> 0 | E23: ='Cost Plan'!J55 -> 0 | F23: ='Monthly Actuals'!J127 -> 0 | G23: =F23-E23 -> 0 | H23: =B23-E23 -> 0 | I23: =C23-F23 -> 0
A24: Nov | B24: ='Revenue Impact'!K71 -> 0 | C24: ='Monthly Actuals'!K73 -> 0 | D24: =C24-B24 -> 0 | E24: ='Cost Plan'!K55 -> 0 | F24: ='Monthly Actuals'!K127 -> 0 | G24: =F24-E24 -> 0 | H24: =B24-E24 -> 0 | I24: =C24-F24 -> 0
A25: Dec | B25: ='Revenue Impact'!L71 -> 0 | C25: ='Monthly Actuals'!L73 -> 0 | D25: =C25-B25 -> 0 | E25: ='Cost Plan'!L55 -> 0 | F25: ='Monthly Actuals'!L127 -> 0 | G25: =F25-E25 -> 0 | H25: =B25-E25 -> 0 | I25: =C25-F25 -> 0
A26: Jan | B26: ='Revenue Impact'!M71 -> 0 | C26: ='Monthly Actuals'!M73 -> 0 | D26: =C26-B26 -> 0 | E26: ='Cost Plan'!M55 -> 0 | F26: ='Monthly Actuals'!M127 -> 0 | G26: =F26-E26 -> 0 | H26: =B26-E26 -> 0 | I26: =C26-F26 -> 0
A27: Feb | B27: ='Revenue Impact'!N71 -> 0 | C27: ='Monthly Actuals'!N73 -> 0 | D27: =C27-B27 -> 0 | E27: ='Cost Plan'!N55 -> 0 | F27: ='Monthly Actuals'!N127 -> 0 | G27: =F27-E27 -> 0 | H27: =B27-E27 -> 0 | I27: =C27-F27 -> 0
A28: Mar | B28: ='Revenue Impact'!O71 -> 0 | C28: ='Monthly Actuals'!O73 -> 0 | D28: =C28-B28 -> 0 | E28: ='Cost Plan'!O55 -> 0 | F28: ='Monthly Actuals'!O127 -> 0 | G28: =F28-E28 -> 0 | H28: =B28-E28 -> 0 | I28: =C28-F28 -> 0
A30: EXCEPTION LOG — Initiatives Flagged
A31: # | B31: Initiative ID | C31: Initiative Name | D31: Status | E31: Ann Budget (Rs) | F31: Ann Actual (Rs) | G31: Variance (Rs) | H31: Var % | I31: Exception Flag
A32: 1 | B32: ='Initiative Register'!B5 -> INI-001 | C32: ='Initiative Register'!C5 -> Campaign- Patient experience improvement | D32: ='Initiative Register'!R5 -> Completed | E32: ='Cost Plan'!P5 -> 0 | F32: ='Monthly Actuals'!P77 -> 0 | G32: =F32-E32 -> 0 | H32: =IFERROR(IF(E32=0,"",G32/E32),"" ) | I32: ='Variance Analysis'!X5
A33: 2 | B33: ='Initiative Register'!B6 | C33: ='Initiative Register'!C6 -> 0 | D33: ='Initiative Register'!R6 -> 0 | E33: ='Cost Plan'!P6 -> 0 | F33: ='Monthly Actuals'!P78 -> 0 | G33: =F33-E33 -> 0 | H33: =IFERROR(IF(E33=0,"",G33/E33),"" ) | I33: ='Variance Analysis'!X6
A34: 3 | B34: ='Initiative Register'!B7 -> INI-003 | C34: ='Initiative Register'!C7 -> Geriatric ward | D34: ='Initiative Register'!R7 -> Not Started | E34: ='Cost Plan'!P7 -> 0 | F34: ='Monthly Actuals'!P79 -> 0 | G34: =F34-E34 -> 0 | H34: =IFERROR(IF(E34=0,"",G34/E34),"" ) | I34: ='Variance Analysis'!X7
A35: 4 | B35: ='Initiative Register'!B8 -> INI-004 | C35: ='Initiative Register'!C8 -> Appointment of Specialized Doctors and development of existing department | D35: ='Initiative Register'!R8 -> Not Started | E35: ='Cost Plan'!P8 -> 0 | F35: ='Monthly Actuals'!P80 -> 0 | G35: =F35-E35 -> 0 | H35: =IFERROR(IF(E35=0,"",G35/E35),"" ) | I35: ='Variance Analysis'!X8
A36: 5 | B36: ='Initiative Register'!B9 -> INI-005 | C36: ='Initiative Register'!C9 -> Patient companion | D36: ='Initiative Register'!R9 -> Not Started | E36: ='Cost Plan'!P9 -> 0 | F36: ='Monthly Actuals'!P81 -> 0 | G36: =F36-E36 -> 0 | H36: =IFERROR(IF(E36=0,"",G36/E36),"" ) | I36: ='Variance Analysis'!X9
A37: 6 | B37: ='Initiative Register'!B10 -> INI-006 | C37: ='Initiative Register'!C10 -> Newborn Care Enhancement | D37: ='Initiative Register'!R10 -> Not Started | E37: ='Cost Plan'!P10 -> 0 | F37: ='Monthly Actuals'!P82 -> 0 | G37: =F37-E37 -> 0 | H37: =IFERROR(IF(E37=0,"",G37/E37),"" ) | I37: ='Variance Analysis'!X10
A38: 7 | B38: ='Initiative Register'!B11 -> INI-007 | C38: ='Initiative Register'!C11 -> Digital Patient Acquisition Funnel | D38: ='Initiative Register'!R11 -> Not Started | E38: ='Cost Plan'!P11 -> 0 | F38: ='Monthly Actuals'!P83 -> 0 | G38: =F38-E38 -> 0 | H38: =IFERROR(IF(E38=0,"",G38/E38),"" ) | I38: ='Variance Analysis'!X11
A39: 8 | B39: ='Initiative Register'!B12 -> INI-008 | C39: ='Initiative Register'!C12 -> Development of KPI for Doctors | D39: ='Initiative Register'!R12 -> Not Started | E39: ='Cost Plan'!P12 -> 0 | F39: ='Monthly Actuals'!P84 -> 0 | G39: =F39-E39 -> 0 | H39: =IFERROR(IF(E39=0,"",G39/E39),"" ) | I39: ='Variance Analysis'!X12
A40: 9 | B40: ='Initiative Register'!B13 -> INI-009 | C40: ='Initiative Register'!C13 -> Daycare and Minimaly Invasive Shift | D40: ='Initiative Register'!R13 -> Not Started | E40: ='Cost Plan'!P13 -> 0 | F40: ='Monthly Actuals'!P85 -> 0 | G40: =F40-E40 -> 0 | H40: =IFERROR(IF(E40=0,"",G40/E40),"" ) | I40: ='Variance Analysis'!X13
A41: 10 | B41: ='Initiative Register'!B14 -> INI-010 | C41: ='Initiative Register'!C14 -> Consumables standardization model | D41: ='Initiative Register'!R14 -> Not Started | E41: ='Cost Plan'!P14 -> 0 | F41: ='Monthly Actuals'!P86 -> 0 | G41: =F41-E41 -> 0 | H41: =IFERROR(IF(E41=0,"",G41/E41),"" ) | I41: ='Variance Analysis'!X14
A42: 11 | B42: ='Initiative Register'!B15 -> INI-011 | C42: ='Initiative Register'!C15 -> Collaboration with other Hospitals | D42: ='Initiative Register'!R15 -> Not Started | E42: ='Cost Plan'!P15 -> 0 | F42: ='Monthly Actuals'!P87 -> 0 | G42: =F42-E42 -> 0 | H42: =IFERROR(IF(E42=0,"",G42/E42),"" ) | I42: ='Variance Analysis'!X15
A43: 12 | B43: ='Initiative Register'!B16 -> INI-012 | C43: ='Initiative Register'!C16 -> ANNUAL RATE REVISION POLICY | D43: ='Initiative Register'!R16 -> Not Started | E43: ='Cost Plan'!P16 -> 0 | F43: ='Monthly Actuals'!P88 -> 0 | G43: =F43-E43 -> 0 | H43: =IFERROR(IF(E43=0,"",G43/E43),"" ) | I43: ='Variance Analysis'!X16
... A51: 20 | B51: ='Initiative Register'!B24 -> INI-020 | C51: ='Initiative Register'!C24 -> CME AND CLINICAL CONNECT PROGRAMME | D51: ='Initiative Register'!R24 -> Not Started | E51: ='Cost Plan'!P24 -> 0 | F51: ='Monthly Actuals'!P96 -> 0 | G51: =F51-E51 -> 0 | H51: =IFERROR(IF(E51=0,"",G51/E51),"" ) | I51: ='Variance Analysis'!X24

Sheet Initiative Register
A1: AOP INITIATIVE REGISTER — FY 2026-27
A3: IDENTIFICATION | C3: DESCRIPTION | F3: OWNERSHIP | H3: TIMELINE | K3: COST | M3: SUCCESS CRITERIA | O3: FINANCIAL IMPACT | Q3: STATUS | S3: REMARKS
A4: # | B4: Initiative ID | C4: Initiative Name | D4: Function / Dept | E4: Description / Objective | F4: Owner | G4: Designation | H4: Start Month | I4: End Month | J4: Duration (Mths) | K4: Cost Type | L4: Est. Cost (Rs Lkh) | M4: KRA | N4: KPI / Metric | O4: Est. Revenue Impact (Rs Lkh) | P4: Benefit Month | Q4: Priority | R4: Status | S4: Remarks / Dependencies
A5: 1 | B5: =IF(C5<>"","INI-"&TEXT(A5,"000"),"") -> INI-001 | C5: Campaign- Patient experience improvement | D5: Marketing | E5: To enhance overall patient satisfaction by collecting structured feedback, identifying service gaps, and implementing improvement initiatives across departments. | F5: Marketing Head | G5: Manager – Marketing | H5: Mar | I5: Mar | J5: =IFERROR(IF(AND(H5<>"",I5<>""),MATCH(I5,{"Apr","May","Jun","Jul","Aug","Sep","Oct","Nov","Dec","Jan","Feb","Mar"},0)-MATCH(H5,{"Apr","May","Jun","Jul","Aug","Sep","Oct","Nov","Dec","Jan","Feb","Mar"},0)+1,""),"" ) -> 1 | L5: 0 | O5: 0 | R5: Completed | S5: No direct financial implication points | T5: final report to receive
A6: =+A5+1 -> 2 | B6: =IF(C6<>"","INI-"&TEXT(A6,"000"),"")
A7: =+A6+1 -> 3 | B7: =IF(C7<>"","INI-"&TEXT(A7,"000"),"") -> INI-003 | C7: Geriatric ward | D7: HR & Admin | E7: To establish and operationalize a dedicated geriatric care unit aimed at improving clinical outcomes, patient comfort, and specialized services for elderly patients. | F7: Admin Head | G7: Manager – HR & Administration | J7: =IFERROR(IF(AND(H7<>"",I7<>""),MATCH(I7,{"Apr","May","Jun","Jul","Aug","Sep","Oct","Nov","Dec","Jan","Feb","Mar"},0)-MATCH(H7,{"Apr","May","Jun","Jul","Aug","Sep","Oct","Nov","Dec","Jan","Feb","Mar"},0)+1,""),"" ) | R7: Not Started | S7: Set up a meeting with Kancare a senior care startup (SVP suggestion)
A8: =+A7+1 -> 4 | B8: =IF(C8<>"","INI-"&TEXT(A8,"000"),"") -> INI-004 | C8: Appointment of Specialized Doctors and development of existing department | D8: HR & Admin | E8: To strengthen clinical capabilities by onboarding specialized doctors and enhancing existing departments to improve service quality and increase patient inflow. | F8: Medical Director | G8: Head – Clinical Services | J8: =IFERROR(IF(AND(H8<>"",I8<>""),MATCH(I8,{"Apr","May","Jun","Jul","Aug","Sep","Oct","Nov","Dec","Jan","Feb","Mar"},0)-MATCH(H8,{"Apr","May","Jun","Jul","Aug","Sep","Oct","Nov","Dec","Jan","Feb","Mar"},0)+1,""),"" ) | R8: Not Started
A9: =+A8+1 -> 5 | B9: =IF(C9<>"","INI-"&TEXT(A9,"000"),"") -> INI-005 | C9: Patient companion | D9: HR & Admin | E9: To enhance patient experience and continuity of care by providing dedicated patient companions to assist throughout the hospital journey, including admission, in-hospital support, discharge coordination, and periodic follow-up, thereby improving patient satisfaction and retention. | F9: HR Head | G9: Manager | J9: =IFERROR(IF(AND(H9<>"",I9<>""),MATCH(I9,{"Apr","May","Jun","Jul","Aug","Sep","Oct","Nov","Dec","Jan","Feb","Mar"},0)-MATCH(H9,{"Apr","May","Jun","Jul","Aug","Sep","Oct","Nov","Dec","Jan","Feb","Mar"},0)+1,""),"" ) | R9: Not Started | S9: Set up a meeting with Healtheease a Health Startup (SVP suggestion)
A10: =+A9+1 -> 6 | B10: =IF(C10<>"","INI-"&TEXT(A10,"000"),"") -> INI-006 | C10: Newborn Care Enhancement | D10: Operations | E10: To enhance maternal and neonatal care services by providing comprehensive post-delivery support, including newborn care, mother care, lactation guidance, and structured follow-up programs, thereby improving clinical outcomes and patient satisfaction. | F10: Operations Head | G10: Manager – Operations / Head – Nursing | J10: =IFERROR(IF(AND(H10<>"",I10<>""),MATCH(I10,{"Apr","May","Jun","Jul","Aug","Sep","Oct","Nov","Dec","Jan","Feb","Mar"},0)-MATCH(H10,{"Apr","May","Jun","Jul","Aug","Sep","Oct","Nov","Dec","Jan","Feb","Mar"},0)+1,""),"" ) | R10: Not Started
A11: =+A10+1 -> 7 | B11: =IF(C11<>"","INI-"&TEXT(A11,"000"),"") -> INI-007 | C11: Digital Patient Acquisition Funnel | D11: Business Development | E11: To strengthen digital patient acquisition by leveraging teleconsultation, digital marketing channels, and conversion optimization strategies to increase OP footfall and IP admissions. | F11: Business Development Head | G11: Manager – Business Development | H11: May | I11: Mar | J11: =IFERROR(IF(AND(H11<>"",I11<>""),MATCH(I11,{"Apr","May","Jun","Jul","Aug","Sep","Oct","Nov","Dec","Jan","Feb","Mar"},0)-MATCH(H11,{"Apr","May","Jun","Jul","Aug","Sep","Oct","Nov","Dec","Jan","Feb","Mar"},0)+1,""),"" ) -> 11 | O11: 0 | R11: Not Started
A12: =+A11+1 -> 8 | B12: =IF(C12<>"","INI-"&TEXT(A12,"000"),"") -> INI-008 | C12: Development of KPI for Doctors | D12: HR & Admin | E12: To establish a structured performance management framework for doctors by defining key performance indicators (KPIs) aligned with revenue, clinical outcomes, and patient engagement. | F12: HR Head | G12: Manager – HR | J12: =IFERROR(IF(AND(H12<>"",I12<>""),MATCH(I12,{"Apr","May","Jun","Jul","Aug","Sep","Oct","Nov","Dec","Jan","Feb","Mar"},0)-MATCH(H12,{"Apr","May","Jun","Jul","Aug","Sep","Oct","Nov","Dec","Jan","Feb","Mar"},0)+1,""),"" ) | R12: Not Started
A13: =+A12+1 -> 9 | B13: =IF(C13<>"","INI-"&TEXT(A13,"000"),"") -> INI-009 | C13: Daycare and Minimaly Invasive Shift | D13: Operations | E13: To improve operational efficiency and reduce average length of stay (ALOS) by promoting daycare procedures and minimally invasive surgical techniques. | F13: Operations Head | G13: Manager – Operations | J13: =IFERROR(IF(AND(H13<>"",I13<>""),MATCH(I13,{"Apr","May","Jun","Jul","Aug","Sep","Oct","Nov","Dec","Jan","Feb","Mar"},0)-MATCH(H13,{"Apr","May","Jun","Jul","Aug","Sep","Oct","Nov","Dec","Jan","Feb","Mar"},0)+1,""),"" ) | R13: Not Started
A14: =+A13+1 -> 10 | B14: =IF(C14<>"","INI-"&TEXT(A14,"000"),"") -> INI-010 | C14: Consumables standardization model | D14: Supply Chain / Purchase | E14: To optimize cost efficiency by standardizing consumable usage through procedure-wise bundling and reducing wastage across departments. | F14: Purchase Head | G14: Manager – Supply Chain | J14: =IFERROR(IF(AND(H14<>"",I14<>""),MATCH(I14,{"Apr","May","Jun","Jul","Aug","Sep","Oct","Nov","Dec","Jan","Feb","Mar"},0)-MATCH(H14,{"Apr","May","Jun","Jul","Aug","Sep","Oct","Nov","Dec","Jan","Feb","Mar"},0)+1,""),"" ) | R14: Not Started
A15: =+A14+1 -> 11 | B15: =IF(C15<>"","INI-"&TEXT(A15,"000"),"") -> INI-011 | C15: Collaboration with other Hospitals | D15: Business Development | E15: To expand patient inflow and service capabilities through strategic partnerships and referral networks with other hospitals and specialty centers. | F15: Business Development Head | G15: Manager – Business Development | J15: =IFERROR(IF(AND(H15<>"",I15<>""),MATCH(I15,{"Apr","May","Jun","Jul","Aug","Sep","Oct","Nov","Dec","Jan","Feb","Mar"},0)-MATCH(H15,{"Apr","May","Jun","Jul","Aug","Sep","Oct","Nov","Dec","Jan","Feb","Mar"},0)+1,""),"" ) | R15: Not Started
A16: =+A15+1 -> 12 | B16: =IF(C16<>"","INI-"&TEXT(A16,"000"),"") -> INI-012 | C16: ANNUAL RATE REVISION POLICY | D16: Finance | E16: Institutionalise a pricing committee meeting every April. Revise all IP rates (room, procedures, OT charges, nursing, clinical charges) by CPI+2% for cash patients. Simultaneously renegotiate TPA/insurance tariffs annually. Prevents multi-year price stagnation — the single biggest structural margin leak in private hospitals. | F16: Finance Head | G16: CFO + CEO | H16: May | I16: May | J16: =IFERROR(IF(AND(H16<>"",I16<>""),MATCH(I16,{"Apr","May","Jun","Jul","Aug","Sep","Oct","Nov","Dec","Jan","Feb","Mar"},0)-MATCH(H16,{"Apr","May","Jun","Jul","Aug","Sep","Oct","Nov","Dec","Jan","Feb","Mar"},0)+1,""),"" ) -> 1 | L16: 0 | O16: 634.84 | P16: May | Q16: High | R16: Not Started | S16: Revenue impact starts from May 2026 onwards- Only the annual impact shown.
A17: =+A16+1 -> 13 | B17: =IF(C17<>"","INI-"&TEXT(A17,"000"),"") -> INI-013 | C17: PROCEDURE CONTRIBUTION AUDIT AND REPRICING | D17: Finance | E17: Cost out the top 50 procedures by revenue value. For 26% EBITDA, procedure-level contribution must average 58%. Identify all procedures where contribution is below 50%. Revise cash rates. Flag TPA tariff renegotiation list separately. | F17: Finance Head | G17: CFO + Medical Director | H17: May | I17: Jun | J17: =IFERROR(IF(AND(H17<>"",I17<>""),MATCH(I17,{"Apr","May","Jun","Jul","Aug","Sep","Oct","Nov","Dec","Jan","Feb","Mar"},0)-MATCH(H17,{"Apr","May","Jun","Jul","Aug","Sep","Oct","Nov","Dec","Jan","Feb","Mar"},0)+1,""),"" ) -> 2 | L17: 0 | O17: 9.35 | P17: Jun | Q17: High | R17: Not Started
A18: =+A17+1 -> 14 | B18: =IF(C18<>"","INI-"&TEXT(A18,"000"),"") -> INI-014 | C18: INSURANCE CHARGE CAPTURE — BILL WHAT IS COVERED | D18: Finance | E18: Audit current insurance bills against TPA tariff schedules. Multiple line items (nursing charges, monitoring, clinical charges, physiotherapy, ICU-specific charges) are covered under TPA tariffs but not systematically raised in bills. Fix charge master. Immediate revenue recovery with no new service needed. | F18: Accounts Head | G18: Billing Head | H18: May | I18: May | J18: =IFERROR(IF(AND(H18<>"",I18<>""),MATCH(I18,{"Apr","May","Jun","Jul","Aug","Sep","Oct","Nov","Dec","Jan","Feb","Mar"},0)-MATCH(H18,{"Apr","May","Jun","Jul","Aug","Sep","Oct","Nov","Dec","Jan","Feb","Mar"},0)+1,""),"" ) -> 1 | L18: 0 | R18: Not Started | S18: Detailes pending | T18: TPA agreements list
A19: =+A18+1 -> 15 | B19: =IF(C19<>"","INI-"&TEXT(A19,"000"),"") -> INI-015 | C19: SATELLITE CLINIC NETWORK — SURGEON-LED OFF-CAMPUS OPDs | D19: Business Development | E19: Deploy 6–8 surgeons to run weekly OPD clinics in suburban and district locations (Aluva, Angamaly, Muvattupuzha, Thrippunithura, Kakkanad, Thrissur). Hospital provides space, admin, and branding. Surgeon does one day per week off-campus. Consults convert to admissions at main campus. | F19: Operations Head | G19: COO | H19: May | I19: Oct | J19: =IFERROR(IF(AND(H19<>"",I19<>""),MATCH(I19,{"Apr","May","Jun","Jul","Aug","Sep","Oct","Nov","Dec","Jan","Feb","Mar"},0)-MATCH(H19,{"Apr","May","Jun","Jul","Aug","Sep","Oct","Nov","Dec","Jan","Feb","Mar"},0)+1,""),"" ) -> 6 | O19: 4320 | Q19: High | R19: Not Started | S19: List of surgical doctors prepared, management to speak to these doctors
A20: =+A19+1 -> 16 | B20: =IF(C20<>"","INI-"&TEXT(A20,"000"),"") -> INI-016 | C20: CORPORATE HEALTH PROGRAMME | D20: Business Development | E20: Approach top 50 corporates in Kochi (Infopark, Smartcity, BPCL, Cochin Port, FACT, Kochi Metro, KSEB, major hotel chains) for tiered employee health packages: annual health check + OPD benefit + preferential IP rates. Assign dedicated corporate relationship managers. Volume is captive and predictable. | F20: Finance Head | G20: Business Development Head | H20: May | I20: Aug | J20: =IFERROR(IF(AND(H20<>"",I20<>""),MATCH(I20,{"Apr","May","Jun","Jul","Aug","Sep","Oct","Nov","Dec","Jan","Feb","Mar"},0)-MATCH(H20,{"Apr","May","Jun","Jul","Aug","Sep","Oct","Nov","Dec","Jan","Feb","Mar"},0)+1,""),"" ) -> 4 | O20: 354.52 | P20: Aug | Q20: High | R20: Not Started | S20: List of corporate received, grouping has to be done
A21: =+A20+1 -> 17 | B21: =IF(C21<>"","INI-"&TEXT(A21,"000"),"") -> INI-017 | C21: RESIDENTIAL COLONY AND COMMUNITY HEALTH PROGRAMMES | D21: Business Development | E21: Partner with major gated communities and apartment complexes in Kochi (Sobha, Prestige, Purva in Kakkanad, Edapally, Thrippunithura) for on-site health camps, resident doctor visits, and emergency response agreements. Low acquisition cost. Drives OPD footfall and diagnostics. | F21: Operations Head | G21: Marketing Head | H21: May | I21: Jul | J21: =IFERROR(IF(AND(H21<>"",I21<>""),MATCH(I21,{"Apr","May","Jun","Jul","Aug","Sep","Oct","Nov","Dec","Jan","Feb","Mar"},0)-MATCH(H21,{"Apr","May","Jun","Jul","Aug","Sep","Oct","Nov","Dec","Jan","Feb","Mar"},0)+1,""),"" ) -> 3 | O21: 0 | P21: May | Q21: High | R21: Not Started | S21: General measure already covered in campaign programme
A22: =+A21+1 -> 18 | B22: =IF(C22<>"","INI-"&TEXT(A22,"000"),"") -> INI-018 | C22: INTERNATIONAL MEDICAL VALUE TOURISM — GULF, MALDIVES, BANGLADESH | D22: Business Development | E22: Kochi airport has direct flights to 12+ Middle East cities. Lakeshore is already on the Kerala Medical Value Travel Society registry and has multilingual (Arabic, Hindi, English, Malayalam) staff and international patient services. Formalise MVT as a growth vertical: empanel with aggregators, assign dedicated MVT coordinator, develop Arabic-language digital content. | F22: Strategy Head | G22: Business Development Head | H22: May | I22: Oct | J22: =IFERROR(IF(AND(H22<>"",I22<>""),MATCH(I22,{"Apr","May","Jun","Jul","Aug","Sep","Oct","Nov","Dec","Jan","Feb","Mar"},0)-MATCH(H22,{"Apr","May","Jun","Jul","Aug","Sep","Oct","Nov","Dec","Jan","Feb","Mar"},0)+1,""),"" ) -> 6 | O22: 614.82 | P22: Oct | Q22: High | R22: Not Started
A23: =+A22+1 -> 19 | B23: =IF(C23<>"","INI-"&TEXT(A23,"000"),"") -> INI-019 | C23: STRUCTURED REFERRAL DOCTOR PROGRAMME | D23: Business Development | E23: Map all referring doctors within 50km by specialty and volume. Classify as A/B/C tiers. Assign BD field executives to A-tier (top 100 referrers) with monthly visit cadence. Implement 24-hour discharge summary SOP as a non-negotiable feedback loop for referrers. Track referral volume monthly by doctor. | F23: Finance Head | G23: Business Development Head | H23: May | I23: Aug | J23: =IFERROR(IF(AND(H23<>"",I23<>""),MATCH(I23,{"Apr","May","Jun","Jul","Aug","Sep","Oct","Nov","Dec","Jan","Feb","Mar"},0)-MATCH(H23,{"Apr","May","Jun","Jul","Aug","Sep","Oct","Nov","Dec","Jan","Feb","Mar"},0)+1,""),"" ) -> 4 | Q23: Medium | R23: Not Started | S23: Data collected from website
A24: =+A23+1 -> 20 | B24: =IF(C24<>"","INI-"&TEXT(A24,"000"),"") -> INI-020 | C24: CME AND CLINICAL CONNECT PROGRAMME | D24: Business Development | E24: Run monthly CMEs for referring doctors — specialty-specific, with Lakeshore faculty. Rotate across suburban and district locations (Thrissur, Kottayam, Alappuzha, Ernakulam suburbs). Build a registered community of 500+ referring doctors. CMEs generate clinical credibility and direct referral uplift. | F24: Finance Head | G24: Marketing Head | H24: May | I24: Jun | J24: =IFERROR(IF(AND(H24<>"",I24<>""),MATCH(I24,{"Apr","May","Jun","Jul","Aug","Sep","Oct","Nov","Dec","Jan","Feb","Mar"},0)-MATCH(H24,{"Apr","May","Jun","Jul","Aug","Sep","Oct","Nov","Dec","Jan","Feb","Mar"},0)+1,""),"" ) -> 2 | Q24: Medium | R24: Not Started | S24: CME has to be conducted
A25: =+A24+1 -> 21 | B25: =IF(C25<>"","INI-"&TEXT(A25,"000"),"") -> INI-021 | C25: GOVERNMENT SCHEME EMPANELMENT OPTIMISATION | D25: Finance | E25: Review PMJAY, KASP, CGHS, ECHS, and ESI empanelments. Ensure all eligible procedures — including complex ones like transplant components, cardiac interventions, cancer treatments — are listed. Renegotiate rates for high-volume procedures. At current occupancy levels, scheme patients fill beds that would otherwise be vacant. | F25: Finance Head | G25: Finance Head | H25: May | I25: Jul | J25: =IFERROR(IF(AND(H25<>"",I25<>""),MATCH(I25,{"Apr","May","Jun","Jul","Aug","Sep","Oct","Nov","Dec","Jan","Feb","Mar"},0)-MATCH(H25,{"Apr","May","Jun","Jul","Aug","Sep","Oct","Nov","Dec","Jan","Feb","Mar"},0)+1,""),"" ) -> 3 | O25: 108.39 | P25: Jul | Q25: Medium | R25: Not Started
A26: =+A25+1 -> 22 | B26: =IF(C26<>"","INI-"&TEXT(A26,"000"),"") -> INI-022 | C26: TRANSPLANT CENTRE — VOLUME GROWTH AND DONOR PROGRAMME ACTIVATION | D26: Operations | E26: Multi-organ transplant (liver, kidney, pancreas, combined) is Lakeshore's signature clinical programme. Levers: increase deceased donor programme activity, expand living donor evaluation capacity, grow pre- and post-transplant outpatient care, develop dedicated transplant coordinator network. | F26: Operations Head | G26: COO + CEO | H26: May | I26: Jan | J26: =IFERROR(IF(AND(H26<>"",I26<>""),MATCH(I26,{"Apr","May","Jun","Jul","Aug","Sep","Oct","Nov","Dec","Jan","Feb","Mar"},0)-MATCH(H26,{"Apr","May","Jun","Jul","Aug","Sep","Oct","Nov","Dec","Jan","Feb","Mar"},0)+1,""),"" ) -> 9 | O26: 0 | P26: May | Q26: High | R26: Not Started
A27: =+A26+1 -> 23 | B27: =IF(C27<>"","INI-"&TEXT(A27,"000"),"") -> INI-023 | C27: CARDIAC SCIENCES — STRUCTURAL HEART AND ELECTROPHYSIOLOGY VOLUME BUILD | D27: Marketing | E27: Lakeshore is recognised for comprehensive cardiac care including interventional cardiology, paediatric cardiology, electrophysiology, structural heart disease, CABG, and LVAD implantation. Growth levers: increase EP lab utilisation, develop structural heart disease programme (TAVR, MitraClip), grow paediatric cardiac surgical volume. | F27: Operations Head | G27: COO + CEO | H27: May | I27: Oct | J27: =IFERROR(IF(AND(H27<>"",I27<>""),MATCH(I27,{"Apr","May","Jun","Jul","Aug","Sep","Oct","Nov","Dec","Jan","Feb","Mar"},0)-MATCH(H27,{"Apr","May","Jun","Jul","Aug","Sep","Oct","Nov","Dec","Jan","Feb","Mar"},0)+1,""),"" ) -> 6 | R27: Not Started
A28: =+A27+1 -> 24 | B28: =IF(C28<>"","INI-"&TEXT(A28,"000"),"") -> INI-024 | C28: ONCOLOGY — EARLY DETECTION, SATELLITE CLINICS AND SURGICAL VOLUME GROWTH | D28: Business Development | E28: Build a hub-and-spoke oncology model. Hub: Lakeshore for radiation oncology and complex cancer surgery. Spokes: satellite oncology clinics embedded within partner general hospitals and diagnostic centres across Kerala. Spokes drive early detection (oral, breast, cervical, colorectal screening) and funnel diagnosed cases to Lakeshore for surgery and radiation. Chemotherapy delivery at partner sites where appropriate. | F28: Operations Head | G28: COO + CEO | H28: May | I28: Jan | J28: =IFERROR(IF(AND(H28<>"",I28<>""),MATCH(I28,{"Apr","May","Jun","Jul","Aug","Sep","Oct","Nov","Dec","Jan","Feb","Mar"},0)-MATCH(H28,{"Apr","May","Jun","Jul","Aug","Sep","Oct","Nov","Dec","Jan","Feb","Mar"},0)+1,""),"" ) -> 9 | O28: 2126.88 | P28: Feb | Q28: High | R28: Not Started
A29: =+A28+1 -> 25 | B29: =IF(C29<>"","INI-"&TEXT(A29,"000"),"") -> INI-025 | C29: ORTHOPAEDICS AND JOINT REPLACEMENT — VOLUME AND PACKAGE PROGRAMME | D29: Business Development | E29: Lakeshore has India's first digitally integrated orthopaedic OT with guided airflow. Performed first bilateral total hip replacement using ceramic head with metal liner in Asia. Growth levers: fixed-price joint replacement packages, sports medicine programme, fracture care and trauma protocols, robotic-assisted joint replacement. | F29: Operations Head | G29: COO + CEO | H29: May | I29: Aug | J29: =IFERROR(IF(AND(H29<>"",I29<>""),MATCH(I29,{"Apr","May","Jun","Jul","Aug","Sep","Oct","Nov","Dec","Jan","Feb","Mar"},0)-MATCH(H29,{"Apr","May","Jun","Jul","Aug","Sep","Oct","Nov","Dec","Jan","Feb","Mar"},0)+1,""),"" ) -> 4 | O29: 1284.97 | Q29: High | R29: Not Started
A30: =+A29+1 -> 26 | B30: =IF(C30<>"","INI-"&TEXT(A30,"000"),"") -> INI-026 | C30: LAKESHORE HEART RUN — ANNUAL CARDIAC HEALTH EVENT | D30: Business Development | E30: Organise annual half-marathon or 10K run branded around cardiac health awareness. 3,000–5,000 participants. Entry fee plus sponsorship covers cost. Generates: brand visibility, cardiac health screenings at event (ECG, BP, lipid), OPD follow-ups, cardiologist consultations, and media coverage. | F30: Strategy Head | G30: Business Development Head | H30: Sep | I30: Sep | J30: =IFERROR(IF(AND(H30<>"",I30<>""),MATCH(I30,{"Apr","May","Jun","Jul","Aug","Sep","Oct","Nov","Dec","Jan","Feb","Mar"},0)-MATCH(H30,{"Apr","May","Jun","Jul","Aug","Sep","Oct","Nov","Dec","Jan","Feb","Mar"},0)+1,""),"" ) -> 1 | K30: Opex - One Time | R30: Not Started
A31: =+A30+1 -> 27 | B31: =IF(C31<>"","INI-"&TEXT(A31,"000"),"") -> INI-027 | C31: PREVENTIVE HEALTH + LIVER SCREENING CAMPAIGN | D31: Business Development | E31: Promote preventive healthcare during World Health Day through full body checkups, LFT packages, and fatty liver screening to increase early diagnosis and package conversions.April 19th Liver Day | F31: Marketing Head | G31: Business Development Head | H31: Apr | I31: Apr | J31: =IFERROR(IF(AND(H31<>"",I31<>""),MATCH(I31,{"Apr","May","Jun","Jul","Aug","Sep","Oct","Nov","Dec","Jan","Feb","Mar"},0)-MATCH(H31,{"Apr","May","Jun","Jul","Aug","Sep","Oct","Nov","Dec","Jan","Feb","Mar"},0)+1,""),"" ) -> 1 | K31: Opex - One Time | L31: 1.12 | O31: 34.25 | P31: Apr | Q31: High | R31: Not Started
A32: =+A31+1 -> 28 | B32: =IF(C32<>"","INI-"&TEXT(A32,"000"),"") -> INI-028 | C32: DIGITAL CONTENT PLATFORM — MALAYALAM AND ENGLISH | D32: Business Development | E32: Build a sustained health content library across specialties: YouTube, Facebook, Instagram, hospital website. Procedure explainers, doctor Q&As, patient testimonials, disease awareness. Prioritise Lakeshore's clinical differentiators: transplant journeys, cardiac interventions, robotic surgery, cancer care. Malayalam is significantly underserved on health content platforms. | F32: Strategy Head | G32: Business Development Head | H32: Apr | I32: Jun | J32: =IFERROR(IF(AND(H32<>"",I32<>""),MATCH(I32,{"Apr","May","Jun","Jul","Aug","Sep","Oct","Nov","Dec","Jan","Feb","Mar"},0)-MATCH(H32,{"Apr","May","Jun","Jul","Aug","Sep","Oct","Nov","Dec","Jan","Feb","Mar"},0)+1,""),"" ) -> 3 | K32: Opex - Recurring Monthly | O32: 0 | Q32: High | R32: Not Started
A33: =+A32+1 -> 29 | B33: =IF(C33<>"","INI-"&TEXT(A33,"000"),"") -> INI-029 | C33: COMMUNITY HEALTH CAMPS — SCHOOLS, PLACES OF WORSHIP, RESIDENTIAL AREAS | D33: Business Development | E33: Run monthly health awareness programmes in schools (adolescent health, vision, nutrition), temples and mosques (senior citizen camps during festivals, post-Ramadan diabetes and cardiac screening), and residential complexes. Low cost. High community trust. Converts to OPD footfall. | F33: Strategy Head | G33: Business Development Head | H33: May | I33: Jun | J33: =IFERROR(IF(AND(H33<>"",I33<>""),MATCH(I33,{"Apr","May","Jun","Jul","Aug","Sep","Oct","Nov","Dec","Jan","Feb","Mar"},0)-MATCH(H33,{"Apr","May","Jun","Jul","Aug","Sep","Oct","Nov","Dec","Jan","Feb","Mar"},0)+1,""),"" ) -> 2 | R33: Not Started | T33: get the list
A34: =+A33+1 -> 30 | B34: =IF(C34<>"","INI-"&TEXT(A34,"000"),"") -> INI-030 | C34: DOCTOR ONLINE REPUTATION AND DIGITAL DISCOVERABILITY | D34: Marketing | E34: Ensure all senior consultants have optimised Google Business profiles, Practo and Doctorundi listings, and detailed hospital website profiles with specialisation, publications, clinical firsts, and patient reviews. Over 60% of new OP patients in urban Kerala search online before choosing a doctor. | F34: Strategy Head | G34: Business Development Head | H34: May | I34: May | J34: =IFERROR(IF(AND(H34<>"",I34<>""),MATCH(I34,{"Apr","May","Jun","Jul","Aug","Sep","Oct","Nov","Dec","Jan","Feb","Mar"},0)-MATCH(H34,{"Apr","May","Jun","Jul","Aug","Sep","Oct","Nov","Dec","Jan","Feb","Mar"},0)+1,""),"" ) -> 1 | R34: Not Started | S34: social media capacity building and give a startegy
A35: =+A34+1 -> 31 | B35: =IF(C35<>"","INI-"&TEXT(A35,"000"),"") -> INI-031 | C35: TPA AND INSURER TARIFF RENEGOTIATION | D35: Finance | E35: Formal annual tariff revision with all empanelled TPAs and insurers. Most hospital-insurer agreements have not been revised in 2–3 years while costs have risen 12–15%. Engage each TPA separately. Leverage volume and case complexity data. Target: 8–12% rate improvement. | F35: Finance Head | G35: CFO | H35: May | I35: Jul | J35: =IFERROR(IF(AND(H35<>"",I35<>""),MATCH(I35,{"Apr","May","Jun","Jul","Aug","Sep","Oct","Nov","Dec","Jan","Feb","Mar"},0)-MATCH(H35,{"Apr","May","Jun","Jul","Aug","Sep","Oct","Nov","Dec","Jan","Feb","Mar"},0)+1,""),"" ) -> 3 | R35: Not Started | S35: As informed by the croproate manager, many are at cash rate itself.
A36: =+A35+1 -> 32 | B36: =IF(C36<>"","INI-"&TEXT(A36,"000"),"") -> INI-032 | C36: FINANCIAL COUNSELLING AND PRE-AUTHORISATION AT SURGICAL OPD | D36: Operations | E36: Deploy trained financial counsellors at surgical OPD (orthopaedics, cardiac, neurosurgery, oncology, transplant). Role: explain package costs, initiate insurance pre-auth on day of consultation, arrange EMI/loan tie-ups for self-pay patients. Converts deferred decisions to same-week admissions. | F36: Finance Head | G36: CFO | H36: May | I36: Jun | J36: =IFERROR(IF(AND(H36<>"",I36<>""),MATCH(I36,{"Apr","May","Jun","Jul","Aug","Sep","Oct","Nov","Dec","Jan","Feb","Mar"},0)-MATCH(H36,{"Apr","May","Jun","Jul","Aug","Sep","Oct","Nov","Dec","Jan","Feb","Mar"},0)+1,""),"" ) -> 2 | R36: Not Started | S36: Currently we have financial counsellors who look into all IP | T36: How many additional finance councellors would be required?
A37: =+A36+1 -> 33 | B37: =IF(C37<>"","INI-"&TEXT(A37,"000"),"") -> INI-033 | C37: BUILD A SCALED BD ORGANISATION | D37: Business Development | E37: Expand from the current referral-focused BD team to a 27-person full-spectrum function covering: referral development across 3 zones (North, Central, South Kerala); institutional and partnerships (corporate accounts, MVT, satellite clinics, CME); and communications and branding (Arogyam digital platform, PR). Structured under BD Head (Rosh Mohan) reporting to CEO. | F37: Strategy Head | G37: Business Development Head | H37: Apr | I37: Dec | J37: =IFERROR(IF(AND(H37<>"",I37<>""),MATCH(I37,{"Apr","May","Jun","Jul","Aug","Sep","Oct","Nov","Dec","Jan","Feb","Mar"},0)-MATCH(H37,{"Apr","May","Jun","Jul","Aug","Sep","Oct","Nov","Dec","Jan","Feb","Mar"},0)+1,""),"" ) -> 9 | R37: Not Started
A38: =+A37+1 -> 34 | B38: =IF(C38<>"","INI-"&TEXT(A38,"000"),"") -> INI-034 | C38: MATERIALS / DRUG COST & CONSUMABLES | D38: Supply Chain / Purchase | E38: Replace branded drugs with equivalent generics/lower-cost brands ensuring same clinical outcome; focus on high-value molecules | F38: Medical Director + Pharmacy Head | G38: Pharmacy Head | H38: Apr | I38: Jun | J38: =IFERROR(IF(AND(H38<>"",I38<>""),MATCH(I38,{"Apr","May","Jun","Jul","Aug","Sep","Oct","Nov","Dec","Jan","Feb","Mar"},0)-MATCH(H38,{"Apr","May","Jun","Jul","Aug","Sep","Oct","Nov","Dec","Jan","Feb","Mar"},0)+1,""),"" ) -> 3 | R38: In Progress
A39: =+A38+1 -> 35 | B39: =IF(C39<>"","INI-"&TEXT(A39,"000"),"") -> INI-035 | C39: MATERIALS / DRUG COST & CONSUMABLES | D39: Supply Chain / Purchase | E39: Negotiate higher discounts from manufacturers through volume commitment and MD-level engagement | F39: Purchase Head + MD | G39: Purchase Manager | H39: Apr | I39: May | J39: =IFERROR(IF(AND(H39<>"",I39<>""),MATCH(I39,{"Apr","May","Jun","Jul","Aug","Sep","Oct","Nov","Dec","Jan","Feb","Mar"},0)-MATCH(H39,{"Apr","May","Jun","Jul","Aug","Sep","Oct","Nov","Dec","Jan","Feb","Mar"},0)+1,""),"" ) -> 2 | R39: Not Started
A40: =+A39+1 -> 36 | B40: =IF(C40<>"","INI-"&TEXT(A40,"000"),"") -> INI-036 | C40: MATERIALS / DRUG COST & CONSUMABLES | D40: Supply Chain / Purchase | E40: Reduce distributor base and consolidate procurement to extract volume-linked discounts | F40: Purchase Head | G40: Purchase Manager | H40: Apr | I40: Jun | J40: =IFERROR(IF(AND(H40<>"",I40<>""),MATCH(I40,{"Apr","May","Jun","Jul","Aug","Sep","Oct","Nov","Dec","Jan","Feb","Mar"},0)-MATCH(H40,{"Apr","May","Jun","Jul","Aug","Sep","Oct","Nov","Dec","Jan","Feb","Mar"},0)+1,""),"" ) -> 3 | R40: Not Started
A41: =+A40+1 -> 37 | B41: =IF(C41<>"","INI-"&TEXT(A41,"000"),"") -> INI-037 | C41: MATERIALS / DRUG COST & CONSUMABLES | D41: Supply Chain / Purchase | E41: Implement competitive tendering and rate contracts for high-value consumables replacing spot purchase | F41: Purchase Head + Medical Director | G41: Purchase Manager | H41: May | I41: Aug | J41: =IFERROR(IF(AND(H41<>"",I41<>""),MATCH(I41,{"Apr","May","Jun","Jul","Aug","Sep","Oct","Nov","Dec","Jan","Feb","Mar"},0)-MATCH(H41,{"Apr","May","Jun","Jul","Aug","Sep","Oct","Nov","Dec","Jan","Feb","Mar"},0)+1,""),"" ) -> 4 | R41: Not Started
...

Sheet Monthly Plan
A1: MONTHLY EXECUTION PLAN — Activity Grid (1=Active, 0=Inactive)
A2: Enter 1 in months when the initiative is active. Linked from Initiative Register.
A4: # | B4: Initiative ID | C4: Initiative Name | D4: Apr | E4: May | F4: Jun | G4: Jul | H4: Aug | I4: Sep | J4: Oct | K4: Nov | L4: Dec | M4: Jan | N4: Feb | O4: Mar | P4: Active Months
A5: 1 | B5: ='Initiative Register'!B5 -> INI-001 | C5: ='Initiative Register'!C5 -> Campaign- Patient experience improvement | D5: 0 | E5: 0 | F5: 0 | G5: 0 | H5: 0 | I5: 0 | J5: 0 | K5: 0 | L5: 0 | M5: 0 | N5: 0 | O5: 0 | P5: =SUM(D5:O5) -> 0
A6: 2 | B6: ='Initiative Register'!B6 | C6: ='Initiative Register'!C6 -> 0 | D6: 0 | E6: 0 | F6: 0 | G6: 0 | H6: 0 | I6: 0 | J6: 0 | K6: 0 | L6: 0 | M6: 0 | N6: 0 | O6: 0 | P6: =SUM(D6:O6) -> 0
A7: 3 | B7: ='Initiative Register'!B7 -> INI-003 | C7: ='Initiative Register'!C7 -> Geriatric ward | D7: 0 | E7: 0 | F7: 0 | G7: 0 | H7: 0 | I7: 0 | J7: 0 | K7: 0 | L7: 0 | M7: 0 | N7: 0 | O7: 0 | P7: =SUM(D7:O7) -> 0
A8: 4 | B8: ='Initiative Register'!B8 -> INI-004 | C8: ='Initiative Register'!C8 -> Appointment of Specialized Doctors and development of existing department | D8: 0 | E8: 0 | F8: 0 | G8: 0 | H8: 0 | I8: 0 | J8: 0 | K8: 0 | L8: 0 | M8: 0 | N8: 0 | O8: 0 | P8: =SUM(D8:O8) -> 0
A9: 5 | B9: ='Initiative Register'!B9 -> INI-005 | C9: ='Initiative Register'!C9 -> Patient companion | D9: 0 | E9: 0 | F9: 0 | G9: 0 | H9: 0 | I9: 0 | J9: 0 | K9: 0 | L9: 0 | M9: 0 | N9: 0 | O9: 0 | P9: =SUM(D9:O9) -> 0
A10: 6 | B10: ='Initiative Register'!B10 -> INI-006 | C10: ='Initiative Register'!C10 -> Newborn Care Enhancement | D10: 0 | E10: 0 | F10: 0 | G10: 0 | H10: 0 | I10: 0 | J10: 0 | K10: 0 | L10: 0 | M10: 0 | N10: 0 | O10: 0 | P10: =SUM(D10:O10) -> 0
A11: 7 | B11: ='Initiative Register'!B11 -> INI-007 | C11: ='Initiative Register'!C11 -> Digital Patient Acquisition Funnel | D11: 0 | E11: 0 | F11: 0 | G11: 0 | H11: 0 | I11: 0 | J11: 0 | K11: 0 | L11: 0 | M11: 0 | N11: 0 | O11: 0 | P11: =SUM(D11:O11) -> 0
A12: 8 | B12: ='Initiative Register'!B12 -> INI-008 | C12: ='Initiative Register'!C12 -> Development of KPI for Doctors | D12: 0 | E12: 0 | F12: 0 | G12: 0 | H12: 0 | I12: 0 | J12: 0 | K12: 0 | L12: 0 | M12: 0 | N12: 0 | O12: 0 | P12: =SUM(D12:O12) -> 0
A13: 9 | B13: ='Initiative Register'!B13 -> INI-009 | C13: ='Initiative Register'!C13 -> Daycare and Minimaly Invasive Shift | D13: 0 | E13: 0 | F13: 0 | G13: 0 | H13: 0 | I13: 0 | J13: 0 | K13: 0 | L13: 0 | M13: 0 | N13: 0 | O13: 0 | P13: =SUM(D13:O13) -> 0
A14: 10 | B14: ='Initiative Register'!B14 -> INI-010 | C14: ='Initiative Register'!C14 -> Consumables standardization model | D14: 0 | E14: 0 | F14: 0 | G14: 0 | H14: 0 | I14: 0 | J14: 0 | K14: 0 | L14: 0 | M14: 0 | N14: 0 | O14: 0 | P14: =SUM(D14:O14) -> 0
A15: 11 | B15: ='Initiative Register'!B15 -> INI-011 | C15: ='Initiative Register'!C15 -> Collaboration with other Hospitals | D15: 0 | E15: 0 | F15: 0 | G15: 0 | H15: 0 | I15: 0 | J15: 0 | K15: 0 | L15: 0 | M15: 0 | N15: 0 | O15: 0 | P15: =SUM(D15:O15) -> 0
A16: 12 | B16: ='Initiative Register'!B16 -> INI-012 | C16: ='Initiative Register'!C16 -> ANNUAL RATE REVISION POLICY | D16: 0 | E16: 0 | F16: 0 | G16: 0 | H16: 0 | I16: 0 | J16: 0 | K16: 0 | L16: 0 | M16: 0 | N16: 0 | O16: 0 | P16: =SUM(D16:O16) -> 0
... A30: 26 | B30: ='Initiative Register'!B30 -> INI-026 | C30: ='Initiative Register'!C30 -> LAKESHORE HEART RUN — ANNUAL CARDIAC HEALTH EVENT | D30: 0 | E30: 0 | F30: 0 | G30: 0 | H30: 0 | I30: 0 | J30: 0 | K30: 0 | L30: 0 | M30: 0 | N30: 0 | O30: 0 | P30: =SUM(D30:O30) -> 0
A31: 27 | B31: ='Initiative Register'!B32 -> INI-028 | C31: ='Initiative Register'!C32 -> DIGITAL CONTENT PLATFORM — MALAYALAM AND ENGLISH | D31: 0 | E31: 0 | F31: 0 | G31: 0 | H31: 0 | I31: 0 | J31: 0 | K31: 0 | L31: 0 | M31: 0 | N31: 0 | O31: 0 | P31: =SUM(D31:O31) -> 0
A32: 28 | B32: ='Initiative Register'!B33 -> INI-029 | C32: ='Initiative Register'!C33 -> COMMUNITY HEALTH CAMPS — SCHOOLS, PLACES OF WORSHIP, RESIDENTIAL AREAS | D32: 0 | E32: 0 | F32: 0 | G32: 0 | H32: 0 | I32: 0 | J32: 0 | K32: 0 | L32: 0 | M32: 0 | N32: 0 | O32: 0 | P32: =SUM(D32:O32) -> 0
A33: 29 | B33: ='Initiative Register'!B34 -> INI-030 | C33: ='Initiative Register'!C34 -> DOCTOR ONLINE REPUTATION AND DIGITAL DISCOVERABILITY | D33: 0 | E33: 0 | F33: 0 | G33: 0 | H33: 0 | I33: 0 | J33: 0 | K33: 0 | L33: 0 | M33: 0 | N33: 0 | O33: 0 | P33: =SUM(D33:O33) -> 0
A34: 30 | B34: ='Initiative Register'!B35 -> INI-031 | C34: ='Initiative Register'!C35 -> TPA AND INSURER TARIFF RENEGOTIATION | D34: 0 | E34: 0 | F34: 0 | G34: 0 | H34: 0 | I34: 0 | J34: 0 | K34: 0 | L34: 0 | M34: 0 | N34: 0 | O34: 0 | P34: =SUM(D34:O34) -> 0
A35: 31 | B35: ='Initiative Register'!B36 -> INI-032 | C35: ='Initiative Register'!C36 -> FINANCIAL COUNSELLING AND PRE-AUTHORISATION AT SURGICAL OPD | D35: 0 | E35: 0 | F35: 0 | G35: 0 | H35: 0 | I35: 0 | J35: 0 | K35: 0 | L35: 0 | M35: 0 | N35: 0 | O35: 0 | P35: =SUM(D35:O35) -> 0
A36: 32 | B36: ='Initiative Register'!B37 -> INI-033 | C36: ='Initiative Register'!C37 -> BUILD A SCALED BD ORGANISATION | D36: 0 | E36: 0 | F36: 0 | G36: 0 | H36: 0 | I36: 0 | J36: 0 | K36: 0 | L36: 0 | M36: 0 | N36: 0 | O36: 0 | P36: =SUM(D36:O36) -> 0
A37: 33 | B37: ='Initiative Register'!B38 -> INI-034 | C37: ='Initiative Register'!C38 -> MATERIALS / DRUG COST & CONSUMABLES | D37: 0 | E37: 0 | F37: 0 | G37: 0 | H37: 0 | I37: 0 | J37: 0 | K37: 0 | L37: 0 | M37: 0 | N37: 0 | O37: 0 | P37: =SUM(D37:O37) -> 0
A38: 34 | B38: ='Initiative Register'!B39 -> INI-035 | C38: ='Initiative Register'!C39 -> MATERIALS / DRUG COST & CONSUMABLES | D38: 0 | E38: 0 | F38: 0 | G38: 0 | H38: 0 | I38: 0 | J38: 0 | K38: 0 | L38: 0 | M38: 0 | N38: 0 | O38: 0 | P38: =SUM(D38:O38) -> 0
A39: 35 | B39: ='Initiative Register'!B40 -> INI-036 | C39: ='Initiative Register'!C40 -> MATERIALS / DRUG COST & CONSUMABLES | D39: 0 | E39: 0 | F39: 0 | G39: 0 | H39: 0 | I39: 0 | J39: 0 | K39: 0 | L39: 0 | M39: 0 | N39: 0 | O39: 0 | P39: =SUM(D39:O39) -> 0
A40: 36 | B40: ='Initiative Register'!B41 -> INI-037 | C40: ='Initiative Register'!C41 -> MATERIALS / DRUG COST & CONSUMABLES | D40: 0 | E40: 0 | F40: 0 | G40: 0 | H40: 0 | I40: 0 | J40: 0 | K40: 0 | L40: 0 | M40: 0 | N40: 0 | O40: 0 | P40: =SUM(D40:O40) -> 0
A41: 37 | B41: ='Initiative Register'!B42 -> INI-038 | C41: ='Initiative Register'!C42 -> MATERIALS / DRUG COST & CONSUMABLES | D41: 0 | E41: 0 | F41: 0 | G41: 0 | H41: 0 | I41: 0 | J41: 0 | K41: 0 | L41: 0 | M41: 0 | N41: 0 | O41: 0 | P41: =SUM(D41:O41) -> 0
A42: 38 | B42: ='Initiative Register'!B43 -> INI-039 | C42: ='Initiative Register'!C43 -> MATERIALS / DRUG COST & CONSUMABLES | D42: 0 | E42: 0 | F42: 0 | G42: 0 | H42: 0 | I42: 0 | J42: 0 | K42: 0 | L42: 0 | M42: 0 | N42: 0 | O42: 0 | P42: =SUM(D42:O42) -> 0
... A54: 50 | B54: ='Initiative Register'!B55 -> INI-051 | C54: ='Initiative Register'!C55 -> OVERHEAD – REVENUE LEAKAGE RECOVERY | D54: 0 | E54: 0 | F54: 0 | G54: 0 | H54: 0 | I54: 0 | J54: 0 | K54: 0 | L54: 0 | M54: 0 | N54: 0 | O54: 0 | P54: =SUM(D54:O54) -> 0

Sheet Cost Plan
A1: COST PLAN — FY 2026-27 | Monthly Budgeted Cost per Initiative (Rs Lakhs)
A4: # | B4: Initiative ID | C4: Initiative Name | D4: Apr | E4: May | F4: Jun | G4: Jul | H4: Aug | I4: Sep | J4: Oct | K4: Nov | L4: Dec | M4: Jan | N4: Feb | O4: Mar | P4: Annual Total
A5: 1 | B5: ='Initiative Register'!B5 -> INI-001 | C5: ='Initiative Register'!C5 -> Campaign- Patient experience improvement | D5: 0 | E5: 0 | F5: 0 | G5: 0 | H5: 0 | I5: 0 | J5: 0 | K5: 0 | L5: 0 | M5: 0 | N5: 0 | O5: 0 | P5: =SUM(D5:O5) -> 0
A6: 2 | B6: ='Initiative Register'!B6 | C6: ='Initiative Register'!C6 -> 0 | D6: 0 | E6: 0 | F6: 0 | G6: 0 | H6: 0 | I6: 0 | J6: 0 | K6: 0 | L6: 0 | M6: 0 | N6: 0 | O6: 0 | P6: =SUM(D6:O6) -> 0
A7: 3 | B7: ='Initiative Register'!B7 -> INI-003 | C7: ='Initiative Register'!C7 -> Geriatric ward | D7: 0 | E7: 0 | F7: 0 | G7: 0 | H7: 0 | I7: 0 | J7: 0 | K7: 0 | L7: 0 | M7: 0 | N7: 0 | O7: 0 | P7: =SUM(D7:O7) -> 0
A8: 4 | B8: ='Initiative Register'!B8 -> INI-004 | C8: ='Initiative Register'!C8 -> Appointment of Specialized Doctors and development of existing department | D8: 0 | E8: 0 | F8: 0 | G8: 0 | H8: 0 | I8: 0 | J8: 0 | K8: 0 | L8: 0 | M8: 0 | N8: 0 | O8: 0 | P8: =SUM(D8:O8) -> 0
A9: 5 | B9: ='Initiative Register'!B9 -> INI-005 | C9: ='Initiative Register'!C9 -> Patient companion | D9: 0 | E9: 0 | F9: 0 | G9: 0 | H9: 0 | I9: 0 | J9: 0 | K9: 0 | L9: 0 | M9: 0 | N9: 0 | O9: 0 | P9: =SUM(D9:O9) -> 0
A10: 6 | B10: ='Initiative Register'!B10 -> INI-006 | C10: ='Initiative Register'!C10 -> Newborn Care Enhancement | D10: 0 | E10: 0 | F10: 0 | G10: 0 | H10: 0 | I10: 0 | J10: 0 | K10: 0 | L10: 0 | M10: 0 | N10: 0 | O10: 0 | P10: =SUM(D10:O10) -> 0
A11: 7 | B11: ='Initiative Register'!B11 -> INI-007 | C11: ='Initiative Register'!C11 -> Digital Patient Acquisition Funnel | D11: 0 | E11: 0 | F11: 0 | G11: 0 | H11: 0 | I11: 0 | J11: 0 | K11: 0 | L11: 0 | M11: 0 | N11: 0 | O11: 0 | P11: =SUM(D11:O11) -> 0
A12: 8 | B12: ='Initiative Register'!B12 -> INI-008 | C12: ='Initiative Register'!C12 -> Development of KPI for Doctors | D12: 0 | E12: 0 | F12: 0 | G12: 0 | H12: 0 | I12: 0 | J12: 0 | K12: 0 | L12: 0 | M12: 0 | N12: 0 | O12: 0 | P12: =SUM(D12:O12) -> 0
A13: 9 | B13: ='Initiative Register'!B13 -> INI-009 | C13: ='Initiative Register'!C13 -> Daycare and Minimaly Invasive Shift | D13: 0 | E13: 0 | F13: 0 | G13: 0 | H13: 0 | I13: 0 | J13: 0 | K13: 0 | L13: 0 | M13: 0 | N13: 0 | O13: 0 | P13: =SUM(D13:O13) -> 0
A14: 10 | B14: ='Initiative Register'!B14 -> INI-010 | C14: ='Initiative Register'!C14 -> Consumables standardization model | D14: 0 | E14: 0 | F14: 0 | G14: 0 | H14: 0 | I14: 0 | J14: 0 | K14: 0 | L14: 0 | M14: 0 | N14: 0 | O14: 0 | P14: =SUM(D14:O14) -> 0
A15: 11 | B15: ='Initiative Register'!B15 -> INI-011 | C15: ='Initiative Register'!C15 -> Collaboration with other Hospitals | D15: 0 | E15: 0 | F15: 0 | G15: 0 | H15: 0 | I15: 0 | J15: 0 | K15: 0 | L15: 0 | M15: 0 | N15: 0 | O15: 0 | P15: =SUM(D15:O15) -> 0
A16: 12 | B16: ='Initiative Register'!B16 -> INI-012 | C16: ='Initiative Register'!C16 -> ANNUAL RATE REVISION POLICY | D16: 0 | E16: 0 | F16: 0 | G16: 0 | H16: 0 | I16: 0 | J16: 0 | K16: 0 | L16: 0 | M16: 0 | N16: 0 | O16: 0 | P16: =SUM(D16:O16) -> 0
... A30: 26 | B30: ='Initiative Register'!B30 -> INI-026 | C30: ='Initiative Register'!C30 -> LAKESHORE HEART RUN — ANNUAL CARDIAC HEALTH EVENT | D30: 0 | E30: 0 | F30: 0 | G30: 0 | H30: 0 | I30: 0 | J30: 0 | K30: 0 | L30: 0 | M30: 0 | N30: 0 | O30: 0 | P30: =SUM(D30:O30) -> 0
A31: 27 | B31: ='Initiative Register'!B32 -> INI-028 | C31: ='Initiative Register'!C32 -> DIGITAL CONTENT PLATFORM — MALAYALAM AND ENGLISH | D31: 0 | E31: 0 | F31: 0 | G31: 0 | H31: 0 | I31: 0 | J31: 0 | K31: 0 | L31: 0 | M31: 0 | N31: 0 | O31: 0 | P31: =SUM(D31:O31) -> 0
A32: 28 | B32: ='Initiative Register'!B33 -> INI-029 | C32: ='Initiative Register'!C33 -> COMMUNITY HEALTH CAMPS — SCHOOLS, PLACES OF WORSHIP, RESIDENTIAL AREAS | D32: 0 | E32: 0 | F32: 0 | G32: 0 | H32: 0 | I32: 0 | J32: 0 | K32: 0 | L32: 0 | M32: 0 | N32: 0 | O32: 0 | P32: =SUM(D32:O32) -> 0
A33: 29 | B33: ='Initiative Register'!B34 -> INI-030 | C33: ='Initiative Register'!C34 -> DOCTOR ONLINE REPUTATION AND DIGITAL DISCOVERABILITY | D33: 0 | E33: 0 | F33: 0 | G33: 0 | H33: 0 | I33: 0 | J33: 0 | K33: 0 | L33: 0 | M33: 0 | N33: 0 | O33: 0 | P33: =SUM(D33:O33) -> 0
A34: 30 | B34: ='Initiative Register'!B35 -> INI-031 | C34: ='Initiative Register'!C35 -> TPA AND INSURER TARIFF RENEGOTIATION | D34: 0 | E34: 0 | F34: 0 | G34: 0 | H34: 0 | I34: 0 | J34: 0 | K34: 0 | L34: 0 | M34: 0 | N34: 0 | O34: 0 | P34: =SUM(D34:O34) -> 0
A35: 31 | B35: ='Initiative Register'!B36 -> INI-032 | C35: ='Initiative Register'!C36 -> FINANCIAL COUNSELLING AND PRE-AUTHORISATION AT SURGICAL OPD | D35: 0 | E35: 0 | F35: 0 | G35: 0 | H35: 0 | I35: 0 | J35: 0 | K35: 0 | L35: 0 | M35: 0 | N35: 0 | O35: 0 | P35: =SUM(D35:O35) -> 0
A36: 32 | B36: ='Initiative Register'!B37 -> INI-033 | C36: ='Initiative Register'!C37 -> BUILD A SCALED BD ORGANISATION | D36: 0 | E36: 0 | F36: 0 | G36: 0 | H36: 0 | I36: 0 | J36: 0 | K36: 0 | L36: 0 | M36: 0 | N36: 0 | O36: 0 | P36: =SUM(D36:O36) -> 0
A37: 33 | B37: ='Initiative Register'!B38 -> INI-034 | C37: ='Initiative Register'!C38 -> MATERIALS / DRUG COST & CONSUMABLES | D37: 0 | E37: 0 | F37: 0 | G37: 0 | H37: 0 | I37: 0 | J37: 0 | K37: 0 | L37: 0 | M37: 0 | N37: 0 | O37: 0 | P37: =SUM(D37:O37) -> 0
A38: 34 | B38: ='Initiative Register'!B39 -> INI-035 | C38: ='Initiative Register'!C39 -> MATERIALS / DRUG COST & CONSUMABLES | D38: 0 | E38: 0 | F38: 0 | G38: 0 | H38: 0 | I38: 0 | J38: 0 | K38: 0 | L38: 0 | M38: 0 | N38: 0 | O38: 0 | P38: =SUM(D38:O38) -> 0
A39: 35 | B39: ='Initiative Register'!B40 -> INI-036 | C39: ='Initiative Register'!C40 -> MATERIALS / DRUG COST & CONSUMABLES | D39: 0 | E39: 0 | F39: 0 | G39: 0 | H39: 0 | I39: 0 | J39: 0 | K39: 0 | L39: 0 | M39: 0 | N39: 0 | O39: 0 | P39: =SUM(D39:O39) -> 0
A40: 36 | B40: ='Initiative Register'!B41 -> INI-037 | C40: ='Initiative Register'!C41 -> MATERIALS / DRUG COST & CONSUMABLES | D40: 0 | E40: 0 | F40: 0 | G40: 0 | H40: 0 | I40: 0 | J40: 0 | K40: 0 | L40: 0 | M40: 0 | N40: 0 | O40: 0 | P40: =SUM(D40:O40) -> 0
A41: 37 | B41: ='Initiative Register'!B42 -> INI-038 | C41: ='Initiative Register'!C42 -> MATERIALS / DRUG COST & CONSUMABLES | D41: 0 | E41: 0 | F41: 0 | G41: 0 | H41: 0 | I41: 0 | J41: 0 | K41: 0 | L41: 0 | M41: 0 | N41: 0 | O41: 0 | P41: =SUM(D41:O41) -> 0
A42: 38 | B42: ='Initiative Register'!B43 -> INI-039 | C42: ='Initiative Register'!C43 -> MATERIALS / DRUG COST & CONSUMABLES | D42: 0 | E42: 0 | F42: 0 | G42: 0 | H42: 0 | I42: 0 | J42: 0 | K42: 0 | L42: 0 | M42: 0 | N42: 0 | O42: 0 | P42: =SUM(D42:O42) -> 0
... A54: 50 | B54: ='Initiative Register'!B55 -> INI-051 | C54: ='Initiative Register'!C55 -> OVERHEAD – REVENUE LEAKAGE RECOVERY | D54: 0 | E54: 0 | F54: 0 | G54: 0 | H54: 0 | I54: 0 | J54: 0 | K54: 0 | L54: 0 | M54: 0 | N54: 0 | O54: 0 | P54: =SUM(D54:O54) -> 0
A55: TOTAL | D55: =SUM(D5:D54) -> 0 | E55: =SUM(E5:E54) -> 0 | F55: =SUM(F5:F54) -> 0 | G55: =SUM(G5:G54) -> 0 | H55: =SUM(H5:H54) -> 0 | I55: =SUM(I5:I54) -> 0 | J55: =SUM(J5:J54) -> 0 | K55: =SUM(K5:K54) -> 0 | ... P55: =SUM(P5:P54) -> 0

Sheet Revenue Impact
A1: REVENUE IMPACT PLAN — FY 2026-27 | Expected Revenue Uplift per Initiative (Rs Lakhs)
A4: # | B4: Initiative ID | C4: Initiative Name | D4: Apr | E4: May | F4: Jun | G4: Jul | H4: Aug | I4: Sep | J4: Oct | K4: Nov | L4: Dec | M4: Jan | N4: Feb | O4: Mar | P4: Annual Total
A5: 1 | B5: ='Initiative Register'!B5 -> INI-001 | C5: ='Initiative Register'!C5 -> Campaign- Patient experience improvement | D5: 0 | E5: 0 | F5: 0 | G5: 0 | H5: 0 | I5: 0 | J5: 0 | K5: 0 | L5: 0 | M5: 0 | N5: 0 | O5: 0 | P5: =SUM(D5:O5) -> 0
A6: 2 | B6: ='Initiative Register'!B6 | C6: ='Initiative Register'!C6 -> 0 | D6: 0 | E6: 0 | F6: 0 | G6: 0 | H6: 0 | I6: 0 | J6: 0 | K6: 0 | L6: 0 | M6: 0 | N6: 0 | O6: 0 | P6: =SUM(D6:O6) -> 0
A7: 3 | B7: ='Initiative Register'!B7 -> INI-003 | C7: ='Initiative Register'!C7 -> Geriatric ward | D7: 0 | E7: 0 | F7: 0 | G7: 0 | H7: 0 | I7: 0 | J7: 0 | K7: 0 | L7: 0 | M7: 0 | N7: 0 | O7: 0 | P7: =SUM(D7:O7) -> 0
A8: 4 | B8: ='Initiative Register'!B8 -> INI-004 | C8: ='Initiative Register'!C8 -> Appointment of Specialized Doctors and development of existing department | D8: 0 | E8: 0 | F8: 0 | G8: 0 | H8: 0 | I8: 0 | J8: 0 | K8: 0 | L8: 0 | M8: 0 | N8: 0 | O8: 0 | P8: =SUM(D8:O8) -> 0
A9: 5 | B9: ='Initiative Register'!B9 -> INI-005 | C9: ='Initiative Register'!C9 -> Patient companion | D9: 0 | E9: 0 | F9: 0 | G9: 0 | H9: 0 | I9: 0 | J9: 0 | K9: 0 | L9: 0 | M9: 0 | N9: 0 | O9: 0 | P9: =SUM(D9:O9) -> 0
A10: 6 | B10: ='Initiative Register'!B10 -> INI-006 | C10: ='Initiative Register'!C10 -> Newborn Care Enhancement | D10: 0 | E10: 0 | F10: 0 | G10: 0 | H10: 0 | I10: 0 | J10: 0 | K10: 0 | L10: 0 | M10: 0 | N10: 0 | O10: 0 | P10: =SUM(D10:O10) -> 0
A11: 7 | B11: ='Initiative Register'!B11 -> INI-007 | C11: ='Initiative Register'!C11 -> Digital Patient Acquisition Funnel | D11: 0 | E11: 0 | F11: 0 | G11: 0 | H11: 0 | I11: 0 | J11: 0 | K11: 0 | L11: 0 | M11: 0 | N11: 0 | O11: 0 | P11: =SUM(D11:O11) -> 0
A12: 8 | B12: ='Initiative Register'!B12 -> INI-008 | C12: ='Initiative Register'!C12 -> Development of KPI for Doctors | D12: 0 | E12: 0 | F12: 0 | G12: 0 | H12: 0 | I12: 0 | J12: 0 | K12: 0 | L12: 0 | M12: 0 | N12: 0 | O12: 0 | P12: =SUM(D12:O12) -> 0
A13: 9 | B13: ='Initiative Register'!B13 -> INI-009 | C13: ='Initiative Register'!C13 -> Daycare and Minimaly Invasive Shift | D13: 0 | E13: 0 | F13: 0 | G13: 0 | H13: 0 | I13: 0 | J13: 0 | K13: 0 | L13: 0 | M13: 0 | N13: 0 | O13: 0 | P13: =SUM(D13:O13) -> 0
A14: 10 | B14: ='Initiative Register'!B14 -> INI-010 | C14: ='Initiative Register'!C14 -> Consumables standardization model | D14: 0 | E14: 0 | F14: 0 | G14: 0 | H14: 0 | I14: 0 | J14: 0 | K14: 0 | L14: 0 | M14: 0 | N14: 0 | O14: 0 | P14: =SUM(D14:O14) -> 0
A15: 11 | B15: ='Initiative Register'!B15 -> INI-011 | C15: ='Initiative Register'!C15 -> Collaboration with other Hospitals | D15: 0 | E15: 0 | F15: 0 | G15: 0 | H15: 0 | I15: 0 | J15: 0 | K15: 0 | L15: 0 | M15: 0 | N15: 0 | O15: 0 | P15: =SUM(D15:O15) -> 0
A16: 12 | B16: ='Initiative Register'!B16 -> INI-012 | C16: ='Initiative Register'!C16 -> ANNUAL RATE REVISION POLICY | D16: 0 | E16: 0 | F16: 0 | G16: 0 | H16: 0 | I16: 0 | J16: 0 | K16: 0 | L16: 0 | M16: 0 | N16: 0 | O16: 0 | P16: =SUM(D16:O16) -> 0
... A70: 66 | B70: ='Initiative Register'!B70 -> 0 | C70: ='Initiative Register'!C70 -> 0 | D70: 0 | E70: 0 | F70: 0 | G70: 0 | H70: 0 | I70: 0 | J70: 0 | K70: 0 | L70: 0 | M70: 0 | N70: 0 | O70: 0 | P70: =SUM(D70:O70) -> 0
A71: TOTAL | D71: =SUM(D5:D55) -> 0 | E71: =SUM(E5:E55) -> 0 | F71: =SUM(F5:F55) -> 0 | G71: =SUM(G5:G55) -> 0 | H71: =SUM(H5:H55) -> 0 | I71: =SUM(I5:I55) -> 0 | J71: =SUM(J5:J55) -> 0 | K71: =SUM(K5:K55) -> 0 | ... P71: =SUM(P5:P55) -> 0

Sheet Monthly Actuals
A1: MONTHLY ACTUALS — FY 2026-27 | Enter after each month close (Rs Lakhs)
A2: Section A = Actual Revenue Realised | Section B = Actual Cost Incurred
A3: SECTION A — ACTUAL REVENUE REALISED
A4: # | B4: Initiative ID | C4: Initiative Name | D4: Apr | E4: May | F4: Jun | G4: Jul | H4: Aug | I4: Sep | J4: Oct | K4: Nov | L4: Dec | M4: Jan | N4: Feb | O4: Mar | P4: YTD Total
A5: 1 | B5: ='Initiative Register'!B5 -> INI-001 | C5: ='Initiative Register'!C5 -> Campaign- Patient experience improvement | D5: 0 | E5: 0 | F5: 0 | G5: 0 | H5: 0 | I5: 0 | J5: 0 | K5: 0 | L5: 0 | M5: 0 | N5: 0 | O5: 0 | P5: =SUM(D5:O5) -> 0
A6: 2 | B6: ='Initiative Register'!B6 | C6: ='Initiative Register'!C6 -> 0 | D6: 0 | E6: 0 | F6: 0 | G6: 0 | H6: 0 | I6: 0 | J6: 0 | K6: 0 | L6: 0 | M6: 0 | N6: 0 | O6: 0 | P6: =SUM(D6:O6) -> 0
A7: 3 | B7: ='Initiative Register'!B7 -> INI-003 | C7: ='Initiative Register'!C7 -> Geriatric ward | D7: 0 | E7: 0 | F7: 0 | G7: 0 | H7: 0 | I7: 0 | J7: 0 | K7: 0 | L7: 0 | M7: 0 | N7: 0 | O7: 0 | P7: =SUM(D7:O7) -> 0
A8: 4 | B8: ='Initiative Register'!B8 -> INI-004 | C8: ='Initiative Register'!C8 -> Appointment of Specialized Doctors and development of existing department | D8: 0 | E8: 0 | F8: 0 | G8: 0 | H8: 0 | I8: 0 | J8: 0 | K8: 0 | L8: 0 | M8: 0 | N8: 0 | O8: 0 | P8: =SUM(D8:O8) -> 0
A9: 5 | B9: ='Initiative Register'!B9 -> INI-005 | C9: ='Initiative Register'!C9 -> Patient companion | D9: 0 | E9: 0 | F9: 0 | G9: 0 | H9: 0 | I9: 0 | J9: 0 | K9: 0 | L9: 0 | M9: 0 | N9: 0 | O9: 0 | P9: =SUM(D9:O9) -> 0
A10: 6 | B10: ='Initiative Register'!B10 -> INI-006 | C10: ='Initiative Register'!C10 -> Newborn Care Enhancement | D10: 0 | E10: 0 | F10: 0 | G10: 0 | H10: 0 | I10: 0 | J10: 0 | K10: 0 | L10: 0 | M10: 0 | N10: 0 | O10: 0 | P10: =SUM(D10:O10) -> 0
A11: 7 | B11: ='Initiative Register'!B11 -> INI-007 | C11: ='Initiative Register'!C11 -> Digital Patient Acquisition Funnel | D11: 0 | E11: 0 | F11: 0 | G11: 0 | H11: 0 | I11: 0 | J11: 0 | K11: 0 | L11: 0 | M11: 0 | N11: 0 | O11: 0 | P11: =SUM(D11:O11) -> 0
A12: 8 | B12: ='Initiative Register'!B12 -> INI-008 | C12: ='Initiative Register'!C12 -> Development of KPI for Doctors | D12: 0 | E12: 0 | F12: 0 | G12: 0 | H12: 0 | I12: 0 | J12: 0 | K12: 0 | L12: 0 | M12: 0 | N12: 0 | O12: 0 | P12: =SUM(D12:O12) -> 0
A13: 9 | B13: ='Initiative Register'!B13 -> INI-009 | C13: ='Initiative Register'!C13 -> Daycare and Minimaly Invasive Shift | D13: 0 | E13: 0 | F13: 0 | G13: 0 | H13: 0 | I13: 0 | J13: 0 | K13: 0 | L13: 0 | M13: 0 | N13: 0 | O13: 0 | P13: =SUM(D13:O13) -> 0
A14: 10 | B14: ='Initiative Register'!B14 -> INI-010 | C14: ='Initiative Register'!C14 -> Consumables standardization model | D14: 0 | E14: 0 | F14: 0 | G14: 0 | H14: 0 | I14: 0 | J14: 0 | K14: 0 | L14: 0 | M14: 0 | N14: 0 | O14: 0 | P14: =SUM(D14:O14) -> 0
A15: 11 | B15: ='Initiative Register'!B15 -> INI-011 | C15: ='Initiative Register'!C15 -> Collaboration with other Hospitals | D15: 0 | E15: 0 | F15: 0 | G15: 0 | H15: 0 | I15: 0 | J15: 0 | K15: 0 | L15: 0 | M15: 0 | N15: 0 | O15: 0 | P15: =SUM(D15:O15) -> 0
A16: 12 | B16: ='Initiative Register'!B16 -> INI-012 | C16: ='Initiative Register'!C16 -> ANNUAL RATE REVISION POLICY | D16: 0 | E16: 0 | F16: 0 | G16: 0 | H16: 0 | I16: 0 | J16: 0 | K16: 0 | L16: 0 | M16: 0 | N16: 0 | O16: 0 | P16: =SUM(D16:O16) -> 0
... A72: 68 | B72: ='Initiative Register'!B72 -> 0 | C72: ='Initiative Register'!C72 -> 0 | D72: 0 | E72: 0 | F72: 0 | G72: 0 | H72: 0 | I72: 0 | J72: 0 | K72: 0 | L72: 0 | M72: 0 | N72: 0 | O72: 0 | P72: =SUM(D72:O72) -> 0
A73: TOTAL | D73: =SUM(D5:D54) -> 0 | E73: =SUM(E5:E54) -> 0 | F73: =SUM(F5:F54) -> 0 | G73: =SUM(G5:G54) -> 0 | H73: =SUM(H5:H54) -> 0 | I73: =SUM(I5:I54) -> 0 | J73: =SUM(J5:J54) -> 0 | K73: =SUM(K5:K54) -> 0 | ... P73: =SUM(P5:P54) -> 0
A75: SECTION B — ACTUAL COST INCURRED
A76: # | B76: Initiative ID | C76: Initiative Name | D76: Apr | E76: May | F76: Jun | G76: Jul | H76: Aug | I76: Sep | J76: Oct | K76: Nov | L76: Dec | M76: Jan | N76: Feb | O76: Mar | P76: YTD Total
A77: 1 | B77: ='Initiative Register'!B5 -> INI-001 | C77: ='Initiative Register'!C5 -> Campaign- Patient experience improvement | D77: 0 | E77: 0 | F77: 0 | G77: 0 | H77: 0 | I77: 0 | J77: 0 | K77: 0 | L77: 0 | M77: 0 | N77: 0 | O77: 0 | P77: =SUM(D77:O77) -> 0
A78: 2 | B78: ='Initiative Register'!B6 | C78: ='Initiative Register'!C6 -> 0 | D78: 0 | E78: 0 | F78: 0 | G78: 0 | H78: 0 | I78: 0 | J78: 0 | K78: 0 | L78: 0 | M78: 0 | N78: 0 | O78: 0 | P78: =SUM(D78:O78) -> 0
A79: 3 | B79: ='Initiative Register'!B7 -> INI-003 | C79: ='Initiative Register'!C7 -> Geriatric ward | D79: 0 | E79: 0 | F79: 0 | G79: 0 | H79: 0 | I79: 0 | J79: 0 | K79: 0 | L79: 0 | M79: 0 | N79: 0 | O79: 0 | P79: =SUM(D79:O79) -> 0
A80: 4 | B80: ='Initiative Register'!B8 -> INI-004 | C80: ='Initiative Register'!C8 -> Appointment of Specialized Doctors and development of existing department | D80: 0 | E80: 0 | F80: 0 | G80: 0 | H80: 0 | I80: 0 | J80: 0 | K80: 0 | L80: 0 | M80: 0 | N80: 0 | O80: 0 | P80: =SUM(D80:O80) -> 0
A81: 5 | B81: ='Initiative Register'!B9 -> INI-005 | C81: ='Initiative Register'!C9 -> Patient companion | D81: 0 | E81: 0 | F81: 0 | G81: 0 | H81: 0 | I81: 0 | J81: 0 | K81: 0 | L81: 0 | M81: 0 | N81: 0 | O81: 0 | P81: =SUM(D81:O81) -> 0
